Workbook

Sheet Specified Annual Demand
B1: >2018-2021 based on JRC-IDEES 2021
B2: >2022-2050 projections based on final energy demand from EU Reference Scenario 2020
H3: 3 | I3: 4 | J3: 5 | K3: 6 | L3: 7 | M3: 8 | N3: 9 | O3: 10 | P3: 11 | Q3: 12 | R3: 13 | S3: 14 | T3: 15 | U3: 16 | V3: 17 | W3: 18 | X3: 19 | Y3: 20 | Z3: 21 | AA3: 22 | AB3: 23 | AC3: 24 | AD3: 25 | AE3: 26 | AF3: 27 | AG3: 28 | AH3: 29 | AI3: 30 | AJ3: 31
A4: Energy service | B4: Country | C4: FUEL | D4: 2018 | E4: 2019 | F4: 2020 | G4: 2021 | H4: 2022 | I4: 2023 | J4: 2024 | K4: 2025 | L4: 2026 | M4: 2027 | N4: 2028 | O4: 2029 | P4: 2030 | Q4: 2031 | R4: 2032 | S4: 2033 | T4: 2034 | U4: 2035 | V4: 2036 | W4: 2037 | X4: 2038 | Y4: 2039 | Z4: 2040 | AA4: 2041 | AB4: 2042 | AC4: 2043 | AD4: 2044 | AE4: 2045 | AF4: 2046 | AG4: 2047 | AH4: 2048 | AI4: 2049 | AJ4: 2050 | AK4: 2051 | AL4: 2052 | AM4: 2053 | AN4: 2054 | AO4: 2055
A5: Space heating & Hot Water | B5: =LEFT(C5,2) -> AT | C5: ATEUHT | D5: 237.62946 | E5: 247.30446 | F5: 255.23032 | G5: 287.38468 | H5: =G5*VLOOKUP($B5,'EU Ref Scenario 2020'!$A$126:$AE$153,'Specified Annual Demand'!H$3,FALSE) -> 285.15519 | I5: =H5*VLOOKUP($B5,'EU Ref Scenario 2020'!$A$126:$AE$153,'Specified Annual Demand'!I$3,FALSE) -> 282.9257 | J5: =I5*VLOOKUP($B5,'EU Ref Scenario 2020'!$A$126:$AE$153,'Specified Annual Demand'!J$3,FALSE) -> 280.69621 | K5: =J5*VLOOKUP($B5,'EU Ref Scenario 2020'!$A$126:$AE$153,'Specified Annual Demand'!K$3,FALSE) -> 278.46672 | L5: =K5*VLOOKUP($B5,'EU Ref Scenario 2020'!$A$126:$AE$153,'Specified Annual Demand'!L$3,FALSE) -> 276.24832 | M5: =L5*VLOOKUP($B5,'EU Ref Scenario 2020'!$A$126:$AE$153,'Specified Annual Demand'!M$3,FALSE) -> 274.02992 | N5: =M5*VLOOKUP($B5,'EU Ref Scenario 2020'!$A$126:$AE$153,'Specified Annual Demand'!N$3,FALSE) -> 271.81152 | O5: =N5*VLOOKUP($B5,'EU Ref Scenario 2020'!$A$126:$AE$153,'Specified Annual Demand'!O$3,FALSE) -> 269.59311 | ... AJ5: =AI5*VLOOKUP($B5,'EU Ref Scenario 2020'!$A$126:$AE$153,'Specified Annual Demand'!AJ$3,FALSE) -> 267.46987 | AK5: =AJ5 -> 267.46987 | AL5: =AK5 -> 267.46987 | AM5: =AL5 -> 267.46987 | AN5: =AM5 -> 267.46987 | AO5: =AN5 -> 267.46987
A6: Space cooling | B6: =LEFT(C6,2) -> AT | C6: ATEUCL | D6: 3.3029913 | E6: 3.4885905 | F6: 3.2809862 | G6: 3.4405496 | H6: =G6*VLOOKUP($B6,'EU Ref Scenario 2020'!$A$126:$AE$153,'Specified Annual Demand'!H$3,FALSE) -> 3.4138583 | I6: =H6*VLOOKUP($B6,'EU Ref Scenario 2020'!$A$126:$AE$153,'Specified Annual Demand'!I$3,FALSE) -> 3.387167 | J6: =I6*VLOOKUP($B6,'EU Ref Scenario 2020'!$A$126:$AE$153,'Specified Annual Demand'!J$3,FALSE) -> 3.3604757 | K6: =J6*VLOOKUP($B6,'EU Ref Scenario 2020'!$A$126:$AE$153,'Specified Annual Demand'!K$3,FALSE) -> 3.3337844 | L6: =K6*VLOOKUP($B6,'EU Ref Scenario 2020'!$A$126:$AE$153,'Specified Annual Demand'!L$3,FALSE) -> 3.3072258 | M6: =L6*VLOOKUP($B6,'EU Ref Scenario 2020'!$A$126:$AE$153,'Specified Annual Demand'!M$3,FALSE) -> 3.2806673 | N6: =M6*VLOOKUP($B6,'EU Ref Scenario 2020'!$A$126:$AE$153,'Specified Annual Demand'!N$3,FALSE) -> 3.2541087 | O6: =N6*VLOOKUP($B6,'EU Ref Scenario 2020'!$A$126:$AE$153,'Specified Annual Demand'!O$3,FALSE) -> 3.2275502 | ... AJ6: =AI6*VLOOKUP($B6,'EU Ref Scenario 2020'!$A$126:$AE$153,'Specified Annual Demand'!AJ$3,FALSE) -> 3.2021309 | AK6: =AJ6 -> 3.2021309 | AL6: =AK6 -> 3.2021309 | AM6: =AL6 -> 3.2021309 | AN6: =AM6 -> 3.2021309 | AO6: =AN6 -> 3.2021309
A7: Cooking | B7: =LEFT(C7,2) -> AT | C7: ATEUCK | D7: 13.727706 | E7: 13.97641 | F7: 13.684323 | G7: 14.865887 | H7: =G7*VLOOKUP($B7,'EU Ref Scenario 2020'!$A$126:$AE$153,'Specified Annual Demand'!H$3,FALSE) -> 14.750559 | I7: =H7*VLOOKUP($B7,'EU Ref Scenario 2020'!$A$126:$AE$153,'Specified Annual Demand'!I$3,FALSE) -> 14.635232 | J7: =I7*VLOOKUP($B7,'EU Ref Scenario 2020'!$A$126:$AE$153,'Specified Annual Demand'!J$3,FALSE) -> 14.519904 | K7: =J7*VLOOKUP($B7,'EU Ref Scenario 2020'!$A$126:$AE$153,'Specified Annual Demand'!K$3,FALSE) -> 14.404577 | L7: =K7*VLOOKUP($B7,'EU Ref Scenario 2020'!$A$126:$AE$153,'Specified Annual Demand'!L$3,FALSE) -> 14.289823 | M7: =L7*VLOOKUP($B7,'EU Ref Scenario 2020'!$A$126:$AE$153,'Specified Annual Demand'!M$3,FALSE) -> 14.175069 | N7: =M7*VLOOKUP($B7,'EU Ref Scenario 2020'!$A$126:$AE$153,'Specified Annual Demand'!N$3,FALSE) -> 14.060315 | O7: =N7*VLOOKUP($B7,'EU Ref Scenario 2020'!$A$126:$AE$153,'Specified Annual Demand'!O$3,FALSE) -> 13.945561 | ... AJ7: =AI7*VLOOKUP($B7,'EU Ref Scenario 2020'!$A$126:$AE$153,'Specified Annual Demand'!AJ$3,FALSE) -> 13.83573 | AK7: =AJ7 -> 13.83573 | AL7: =AK7 -> 13.83573 | AM7: =AL7 -> 13.83573 | AN7: =AM7 -> 13.83573 | AO7: =AN7 -> 13.83573
A8: Useful energy for appliances | B8: =LEFT(C8,2) -> AT | C8: ATEUSE | D8: 60.058046 | E8: 60.275847 | F8: 57.603763 | G8: 61.114931 | H8: =G8*VLOOKUP($B8,'EU Ref Scenario 2020'!$A$126:$AE$153,'Specified Annual Demand'!H$3,FALSE) -> 60.64081 | I8: =H8*VLOOKUP($B8,'EU Ref Scenario 2020'!$A$126:$AE$153,'Specified Annual Demand'!I$3,FALSE) -> 60.166689 | J8: =I8*VLOOKUP($B8,'EU Ref Scenario 2020'!$A$126:$AE$153,'Specified Annual Demand'!J$3,FALSE) -> 59.692568 | K8: =J8*VLOOKUP($B8,'EU Ref Scenario 2020'!$A$126:$AE$153,'Specified Annual Demand'!K$3,FALSE) -> 59.218447 | L8: =K8*VLOOKUP($B8,'EU Ref Scenario 2020'!$A$126:$AE$153,'Specified Annual Demand'!L$3,FALSE) -> 58.746684 | M8: =L8*VLOOKUP($B8,'EU Ref Scenario 2020'!$A$126:$AE$153,'Specified Annual Demand'!M$3,FALSE) -> 58.274921 | N8: =M8*VLOOKUP($B8,'EU Ref Scenario 2020'!$A$126:$AE$153,'Specified Annual Demand'!N$3,FALSE) -> 57.803158 | O8: =N8*VLOOKUP($B8,'EU Ref Scenario 2020'!$A$126:$AE$153,'Specified Annual Demand'!O$3,FALSE) -> 57.331395 | ... AJ8: =AI8*VLOOKUP($B8,'EU Ref Scenario 2020'!$A$126:$AE$153,'Specified Annual Demand'!AJ$3,FALSE) -> 56.879869 | AK8: =AJ8 -> 56.879869 | AL8: =AK8 -> 56.879869 | AM8: =AL8 -> 56.879869 | AN8: =AM8 -> 56.879869 | AO8: =AN8 -> 56.879869
A9: Space heating & Hot Water | B9: =LEFT(C9,2) -> BE | C9: BEEUHT | D9: 292.75854 | E9: 293.20673 | F9: 292.03074 | G9: 325.076 | H9: =G9*VLOOKUP($B9,'EU Ref Scenario 2020'!$A$126:$AE$153,'Specified Annual Demand'!H$3,FALSE) -> 325.69977 | I9: =H9*VLOOKUP($B9,'EU Ref Scenario 2020'!$A$126:$AE$153,'Specified Annual Demand'!I$3,FALSE) -> 326.32354 | J9: =I9*VLOOKUP($B9,'EU Ref Scenario 2020'!$A$126:$AE$153,'Specified Annual Demand'!J$3,FALSE) -> 326.94732 | K9: =J9*VLOOKUP($B9,'EU Ref Scenario 2020'!$A$126:$AE$153,'Specified Annual Demand'!K$3,FALSE) -> 327.57109 | L9: =K9*VLOOKUP($B9,'EU Ref Scenario 2020'!$A$126:$AE$153,'Specified Annual Demand'!L$3,FALSE) -> 323.36643 | M9: =L9*VLOOKUP($B9,'EU Ref Scenario 2020'!$A$126:$AE$153,'Specified Annual Demand'!M$3,FALSE) -> 319.16176 | N9: =M9*VLOOKUP($B9,'EU Ref Scenario 2020'!$A$126:$AE$153,'Specified Annual Demand'!N$3,FALSE) -> 314.9571 | O9: =N9*VLOOKUP($B9,'EU Ref Scenario 2020'!$A$126:$AE$153,'Specified Annual Demand'!O$3,FALSE) -> 310.75244 | ... AJ9: =AI9*VLOOKUP($B9,'EU Ref Scenario 2020'!$A$126:$AE$153,'Specified Annual Demand'!AJ$3,FALSE) -> 292.4635 | AK9: =AJ9 -> 292.4635 | AL9: =AK9 -> 292.4635 | AM9: =AL9 -> 292.4635 | AN9: =AM9 -> 292.4635 | AO9: =AN9 -> 292.4635
A10: Space cooling | B10: =LEFT(C10,2) -> BE | C10: BEEUCL | D10: 14.182777 | E10: 13.962667 | F10: 15.676903 | G10: 13.40622 | H10: =G10*VLOOKUP($B10,'EU Ref Scenario 2020'!$A$126:$AE$153,'Specified Annual Demand'!H$3,FALSE) -> 13.431944 | I10: =H10*VLOOKUP($B10,'EU Ref Scenario 2020'!$A$126:$AE$153,'Specified Annual Demand'!I$3,FALSE) -> 13.457669 | J10: =I10*VLOOKUP($B10,'EU Ref Scenario 2020'!$A$126:$AE$153,'Specified Annual Demand'!J$3,FALSE) -> 13.483394 | K10: =J10*VLOOKUP($B10,'EU Ref Scenario 2020'!$A$126:$AE$153,'Specified Annual Demand'!K$3,FALSE) -> 13.509118 | L10: =K10*VLOOKUP($B10,'EU Ref Scenario 2020'!$A$126:$AE$153,'Specified Annual Demand'!L$3,FALSE) -> 13.335717 | M10: =L10*VLOOKUP($B10,'EU Ref Scenario 2020'!$A$126:$AE$153,'Specified Annual Demand'!M$3,FALSE) -> 13.162315 | N10: =M10*VLOOKUP($B10,'EU Ref Scenario 2020'!$A$126:$AE$153,'Specified Annual Demand'!N$3,FALSE) -> 12.988914 | O10: =N10*VLOOKUP($B10,'EU Ref Scenario 2020'!$A$126:$AE$153,'Specified Annual Demand'!O$3,FALSE) -> 12.815512 | ... AJ10: =AI10*VLOOKUP($B10,'EU Ref Scenario 2020'!$A$126:$AE$153,'Specified Annual Demand'!AJ$3,FALSE) -> 12.061272 | AK10: =AJ10 -> 12.061272 | AL10: =AK10 -> 12.061272 | AM10: =AL10 -> 12.061272 | AN10: =AM10 -> 12.061272 | AO10: =AN10 -> 12.061272
A11: Cooking | B11: =LEFT(C11,2) -> BE | C11: BEEUCK | D11: 14.14823 | E11: 14.169729 | F11: 14.155313 | G11: 14.772392 | H11: =G11*VLOOKUP($B11,'EU Ref Scenario 2020'!$A$126:$AE$153,'Specified Annual Demand'!H$3,FALSE) -> 14.800738 | I11: =H11*VLOOKUP($B11,'EU Ref Scenario 2020'!$A$126:$AE$153,'Specified Annual Demand'!I$3,FALSE) -> 14.829084 | J11: =I11*VLOOKUP($B11,'EU Ref Scenario 2020'!$A$126:$AE$153,'Specified Annual Demand'!J$3,FALSE) -> 14.85743 | K11: =J11*VLOOKUP($B11,'EU Ref Scenario 2020'!$A$126:$AE$153,'Specified Annual Demand'!K$3,FALSE) -> 14.885776 | L11: =K11*VLOOKUP($B11,'EU Ref Scenario 2020'!$A$126:$AE$153,'Specified Annual Demand'!L$3,FALSE) -> 14.694704 | M11: =L11*VLOOKUP($B11,'EU Ref Scenario 2020'!$A$126:$AE$153,'Specified Annual Demand'!M$3,FALSE) -> 14.503632 | N11: =M11*VLOOKUP($B11,'EU Ref Scenario 2020'!$A$126:$AE$153,'Specified Annual Demand'!N$3,FALSE) -> 14.31256 | O11: =N11*VLOOKUP($B11,'EU Ref Scenario 2020'!$A$126:$AE$153,'Specified Annual Demand'!O$3,FALSE) -> 14.121488 | ... AJ11: =AI11*VLOOKUP($B11,'EU Ref Scenario 2020'!$A$126:$AE$153,'Specified Annual Demand'!AJ$3,FALSE) -> 13.290386 | AK11: =AJ11 -> 13.290386 | AL11: =AK11 -> 13.290386 | AM11: =AL11 -> 13.290386 | AN11: =AM11 -> 13.290386 | AO11: =AN11 -> 13.290386
A12: Useful energy for appliances | B12: =LEFT(C12,2) -> BE | C12: BEEUSE | D12: 96.412116 | E12: 93.67516 | F12: 92.448955 | G12: 91.730312 | H12: =G12*VLOOKUP($B12,'EU Ref Scenario 2020'!$A$126:$AE$153,'Specified Annual Demand'!H$3,FALSE) -> 91.906329 | I12: =H12*VLOOKUP($B12,'EU Ref Scenario 2020'!$A$126:$AE$153,'Specified Annual Demand'!I$3,FALSE) -> 92.082346 | J12: =I12*VLOOKUP($B12,'EU Ref Scenario 2020'!$A$126:$AE$153,'Specified Annual Demand'!J$3,FALSE) -> 92.258363 | K12: =J12*VLOOKUP($B12,'EU Ref Scenario 2020'!$A$126:$AE$153,'Specified Annual Demand'!K$3,FALSE) -> 92.43438 | L12: =K12*VLOOKUP($B12,'EU Ref Scenario 2020'!$A$126:$AE$153,'Specified Annual Demand'!L$3,FALSE) -> 91.247904 | M12: =L12*VLOOKUP($B12,'EU Ref Scenario 2020'!$A$126:$AE$153,'Specified Annual Demand'!M$3,FALSE) -> 90.061427 | N12: =M12*VLOOKUP($B12,'EU Ref Scenario 2020'!$A$126:$AE$153,'Specified Annual Demand'!N$3,FALSE) -> 88.87495 | O12: =N12*VLOOKUP($B12,'EU Ref Scenario 2020'!$A$126:$AE$153,'Specified Annual Demand'!O$3,FALSE) -> 87.688473 | ... AJ12: =AI12*VLOOKUP($B12,'EU Ref Scenario 2020'!$A$126:$AE$153,'Specified Annual Demand'!AJ$3,FALSE) -> 82.527682 | AK12: =AJ12 -> 82.527682 | AL12: =AK12 -> 82.527682 | AM12: =AL12 -> 82.527682 | AN12: =AM12 -> 82.527682 | AO12: =AN12 -> 82.527682
A13: Space heating & Hot Water | B13: =LEFT(C13,2) -> BG | C13: BGEUHT | D13: 63.129233 | E13: 63.541148 | F13: 65.920796 | G13: 71.918656 | H13: =G13*VLOOKUP($B13,'EU Ref Scenario 2020'!$A$126:$AE$153,'Specified Annual Demand'!H$3,FALSE) -> 73.163249 | I13: =H13*VLOOKUP($B13,'EU Ref Scenario 2020'!$A$126:$AE$153,'Specified Annual Demand'!I$3,FALSE) -> 74.407843 | J13: =I13*VLOOKUP($B13,'EU Ref Scenario 2020'!$A$126:$AE$153,'Specified Annual Demand'!J$3,FALSE) -> 75.652437 | K13: =J13*VLOOKUP($B13,'EU Ref Scenario 2020'!$A$126:$AE$153,'Specified Annual Demand'!K$3,FALSE) -> 76.89703 | L13: =K13*VLOOKUP($B13,'EU Ref Scenario 2020'!$A$126:$AE$153,'Specified Annual Demand'!L$3,FALSE) -> 76.770026 | M13: =L13*VLOOKUP($B13,'EU Ref Scenario 2020'!$A$126:$AE$153,'Specified Annual Demand'!M$3,FALSE) -> 76.643021 | N13: =M13*VLOOKUP($B13,'EU Ref Scenario 2020'!$A$126:$AE$153,'Specified Annual Demand'!N$3,FALSE) -> 76.516017 | O13: =N13*VLOOKUP($B13,'EU Ref Scenario 2020'!$A$126:$AE$153,'Specified Annual Demand'!O$3,FALSE) -> 76.389012 | ... AJ13: =AI13*VLOOKUP($B13,'EU Ref Scenario 2020'!$A$126:$AE$153,'Specified Annual Demand'!AJ$3,FALSE) -> 75.038691 | AK13: =AJ13 -> 75.038691 | AL13: =AK13 -> 75.038691 | AM13: =AL13 -> 75.038691 | AN13: =AM13 -> 75.038691 | AO13: =AN13 -> 75.038691
A14: Space cooling | B14: =LEFT(C14,2) -> BG | C14: BGEUCL | D14: 3.5647225 | E14: 3.995856 | F14: 4.0498065 | G14: 5.2150729 | H14: =G14*VLOOKUP($B14,'EU Ref Scenario 2020'!$A$126:$AE$153,'Specified Annual Demand'!H$3,FALSE) -> 5.3053228 | I14: =H14*VLOOKUP($B14,'EU Ref Scenario 2020'!$A$126:$AE$153,'Specified Annual Demand'!I$3,FALSE) -> 5.3955726 | J14: =I14*VLOOKUP($B14,'EU Ref Scenario 2020'!$A$126:$AE$153,'Specified Annual Demand'!J$3,FALSE) -> 5.4858224 | K14: =J14*VLOOKUP($B14,'EU Ref Scenario 2020'!$A$126:$AE$153,'Specified Annual Demand'!K$3,FALSE) -> 5.5760723 | L14: =K14*VLOOKUP($B14,'EU Ref Scenario 2020'!$A$126:$AE$153,'Specified Annual Demand'!L$3,FALSE) -> 5.5668627 | M14: =L14*VLOOKUP($B14,'EU Ref Scenario 2020'!$A$126:$AE$153,'Specified Annual Demand'!M$3,FALSE) -> 5.5576532 | N14: =M14*VLOOKUP($B14,'EU Ref Scenario 2020'!$A$126:$AE$153,'Specified Annual Demand'!N$3,FALSE) -> 5.5484436 | O14: =N14*VLOOKUP($B14,'EU Ref Scenario 2020'!$A$126:$AE$153,'Specified Annual Demand'!O$3,FALSE) -> 5.5392341 | ... AJ14: =AI14*VLOOKUP($B14,'EU Ref Scenario 2020'!$A$126:$AE$153,'Specified Annual Demand'!AJ$3,FALSE) -> 5.4413176 | AK14: =AJ14 -> 5.4413176 | AL14: =AK14 -> 5.4413176 | AM14: =AL14 -> 5.4413176 | AN14: =AM14 -> 5.4413176 | AO14: =AN14 -> 5.4413176
A15: Cooking | B15: =LEFT(C15,2) -> BG | C15: BGEUCK | D15: 9.5462196 | E15: 9.5376599 | F15: 9.3595799 | G15: 10.178402 | H15: =G15*VLOOKUP($B15,'EU Ref Scenario 2020'!$A$126:$AE$153,'Specified Annual Demand'!H$3,FALSE) -> 10.354545 | I15: =H15*VLOOKUP($B15,'EU Ref Scenario 2020'!$A$126:$AE$153,'Specified Annual Demand'!I$3,FALSE) -> 10.530688 | J15: =I15*VLOOKUP($B15,'EU Ref Scenario 2020'!$A$126:$AE$153,'Specified Annual Demand'!J$3,FALSE) -> 10.706831 | K15: =J15*VLOOKUP($B15,'EU Ref Scenario 2020'!$A$126:$AE$153,'Specified Annual Demand'!K$3,FALSE) -> 10.882974 | L15: =K15*VLOOKUP($B15,'EU Ref Scenario 2020'!$A$126:$AE$153,'Specified Annual Demand'!L$3,FALSE) -> 10.865 | M15: =L15*VLOOKUP($B15,'EU Ref Scenario 2020'!$A$126:$AE$153,'Specified Annual Demand'!M$3,FALSE) -> 10.847025 | N15: =M15*VLOOKUP($B15,'EU Ref Scenario 2020'!$A$126:$AE$153,'Specified Annual Demand'!N$3,FALSE) -> 10.829051 | O15: =N15*VLOOKUP($B15,'EU Ref Scenario 2020'!$A$126:$AE$153,'Specified Annual Demand'!O$3,FALSE) -> 10.811076 | ... AJ15: =AI15*VLOOKUP($B15,'EU Ref Scenario 2020'!$A$126:$AE$153,'Specified Annual Demand'!AJ$3,FALSE) -> 10.61997 | AK15: =AJ15 -> 10.61997 | AL15: =AK15 -> 10.61997 | AM15: =AL15 -> 10.61997 | AN15: =AM15 -> 10.61997 | AO15: =AN15 -> 10.61997
A16: Useful energy for appliances | B16: =LEFT(C16,2) -> BG | C16: BGEUSE | D16: 35.450777 | E16: 34.803344 | F16: 33.306491 | G16: 35.688404 | H16: =G16*VLOOKUP($B16,'EU Ref Scenario 2020'!$A$126:$AE$153,'Specified Annual Demand'!H$3,FALSE) -> 36.306012 | I16: =H16*VLOOKUP($B16,'EU Ref Scenario 2020'!$A$126:$AE$153,'Specified Annual Demand'!I$3,FALSE) -> 36.92362 | J16: =I16*VLOOKUP($B16,'EU Ref Scenario 2020'!$A$126:$AE$153,'Specified Annual Demand'!J$3,FALSE) -> 37.541229 | K16: =J16*VLOOKUP($B16,'EU Ref Scenario 2020'!$A$126:$AE$153,'Specified Annual Demand'!K$3,FALSE) -> 38.158837 | L16: =K16*VLOOKUP($B16,'EU Ref Scenario 2020'!$A$126:$AE$153,'Specified Annual Demand'!L$3,FALSE) -> 38.095813 | M16: =L16*VLOOKUP($B16,'EU Ref Scenario 2020'!$A$126:$AE$153,'Specified Annual Demand'!M$3,FALSE) -> 38.032789 | N16: =M16*VLOOKUP($B16,'EU Ref Scenario 2020'!$A$126:$AE$153,'Specified Annual Demand'!N$3,FALSE) -> 37.969766 | O16: =N16*VLOOKUP($B16,'EU Ref Scenario 2020'!$A$126:$AE$153,'Specified Annual Demand'!O$3,FALSE) -> 37.906742 | ... AJ16: =AI16*VLOOKUP($B16,'EU Ref Scenario 2020'!$A$126:$AE$153,'Specified Annual Demand'!AJ$3,FALSE) -> 37.236668 | AK16: =AJ16 -> 37.236668 | AL16: =AK16 -> 37.236668 | AM16: =AL16 -> 37.236668 | AN16: =AM16 -> 37.236668 | AO16: =AN16 -> 37.236668
... A112: Useful energy for appliances | B112: =LEFT(C112,2) -> SK | C112: SKEUSE | D112: 22.159862 | E112: 22.083561 | F112: 22.449473 | G112: 22.537091 | H112: =G112*VLOOKUP($B112,'EU Ref Scenario 2020'!$A$126:$AE$153,'Specified Annual Demand'!H$3,FALSE) -> 22.750031 | I112: =H112*VLOOKUP($B112,'EU Ref Scenario 2020'!$A$126:$AE$153,'Specified Annual Demand'!I$3,FALSE) -> 22.962971 | J112: =I112*VLOOKUP($B112,'EU Ref Scenario 2020'!$A$126:$AE$153,'Specified Annual Demand'!J$3,FALSE) -> 23.175911 | K112: =J112*VLOOKUP($B112,'EU Ref Scenario 2020'!$A$126:$AE$153,'Specified Annual Demand'!K$3,FALSE) -> 23.38885 | L112: =K112*VLOOKUP($B112,'EU Ref Scenario 2020'!$A$126:$AE$153,'Specified Annual Demand'!L$3,FALSE) -> 23.458911 | M112: =L112*VLOOKUP($B112,'EU Ref Scenario 2020'!$A$126:$AE$153,'Specified Annual Demand'!M$3,FALSE) -> 23.528972 | N112: =M112*VLOOKUP($B112,'EU Ref Scenario 2020'!$A$126:$AE$153,'Specified Annual Demand'!N$3,FALSE) -> 23.599032 | O112: =N112*VLOOKUP($B112,'EU Ref Scenario 2020'!$A$126:$AE$153,'Specified Annual Demand'!O$3,FALSE) -> 23.669093 | ... AJ112: =AI112*VLOOKUP($B112,'EU Ref Scenario 2020'!$A$126:$AE$153,'Specified Annual Demand'!AJ$3,FALSE) -> 24.510356 | AK112: =AJ112 -> 24.510356 | AL112: =AK112 -> 24.510356 | AM112: =AL112 -> 24.510356 | AN112: =AM112 -> 24.510356 | AO112: =AN112 -> 24.510356

Sheet EU Ref Scenario 2020
A1: ktoe | C1: 2020 | D1: 2021 | E1: 2022 | F1: 2023 | G1: 2024 | H1: 2025 | I1: 2026 | J1: 2027 | K1: 2028 | L1: 2029 | M1: 2030 | N1: 2031 | O1: 2032 | P1: 2033 | Q1: 2034 | R1: 2035 | S1: 2036 | T1: 2037 | U1: 2038 | V1: 2039 | W1: 2040 | X1: 2041 | Y1: 2042 | Z1: 2043 | AA1: 2044 | AB1: 2045 | AC1: 2046 | AD1: 2047 | AE1: 2048 | AF1: 2049 | AG1: 2050
A2: EU | B2: Residential | C2: 251101.35 | D2: =C2+(($H2-$C2)/5) -> 247863.39 | E2: =D2+(($H2-$C2)/5) -> 244625.42 | F2: =E2+(($H2-$C2)/5) -> 241387.46 | G2: =F2+(($H2-$C2)/5) -> 238149.5 | H2: 234911.53 | I2: =H2+(($M2-$H2)/5) -> 232606.71 | J2: =I2+(($M2-$H2)/5) -> 230301.9 | K2: =J2+(($M2-$H2)/5) -> 227997.08 | L2: =K2+(($M2-$H2)/5) -> 225692.26 | M2: 223387.45 | N2: =M2+(($R2-$M2)/5) -> 222202.33 | O2: =N2+(($R2-$M2)/5) -> 221017.22 | P2: =O2+(($R2-$M2)/5) -> 219832.1 | Q2: =P2+(($R2-$M2)/5) -> 218646.99 | R2: 217461.87 | S2: =R2+(($W2-$R2)/5) -> 216295.59 | T2: =S2+(($W2-$R2)/5) -> 215129.3 | U2: =T2+(($W2-$R2)/5) -> 213963.01 | V2: =U2+(($W2-$R2)/5) -> 212796.73 | W2: 211630.44 | X2: =W2+(($AB2-$W2)/5) -> 210637.83 | Y2: =X2+(($AB2-$W2)/5) -> 209645.21 | Z2: =Y2+(($AB2-$W2)/5) -> 208652.59 | AA2: =Z2+(($AB2-$W2)/5) -> 207659.97 | AB2: 206667.36 | AC2: =AB2+(($AG2-$AB2)/5) -> 205710.29 | AD2: =AC2+(($AG2-$AB2)/5) -> 204753.22 | AE2: =AD2+(($AG2-$AB2)/5) -> 203796.15 | AF2: =AE2+(($AG2-$AB2)/5) -> 202839.09 | AG2: 201882.02
A3: EU | B3: Tertiary (8) | C3: 140269.32 | D3: =C3+(($H3-$C3)/5) -> 143973.19 | E3: =D3+(($H3-$C3)/5) -> 147677.06 | F3: =E3+(($H3-$C3)/5) -> 151380.94 | G3: =F3+(($H3-$C3)/5) -> 155084.81 | H3: 158788.68 | I3: =H3+(($M3-$H3)/5) -> 157576.51 | J3: =I3+(($M3-$H3)/5) -> 156364.33 | K3: =J3+(($M3-$H3)/5) -> 155152.16 | L3: =K3+(($M3-$H3)/5) -> 153939.98 | M3: 152727.8 | N3: =M3+(($R3-$M3)/5) -> 152832.41 | O3: =N3+(($R3-$M3)/5) -> 152937.01 | P3: =O3+(($R3-$M3)/5) -> 153041.62 | Q3: =P3+(($R3-$M3)/5) -> 153146.22 | R3: 153250.83 | S3: =R3+(($W3-$R3)/5) -> 153003.18 | T3: =S3+(($W3-$R3)/5) -> 152755.53 | U3: =T3+(($W3-$R3)/5) -> 152507.88 | V3: =U3+(($W3-$R3)/5) -> 152260.24 | W3: 152012.59 | X3: =W3+(($AB3-$W3)/5) -> 151802.59 | Y3: =X3+(($AB3-$W3)/5) -> 151592.59 | Z3: =Y3+(($AB3-$W3)/5) -> 151382.6 | AA3: =Z3+(($AB3-$W3)/5) -> 151172.6 | AB3: 150962.6 | AC3: =AB3+(($AG3-$AB3)/5) -> 150908.53 | AD3: =AC3+(($AG3-$AB3)/5) -> 150854.47 | AE3: =AD3+(($AG3-$AB3)/5) -> 150800.4 | AF3: =AE3+(($AG3-$AB3)/5) -> 150746.34 | AG3: 150692.27
A4: =A3 -> EU | B4: Buildings Total | C4: =SUM(C2:C3) -> 391370.67 | D4: =C4+(($H4-$C4)/5) -> 391836.58 | E4: =D4+(($H4-$C4)/5) -> 392302.49 | F4: =E4+(($H4-$C4)/5) -> 392768.4 | G4: =F4+(($H4-$C4)/5) -> 393234.31 | H4: =SUM(H2:H3) -> 393700.22 | I4: =H4+(($M4-$H4)/5) -> 390183.22 | J4: =I4+(($M4-$H4)/5) -> 386666.23 | K4: =J4+(($M4-$H4)/5) -> 383149.24 | L4: =K4+(($M4-$H4)/5) -> 379632.24 | M4: =SUM(M2:M3) -> 376115.25 | N4: =M4+(($R4-$M4)/5) -> 375034.74 | O4: =N4+(($R4-$M4)/5) -> 373954.23 | P4: =O4+(($R4-$M4)/5) -> 372873.72 | Q4: =P4+(($R4-$M4)/5) -> 371793.21 | R4: =SUM(R2:R3) -> 370712.7 | S4: =R4+(($W4-$R4)/5) -> 369298.76 | T4: =S4+(($W4-$R4)/5) -> 367884.83 | U4: =T4+(($W4-$R4)/5) -> 366470.9 | V4: =U4+(($W4-$R4)/5) -> 365056.97 | W4: =SUM(W2:W3) -> 363643.03 | X4: =W4+(($AB4-$W4)/5) -> 362440.42 | Y4: =X4+(($AB4-$W4)/5) -> 361237.8 | Z4: =Y4+(($AB4-$W4)/5) -> 360035.19 | AA4: =Z4+(($AB4-$W4)/5) -> 358832.57 | AB4: =SUM(AB2:AB3) -> 357629.96 | AC4: =AB4+(($AG4-$AB4)/5) -> 356618.83 | AD4: =AC4+(($AG4-$AB4)/5) -> 355607.69 | AE4: =AD4+(($AG4-$AB4)/5) -> 354596.56 | AF4: =AE4+(($AG4-$AB4)/5) -> 353585.42 | AG4: =SUM(AG2:AG3) -> 352574.29
A5: AT | B5: Residential | C5: 6815.4933 | D5: =C5+(($H5-$C5)/5) -> 6755.7051 | E5: =D5+(($H5-$C5)/5) -> 6695.9169 | F5: =E5+(($H5-$C5)/5) -> 6636.1286 | G5: =F5+(($H5-$C5)/5) -> 6576.3404 | H5: 6516.5522 | I5: =H5+(($M5-$H5)/5) -> 6480.7071 | J5: =I5+(($M5-$H5)/5) -> 6444.862 | K5: =J5+(($M5-$H5)/5) -> 6409.0169 | L5: =K5+(($M5-$H5)/5) -> 6373.1717 | M5: 6337.3266 | N5: =M5+(($R5-$M5)/5) -> 6339.1376 | O5: =N5+(($R5-$M5)/5) -> 6340.9486 | P5: =O5+(($R5-$M5)/5) -> 6342.7596 | Q5: =P5+(($R5-$M5)/5) -> 6344.5706 | R5: 6346.3817 | S5: =R5+(($W5-$R5)/5) -> 6338.7037 | T5: =S5+(($W5-$R5)/5) -> 6331.0257 | U5: =T5+(($W5-$R5)/5) -> 6323.3477 | V5: =U5+(($W5-$R5)/5) -> 6315.6697 | W5: 6307.9917 | X5: =W5+(($AB5-$W5)/5) -> 6313.3931 | Y5: =X5+(($AB5-$W5)/5) -> 6318.7945 | Z5: =Y5+(($AB5-$W5)/5) -> 6324.1958 | AA5: =Z5+(($AB5-$W5)/5) -> 6329.5972 | AB5: 6334.9986 | AC5: =AB5+(($AG5-$AB5)/5) -> 6335.9625 | AD5: =AC5+(($AG5-$AB5)/5) -> 6336.9264 | AE5: =AD5+(($AG5-$AB5)/5) -> 6337.8904 | AF5: =AE5+(($AG5-$AB5)/5) -> 6338.8543 | AG5: 6339.8183
A6: AT | B6: Tertiary (8) | C6: 2887.9617 | D6: =C6+(($H6-$C6)/5) -> 2873.0514 | E6: =D6+(($H6-$C6)/5) -> 2858.141 | F6: =E6+(($H6-$C6)/5) -> 2843.2307 | G6: =F6+(($H6-$C6)/5) -> 2828.3203 | H6: 2813.41 | I6: =H6+(($M6-$H6)/5) -> 2774.9281 | J6: =I6+(($M6-$H6)/5) -> 2736.4462 | K6: =J6+(($M6-$H6)/5) -> 2697.9643 | L6: =K6+(($M6-$H6)/5) -> 2659.4824 | M6: 2621.0005 | N6: =M6+(($R6-$M6)/5) -> 2629.5932 | O6: =N6+(($R6-$M6)/5) -> 2638.1858 | P6: =O6+(($R6-$M6)/5) -> 2646.7785 | Q6: =P6+(($R6-$M6)/5) -> 2655.3712 | R6: 2663.9638 | S6: =R6+(($W6-$R6)/5) -> 2664.1827 | T6: =S6+(($W6-$R6)/5) -> 2664.4016 | U6: =T6+(($W6-$R6)/5) -> 2664.6205 | V6: =U6+(($W6-$R6)/5) -> 2664.8394 | W6: 2665.0583 | X6: =W6+(($AB6-$W6)/5) -> 2661.8383 | Y6: =X6+(($AB6-$W6)/5) -> 2658.6182 | Z6: =Y6+(($AB6-$W6)/5) -> 2655.3982 | AA6: =Z6+(($AB6-$W6)/5) -> 2652.1782 | AB6: 2648.9582 | AC6: =AB6+(($AG6-$AB6)/5) -> 2643.506 | AD6: =AC6+(($AG6-$AB6)/5) -> 2638.0538 | AE6: =AD6+(($AG6-$AB6)/5) -> 2632.6016 | AF6: =AE6+(($AG6-$AB6)/5) -> 2627.1494 | AG6: 2621.6972
A7: =A6 -> AT | B7: Buildings Total | C7: =SUM(C5:C6) -> 9703.455 | D7: =C7+(($H7-$C7)/5) -> 9628.7564 | E7: =D7+(($H7-$C7)/5) -> 9554.0579 | F7: =E7+(($H7-$C7)/5) -> 9479.3593 | G7: =F7+(($H7-$C7)/5) -> 9404.6608 | H7: =SUM(H5:H6) -> 9329.9622 | I7: =H7+(($M7-$H7)/5) -> 9255.6352 | J7: =I7+(($M7-$H7)/5) -> 9181.3082 | K7: =J7+(($M7-$H7)/5) -> 9106.9811 | L7: =K7+(($M7-$H7)/5) -> 9032.6541 | M7: =SUM(M5:M6) -> 8958.3271 | N7: =M7+(($R7-$M7)/5) -> 8968.7308 | O7: =N7+(($R7-$M7)/5) -> 8979.1345 | P7: =O7+(($R7-$M7)/5) -> 8989.5381 | Q7: =P7+(($R7-$M7)/5) -> 8999.9418 | R7: =SUM(R5:R6) -> 9010.3455 | S7: =R7+(($W7-$R7)/5) -> 9002.8864 | T7: =S7+(($W7-$R7)/5) -> 8995.4273 | U7: =T7+(($W7-$R7)/5) -> 8987.9682 | V7: =U7+(($W7-$R7)/5) -> 8980.5091 | W7: =SUM(W5:W6) -> 8973.05 | X7: =W7+(($AB7-$W7)/5) -> 8975.2314 | Y7: =X7+(($AB7-$W7)/5) -> 8977.4127 | Z7: =Y7+(($AB7-$W7)/5) -> 8979.5941 | AA7: =Z7+(($AB7-$W7)/5) -> 8981.7754 | AB7: =SUM(AB5:AB6) -> 8983.9568 | AC7: =AB7+(($AG7-$AB7)/5) -> 8979.4685 | AD7: =AC7+(($AG7-$AB7)/5) -> 8974.9802 | AE7: =AD7+(($AG7-$AB7)/5) -> 8970.492 | AF7: =AE7+(($AG7-$AB7)/5) -> 8966.0037 | AG7: =SUM(AG5:AG6) -> 8961.5155
A8: BE | B8: Residential | C8: 8058.775 | D8: =C8+(($H8-$C8)/5) -> 7994.0359 | E8: =D8+(($H8-$C8)/5) -> 7929.2967 | F8: =E8+(($H8-$C8)/5) -> 7864.5576 | G8: =F8+(($H8-$C8)/5) -> 7799.8184 | H8: 7735.0793 | I8: =H8+(($M8-$H8)/5) -> 7607.2467 | J8: =I8+(($M8-$H8)/5) -> 7479.4142 | K8: =J8+(($M8-$H8)/5) -> 7351.5816 | L8: =K8+(($M8-$H8)/5) -> 7223.749 | M8: 7095.9165 | N8: =M8+(($R8-$M8)/5) -> 6986.2644 | O8: =N8+(($R8-$M8)/5) -> 6876.6123 | P8: =O8+(($R8-$M8)/5) -> 6766.9602 | Q8: =P8+(($R8-$M8)/5) -> 6657.3082 | R8: 6547.6561 | S8: =R8+(($W8-$R8)/5) -> 6509.8184 | T8: =S8+(($W8-$R8)/5) -> 6471.9806 | U8: =T8+(($W8-$R8)/5) -> 6434.1429 | V8: =U8+(($W8-$R8)/5) -> 6396.3052 | W8: 6358.4675 | X8: =W8+(($AB8-$W8)/5) -> 6333.8246 | Y8: =X8+(($AB8-$W8)/5) -> 6309.1818 | Z8: =Y8+(($AB8-$W8)/5) -> 6284.539 | AA8: =Z8+(($AB8-$W8)/5) -> 6259.8962 | AB8: 6235.2533 | AC8: =AB8+(($AG8-$AB8)/5) -> 6211.3851 | AD8: =AC8+(($AG8-$AB8)/5) -> 6187.5169 | AE8: =AD8+(($AG8-$AB8)/5) -> 6163.6487 | AF8: =AE8+(($AG8-$AB8)/5) -> 6139.7805 | AG8: 6115.9123
A9: BE | B9: Tertiary (8) | C9: 4641.4945 | D9: =C9+(($H9-$C9)/5) -> 4730.6504 | E9: =D9+(($H9-$C9)/5) -> 4819.8064 | F9: =E9+(($H9-$C9)/5) -> 4908.9624 | G9: =F9+(($H9-$C9)/5) -> 4998.1183 | H9: 5087.2743 | I9: =H9+(($M9-$H9)/5) -> 5050.5206 | J9: =I9+(($M9-$H9)/5) -> 5013.767 | K9: =J9+(($M9-$H9)/5) -> 4977.0133 | L9: =K9+(($M9-$H9)/5) -> 4940.2597 | M9: 4903.506 | N9: =M9+(($R9-$M9)/5) -> 4970.333 | O9: =N9+(($R9-$M9)/5) -> 5037.1599 | P9: =O9+(($R9-$M9)/5) -> 5103.9869 | Q9: =P9+(($R9-$M9)/5) -> 5170.8138 | R9: 5237.6408 | S9: =R9+(($W9-$R9)/5) -> 5254.0956 | T9: =S9+(($W9-$R9)/5) -> 5270.5505 | U9: =T9+(($W9-$R9)/5) -> 5287.0054 | V9: =U9+(($W9-$R9)/5) -> 5303.4603 | W9: 5319.9151 | X9: =W9+(($AB9-$W9)/5) -> 5333.4538 | Y9: =X9+(($AB9-$W9)/5) -> 5346.9924 | Z9: =Y9+(($AB9-$W9)/5) -> 5360.5311 | AA9: =Z9+(($AB9-$W9)/5) -> 5374.0698 | AB9: 5387.6084 | AC9: =AB9+(($AG9-$AB9)/5) -> 5376.5266 | AD9: =AC9+(($AG9-$AB9)/5) -> 5365.4448 | AE9: =AD9+(($AG9-$AB9)/5) -> 5354.3631 | AF9: =AE9+(($AG9-$AB9)/5) -> 5343.2813 | AG9: 5332.1995
A10: =A9 -> BE | B10: Buildings Total | C10: =SUM(C8:C9) -> 12700.27 | D10: =C10+(($H10-$C10)/5) -> 12724.686 | E10: =D10+(($H10-$C10)/5) -> 12749.103 | F10: =E10+(($H10-$C10)/5) -> 12773.52 | G10: =F10+(($H10-$C10)/5) -> 12797.937 | H10: =SUM(H8:H9) -> 12822.354 | I10: =H10+(($M10-$H10)/5) -> 12657.767 | J10: =I10+(($M10-$H10)/5) -> 12493.181 | K10: =J10+(($M10-$H10)/5) -> 12328.595 | L10: =K10+(($M10-$H10)/5) -> 12164.009 | M10: =SUM(M8:M9) -> 11999.423 | N10: =M10+(($R10-$M10)/5) -> 11956.597 | O10: =N10+(($R10-$M10)/5) -> 11913.772 | P10: =O10+(($R10-$M10)/5) -> 11870.947 | Q10: =P10+(($R10-$M10)/5) -> 11828.122 | R10: =SUM(R8:R9) -> 11785.297 | S10: =R10+(($W10-$R10)/5) -> 11763.914 | T10: =S10+(($W10-$R10)/5) -> 11742.531 | U10: =T10+(($W10-$R10)/5) -> 11721.148 | V10: =U10+(($W10-$R10)/5) -> 11699.765 | W10: =SUM(W8:W9) -> 11678.383 | X10: =W10+(($AB10-$W10)/5) -> 11667.278 | Y10: =X10+(($AB10-$W10)/5) -> 11656.174 | Z10: =Y10+(($AB10-$W10)/5) -> 11645.07 | AA10: =Z10+(($AB10-$W10)/5) -> 11633.966 | AB10: =SUM(AB8:AB9) -> 11622.862 | AC10: =AB10+(($AG10-$AB10)/5) -> 11587.912 | AD10: =AC10+(($AG10-$AB10)/5) -> 11552.962 | AE10: =AD10+(($AG10-$AB10)/5) -> 11518.012 | AF10: =AE10+(($AG10-$AB10)/5) -> 11483.062 | AG10: =SUM(AG8:AG9) -> 11448.112
A11: BG | B11: Residential | C11: 2185.9519 | D11: =C11+(($H11-$C11)/5) -> 2206.3303 | E11: =D11+(($H11-$C11)/5) -> 2226.7087 | F11: =E11+(($H11-$C11)/5) -> 2247.0871 | G11: =F11+(($H11-$C11)/5) -> 2267.4655 | H11: 2287.8438 | I11: =H11+(($M11-$H11)/5) -> 2294.6227 | J11: =I11+(($M11-$H11)/5) -> 2301.4016 | K11: =J11+(($M11-$H11)/5) -> 2308.1805 | L11: =K11+(($M11-$H11)/5) -> 2314.9595 | M11: 2321.7384 | N11: =M11+(($R11-$M11)/5) -> 2328.8192 | O11: =N11+(($R11-$M11)/5) -> 2335.9001 | P11: =O11+(($R11-$M11)/5) -> 2342.981 | Q11: =P11+(($R11-$M11)/5) -> 2350.0619 | R11: 2357.1428 | S11: =R11+(($W11-$R11)/5) -> 2358.9932 | T11: =S11+(($W11-$R11)/5) -> 2360.8437 | U11: =T11+(($W11-$R11)/5) -> 2362.6941 | V11: =U11+(($W11-$R11)/5) -> 2364.5445 | W11: 2366.395 | X11: =W11+(($AB11-$W11)/5) -> 2366.5731 | Y11: =X11+(($AB11-$W11)/5) -> 2366.7512 | Z11: =Y11+(($AB11-$W11)/5) -> 2366.9293 | AA11: =Z11+(($AB11-$W11)/5) -> 2367.1074 | AB11: 2367.2856 | AC11: =AB11+(($AG11-$AB11)/5) -> 2362.8297 | AD11: =AC11+(($AG11-$AB11)/5) -> 2358.3739 | AE11: =AD11+(($AG11-$AB11)/5) -> 2353.918 | AF11: =AE11+(($AG11-$AB11)/5) -> 2349.4622 | AG11: 2345.0063
A12: BG | B12: Tertiary (8) | C12: 1228.0164 | D12: =C12+(($H12-$C12)/5) -> 1267.7592 | E12: =D12+(($H12-$C12)/5) -> 1307.5019 | F12: =E12+(($H12-$C12)/5) -> 1347.2446 | G12: =F12+(($H12-$C12)/5) -> 1386.9874 | H12: 1426.7301 | I12: =H12+(($M12-$H12)/5) -> 1413.8162 | J12: =I12+(($M12-$H12)/5) -> 1400.9022 | K12: =J12+(($M12-$H12)/5) -> 1387.9882 | L12: =K12+(($M12-$H12)/5) -> 1375.0743 | M12: 1362.1603 | N12: =M12+(($R12-$M12)/5) -> 1361.6194 | O12: =N12+(($R12-$M12)/5) -> 1361.0785 | P12: =O12+(($R12-$M12)/5) -> 1360.5376 | Q12: =P12+(($R12-$M12)/5) -> 1359.9967 | R12: 1359.4558 | S12: =R12+(($W12-$R12)/5) -> 1350.0761 | T12: =S12+(($W12-$R12)/5) -> 1340.6963 | U12: =T12+(($W12-$R12)/5) -> 1331.3165 | V12: =U12+(($W12-$R12)/5) -> 1321.9367 | W12: 1312.557 | X12: =W12+(($AB12-$W12)/5) -> 1308.5852 | Y12: =X12+(($AB12-$W12)/5) -> 1304.6135 | Z12: =Y12+(($AB12-$W12)/5) -> 1300.6418 | AA12: =Z12+(($AB12-$W12)/5) -> 1296.67 | AB12: 1292.6983 | AC12: =AB12+(($AG12-$AB12)/5) -> 1290.1184 | AD12: =AC12+(($AG12-$AB12)/5) -> 1287.5386 | AE12: =AD12+(($AG12-$AB12)/5) -> 1284.9587 | AF12: =AE12+(($AG12-$AB12)/5) -> 1282.3789 | AG12: 1279.799
A13: =A12 -> BG | B13: Buildings Total | C13: =SUM(C11:C12) -> 3413.9684 | D13: =C13+(($H13-$C13)/5) -> 3474.0895 | E13: =D13+(($H13-$C13)/5) -> 3534.2106 | F13: =E13+(($H13-$C13)/5) -> 3594.3317 | G13: =F13+(($H13-$C13)/5) -> 3654.4528 | H13: =SUM(H11:H12) -> 3714.574 | I13: =H13+(($M13-$H13)/5) -> 3708.4389 | J13: =I13+(($M13-$H13)/5) -> 3702.3038 | K13: =J13+(($M13-$H13)/5) -> 3696.1688 | L13: =K13+(($M13-$H13)/5) -> 3690.0337 | M13: =SUM(M11:M12) -> 3683.8987 | N13: =M13+(($R13-$M13)/5) -> 3690.4387 | O13: =N13+(($R13-$M13)/5) -> 3696.9787 | P13: =O13+(($R13-$M13)/5) -> 3703.5186 | Q13: =P13+(($R13-$M13)/5) -> 3710.0586 | R13: =SUM(R11:R12) -> 3716.5986 | S13: =R13+(($W13-$R13)/5) -> 3709.0693 | T13: =S13+(($W13-$R13)/5) -> 3701.5399 | U13: =T13+(($W13-$R13)/5) -> 3694.0106 | V13: =U13+(($W13-$R13)/5) -> 3686.4813 | W13: =SUM(W11:W12) -> 3678.9519 | X13: =W13+(($AB13-$W13)/5) -> 3675.1583 | Y13: =X13+(($AB13-$W13)/5) -> 3671.3647 | Z13: =Y13+(($AB13-$W13)/5) -> 3667.5711 | AA13: =Z13+(($AB13-$W13)/5) -> 3663.7775 | AB13: =SUM(AB11:AB12) -> 3659.9838 | AC13: =AB13+(($AG13-$AB13)/5) -> 3652.9481 | AD13: =AC13+(($AG13-$AB13)/5) -> 3645.9125 | AE13: =AD13+(($AG13-$AB13)/5) -> 3638.8768 | AF13: =AE13+(($AG13-$AB13)/5) -> 3631.8411 | AG13: =SUM(AG11:AG12) -> 3624.8054
A14: CY | B14: Residential | C14: 367.45547 | D14: =C14+(($H14-$C14)/5) -> 380.77473 | E14: =D14+(($H14-$C14)/5) -> 394.09399 | F14: =E14+(($H14-$C14)/5) -> 407.41325 | G14: =F14+(($H14-$C14)/5) -> 420.73251 | H14: 434.05177 | I14: =H14+(($M14-$H14)/5) -> 442.11908 | J14: =I14+(($M14-$H14)/5) -> 450.18639 | K14: =J14+(($M14-$H14)/5) -> 458.25371 | L14: =K14+(($M14-$H14)/5) -> 466.32102 | M14: 474.38833 | N14: =M14+(($R14-$M14)/5) -> 478.03928 | O14: =N14+(($R14-$M14)/5) -> 481.69023 | P14: =O14+(($R14-$M14)/5) -> 485.34118 | Q14: =P14+(($R14-$M14)/5) -> 488.99212 | R14: 492.64307 | S14: =R14+(($W14-$R14)/5) -> 492.42497 | T14: =S14+(($W14-$R14)/5) -> 492.20687 | U14: =T14+(($W14-$R14)/5) -> 491.98877 | V14: =U14+(($W14-$R14)/5) -> 491.77067 | W14: 491.55257 | X14: =W14+(($AB14-$W14)/5) -> 493.51253 | Y14: =X14+(($AB14-$W14)/5) -> 495.47249 | Z14: =Y14+(($AB14-$W14)/5) -> 497.43246 | AA14: =Z14+(($AB14-$W14)/5) -> 499.39242 | AB14: 501.35239 | AC14: =AB14+(($AG14-$AB14)/5) -> 505.43988 | AD14: =AC14+(($AG14-$AB14)/5) -> 509.52737 | AE14: =AD14+(($AG14-$AB14)/5) -> 513.61487 | AF14: =AE14+(($AG14-$AB14)/5) -> 517.70236 | AG14: 521.78985
A15: CY | B15: Tertiary (8) | C15: 294.68605 | D15: =C15+(($H15-$C15)/5) -> 312.5934 | E15: =D15+(($H15-$C15)/5) -> 330.50075 | F15: =E15+(($H15-$C15)/5) -> 348.4081 | G15: =F15+(($H15-$C15)/5) -> 366.31544 | H15: 384.22279 | I15: =H15+(($M15-$H15)/5) -> 388.47259 | J15: =I15+(($M15-$H15)/5) -> 392.72239 | K15: =J15+(($M15-$H15)/5) -> 396.97219 | L15: =K15+(($M15-$H15)/5) -> 401.22199 | M15: 405.47179 | N15: =M15+(($R15-$M15)/5) -> 410.46641 | O15: =N15+(($R15-$M15)/5) -> 415.46104 | P15: =O15+(($R15-$M15)/5) -> 420.45567 | Q15: =P15+(($R15-$M15)/5) -> 425.4503 | R15: 430.44493 | S15: =R15+(($W15-$R15)/5) -> 432.50883 | T15: =S15+(($W15-$R15)/5) -> 434.57274 | U15: =T15+(($W15-$R15)/5) -> 436.63664 | V15: =U15+(($W15-$R15)/5) -> 438.70055 | W15: 440.76445 | X15: =W15+(($AB15-$W15)/5) -> 439.79414 | Y15: =X15+(($AB15-$W15)/5) -> 438.82384 | Z15: =Y15+(($AB15-$W15)/5) -> 437.85353 | AA15: =Z15+(($AB15-$W15)/5) -> 436.88323 | AB15: 435.91292 | AC15: =AB15+(($AG15-$AB15)/5) -> 434.13308 | AD15: =AC15+(($AG15-$AB15)/5) -> 432.35324 | AE15: =AD15+(($AG15-$AB15)/5) -> 430.5734 | AF15: =AE15+(($AG15-$AB15)/5) -> 428.79356 | AG15: 427.01372
A16: =A15 -> CY | B16: Buildings Total | C16: =SUM(C14:C15) -> 662.14152 | D16: =C16+(($H16-$C16)/5) -> 693.36813 | E16: =D16+(($H16-$C16)/5) -> 724.59473 | F16: =E16+(($H16-$C16)/5) -> 755.82134 | G16: =F16+(($H16-$C16)/5) -> 787.04795 | H16: =SUM(H14:H15) -> 818.27456 | I16: =H16+(($M16-$H16)/5) -> 830.59167 | J16: =I16+(($M16-$H16)/5) -> 842.90878 | K16: =J16+(($M16-$H16)/5) -> 855.2259 | L16: =K16+(($M16-$H16)/5) -> 867.54301 | M16: =SUM(M14:M15) -> 879.86012 | N16: =M16+(($R16-$M16)/5) -> 888.5057 | O16: =N16+(($R16-$M16)/5) -> 897.15127 | P16: =O16+(($R16-$M16)/5) -> 905.79685 | Q16: =P16+(($R16-$M16)/5) -> 914.44242 | R16: =SUM(R14:R15) -> 923.088 | S16: =R16+(($W16-$R16)/5) -> 924.9338 | T16: =S16+(($W16-$R16)/5) -> 926.7796 | U16: =T16+(($W16-$R16)/5) -> 928.62541 | V16: =U16+(($W16-$R16)/5) -> 930.47121 | W16: =SUM(W14:W15) -> 932.31701 | X16: =W16+(($AB16-$W16)/5) -> 933.30667 | Y16: =X16+(($AB16-$W16)/5) -> 934.29633 | Z16: =Y16+(($AB16-$W16)/5) -> 935.28599 | AA16: =Z16+(($AB16-$W16)/5) -> 936.27565 | AB16: =SUM(AB14:AB15) -> 937.26531 | AC16: =AB16+(($AG16-$AB16)/5) -> 939.57297 | AD16: =AC16+(($AG16-$AB16)/5) -> 941.88062 | AE16: =AD16+(($AG16-$AB16)/5) -> 944.18827 | AF16: =AE16+(($AG16-$AB16)/5) -> 946.49592 | AG16: =SUM(AG14:AG15) -> 948.80358
A17: CZ | B17: Residential | C17: 7041.5527 | D17: =C17+(($H17-$C17)/5) -> 7003.4097 | E17: =D17+(($H17-$C17)/5) -> 6965.2667 | F17: =E17+(($H17-$C17)/5) -> 6927.1238 | G17: =F17+(($H17-$C17)/5) -> 6888.9808 | H17: 6850.8378 | I17: =H17+(($M17-$H17)/5) -> 6784.6595 | J17: =I17+(($M17-$H17)/5) -> 6718.4812 | K17: =J17+(($M17-$H17)/5) -> 6652.3029 | L17: =K17+(($M17-$H17)/5) -> 6586.1246 | M17: 6519.9463 | N17: =M17+(($R17-$M17)/5) -> 6489.1471 | O17: =N17+(($R17-$M17)/5) -> 6458.3479 | P17: =O17+(($R17-$M17)/5) -> 6427.5487 | Q17: =P17+(($R17-$M17)/5) -> 6396.7495 | R17: 6365.9503 | S17: =R17+(($W17-$R17)/5) -> 6332.2588 | T17: =S17+(($W17-$R17)/5) -> 6298.5673 | U17: =T17+(($W17-$R17)/5) -> 6264.8758 | V17: =U17+(($W17-$R17)/5) -> 6231.1843 | W17: 6197.4928 | X17: =W17+(($AB17-$W17)/5) -> 6170.8701 | Y17: =X17+(($AB17-$W17)/5) -> 6144.2474 | Z17: =Y17+(($AB17-$W17)/5) -> 6117.6247 | AA17: =Z17+(($AB17-$W17)/5) -> 6091.002 | AB17: 6064.3793 | AC17: =AB17+(($AG17-$AB17)/5) -> 6048.5612 | AD17: =AC17+(($AG17-$AB17)/5) -> 6032.743 | AE17: =AD17+(($AG17-$AB17)/5) -> 6016.9249 | AF17: =AE17+(($AG17-$AB17)/5) -> 6001.1067 | AG17: 5985.2886
A18: CZ | B18: Tertiary (8) | C18: 3317.2268 | D18: =C18+(($H18-$C18)/5) -> 3421.3773 | E18: =D18+(($H18-$C18)/5) -> 3525.5278 | F18: =E18+(($H18-$C18)/5) -> 3629.6783 | G18: =F18+(($H18-$C18)/5) -> 3733.8288 | H18: 3837.9793 | I18: =H18+(($M18-$H18)/5) -> 3796.8602 | J18: =I18+(($M18-$H18)/5) -> 3755.741 | K18: =J18+(($M18-$H18)/5) -> 3714.6218 | L18: =K18+(($M18-$H18)/5) -> 3673.5027 | M18: 3632.3835 | N18: =M18+(($R18-$M18)/5) -> 3641.9601 | O18: =N18+(($R18-$M18)/5) -> 3651.5367 | P18: =O18+(($R18-$M18)/5) -> 3661.1134 | Q18: =P18+(($R18-$M18)/5) -> 3670.69 | R18: 3680.2666 | S18: =R18+(($W18-$R18)/5) -> 3680.893 | T18: =S18+(($W18-$R18)/5) -> 3681.5194 | U18: =T18+(($W18-$R18)/5) -> 3682.1458 | V18: =U18+(($W18-$R18)/5) -> 3682.7722 | W18: 3683.3986 | X18: =W18+(($AB18-$W18)/5) -> 3680.8807 | Y18: =X18+(($AB18-$W18)/5) -> 3678.3628 | Z18: =Y18+(($AB18-$W18)/5) -> 3675.8448 | AA18: =Z18+(($AB18-$W18)/5) -> 3673.3269 | AB18: 3670.8089 | AC18: =AB18+(($AG18-$AB18)/5) -> 3667.9598 | AD18: =AC18+(($AG18-$AB18)/5) -> 3665.1106 | AE18: =AD18+(($AG18-$AB18)/5) -> 3662.2615 | AF18: =AE18+(($AG18-$AB18)/5) -> 3659.4123 | AG18: 3656.5631
A19: =A18 -> CZ | B19: Buildings Total | C19: =SUM(C17:C18) -> 10358.779 | D19: =C19+(($H19-$C19)/5) -> 10424.787 | E19: =D19+(($H19-$C19)/5) -> 10490.795 | F19: =E19+(($H19-$C19)/5) -> 10556.802 | G19: =F19+(($H19-$C19)/5) -> 10622.81 | H19: =SUM(H17:H18) -> 10688.817 | I19: =H19+(($M19-$H19)/5) -> 10581.52 | J19: =I19+(($M19-$H19)/5) -> 10474.222 | K19: =J19+(($M19-$H19)/5) -> 10366.925 | L19: =K19+(($M19-$H19)/5) -> 10259.627 | M19: =SUM(M17:M18) -> 10152.33 | N19: =M19+(($R19-$M19)/5) -> 10131.107 | O19: =N19+(($R19-$M19)/5) -> 10109.885 | P19: =O19+(($R19-$M19)/5) -> 10088.662 | Q19: =P19+(($R19-$M19)/5) -> 10067.439 | R19: =SUM(R17:R18) -> 10046.217 | S19: =R19+(($W19-$R19)/5) -> 10013.152 | T19: =S19+(($W19-$R19)/5) -> 9980.0867 | U19: =T19+(($W19-$R19)/5) -> 9947.0216 | V19: =U19+(($W19-$R19)/5) -> 9913.9565 | W19: =SUM(W17:W18) -> 9880.8915 | X19: =W19+(($AB19-$W19)/5) -> 9851.7508 | Y19: =X19+(($AB19-$W19)/5) -> 9822.6102 | Z19: =Y19+(($AB19-$W19)/5) -> 9793.4695 | AA19: =Z19+(($AB19-$W19)/5) -> 9764.3289 | AB19: =SUM(AB17:AB18) -> 9735.1882 | AC19: =AB19+(($AG19-$AB19)/5) -> 9716.5209 | AD19: =AC19+(($AG19-$AB19)/5) -> 9697.8536 | AE19: =AD19+(($AG19-$AB19)/5) -> 9679.1863 | AF19: =AE19+(($AG19-$AB19)/5) -> 9660.519 | AG19: =SUM(AG17:AG18) -> 9641.8517
A20: DE | B20: Residential | C20: 58251.362 | D20: =C20+(($H20-$C20)/5) -> 56750.484 | E20: =D20+(($H20-$C20)/5) -> 55249.606 | F20: =E20+(($H20-$C20)/5) -> 53748.728 | G20: =F20+(($H20-$C20)/5) -> 52247.85 | H20: 50746.972 | I20: =H20+(($M20-$H20)/5) -> 50088.882 | J20: =I20+(($M20-$H20)/5) -> 49430.791 | K20: =J20+(($M20-$H20)/5) -> 48772.7 | L20: =K20+(($M20-$H20)/5) -> 48114.609 | M20: 47456.518 | N20: =M20+(($R20-$M20)/5) -> 47121.596 | O20: =N20+(($R20-$M20)/5) -> 46786.673 | P20: =O20+(($R20-$M20)/5) -> 46451.75 | Q20: =P20+(($R20-$M20)/5) -> 46116.827 | R20: 45781.904 | S20: =R20+(($W20-$R20)/5) -> 45390.774 | T20: =S20+(($W20-$R20)/5) -> 44999.645 | U20: =T20+(($W20-$R20)/5) -> 44608.515 | V20: =U20+(($W20-$R20)/5) -> 44217.386 | W20: 43826.256 | X20: =W20+(($AB20-$W20)/5) -> 43582.083 | Y20: =X20+(($AB20-$W20)/5) -> 43337.911 | Z20: =Y20+(($AB20-$W20)/5) -> 43093.738 | AA20: =Z20+(($AB20-$W20)/5) -> 42849.566 | AB20: 42605.393 | AC20: =AB20+(($AG20-$AB20)/5) -> 42410.748 | AD20: =AC20+(($AG20-$AB20)/5) -> 42216.103 | AE20: =AD20+(($AG20-$AB20)/5) -> 42021.458 | AF20: =AE20+(($AG20-$AB20)/5) -> 41826.813 | AG20: 41632.168
A21: DE | B21: Tertiary (8) | C21: 28403.906 | D21: =C21+(($H21-$C21)/5) -> 29366.849 | E21: =D21+(($H21-$C21)/5) -> 30329.792 | F21: =E21+(($H21-$C21)/5) -> 31292.735 | G21: =F21+(($H21-$C21)/5) -> 32255.678 | H21: 33218.622 | I21: =H21+(($M21-$H21)/5) -> 32978.252 | J21: =I21+(($M21-$H21)/5) -> 32737.883 | K21: =J21+(($M21-$H21)/5) -> 32497.514 | L21: =K21+(($M21-$H21)/5) -> 32257.145 | M21: 32016.776 | N21: =M21+(($R21-$M21)/5) -> 32253.299 | O21: =N21+(($R21-$M21)/5) -> 32489.821 | P21: =O21+(($R21-$M21)/5) -> 32726.344 | Q21: =P21+(($R21-$M21)/5) -> 32962.866 | R21: 33199.389 | S21: =R21+(($W21-$R21)/5) -> 33241.153 | T21: =S21+(($W21-$R21)/5) -> 33282.918 | U21: =T21+(($W21-$R21)/5) -> 33324.682 | V21: =U21+(($W21-$R21)/5) -> 33366.446 | W21: 33408.211 | X21: =W21+(($AB21-$W21)/5) -> 33480.469 | Y21: =X21+(($AB21-$W21)/5) -> 33552.726 | Z21: =Y21+(($AB21-$W21)/5) -> 33624.984 | AA21: =Z21+(($AB21-$W21)/5) -> 33697.242 | AB21: 33769.499 | AC21: =AB21+(($AG21-$AB21)/5) -> 33876.666 | AD21: =AC21+(($AG21-$AB21)/5) -> 33983.834 | AE21: =AD21+(($AG21-$AB21)/5) -> 34091.001 | AF21: =AE21+(($AG21-$AB21)/5) -> 34198.168 | AG21: 34305.335
A22: =A21 -> DE | B22: Buildings Total | C22: =SUM(C20:C21) -> 86655.267 | D22: =C22+(($H22-$C22)/5) -> 86117.332 | E22: =D22+(($H22-$C22)/5) -> 85579.398 | F22: =E22+(($H22-$C22)/5) -> 85041.463 | G22: =F22+(($H22-$C22)/5) -> 84503.529 | H22: =SUM(H20:H21) -> 83965.594 | I22: =H22+(($M22-$H22)/5) -> 83067.134 | J22: =I22+(($M22-$H22)/5) -> 82168.674 | K22: =J22+(($M22-$H22)/5) -> 81270.214 | L22: =K22+(($M22-$H22)/5) -> 80371.755 | M22: =SUM(M20:M21) -> 79473.295 | N22: =M22+(($R22-$M22)/5) -> 79374.894 | O22: =N22+(($R22-$M22)/5) -> 79276.494 | P22: =O22+(($R22-$M22)/5) -> 79178.094 | Q22: =P22+(($R22-$M22)/5) -> 79079.693 | R22: =SUM(R20:R21) -> 78981.293 | S22: =R22+(($W22-$R22)/5) -> 78631.928 | T22: =S22+(($W22-$R22)/5) -> 78282.562 | U22: =T22+(($W22-$R22)/5) -> 77933.197 | V22: =U22+(($W22-$R22)/5) -> 77583.832 | W22: =SUM(W20:W21) -> 77234.467 | X22: =W22+(($AB22-$W22)/5) -> 77062.552 | Y22: =X22+(($AB22-$W22)/5) -> 76890.637 | Z22: =Y22+(($AB22-$W22)/5) -> 76718.722 | AA22: =Z22+(($AB22-$W22)/5) -> 76546.807 | AB22: =SUM(AB20:AB21) -> 76374.892 | AC22: =AB22+(($AG22-$AB22)/5) -> 76287.415 | AD22: =AC22+(($AG22-$AB22)/5) -> 76199.937 | AE22: =AD22+(($AG22-$AB22)/5) -> 76112.459 | AF22: =AE22+(($AG22-$AB22)/5) -> 76024.981 | AG22: =SUM(AG20:AG21) -> 75937.503
A23: DK | B23: Residential | C23: 4417.6037 | D23: =C23+(($H23-$C23)/5) -> 4449.0178 | E23: =D23+(($H23-$C23)/5) -> 4480.4319 | F23: =E23+(($H23-$C23)/5) -> 4511.846 | G23: =F23+(($H23-$C23)/5) -> 4543.2602 | H23: 4574.6743 | I23: =H23+(($M23-$H23)/5) -> 4562.5496 | J23: =I23+(($M23-$H23)/5) -> 4550.425 | K23: =J23+(($M23-$H23)/5) -> 4538.3003 | L23: =K23+(($M23-$H23)/5) -> 4526.1757 | M23: 4514.051 | N23: =M23+(($R23-$M23)/5) -> 4509.1873 | O23: =N23+(($R23-$M23)/5) -> 4504.3236 | P23: =O23+(($R23-$M23)/5) -> 4499.4599 | Q23: =P23+(($R23-$M23)/5) -> 4494.5962 | R23: 4489.7325 | S23: =R23+(($W23-$R23)/5) -> 4480.3745 | T23: =S23+(($W23-$R23)/5) -> 4471.0165 | U23: =T23+(($W23-$R23)/5) -> 4461.6585 | V23: =U23+(($W23-$R23)/5) -> 4452.3005 | W23: 4442.9425 | X23: =W23+(($AB23-$W23)/5) -> 4439.8136 | Y23: =X23+(($AB23-$W23)/5) -> 4436.6846 | Z23: =Y23+(($AB23-$W23)/5) -> 4433.5557 | AA23: =Z23+(($AB23-$W23)/5) -> 4430.4268 | AB23: 4427.2979 | AC23: =AB23+(($AG23-$AB23)/5) -> 4425.7621 | AD23: =AC23+(($AG23-$AB23)/5) -> 4424.2264 | AE23: =AD23+(($AG23-$AB23)/5) -> 4422.6906 | AF23: =AE23+(($AG23-$AB23)/5) -> 4421.1549 | AG23: 4419.6192
A24: DK | B24: Tertiary (8) | C24: 2414.5904 | D24: =C24+(($H24-$C24)/5) -> 2655.3685 | E24: =D24+(($H24-$C24)/5) -> 2896.1467 | F24: =E24+(($H24-$C24)/5) -> 3136.9248 | G24: =F24+(($H24-$C24)/5) -> 3377.7029 | H24: 3618.4811 | I24: =H24+(($M24-$H24)/5) -> 3670.1561 | J24: =I24+(($M24-$H24)/5) -> 3721.8311 | K24: =J24+(($M24-$H24)/5) -> 3773.5062 | L24: =K24+(($M24-$H24)/5) -> 3825.1812 | M24: 3876.8562 | N24: =M24+(($R24-$M24)/5) -> 3904.7129 | O24: =N24+(($R24-$M24)/5) -> 3932.5695 | P24: =O24+(($R24-$M24)/5) -> 3960.4262 | Q24: =P24+(($R24-$M24)/5) -> 3988.2828 | R24: 4016.1395 | S24: =R24+(($W24-$R24)/5) -> 4025.7464 | T24: =S24+(($W24-$R24)/5) -> 4035.3533 | U24: =T24+(($W24-$R24)/5) -> 4044.9602 | V24: =U24+(($W24-$R24)/5) -> 4054.5671 | W24: 4064.1739 | X24: =W24+(($AB24-$W24)/5) -> 4070.6958 | Y24: =X24+(($AB24-$W24)/5) -> 4077.2176 | Z24: =Y24+(($AB24-$W24)/5) -> 4083.7394 | AA24: =Z24+(($AB24-$W24)/5) -> 4090.2612 | AB24: 4096.783 | AC24: =AB24+(($AG24-$AB24)/5) -> 4118.9375 | AD24: =AC24+(($AG24-$AB24)/5) -> 4141.0919 | AE24: =AD24+(($AG24-$AB24)/5) -> 4163.2463 | AF24: =AE24+(($AG24-$AB24)/5) -> 4185.4007 | AG24: 4207.5551
A25: =A24 -> DK | B25: Buildings Total | C25: =SUM(C23:C24) -> 6832.1941 | D25: =C25+(($H25-$C25)/5) -> 7104.3863 | E25: =D25+(($H25-$C25)/5) -> 7376.5786 | F25: =E25+(($H25-$C25)/5) -> 7648.7708 | G25: =F25+(($H25-$C25)/5) -> 7920.9631 | H25: =SUM(H23:H24) -> 8193.1553 | I25: =H25+(($M25-$H25)/5) -> 8232.7057 | J25: =I25+(($M25-$H25)/5) -> 8272.2561 | K25: =J25+(($M25-$H25)/5) -> 8311.8065 | L25: =K25+(($M25-$H25)/5) -> 8351.3569 | M25: =SUM(M23:M24) -> 8390.9072 | N25: =M25+(($R25-$M25)/5) -> 8413.9002 | O25: =N25+(($R25-$M25)/5) -> 8436.8931 | P25: =O25+(($R25-$M25)/5) -> 8459.8861 | Q25: =P25+(($R25-$M25)/5) -> 8482.879 | R25: =SUM(R23:R24) -> 8505.872 | S25: =R25+(($W25-$R25)/5) -> 8506.1209 | T25: =S25+(($W25-$R25)/5) -> 8506.3698 | U25: =T25+(($W25-$R25)/5) -> 8506.6186 | V25: =U25+(($W25-$R25)/5) -> 8506.8675 | W25: =SUM(W23:W24) -> 8507.1164 | X25: =W25+(($AB25-$W25)/5) -> 8510.5093 | Y25: =X25+(($AB25-$W25)/5) -> 8513.9022 | Z25: =Y25+(($AB25-$W25)/5) -> 8517.2951 | AA25: =Z25+(($AB25-$W25)/5) -> 8520.688 | AB25: =SUM(AB23:AB24) -> 8524.0809 | AC25: =AB25+(($AG25-$AB25)/5) -> 8544.6996 | AD25: =AC25+(($AG25-$AB25)/5) -> 8565.3183 | AE25: =AD25+(($AG25-$AB25)/5) -> 8585.9369 | AF25: =AE25+(($AG25-$AB25)/5) -> 8606.5556 | AG25: =SUM(AG23:AG24) -> 8627.1743
A26: EE | B26: Residential | C26: 977.7639 | D26: =C26+(($H26-$C26)/5) -> 942.69057 | E26: =D26+(($H26-$C26)/5) -> 907.61725 | F26: =E26+(($H26-$C26)/5) -> 872.54392 | G26: =F26+(($H26-$C26)/5) -> 837.47059 | H26: 802.39726 | I26: =H26+(($M26-$H26)/5) -> 786.93338 | J26: =I26+(($M26-$H26)/5) -> 771.46949 | K26: =J26+(($M26-$H26)/5) -> 756.00561 | L26: =K26+(($M26-$H26)/5) -> 740.54172 | M26: 725.07783 | N26: =M26+(($R26-$M26)/5) -> 718.84116 | O26: =N26+(($R26-$M26)/5) -> 712.60449 | P26: =O26+(($R26-$M26)/5) -> 706.36782 | Q26: =P26+(($R26-$M26)/5) -> 700.13115 | R26: 693.89447 | S26: =R26+(($W26-$R26)/5) -> 689.27034 | T26: =S26+(($W26-$R26)/5) -> 684.64622 | U26: =T26+(($W26-$R26)/5) -> 680.02209 | V26: =U26+(($W26-$R26)/5) -> 675.39796 | W26: 670.77383 | X26: =W26+(($AB26-$W26)/5) -> 667.27379 | Y26: =X26+(($AB26-$W26)/5) -> 663.77374 | Z26: =Y26+(($AB26-$W26)/5) -> 660.2737 | AA26: =Z26+(($AB26-$W26)/5) -> 656.77365 | AB26: 653.27361 | AC26: =AB26+(($AG26-$AB26)/5) -> 650.94829 | AD26: =AC26+(($AG26-$AB26)/5) -> 648.62297 | AE26: =AD26+(($AG26-$AB26)/5) -> 646.29764 | AF26: =AE26+(($AG26-$AB26)/5) -> 643.97232 | AG26: 641.647
A27: EE | B27: Tertiary (8) | C27: 537.00892 | D27: =C27+(($H27-$C27)/5) -> 563.63026 | E27: =D27+(($H27-$C27)/5) -> 590.25159 | F27: =E27+(($H27-$C27)/5) -> 616.87293 | G27: =F27+(($H27-$C27)/5) -> 643.49426 | H27: 670.11559 | I27: =H27+(($M27-$H27)/5) -> 670.84452 | J27: =I27+(($M27-$H27)/5) -> 671.57344 | K27: =J27+(($M27-$H27)/5) -> 672.30237 | L27: =K27+(($M27-$H27)/5) -> 673.03129 | M27: 673.76022 | N27: =M27+(($R27-$M27)/5) -> 675.23166 | O27: =N27+(($R27-$M27)/5) -> 676.7031 | P27: =O27+(($R27-$M27)/5) -> 678.17453 | Q27: =P27+(($R27-$M27)/5) -> 679.64597 | R27: 681.11741 | S27: =R27+(($W27-$R27)/5) -> 681.89202 | T27: =S27+(($W27-$R27)/5) -> 682.66663 | U27: =T27+(($W27-$R27)/5) -> 683.44124 | V27: =U27+(($W27-$R27)/5) -> 684.21585 | W27: 684.99047 | X27: =W27+(($AB27-$W27)/5) -> 684.23397 | Y27: =X27+(($AB27-$W27)/5) -> 683.47748 | Z27: =Y27+(($AB27-$W27)/5) -> 682.72099 | AA27: =Z27+(($AB27-$W27)/5) -> 681.9645 | AB27: 681.20801 | AC27: =AB27+(($AG27-$AB27)/5) -> 681.31337 | AD27: =AC27+(($AG27-$AB27)/5) -> 681.41873 | AE27: =AD27+(($AG27-$AB27)/5) -> 681.5241 | AF27: =AE27+(($AG27-$AB27)/5) -> 681.62946 | AG27: 681.73482
A28: =A27 -> EE | B28: Buildings Total | C28: =SUM(C26:C27) -> 1514.7728 | D28: =C28+(($H28-$C28)/5) -> 1506.3208 | E28: =D28+(($H28-$C28)/5) -> 1497.8688 | F28: =E28+(($H28-$C28)/5) -> 1489.4168 | G28: =F28+(($H28-$C28)/5) -> 1480.9649 | H28: =SUM(H26:H27) -> 1472.5129 | I28: =H28+(($M28-$H28)/5) -> 1457.7779 | J28: =I28+(($M28-$H28)/5) -> 1443.0429 | K28: =J28+(($M28-$H28)/5) -> 1428.308 | L28: =K28+(($M28-$H28)/5) -> 1413.573 | M28: =SUM(M26:M27) -> 1398.8381 | N28: =M28+(($R28-$M28)/5) -> 1394.0728 | O28: =N28+(($R28-$M28)/5) -> 1389.3076 | P28: =O28+(($R28-$M28)/5) -> 1384.5424 | Q28: =P28+(($R28-$M28)/5) -> 1379.7771 | R28: =SUM(R26:R27) -> 1375.0119 | S28: =R28+(($W28-$R28)/5) -> 1371.1624 | T28: =S28+(($W28-$R28)/5) -> 1367.3128 | U28: =T28+(($W28-$R28)/5) -> 1363.4633 | V28: =U28+(($W28-$R28)/5) -> 1359.6138 | W28: =SUM(W26:W27) -> 1355.7643 | X28: =W28+(($AB28-$W28)/5) -> 1351.5078 | Y28: =X28+(($AB28-$W28)/5) -> 1347.2512 | Z28: =Y28+(($AB28-$W28)/5) -> 1342.9947 | AA28: =Z28+(($AB28-$W28)/5) -> 1338.7382 | AB28: =SUM(AB26:AB27) -> 1334.4816 | AC28: =AB28+(($AG28-$AB28)/5) -> 1332.2617 | AD28: =AC28+(($AG28-$AB28)/5) -> 1330.0417 | AE28: =AD28+(($AG28-$AB28)/5) -> 1327.8217 | AF28: =AE28+(($AG28-$AB28)/5) -> 1325.6018 | AG28: =SUM(AG26:AG27) -> 1323.3818
A29: GR | B29: Residential | C29: 4115.8737 | D29: =C29+(($H29-$C29)/5) -> 4220.5143 | E29: =D29+(($H29-$C29)/5) -> 4325.1549 | F29: =E29+(($H29-$C29)/5) -> 4429.7955 | G29: =F29+(($H29-$C29)/5) -> 4534.4361 | H29: 4639.0767 | I29: =H29+(($M29-$H29)/5) -> 4605.4116 | J29: =I29+(($M29-$H29)/5) -> 4571.7465 | K29: =J29+(($M29-$H29)/5) -> 4538.0815 | L29: =K29+(($M29-$H29)/5) -> 4504.4164 | M29: 4470.7514 | N29: =M29+(($R29-$M29)/5) -> 4442.3392 | O29: =N29+(($R29-$M29)/5) -> 4413.927 | P29: =O29+(($R29-$M29)/5) -> 4385.5148 | Q29: =P29+(($R29-$M29)/5) -> 4357.1027 | R29: 4328.6905 | S29: =R29+(($W29-$R29)/5) -> 4308.8002 | T29: =S29+(($W29-$R29)/5) -> 4288.9098 | U29: =T29+(($W29-$R29)/5) -> 4269.0195 | V29: =U29+(($W29-$R29)/5) -> 4249.1292 | W29: 4229.2389 | X29: =W29+(($AB29-$W29)/5) -> 4205.6541 | Y29: =X29+(($AB29-$W29)/5) -> 4182.0693 | Z29: =Y29+(($AB29-$W29)/5) -> 4158.4845 | AA29: =Z29+(($AB29-$W29)/5) -> 4134.8997 | AB29: 4111.3148 | AC29: =AB29+(($AG29-$AB29)/5) -> 4075.557 | AD29: =AC29+(($AG29-$AB29)/5) -> 4039.7992 | AE29: =AD29+(($AG29-$AB29)/5) -> 4004.0414 | AF29: =AE29+(($AG29-$AB29)/5) -> 3968.2836 | AG29: 3932.5257
A30: GR | B30: Tertiary (8) | C30: 2313.571 | D30: =C30+(($H30-$C30)/5) -> 2421.4132 | E30: =D30+(($H30-$C30)/5) -> 2529.2554 | F30: =E30+(($H30-$C30)/5) -> 2637.0976 | G30: =F30+(($H30-$C30)/5) -> 2744.9399 | H30: 2852.7821 | I30: =H30+(($M30-$H30)/5) -> 2838.3805 | J30: =I30+(($M30-$H30)/5) -> 2823.979 | K30: =J30+(($M30-$H30)/5) -> 2809.5774 | L30: =K30+(($M30-$H30)/5) -> 2795.1759 | M30: 2780.7744 | N30: =M30+(($R30-$M30)/5) -> 2769.9163 | O30: =N30+(($R30-$M30)/5) -> 2759.0583 | P30: =O30+(($R30-$M30)/5) -> 2748.2003 | Q30: =P30+(($R30-$M30)/5) -> 2737.3423 | R30: 2726.4843 | S30: =R30+(($W30-$R30)/5) -> 2733.4881 | T30: =S30+(($W30-$R30)/5) -> 2740.4919 | U30: =T30+(($W30-$R30)/5) -> 2747.4957 | V30: =U30+(($W30-$R30)/5) -> 2754.4995 | W30: 2761.5033 | X30: =W30+(($AB30-$W30)/5) -> 2799.8604 | Y30: =X30+(($AB30-$W30)/5) -> 2838.2175 | Z30: =Y30+(($AB30-$W30)/5) -> 2876.5747 | AA30: =Z30+(($AB30-$W30)/5) -> 2914.9318 | AB30: 2953.2889 | AC30: =AB30+(($AG30-$AB30)/5) -> 3051.1859 | AD30: =AC30+(($AG30-$AB30)/5) -> 3149.0829 | AE30: =AD30+(($AG30-$AB30)/5) -> 3246.9799 | AF30: =AE30+(($AG30-$AB30)/5) -> 3344.8769 | AG30: 3442.7739
A31: =A30 -> GR | B31: Buildings Total | C31: =SUM(C29:C30) -> 6429.4446 | D31: =C31+(($H31-$C31)/5) -> 6641.9275 | E31: =D31+(($H31-$C31)/5) -> 6854.4103 | F31: =E31+(($H31-$C31)/5) -> 7066.8931 | G31: =F31+(($H31-$C31)/5) -> 7279.3759 | H31: =SUM(H29:H30) -> 7491.8587 | I31: =H31+(($M31-$H31)/5) -> 7443.7921 | J31: =I31+(($M31-$H31)/5) -> 7395.7255 | K31: =J31+(($M31-$H31)/5) -> 7347.6589 | L31: =K31+(($M31-$H31)/5) -> 7299.5923 | M31: =SUM(M29:M30) -> 7251.5257 | N31: =M31+(($R31-$M31)/5) -> 7212.2555 | O31: =N31+(($R31-$M31)/5) -> 7172.9854 | P31: =O31+(($R31-$M31)/5) -> 7133.7152 | Q31: =P31+(($R31-$M31)/5) -> 7094.445 | R31: =SUM(R29:R30) -> 7055.1748 | S31: =R31+(($W31-$R31)/5) -> 7042.2883 | T31: =S31+(($W31-$R31)/5) -> 7029.4018 | U31: =T31+(($W31-$R31)/5) -> 7016.5153 | V31: =U31+(($W31-$R31)/5) -> 7003.6287 | W31: =SUM(W29:W30) -> 6990.7422 | X31: =W31+(($AB31-$W31)/5) -> 7005.5145 | Y31: =X31+(($AB31-$W31)/5) -> 7020.2868 | Z31: =Y31+(($AB31-$W31)/5) -> 7035.0591 | AA31: =Z31+(($AB31-$W31)/5) -> 7049.8314 | AB31: =SUM(AB29:AB30) -> 7064.6038 | AC31: =AB31+(($AG31-$AB31)/5) -> 7126.7429 | AD31: =AC31+(($AG31-$AB31)/5) -> 7188.8821 | AE31: =AD31+(($AG31-$AB31)/5) -> 7251.0213 | AF31: =AE31+(($AG31-$AB31)/5) -> 7313.1605 | AG31: =SUM(AG29:AG30) -> 7375.2996
A32: ES | B32: Residential | C32: 15058.184 | D32: =C32+(($H32-$C32)/5) -> 14901.256 | E32: =D32+(($H32-$C32)/5) -> 14744.329 | F32: =E32+(($H32-$C32)/5) -> 14587.401 | G32: =F32+(($H32-$C32)/5) -> 14430.474 | H32: 14273.547 | I32: =H32+(($M32-$H32)/5) -> 14059.805 | J32: =I32+(($M32-$H32)/5) -> 13846.063 | K32: =J32+(($M32-$H32)/5) -> 13632.321 | L32: =K32+(($M32-$H32)/5) -> 13418.579 | M32: 13204.837 | N32: =M32+(($R32-$M32)/5) -> 13132.808 | O32: =N32+(($R32-$M32)/5) -> 13060.779 | P32: =O32+(($R32-$M32)/5) -> 12988.749 | Q32: =P32+(($R32-$M32)/5) -> 12916.72 | R32: 12844.691 | S32: =R32+(($W32-$R32)/5) -> 12795.87 | T32: =S32+(($W32-$R32)/5) -> 12747.05 | U32: =T32+(($W32-$R32)/5) -> 12698.23 | V32: =U32+(($W32-$R32)/5) -> 12649.41 | W32: 12600.589 | X32: =W32+(($AB32-$W32)/5) -> 12538.829 | Y32: =X32+(($AB32-$W32)/5) -> 12477.07 | Z32: =Y32+(($AB32-$W32)/5) -> 12415.31 | AA32: =Z32+(($AB32-$W32)/5) -> 12353.55 | AB32: 12291.79 | AC32: =AB32+(($AG32-$AB32)/5) -> 12226.237 | AD32: =AC32+(($AG32-$AB32)/5) -> 12160.685 | AE32: =AD32+(($AG32-$AB32)/5) -> 12095.133 | AF32: =AE32+(($AG32-$AB32)/5) -> 12029.58 | AG32: 11964.028
A33: ES | B33: Tertiary (8) | C33: 11593.017 | D33: =C33+(($H33-$C33)/5) -> 11646.037 | E33: =D33+(($H33-$C33)/5) -> 11699.057 | F33: =E33+(($H33-$C33)/5) -> 11752.077 | G33: =F33+(($H33-$C33)/5) -> 11805.097 | H33: 11858.118 | I33: =H33+(($M33-$H33)/5) -> 11887.023 | J33: =I33+(($M33-$H33)/5) -> 11915.928 | K33: =J33+(($M33-$H33)/5) -> 11944.834 | L33: =K33+(($M33-$H33)/5) -> 11973.739 | M33: 12002.645 | N33: =M33+(($R33-$M33)/5) -> 12094.44 | O33: =N33+(($R33-$M33)/5) -> 12186.236 | P33: =O33+(($R33-$M33)/5) -> 12278.031 | Q33: =P33+(($R33-$M33)/5) -> 12369.826 | R33: 12461.622 | S33: =R33+(($W33-$R33)/5) -> 12442.939 | T33: =S33+(($W33-$R33)/5) -> 12424.257 | U33: =T33+(($W33-$R33)/5) -> 12405.575 | V33: =U33+(($W33-$R33)/5) -> 12386.893 | W33: 12368.211 | X33: =W33+(($AB33-$W33)/5) -> 12305.155 | Y33: =X33+(($AB33-$W33)/5) -> 12242.098 | Z33: =Y33+(($AB33-$W33)/5) -> 12179.042 | AA33: =Z33+(($AB33-$W33)/5) -> 12115.985 | AB33: 12052.929 | AC33: =AB33+(($AG33-$AB33)/5) -> 11993.511 | AD33: =AC33+(($AG33-$AB33)/5) -> 11934.093 | AE33: =AD33+(($AG33-$AB33)/5) -> 11874.675 | AF33: =AE33+(($AG33-$AB33)/5) -> 11815.257 | AG33: 11755.839
A34: =A33 -> ES | B34: Buildings Total | C34: =SUM(C32:C33) -> 26651.2 | D34: =C34+(($H34-$C34)/5) -> 26547.293 | E34: =D34+(($H34-$C34)/5) -> 26443.386 | F34: =E34+(($H34-$C34)/5) -> 26339.479 | G34: =F34+(($H34-$C34)/5) -> 26235.571 | H34: =SUM(H32:H33) -> 26131.664 | I34: =H34+(($M34-$H34)/5) -> 25946.828 | J34: =I34+(($M34-$H34)/5) -> 25761.991 | K34: =J34+(($M34-$H34)/5) -> 25577.155 | L34: =K34+(($M34-$H34)/5) -> 25392.318 | M34: =SUM(M32:M33) -> 25207.482 | N34: =M34+(($R34-$M34)/5) -> 25227.248 | O34: =N34+(($R34-$M34)/5) -> 25247.014 | P34: =O34+(($R34-$M34)/5) -> 25266.78 | Q34: =P34+(($R34-$M34)/5) -> 25286.546 | R34: =SUM(R32:R33) -> 25306.312 | S34: =R34+(($W34-$R34)/5) -> 25238.81 | T34: =S34+(($W34-$R34)/5) -> 25171.308 | U34: =T34+(($W34-$R34)/5) -> 25103.805 | V34: =U34+(($W34-$R34)/5) -> 25036.303 | W34: =SUM(W32:W33) -> 24968.801 | X34: =W34+(($AB34-$W34)/5) -> 24843.984 | Y34: =X34+(($AB34-$W34)/5) -> 24719.168 | Z34: =Y34+(($AB34-$W34)/5) -> 24594.351 | AA34: =Z34+(($AB34-$W34)/5) -> 24469.535 | AB34: =SUM(AB32:AB33) -> 24344.718 | AC34: =AB34+(($AG34-$AB34)/5) -> 24219.748 | AD34: =AC34+(($AG34-$AB34)/5) -> 24094.778 | AE34: =AD34+(($AG34-$AB34)/5) -> 23969.808 | AF34: =AE34+(($AG34-$AB34)/5) -> 23844.838 | AG34: =SUM(AG32:AG33) -> 23719.867
A35: FI | B35: Residential | C35: 5584.3681 | D35: =C35+(($H35-$C35)/5) -> 5579.0827 | E35: =D35+(($H35-$C35)/5) -> 5573.7973 | F35: =E35+(($H35-$C35)/5) -> 5568.5119 | G35: =F35+(($H35-$C35)/5) -> 5563.2265 | H35: 5557.941 | I35: =H35+(($M35-$H35)/5) -> 5598.4997 | J35: =I35+(($M35-$H35)/5) -> 5639.0583 | K35: =J35+(($M35-$H35)/5) -> 5679.6169 | L35: =K35+(($M35-$H35)/5) -> 5720.1755 | M35: 5760.7341 | N35: =M35+(($R35-$M35)/5) -> 5750.9282 | O35: =N35+(($R35-$M35)/5) -> 5741.1222 | P35: =O35+(($R35-$M35)/5) -> 5731.3162 | Q35: =P35+(($R35-$M35)/5) -> 5721.5102 | R35: 5711.7042 | S35: =R35+(($W35-$R35)/5) -> 5712.2911 | T35: =S35+(($W35-$R35)/5) -> 5712.878 | U35: =T35+(($W35-$R35)/5) -> 5713.4648 | V35: =U35+(($W35-$R35)/5) -> 5714.0517 | W35: 5714.6386 | X35: =W35+(($AB35-$W35)/5) -> 5729.5289 | Y35: =X35+(($AB35-$W35)/5) -> 5744.4192 | Z35: =Y35+(($AB35-$W35)/5) -> 5759.3095 | AA35: =Z35+(($AB35-$W35)/5) -> 5774.1999 | AB35: 5789.0902 | AC35: =AB35+(($AG35-$AB35)/5) -> 5800.6121 | AD35: =AC35+(($AG35-$AB35)/5) -> 5812.134 | AE35: =AD35+(($AG35-$AB35)/5) -> 5823.6559 | AF35: =AE35+(($AG35-$AB35)/5) -> 5835.1778 | AG35: 5846.6997
A36: FI | B36: Tertiary (8) | C36: 3589.6814 | D36: =C36+(($H36-$C36)/5) -> 3690.1303 | E36: =D36+(($H36-$C36)/5) -> 3790.5793 | F36: =E36+(($H36-$C36)/5) -> 3891.0282 | G36: =F36+(($H36-$C36)/5) -> 3991.4771 | H36: 4091.926 | I36: =H36+(($M36-$H36)/5) -> 4080.0257 | J36: =I36+(($M36-$H36)/5) -> 4068.1254 | K36: =J36+(($M36-$H36)/5) -> 4056.2251 | L36: =K36+(($M36-$H36)/5) -> 4044.3248 | M36: 4032.4244 | N36: =M36+(($R36-$M36)/5) -> 4022.1604 | O36: =N36+(($R36-$M36)/5) -> 4011.8964 | P36: =O36+(($R36-$M36)/5) -> 4001.6324 | Q36: =P36+(($R36-$M36)/5) -> 3991.3684 | R36: 3981.1044 | S36: =R36+(($W36-$R36)/5) -> 3976.9902 | T36: =S36+(($W36-$R36)/5) -> 3972.8759 | U36: =T36+(($W36-$R36)/5) -> 3968.7617 | V36: =U36+(($W36-$R36)/5) -> 3964.6475 | W36: 3960.5332 | X36: =W36+(($AB36-$W36)/5) -> 3955.0592 | Y36: =X36+(($AB36-$W36)/5) -> 3949.5851 | Z36: =Y36+(($AB36-$W36)/5) -> 3944.1111 | AA36: =Z36+(($AB36-$W36)/5) -> 3938.6371 | AB36: 3933.163 | AC36: =AB36+(($AG36-$AB36)/5) -> 3933.4974 | AD36: =AC36+(($AG36-$AB36)/5) -> 3933.8317 | AE36: =AD36+(($AG36-$AB36)/5) -> 3934.1661 | AF36: =AE36+(($AG36-$AB36)/5) -> 3934.5004 | AG36: 3934.8347
