Workbook

Sheet Useful energy - all
A1: Useful energy stats in PJ after aggregation of sectors (based on JRC-IDEES 2021)
A3: Country | B3: Sector | C3: TECHNOLOGY | D3: 2018 | E3: 2019 | F3: 2020 | G3: 2021
A4: =LEFT(C4,2) -> AT | B4: =RIGHT(C4,1) -> I | C4: ATEINOILFC0I | D4: 0.033 | E4: 0.041 | F4: 0.0254 | G4: 0.0373
A5: =LEFT(C5,2) -> AT | B5: =RIGHT(C5,1) -> I | C5: ATEINCOAFC0I | D5: 2.8024 | E5: 4.0938 | F5: 4.2838 | G5: 4.2633
A6: =LEFT(C6,2) -> AT | B6: =RIGHT(C6,1) -> I | C6: ATEINCOAFCCI | D6: 0 | E6: 0 | F6: 0 | G6: 0
A7: =LEFT(C7,2) -> AT | B7: =RIGHT(C7,1) -> I | C7: ATEINNGSFC0I | D7: 11.9996 | E7: 12.0262 | F7: 11.4296 | G7: 11.5473
A8: =LEFT(C8,2) -> AT | B8: =RIGHT(C8,1) -> I | C8: ATEINNGSFCCI | D8: 0 | E8: 0 | F8: 0 | G8: 0
A9: =LEFT(C9,2) -> AT | B9: =RIGHT(C9,1) -> I | C9: ATEINBIOFC0I | D9: 0.0061 | E9: 0.0053 | F9: 0.006 | G9: 0.0068
A10: =LEFT(C10,2) -> AT | B10: =RIGHT(C10,1) -> I | C10: ATEINELCFC0I | D10: 5.449 | E10: 5.5274 | F10: 5.1102 | G10: 5.5114
A11: =LEFT(C11,2) -> AT | B11: =RIGHT(C11,1) -> I | C11: ATEINELCMC0I | D11: 0.9795 | E11: 1.0011 | F11: 0.952 | G11: 0.9409
A12: =LEFT(C12,2) -> AT | B12: =RIGHT(C12,1) -> I | C12: ATEINHY2FC0I | D12: 0 | E12: 0 | F12: 0 | G12: 0
A13: =LEFT(C13,2) -> AT | B13: =RIGHT(C13,1) -> I | C13: ATEINSTH000I | D13: 0 | E13: 0 | F13: 0 | G13: 0
A14: =LEFT(C14,2) -> AT | B14: =RIGHT(C14,1) -> I | C14: ATEINHEA000I | D14: 1.9664 | E14: 1.9638 | F14: 1.9006 | G14: 2.1878
A15: =LEFT(C15,2) -> AT | B15: =RIGHT(C15,1) -> C | C15: ATEINOILFC0C | D15: 0.2681 | E15: 0.2971 | F15: 0.3841 | G15: 0.2384
... A1389: =LEFT(C1389,2) -> SK | B1389: =RIGHT(C1389,1) -> O | C1389: SKEINHEA000O | D1389: 0.3601 | E1389: 0.5284 | F1389: 0.476 | G1389: 0.5343

Sheet Useful energy - mech
A1: Useful energy stats in PJ after aggregation of sectors (based on JRC-IDEES 2021)
F2: 3 | G2: 4 | H2: 5 | I2: 6 | J2: 7 | K2: 8 | L2: 9 | M2: 10 | N2: 11 | O2: 12 | P2: 13 | Q2: 14 | R2: 15 | S2: 16 | T2: 17 | U2: 18 | V2: 19 | W2: 20 | X2: 21 | Y2: 22 | Z2: 23 | AA2: 24 | AB2: 25 | AC2: 26 | AD2: 27 | AE2: 28 | AF2: 29 | AG2: 30 | AH2: 31 | AI2: 32 | AJ2: 33 | AK2: 34 | AL2: 35 | AM2: 36 | AN2: 37 | AO2: 38 | AP2: 39 | AQ2: 40 | AR2: 41
A3: Country | B3: Sector | C3: TECHNOLOGY | D3: Fuel | E3: 2021 | F3: 2022 | G3: 2023 | H3: 2024 | I3: 2025 | J3: 2026 | K3: 2027 | L3: 2028 | M3: 2029 | N3: 2030 | O3: 2031 | P3: 2032 | Q3: 2033 | R3: 2034 | S3: 2035 | T3: 2036 | U3: 2037 | V3: 2038 | W3: 2039 | X3: 2040 | Y3: 2041 | Z3: 2042 | AA3: 2043 | AB3: 2044 | AC3: 2045 | AD3: 2046 | AE3: 2047 | AF3: 2048 | AG3: 2049 | AH3: 2050 | AI3: 2051 | AJ3: 2052 | AK3: 2053 | AL3: 2054 | AM3: 2055 | AN3: 2056 | AO3: 2057 | AP3: 2058 | AQ3: 2059 | AR3: 2060
A4: EE | B4: W | C4: EEEINELCMC0W | D4: =A4&"IME"&B4 -> EEIMEW | E4: 0.6057 | F4: =E4*VLOOKUP($A4,'EU Ref Sc 2020 Other industries'!$A$5:$AE$33,F$2) -> 0.63107761 | G4: =F4*VLOOKUP($A4,'EU Ref Sc 2020 Other industries'!$A$5:$AE$33,G$2) -> 0.65645522 | H4: =G4*VLOOKUP($A4,'EU Ref Sc 2020 Other industries'!$A$5:$AE$33,H$2) -> 0.68183282 | I4: =H4*VLOOKUP($A4,'EU Ref Sc 2020 Other industries'!$A$5:$AE$33,I$2) -> 0.70721043 | J4: =I4*VLOOKUP($A4,'EU Ref Sc 2020 Other industries'!$A$5:$AE$33,J$2) -> 0.73242383 | K4: =J4*VLOOKUP($A4,'EU Ref Sc 2020 Other industries'!$A$5:$AE$33,K$2) -> 0.75763723 | L4: =K4*VLOOKUP($A4,'EU Ref Sc 2020 Other industries'!$A$5:$AE$33,L$2) -> 0.78285063 | M4: =L4*VLOOKUP($A4,'EU Ref Sc 2020 Other industries'!$A$5:$AE$33,M$2) -> 0.80806403 | ... AH4: =AG4*VLOOKUP($A4,'EU Ref Sc 2020 Other industries'!$A$5:$AE$33,AH$2) -> 0.80824734 | AI4: =AH4 -> 0.80824734 | AJ4: =AI4 -> 0.80824734 | AK4: =AJ4 -> 0.80824734 | AL4: =AK4 -> 0.80824734 | AM4: =AL4 -> 0.80824734 | AN4: =AM4 -> 0.80824734 | AO4: =AN4 -> 0.80824734 | AP4: =AO4 -> 0.80824734 | ... AR4: =AQ4 -> 0.80824734
A5: FI | B5: W | C5: FIEINELCMC0W | D5: =A5&"IME"&B5 -> FIIMEW | E5: 2.2304 | F5: =E5*VLOOKUP($A5,'EU Ref Sc 2020 Other industries'!$A$5:$AE$33,F$2) -> 2.3238493 | G5: =F5*VLOOKUP($A5,'EU Ref Sc 2020 Other industries'!$A$5:$AE$33,G$2) -> 2.4172985 | H5: =G5*VLOOKUP($A5,'EU Ref Sc 2020 Other industries'!$A$5:$AE$33,H$2) -> 2.5107478 | I5: =H5*VLOOKUP($A5,'EU Ref Sc 2020 Other industries'!$A$5:$AE$33,I$2) -> 2.604197 | J5: =I5*VLOOKUP($A5,'EU Ref Sc 2020 Other industries'!$A$5:$AE$33,J$2) -> 2.6970416 | K5: =J5*VLOOKUP($A5,'EU Ref Sc 2020 Other industries'!$A$5:$AE$33,K$2) -> 2.7898862 | L5: =K5*VLOOKUP($A5,'EU Ref Sc 2020 Other industries'!$A$5:$AE$33,L$2) -> 2.8827308 | M5: =L5*VLOOKUP($A5,'EU Ref Sc 2020 Other industries'!$A$5:$AE$33,M$2) -> 2.9755754 | ... AH5: =AG5*VLOOKUP($A5,'EU Ref Sc 2020 Other industries'!$A$5:$AE$33,AH$2) -> 2.9762504 | AI5: =AH5 -> 2.9762504 | AJ5: =AI5 -> 2.9762504 | AK5: =AJ5 -> 2.9762504 | AL5: =AK5 -> 2.9762504 | AM5: =AL5 -> 2.9762504 | AN5: =AM5 -> 2.9762504 | AO5: =AN5 -> 2.9762504 | AP5: =AO5 -> 2.9762504 | ... AR5: =AQ5 -> 2.9762504
A6: LT | B6: W | C6: LTEINELCMC0W | D6: =A6&"IME"&B6 -> LTIMEW | E6: 0.5267 | F6: =E6*VLOOKUP($A6,'EU Ref Sc 2020 Other industries'!$A$5:$AE$33,F$2) -> 0.54002851 | G6: =F6*VLOOKUP($A6,'EU Ref Sc 2020 Other industries'!$A$5:$AE$33,G$2) -> 0.55335702 | H6: =G6*VLOOKUP($A6,'EU Ref Sc 2020 Other industries'!$A$5:$AE$33,H$2) -> 0.56668552 | I6: =H6*VLOOKUP($A6,'EU Ref Sc 2020 Other industries'!$A$5:$AE$33,I$2) -> 0.58001403 | J6: =I6*VLOOKUP($A6,'EU Ref Sc 2020 Other industries'!$A$5:$AE$33,J$2) -> 0.57950226 | K6: =J6*VLOOKUP($A6,'EU Ref Sc 2020 Other industries'!$A$5:$AE$33,K$2) -> 0.57899048 | L6: =K6*VLOOKUP($A6,'EU Ref Sc 2020 Other industries'!$A$5:$AE$33,L$2) -> 0.57847871 | M6: =L6*VLOOKUP($A6,'EU Ref Sc 2020 Other industries'!$A$5:$AE$33,M$2) -> 0.57796693 | ... AH6: =AG6*VLOOKUP($A6,'EU Ref Sc 2020 Other industries'!$A$5:$AE$33,AH$2) -> 0.58974035 | AI6: =AH6 -> 0.58974035 | AJ6: =AI6 -> 0.58974035 | AK6: =AJ6 -> 0.58974035 | AL6: =AK6 -> 0.58974035 | AM6: =AL6 -> 0.58974035 | AN6: =AM6 -> 0.58974035 | AO6: =AN6 -> 0.58974035 | AP6: =AO6 -> 0.58974035 | ... AR6: =AQ6 -> 0.58974035
A7: LV | B7: W | C7: LVEINELCMC0W | D7: =A7&"IME"&B7 -> LVIMEW | E7: 1.2844 | F7: =E7*VLOOKUP($A7,'EU Ref Sc 2020 Other industries'!$A$5:$AE$33,F$2) -> 1.3014488 | G7: =F7*VLOOKUP($A7,'EU Ref Sc 2020 Other industries'!$A$5:$AE$33,G$2) -> 1.3184976 | H7: =G7*VLOOKUP($A7,'EU Ref Sc 2020 Other industries'!$A$5:$AE$33,H$2) -> 1.3355464 | I7: =H7*VLOOKUP($A7,'EU Ref Sc 2020 Other industries'!$A$5:$AE$33,I$2) -> 1.3525952 | J7: =I7*VLOOKUP($A7,'EU Ref Sc 2020 Other industries'!$A$5:$AE$33,J$2) -> 1.3534645 | K7: =J7*VLOOKUP($A7,'EU Ref Sc 2020 Other industries'!$A$5:$AE$33,K$2) -> 1.3543339 | L7: =K7*VLOOKUP($A7,'EU Ref Sc 2020 Other industries'!$A$5:$AE$33,L$2) -> 1.3552032 | M7: =L7*VLOOKUP($A7,'EU Ref Sc 2020 Other industries'!$A$5:$AE$33,M$2) -> 1.3560725 | ... AH7: =AG7*VLOOKUP($A7,'EU Ref Sc 2020 Other industries'!$A$5:$AE$33,AH$2) -> 1.1410078 | AI7: =AH7 -> 1.1410078 | AJ7: =AI7 -> 1.1410078 | AK7: =AJ7 -> 1.1410078 | AL7: =AK7 -> 1.1410078 | AM7: =AL7 -> 1.1410078 | AN7: =AM7 -> 1.1410078 | AO7: =AN7 -> 1.1410078 | AP7: =AO7 -> 1.1410078 | ... AR7: =AQ7 -> 1.1410078
A8: AT | B8: P | C8: ATEINELCMC0P | D8: =A8&"IME"&B8 -> ATIMEP | E8: 4.2201 | F8: =E8*VLOOKUP($A8,'EU Ref Sc 2020 Energy intensive'!$A$5:$AE$33,F$2) -> 4.2518206 | G8: =F8*VLOOKUP($A8,'EU Ref Sc 2020 Energy intensive'!$A$5:$AE$33,G$2) -> 4.2835412 | H8: =G8*VLOOKUP($A8,'EU Ref Sc 2020 Energy intensive'!$A$5:$AE$33,H$2) -> 4.3152619 | I8: =H8*VLOOKUP($A8,'EU Ref Sc 2020 Energy intensive'!$A$5:$AE$33,I$2) -> 4.3469825 | J8: =I8*VLOOKUP($A8,'EU Ref Sc 2020 Energy intensive'!$A$5:$AE$33,J$2) -> 4.3130636 | K8: =J8*VLOOKUP($A8,'EU Ref Sc 2020 Energy intensive'!$A$5:$AE$33,K$2) -> 4.2791447 | L8: =K8*VLOOKUP($A8,'EU Ref Sc 2020 Energy intensive'!$A$5:$AE$33,L$2) -> 4.2452258 | M8: =L8*VLOOKUP($A8,'EU Ref Sc 2020 Energy intensive'!$A$5:$AE$33,M$2) -> 4.2113068 | ... AH8: =AG8*VLOOKUP($A8,'EU Ref Sc 2020 Energy intensive'!$A$5:$AE$33,AH$2) -> 3.6208313 | AI8: =AH8 -> 3.6208313 | AJ8: =AI8 -> 3.6208313 | AK8: =AJ8 -> 3.6208313 | AL8: =AK8 -> 3.6208313 | AM8: =AL8 -> 3.6208313 | AN8: =AM8 -> 3.6208313 | AO8: =AN8 -> 3.6208313 | AP8: =AO8 -> 3.6208313 | ... AR8: =AQ8 -> 3.6208313
A9: CZ | B9: P | C9: CZEINELCMC0P | D9: =A9&"IME"&B9 -> CZIMEP | E9: 2.1454 | F9: =E9*VLOOKUP($A9,'EU Ref Sc 2020 Energy intensive'!$A$5:$AE$33,F$2) -> 2.1506705 | G9: =F9*VLOOKUP($A9,'EU Ref Sc 2020 Energy intensive'!$A$5:$AE$33,G$2) -> 2.1559409 | H9: =G9*VLOOKUP($A9,'EU Ref Sc 2020 Energy intensive'!$A$5:$AE$33,H$2) -> 2.1612114 | I9: =H9*VLOOKUP($A9,'EU Ref Sc 2020 Energy intensive'!$A$5:$AE$33,I$2) -> 2.1664819 | J9: =I9*VLOOKUP($A9,'EU Ref Sc 2020 Energy intensive'!$A$5:$AE$33,J$2) -> 2.1258421 | K9: =J9*VLOOKUP($A9,'EU Ref Sc 2020 Energy intensive'!$A$5:$AE$33,K$2) -> 2.0852024 | L9: =K9*VLOOKUP($A9,'EU Ref Sc 2020 Energy intensive'!$A$5:$AE$33,L$2) -> 2.0445626 | M9: =L9*VLOOKUP($A9,'EU Ref Sc 2020 Energy intensive'!$A$5:$AE$33,M$2) -> 2.0039229 | ... AH9: =AG9*VLOOKUP($A9,'EU Ref Sc 2020 Energy intensive'!$A$5:$AE$33,AH$2) -> 1.6913782 | AI9: =AH9 -> 1.6913782 | AJ9: =AI9 -> 1.6913782 | AK9: =AJ9 -> 1.6913782 | AL9: =AK9 -> 1.6913782 | AM9: =AL9 -> 1.6913782 | AN9: =AM9 -> 1.6913782 | AO9: =AN9 -> 1.6913782 | AP9: =AO9 -> 1.6913782 | ... AR9: =AQ9 -> 1.6913782
A10: DE | B10: P | C10: DEEINELCMC0P | D10: =A10&"IME"&B10 -> DEIMEP | E10: 17.7868 | F10: =E10*VLOOKUP($A10,'EU Ref Sc 2020 Energy intensive'!$A$5:$AE$33,F$2) -> 17.899302 | G10: =F10*VLOOKUP($A10,'EU Ref Sc 2020 Energy intensive'!$A$5:$AE$33,G$2) -> 18.011804 | H10: =G10*VLOOKUP($A10,'EU Ref Sc 2020 Energy intensive'!$A$5:$AE$33,H$2) -> 18.124307 | I10: =H10*VLOOKUP($A10,'EU Ref Sc 2020 Energy intensive'!$A$5:$AE$33,I$2) -> 18.236809 | J10: =I10*VLOOKUP($A10,'EU Ref Sc 2020 Energy intensive'!$A$5:$AE$33,J$2) -> 18.012968 | K10: =J10*VLOOKUP($A10,'EU Ref Sc 2020 Energy intensive'!$A$5:$AE$33,K$2) -> 17.789127 | L10: =K10*VLOOKUP($A10,'EU Ref Sc 2020 Energy intensive'!$A$5:$AE$33,L$2) -> 17.565286 | M10: =L10*VLOOKUP($A10,'EU Ref Sc 2020 Energy intensive'!$A$5:$AE$33,M$2) -> 17.341444 | ... AH10: =AG10*VLOOKUP($A10,'EU Ref Sc 2020 Energy intensive'!$A$5:$AE$33,AH$2) -> 14.131633 | AI10: =AH10 -> 14.131633 | AJ10: =AI10 -> 14.131633 | AK10: =AJ10 -> 14.131633 | AL10: =AK10 -> 14.131633 | AM10: =AL10 -> 14.131633 | AN10: =AM10 -> 14.131633 | AO10: =AN10 -> 14.131633 | AP10: =AO10 -> 14.131633 | ... AR10: =AQ10 -> 14.131633
A11: EE | B11: P | C11: EEEINELCMC0P | D11: =A11&"IME"&B11 -> EEIMEP | E11: 0.399 | F11: =E11*VLOOKUP($A11,'EU Ref Sc 2020 Energy intensive'!$A$5:$AE$33,F$2) -> 0.41734826 | G11: =F11*VLOOKUP($A11,'EU Ref Sc 2020 Energy intensive'!$A$5:$AE$33,G$2) -> 0.43569653 | H11: =G11*VLOOKUP($A11,'EU Ref Sc 2020 Energy intensive'!$A$5:$AE$33,H$2) -> 0.45404479 | I11: =H11*VLOOKUP($A11,'EU Ref Sc 2020 Energy intensive'!$A$5:$AE$33,I$2) -> 0.47239305 | J11: =I11*VLOOKUP($A11,'EU Ref Sc 2020 Energy intensive'!$A$5:$AE$33,J$2) -> 0.47474324 | K11: =J11*VLOOKUP($A11,'EU Ref Sc 2020 Energy intensive'!$A$5:$AE$33,K$2) -> 0.47709343 | L11: =K11*VLOOKUP($A11,'EU Ref Sc 2020 Energy intensive'!$A$5:$AE$33,L$2) -> 0.47944362 | M11: =L11*VLOOKUP($A11,'EU Ref Sc 2020 Energy intensive'!$A$5:$AE$33,M$2) -> 0.48179381 | ... AH11: =AG11*VLOOKUP($A11,'EU Ref Sc 2020 Energy intensive'!$A$5:$AE$33,AH$2) -> 0.39608865 | AI11: =AH11 -> 0.39608865 | AJ11: =AI11 -> 0.39608865 | AK11: =AJ11 -> 0.39608865 | AL11: =AK11 -> 0.39608865 | AM11: =AL11 -> 0.39608865 | AN11: =AM11 -> 0.39608865 | AO11: =AN11 -> 0.39608865 | AP11: =AO11 -> 0.39608865 | ... AR11: =AQ11 -> 0.39608865
A12: FI | B12: P | C12: FIEINELCMC0P | D12: =A12&"IME"&B12 -> FIIMEP | E12: 15.5816 | F12: =E12*VLOOKUP($A12,'EU Ref Sc 2020 Energy intensive'!$A$5:$AE$33,F$2) -> 16.29813 | G12: =F12*VLOOKUP($A12,'EU Ref Sc 2020 Energy intensive'!$A$5:$AE$33,G$2) -> 17.014659 | H12: =G12*VLOOKUP($A12,'EU Ref Sc 2020 Energy intensive'!$A$5:$AE$33,H$2) -> 17.731189 | I12: =H12*VLOOKUP($A12,'EU Ref Sc 2020 Energy intensive'!$A$5:$AE$33,I$2) -> 18.447718 | J12: =I12*VLOOKUP($A12,'EU Ref Sc 2020 Energy intensive'!$A$5:$AE$33,J$2) -> 18.539497 | K12: =J12*VLOOKUP($A12,'EU Ref Sc 2020 Energy intensive'!$A$5:$AE$33,K$2) -> 18.631276 | L12: =K12*VLOOKUP($A12,'EU Ref Sc 2020 Energy intensive'!$A$5:$AE$33,L$2) -> 18.723054 | M12: =L12*VLOOKUP($A12,'EU Ref Sc 2020 Energy intensive'!$A$5:$AE$33,M$2) -> 18.814833 | ... AH12: =AG12*VLOOKUP($A12,'EU Ref Sc 2020 Energy intensive'!$A$5:$AE$33,AH$2) -> 15.467907 | AI12: =AH12 -> 15.467907 | AJ12: =AI12 -> 15.467907 | AK12: =AJ12 -> 15.467907 | AL12: =AK12 -> 15.467907 | AM12: =AL12 -> 15.467907 | AN12: =AM12 -> 15.467907 | AO12: =AN12 -> 15.467907 | AP12: =AO12 -> 15.467907 | ... AR12: =AQ12 -> 15.467907
A13: FR | B13: P | C13: FREINELCMC0P | D13: =A13&"IME"&B13 -> FRIMEP | E13: 7.0568 | F13: =E13*VLOOKUP($A13,'EU Ref Sc 2020 Energy intensive'!$A$5:$AE$33,F$2) -> 7.3813113 | G13: =F13*VLOOKUP($A13,'EU Ref Sc 2020 Energy intensive'!$A$5:$AE$33,G$2) -> 7.7058227 | H13: =G13*VLOOKUP($A13,'EU Ref Sc 2020 Energy intensive'!$A$5:$AE$33,H$2) -> 8.030334 | I13: =H13*VLOOKUP($A13,'EU Ref Sc 2020 Energy intensive'!$A$5:$AE$33,I$2) -> 8.3548453 | J13: =I13*VLOOKUP($A13,'EU Ref Sc 2020 Energy intensive'!$A$5:$AE$33,J$2) -> 8.3964113 | K13: =J13*VLOOKUP($A13,'EU Ref Sc 2020 Energy intensive'!$A$5:$AE$33,K$2) -> 8.4379773 | L13: =K13*VLOOKUP($A13,'EU Ref Sc 2020 Energy intensive'!$A$5:$AE$33,L$2) -> 8.4795432 | M13: =L13*VLOOKUP($A13,'EU Ref Sc 2020 Energy intensive'!$A$5:$AE$33,M$2) -> 8.5211092 | ... AH13: =AG13*VLOOKUP($A13,'EU Ref Sc 2020 Energy intensive'!$A$5:$AE$33,AH$2) -> 7.0053091 | AI13: =AH13 -> 7.0053091 | AJ13: =AI13 -> 7.0053091 | AK13: =AJ13 -> 7.0053091 | AL13: =AK13 -> 7.0053091 | AM13: =AL13 -> 7.0053091 | AN13: =AM13 -> 7.0053091 | AO13: =AN13 -> 7.0053091 | AP13: =AO13 -> 7.0053091 | ... AR13: =AQ13 -> 7.0053091
A14: HR | B14: P | C14: HREINELCMC0P | D14: =A14&"IME"&B14 -> HRIMEP | E14: 0.5162 | F14: =E14*VLOOKUP($A14,'EU Ref Sc 2020 Energy intensive'!$A$5:$AE$33,F$2) -> 0.52195412 | G14: =F14*VLOOKUP($A14,'EU Ref Sc 2020 Energy intensive'!$A$5:$AE$33,G$2) -> 0.52770825 | H14: =G14*VLOOKUP($A14,'EU Ref Sc 2020 Energy intensive'!$A$5:$AE$33,H$2) -> 0.53346237 | I14: =H14*VLOOKUP($A14,'EU Ref Sc 2020 Energy intensive'!$A$5:$AE$33,I$2) -> 0.53921649 | J14: =I14*VLOOKUP($A14,'EU Ref Sc 2020 Energy intensive'!$A$5:$AE$33,J$2) -> 0.52989743 | K14: =J14*VLOOKUP($A14,'EU Ref Sc 2020 Energy intensive'!$A$5:$AE$33,K$2) -> 0.52057836 | L14: =K14*VLOOKUP($A14,'EU Ref Sc 2020 Energy intensive'!$A$5:$AE$33,L$2) -> 0.51125929 | M14: =L14*VLOOKUP($A14,'EU Ref Sc 2020 Energy intensive'!$A$5:$AE$33,M$2) -> 0.50194022 | ... AH14: =AG14*VLOOKUP($A14,'EU Ref Sc 2020 Energy intensive'!$A$5:$AE$33,AH$2) -> 0.49966947 | AI14: =AH14 -> 0.49966947 | AJ14: =AI14 -> 0.49966947 | AK14: =AJ14 -> 0.49966947 | AL14: =AK14 -> 0.49966947 | AM14: =AL14 -> 0.49966947 | AN14: =AM14 -> 0.49966947 | AO14: =AN14 -> 0.49966947 | AP14: =AO14 -> 0.49966947 | ... AR14: =AQ14 -> 0.49966947
A15: PT | B15: P | C15: PTEINELCMC0P | D15: =A15&"IME"&B15 -> PTIMEP | E15: 3.4079 | F15: =E15*VLOOKUP($A15,'EU Ref Sc 2020 Energy intensive'!$A$5:$AE$33,F$2) -> 3.4075643 | G15: =F15*VLOOKUP($A15,'EU Ref Sc 2020 Energy intensive'!$A$5:$AE$33,G$2) -> 3.4072286 | H15: =G15*VLOOKUP($A15,'EU Ref Sc 2020 Energy intensive'!$A$5:$AE$33,H$2) -> 3.4068929 | I15: =H15*VLOOKUP($A15,'EU Ref Sc 2020 Energy intensive'!$A$5:$AE$33,I$2) -> 3.4065572 | J15: =I15*VLOOKUP($A15,'EU Ref Sc 2020 Energy intensive'!$A$5:$AE$33,J$2) -> 3.3791756 | K15: =J15*VLOOKUP($A15,'EU Ref Sc 2020 Energy intensive'!$A$5:$AE$33,K$2) -> 3.3517939 | L15: =K15*VLOOKUP($A15,'EU Ref Sc 2020 Energy intensive'!$A$5:$AE$33,L$2) -> 3.3244123 | M15: =L15*VLOOKUP($A15,'EU Ref Sc 2020 Energy intensive'!$A$5:$AE$33,M$2) -> 3.2970306 | ... AH15: =AG15*VLOOKUP($A15,'EU Ref Sc 2020 Energy intensive'!$A$5:$AE$33,AH$2) -> 2.4646054 | AI15: =AH15 -> 2.4646054 | AJ15: =AI15 -> 2.4646054 | AK15: =AJ15 -> 2.4646054 | AL15: =AK15 -> 2.4646054 | AM15: =AL15 -> 2.4646054 | AN15: =AM15 -> 2.4646054 | AO15: =AN15 -> 2.4646054 | AP15: =AO15 -> 2.4646054 | ... AR15: =AQ15 -> 2.4646054
A16: SE | B16: P | C16: SEEINELCMC0P | D16: =A16&"IME"&B16 -> SEIMEP | E16: 16.8095 | F16: =E16*VLOOKUP($A16,'EU Ref Sc 2020 Energy intensive'!$A$5:$AE$33,F$2) -> 16.808332 | G16: =F16*VLOOKUP($A16,'EU Ref Sc 2020 Energy intensive'!$A$5:$AE$33,G$2) -> 16.807164 | H16: =G16*VLOOKUP($A16,'EU Ref Sc 2020 Energy intensive'!$A$5:$AE$33,H$2) -> 16.805996 | I16: =H16*VLOOKUP($A16,'EU Ref Sc 2020 Energy intensive'!$A$5:$AE$33,I$2) -> 16.804828 | J16: =I16*VLOOKUP($A16,'EU Ref Sc 2020 Energy intensive'!$A$5:$AE$33,J$2) -> 16.782961 | K16: =J16*VLOOKUP($A16,'EU Ref Sc 2020 Energy intensive'!$A$5:$AE$33,K$2) -> 16.761095 | L16: =K16*VLOOKUP($A16,'EU Ref Sc 2020 Energy intensive'!$A$5:$AE$33,L$2) -> 16.739228 | M16: =L16*VLOOKUP($A16,'EU Ref Sc 2020 Energy intensive'!$A$5:$AE$33,M$2) -> 16.717362 | ... AH16: =AG16*VLOOKUP($A16,'EU Ref Sc 2020 Energy intensive'!$A$5:$AE$33,AH$2) -> 13.590735 | AI16: =AH16 -> 13.590735 | AJ16: =AI16 -> 13.590735 | AK16: =AJ16 -> 13.590735 | AL16: =AK16 -> 13.590735 | AM16: =AL16 -> 13.590735 | AN16: =AM16 -> 13.590735 | AO16: =AN16 -> 13.590735 | AP16: =AO16 -> 13.590735 | ... AR16: =AQ16 -> 13.590735
A17: SK | B17: P | C17: SKEINELCMC0P | D17: =A17&"IME"&B17 -> SKIMEP | E17: 1.2402 | F17: =E17*VLOOKUP($A17,'EU Ref Sc 2020 Energy intensive'!$A$5:$AE$33,F$2) -> 1.2449537 | G17: =F17*VLOOKUP($A17,'EU Ref Sc 2020 Energy intensive'!$A$5:$AE$33,G$2) -> 1.2497074 | H17: =G17*VLOOKUP($A17,'EU Ref Sc 2020 Energy intensive'!$A$5:$AE$33,H$2) -> 1.2544611 | I17: =H17*VLOOKUP($A17,'EU Ref Sc 2020 Energy intensive'!$A$5:$AE$33,I$2) -> 1.2592148 | J17: =I17*VLOOKUP($A17,'EU Ref Sc 2020 Energy intensive'!$A$5:$AE$33,J$2) -> 1.2460362 | K17: =J17*VLOOKUP($A17,'EU Ref Sc 2020 Energy intensive'!$A$5:$AE$33,K$2) -> 1.2328576 | L17: =K17*VLOOKUP($A17,'EU Ref Sc 2020 Energy intensive'!$A$5:$AE$33,L$2) -> 1.219679 | M17: =L17*VLOOKUP($A17,'EU Ref Sc 2020 Energy intensive'!$A$5:$AE$33,M$2) -> 1.2065004 | ... AH17: =AG17*VLOOKUP($A17,'EU Ref Sc 2020 Energy intensive'!$A$5:$AE$33,AH$2) -> 0.89146751 | AI17: =AH17 -> 0.89146751 | AJ17: =AI17 -> 0.89146751 | AK17: =AJ17 -> 0.89146751 | AL17: =AK17 -> 0.89146751 | AM17: =AL17 -> 0.89146751 | AN17: =AM17 -> 0.89146751 | AO17: =AN17 -> 0.89146751 | AP17: =AO17 -> 0.89146751 | ... AR17: =AQ17 -> 0.89146751
A18: AT | B18: O | C18: ATEINELCMC0O | D18: =A18&"IME"&B18 -> ATIMEO | E18: 14.5245 | F18: =E18*VLOOKUP($A18,'EU Ref Sc 2020 Other industries'!$A$5:$AE$33,F$2) -> 14.753361 | G18: =F18*VLOOKUP($A18,'EU Ref Sc 2020 Other industries'!$A$5:$AE$33,G$2) -> 14.982221 | H18: =G18*VLOOKUP($A18,'EU Ref Sc 2020 Other industries'!$A$5:$AE$33,H$2) -> 15.211082 | I18: =H18*VLOOKUP($A18,'EU Ref Sc 2020 Other industries'!$A$5:$AE$33,I$2) -> 15.439942 | J18: =I18*VLOOKUP($A18,'EU Ref Sc 2020 Other industries'!$A$5:$AE$33,J$2) -> 15.334296 | K18: =J18*VLOOKUP($A18,'EU Ref Sc 2020 Other industries'!$A$5:$AE$33,K$2) -> 15.22865 | L18: =K18*VLOOKUP($A18,'EU Ref Sc 2020 Other industries'!$A$5:$AE$33,L$2) -> 15.123003 | M18: =L18*VLOOKUP($A18,'EU Ref Sc 2020 Other industries'!$A$5:$AE$33,M$2) -> 15.017357 | ... AH18: =AG18*VLOOKUP($A18,'EU Ref Sc 2020 Other industries'!$A$5:$AE$33,AH$2) -> 18.261408 | AI18: =AH18 -> 18.261408 | AJ18: =AI18 -> 18.261408 | AK18: =AJ18 -> 18.261408 | AL18: =AK18 -> 18.261408 | AM18: =AL18 -> 18.261408 | AN18: =AM18 -> 18.261408 | AO18: =AN18 -> 18.261408 | AP18: =AO18 -> 18.261408 | ... AR18: =AQ18 -> 18.261408
A19: BE | B19: O | C19: BEEINELCMC0O | D19: =A19&"IME"&B19 -> BEIMEO | E19: 13.0382 | F19: =E19*VLOOKUP($A19,'EU Ref Sc 2020 Other industries'!$A$5:$AE$33,F$2) -> 13.377704 | G19: =F19*VLOOKUP($A19,'EU Ref Sc 2020 Other industries'!$A$5:$AE$33,G$2) -> 13.717207 | H19: =G19*VLOOKUP($A19,'EU Ref Sc 2020 Other industries'!$A$5:$AE$33,H$2) -> 14.056711 | I19: =H19*VLOOKUP($A19,'EU Ref Sc 2020 Other industries'!$A$5:$AE$33,I$2) -> 14.396215 | J19: =I19*VLOOKUP($A19,'EU Ref Sc 2020 Other industries'!$A$5:$AE$33,J$2) -> 14.346148 | K19: =J19*VLOOKUP($A19,'EU Ref Sc 2020 Other industries'!$A$5:$AE$33,K$2) -> 14.296081 | L19: =K19*VLOOKUP($A19,'EU Ref Sc 2020 Other industries'!$A$5:$AE$33,L$2) -> 14.246014 | M19: =L19*VLOOKUP($A19,'EU Ref Sc 2020 Other industries'!$A$5:$AE$33,M$2) -> 14.195948 | ... AH19: =AG19*VLOOKUP($A19,'EU Ref Sc 2020 Other industries'!$A$5:$AE$33,AH$2) -> 15.277446 | AI19: =AH19 -> 15.277446 | AJ19: =AI19 -> 15.277446 | AK19: =AJ19 -> 15.277446 | AL19: =AK19 -> 15.277446 | AM19: =AL19 -> 15.277446 | AN19: =AM19 -> 15.277446 | AO19: =AN19 -> 15.277446 | AP19: =AO19 -> 15.277446 | ... AR19: =AQ19 -> 15.277446
A20: BG | B20: O | C20: BGEINELCMC0O | D20: =A20&"IME"&B20 -> BGIMEO | E20: 5.4743 | F20: =E20*VLOOKUP($A20,'EU Ref Sc 2020 Other industries'!$A$5:$AE$33,F$2) -> 5.6672846 | G20: =F20*VLOOKUP($A20,'EU Ref Sc 2020 Other industries'!$A$5:$AE$33,G$2) -> 5.8602691 | H20: =G20*VLOOKUP($A20,'EU Ref Sc 2020 Other industries'!$A$5:$AE$33,H$2) -> 6.0532537 | I20: =H20*VLOOKUP($A20,'EU Ref Sc 2020 Other industries'!$A$5:$AE$33,I$2) -> 6.2462382 | J20: =I20*VLOOKUP($A20,'EU Ref Sc 2020 Other industries'!$A$5:$AE$33,J$2) -> 6.4315634 | K20: =J20*VLOOKUP($A20,'EU Ref Sc 2020 Other industries'!$A$5:$AE$33,K$2) -> 6.6168886 | L20: =K20*VLOOKUP($A20,'EU Ref Sc 2020 Other industries'!$A$5:$AE$33,L$2) -> 6.8022138 | M20: =L20*VLOOKUP($A20,'EU Ref Sc 2020 Other industries'!$A$5:$AE$33,M$2) -> 6.987539 | ... AH20: =AG20*VLOOKUP($A20,'EU Ref Sc 2020 Other industries'!$A$5:$AE$33,AH$2) -> 7.1231774 | AI20: =AH20 -> 7.1231774 | AJ20: =AI20 -> 7.1231774 | AK20: =AJ20 -> 7.1231774 | AL20: =AK20 -> 7.1231774 | AM20: =AL20 -> 7.1231774 | AN20: =AM20 -> 7.1231774 | AO20: =AN20 -> 7.1231774 | AP20: =AO20 -> 7.1231774 | ... AR20: =AQ20 -> 7.1231774
A21: CY | B21: O | C21: CYEINELCMC0O | D21: =A21&"IME"&B21 -> CYIMEO | E21: 0.342 | F21: =E21*VLOOKUP($A21,'EU Ref Sc 2020 Other industries'!$A$5:$AE$33,F$2) -> 0.34593815 | G21: =F21*VLOOKUP($A21,'EU Ref Sc 2020 Other industries'!$A$5:$AE$33,G$2) -> 0.3498763 | H21: =G21*VLOOKUP($A21,'EU Ref Sc 2020 Other industries'!$A$5:$AE$33,H$2) -> 0.35381445 | I21: =H21*VLOOKUP($A21,'EU Ref Sc 2020 Other industries'!$A$5:$AE$33,I$2) -> 0.3577526 | J21: =I21*VLOOKUP($A21,'EU Ref Sc 2020 Other industries'!$A$5:$AE$33,J$2) -> 0.35217754 | K21: =J21*VLOOKUP($A21,'EU Ref Sc 2020 Other industries'!$A$5:$AE$33,K$2) -> 0.34660248 | L21: =K21*VLOOKUP($A21,'EU Ref Sc 2020 Other industries'!$A$5:$AE$33,L$2) -> 0.34102741 | M21: =L21*VLOOKUP($A21,'EU Ref Sc 2020 Other industries'!$A$5:$AE$33,M$2) -> 0.33545235 | ... AH21: =AG21*VLOOKUP($A21,'EU Ref Sc 2020 Other industries'!$A$5:$AE$33,AH$2) -> 0.34911513 | AI21: =AH21 -> 0.34911513 | AJ21: =AI21 -> 0.34911513 | AK21: =AJ21 -> 0.34911513 | AL21: =AK21 -> 0.34911513 | AM21: =AL21 -> 0.34911513 | AN21: =AM21 -> 0.34911513 | AO21: =AN21 -> 0.34911513 | AP21: =AO21 -> 0.34911513 | ... AR21: =AQ21 -> 0.34911513
A22: CZ | B22: O | C22: CZEINELCMC0O | D22: =A22&"IME"&B22 -> CZIMEO | E22: 16.8775 | F22: =E22*VLOOKUP($A22,'EU Ref Sc 2020 Other industries'!$A$5:$AE$33,F$2) -> 17.435175 | G22: =F22*VLOOKUP($A22,'EU Ref Sc 2020 Other industries'!$A$5:$AE$33,G$2) -> 17.992849 | H22: =G22*VLOOKUP($A22,'EU Ref Sc 2020 Other industries'!$A$5:$AE$33,H$2) -> 18.550524 | I22: =H22*VLOOKUP($A22,'EU Ref Sc 2020 Other industries'!$A$5:$AE$33,I$2) -> 19.108199 | J22: =I22*VLOOKUP($A22,'EU Ref Sc 2020 Other industries'!$A$5:$AE$33,J$2) -> 19.281008 | K22: =J22*VLOOKUP($A22,'EU Ref Sc 2020 Other industries'!$A$5:$AE$33,K$2) -> 19.453816 | L22: =K22*VLOOKUP($A22,'EU Ref Sc 2020 Other industries'!$A$5:$AE$33,L$2) -> 19.626625 | M22: =L22*VLOOKUP($A22,'EU Ref Sc 2020 Other industries'!$A$5:$AE$33,M$2) -> 19.799434 | ... AH22: =AG22*VLOOKUP($A22,'EU Ref Sc 2020 Other industries'!$A$5:$AE$33,AH$2) -> 22.329687 | AI22: =AH22 -> 22.329687 | AJ22: =AI22 -> 22.329687 | AK22: =AJ22 -> 22.329687 | AL22: =AK22 -> 22.329687 | AM22: =AL22 -> 22.329687 | AN22: =AM22 -> 22.329687 | AO22: =AN22 -> 22.329687 | AP22: =AO22 -> 22.329687 | ... AR22: =AQ22 -> 22.329687
A23: DE | B23: O | C23: DEEINELCMC0O | D23: =A23&"IME"&B23 -> DEIMEO | E23: 121.4039 | F23: =E23*VLOOKUP($A23,'EU Ref Sc 2020 Other industries'!$A$5:$AE$33,F$2) -> 122.10905 | G23: =F23*VLOOKUP($A23,'EU Ref Sc 2020 Other industries'!$A$5:$AE$33,G$2) -> 122.8142 | H23: =G23*VLOOKUP($A23,'EU Ref Sc 2020 Other industries'!$A$5:$AE$33,H$2) -> 123.51935 | I23: =H23*VLOOKUP($A23,'EU Ref Sc 2020 Other industries'!$A$5:$AE$33,I$2) -> 124.2245 | J23: =I23*VLOOKUP($A23,'EU Ref Sc 2020 Other industries'!$A$5:$AE$33,J$2) -> 122.7873 | K23: =J23*VLOOKUP($A23,'EU Ref Sc 2020 Other industries'!$A$5:$AE$33,K$2) -> 121.35011 | L23: =K23*VLOOKUP($A23,'EU Ref Sc 2020 Other industries'!$A$5:$AE$33,L$2) -> 119.91291 | M23: =L23*VLOOKUP($A23,'EU Ref Sc 2020 Other industries'!$A$5:$AE$33,M$2) -> 118.47572 | ... AH23: =AG23*VLOOKUP($A23,'EU Ref Sc 2020 Other industries'!$A$5:$AE$33,AH$2) -> 113.71507 | AI23: =AH23 -> 113.71507 | AJ23: =AI23 -> 113.71507 | AK23: =AJ23 -> 113.71507 | AL23: =AK23 -> 113.71507 | AM23: =AL23 -> 113.71507 | AN23: =AM23 -> 113.71507 | AO23: =AN23 -> 113.71507 | AP23: =AO23 -> 113.71507 | ... AR23: =AQ23 -> 113.71507
A24: DK | B24: O | C24: DKEINELCMC0O | D24: =A24&"IME"&B24 -> DKIMEO | E24: 3.0503 | F24: =E24*VLOOKUP($A24,'EU Ref Sc 2020 Other industries'!$A$5:$AE$33,F$2) -> 3.0905729 | G24: =F24*VLOOKUP($A24,'EU Ref Sc 2020 Other industries'!$A$5:$AE$33,G$2) -> 3.1308458 | H24: =G24*VLOOKUP($A24,'EU Ref Sc 2020 Other industries'!$A$5:$AE$33,H$2) -> 3.1711187 | I24: =H24*VLOOKUP($A24,'EU Ref Sc 2020 Other industries'!$A$5:$AE$33,I$2) -> 3.2113917 | J24: =I24*VLOOKUP($A24,'EU Ref Sc 2020 Other industries'!$A$5:$AE$33,J$2) -> 3.3249756 | K24: =J24*VLOOKUP($A24,'EU Ref Sc 2020 Other industries'!$A$5:$AE$33,K$2) -> 3.4385595 | L24: =K24*VLOOKUP($A24,'EU Ref Sc 2020 Other industries'!$A$5:$AE$33,L$2) -> 3.5521435 | M24: =L24*VLOOKUP($A24,'EU Ref Sc 2020 Other industries'!$A$5:$AE$33,M$2) -> 3.6657274 | ... AH24: =AG24*VLOOKUP($A24,'EU Ref Sc 2020 Other industries'!$A$5:$AE$33,AH$2) -> 4.4793586 | AI24: =AH24 -> 4.4793586 | AJ24: =AI24 -> 4.4793586 | AK24: =AJ24 -> 4.4793586 | AL24: =AK24 -> 4.4793586 | AM24: =AL24 -> 4.4793586 | AN24: =AM24 -> 4.4793586 | AO24: =AN24 -> 4.4793586 | AP24: =AO24 -> 4.4793586 | ... AR24: =AQ24 -> 4.4793586
A25: EE | B25: O | C25: EEEINELCMC0O | D25: =A25&"IME"&B25 -> EEIMEO | E25: 0.952 | F25: =E25*VLOOKUP($A25,'EU Ref Sc 2020 Other industries'!$A$5:$AE$33,F$2) -> 0.99188688 | G25: =F25*VLOOKUP($A25,'EU Ref Sc 2020 Other industries'!$A$5:$AE$33,G$2) -> 1.0317738 | H25: =G25*VLOOKUP($A25,'EU Ref Sc 2020 Other industries'!$A$5:$AE$33,H$2) -> 1.0716606 | I25: =H25*VLOOKUP($A25,'EU Ref Sc 2020 Other industries'!$A$5:$AE$33,I$2) -> 1.1115475 | J25: =I25*VLOOKUP($A25,'EU Ref Sc 2020 Other industries'!$A$5:$AE$33,J$2) -> 1.1511763 | K25: =J25*VLOOKUP($A25,'EU Ref Sc 2020 Other industries'!$A$5:$AE$33,K$2) -> 1.1908051 | L25: =K25*VLOOKUP($A25,'EU Ref Sc 2020 Other industries'!$A$5:$AE$33,L$2) -> 1.2304339 | M25: =L25*VLOOKUP($A25,'EU Ref Sc 2020 Other industries'!$A$5:$AE$33,M$2) -> 1.2700627 | ... AH25: =AG25*VLOOKUP($A25,'EU Ref Sc 2020 Other industries'!$A$5:$AE$33,AH$2) -> 1.2703508 | AI25: =AH25 -> 1.2703508 | AJ25: =AI25 -> 1.2703508 | AK25: =AJ25 -> 1.2703508 | AL25: =AK25 -> 1.2703508 | AM25: =AL25 -> 1.2703508 | AN25: =AM25 -> 1.2703508 | AO25: =AN25 -> 1.2703508 | AP25: =AO25 -> 1.2703508 | ... AR25: =AQ25 -> 1.2703508
A26: GR | B26: O | C26: GREINELCMC0O | D26: =A26&"IME"&B26 -> GRIMEO | E26: 5.6874 | F26: =E26*VLOOKUP($A26,'EU Ref Sc 2020 Other industries'!$A$5:$AE$33,F$2) -> 5.8167629 | G26: =F26*VLOOKUP($A26,'EU Ref Sc 2020 Other industries'!$A$5:$AE$33,G$2) -> 5.9461259 | H26: =G26*VLOOKUP($A26,'EU Ref Sc 2020 Other industries'!$A$5:$AE$33,H$2) -> 6.0754888 | I26: =H26*VLOOKUP($A26,'EU Ref Sc 2020 Other industries'!$A$5:$AE$33,I$2) -> 6.2048518 | J26: =I26*VLOOKUP($A26,'EU Ref Sc 2020 Other industries'!$A$5:$AE$33,J$2) -> 6.0259571 | K26: =J26*VLOOKUP($A26,'EU Ref Sc 2020 Other industries'!$A$5:$AE$33,K$2) -> 5.8470625 | L26: =K26*VLOOKUP($A26,'EU Ref Sc 2020 Other industries'!$A$5:$AE$33,L$2) -> 5.6681678 | M26: =L26*VLOOKUP($A26,'EU Ref Sc 2020 Other industries'!$A$5:$AE$33,M$2) -> 5.4892732 | ... AH26: =AG26*VLOOKUP($A26,'EU Ref Sc 2020 Other industries'!$A$5:$AE$33,AH$2) -> 6.0415552 | AI26: =AH26 -> 6.0415552 | AJ26: =AI26 -> 6.0415552 | AK26: =AJ26 -> 6.0415552 | AL26: =AK26 -> 6.0415552 | AM26: =AL26 -> 6.0415552 | AN26: =AM26 -> 6.0415552 | AO26: =AN26 -> 6.0415552 | AP26: =AO26 -> 6.0415552 | ... AR26: =AQ26 -> 6.0415552
A27: ES | B27: O | C27: ESEINELCMC0O | D27: =A27&"IME"&B27 -> ESIMEO | E27: 37.4711 | F27: =E27*VLOOKUP($A27,'EU Ref Sc 2020 Other industries'!$A$5:$AE$33,F$2) -> 39.041063 | G27: =F27*VLOOKUP($A27,'EU Ref Sc 2020 Other industries'!$A$5:$AE$33,G$2) -> 40.611027 | H27: =G27*VLOOKUP($A27,'EU Ref Sc 2020 Other industries'!$A$5:$AE$33,H$2) -> 42.18099 | I27: =H27*VLOOKUP($A27,'EU Ref Sc 2020 Other industries'!$A$5:$AE$33,I$2) -> 43.750954 | J27: =I27*VLOOKUP($A27,'EU Ref Sc 2020 Other industries'!$A$5:$AE$33,J$2) -> 45.310759 | K27: =J27*VLOOKUP($A27,'EU Ref Sc 2020 Other industries'!$A$5:$AE$33,K$2) -> 46.870564 | L27: =K27*VLOOKUP($A27,'EU Ref Sc 2020 Other industries'!$A$5:$AE$33,L$2) -> 48.430368 | M27: =L27*VLOOKUP($A27,'EU Ref Sc 2020 Other industries'!$A$5:$AE$33,M$2) -> 49.990173 | ... AH27: =AG27*VLOOKUP($A27,'EU Ref Sc 2020 Other industries'!$A$5:$AE$33,AH$2) -> 50.001514 | AI27: =AH27 -> 50.001514 | AJ27: =AI27 -> 50.001514 | AK27: =AJ27 -> 50.001514 | AL27: =AK27 -> 50.001514 | AM27: =AL27 -> 50.001514 | AN27: =AM27 -> 50.001514 | AO27: =AN27 -> 50.001514 | AP27: =AO27 -> 50.001514 | ... AR27: =AQ27 -> 50.001514
A28: FI | B28: O | C28: FIEINELCMC0O | D28: =A28&"IME"&B28 -> FIIMEO | E28: 10.012 | F28: =E28*VLOOKUP($A28,'EU Ref Sc 2020 Other industries'!$A$5:$AE$33,F$2) -> 10.431483 | G28: =F28*VLOOKUP($A28,'EU Ref Sc 2020 Other industries'!$A$5:$AE$33,G$2) -> 10.850965 | H28: =G28*VLOOKUP($A28,'EU Ref Sc 2020 Other industries'!$A$5:$AE$33,H$2) -> 11.270448 | I28: =H28*VLOOKUP($A28,'EU Ref Sc 2020 Other industries'!$A$5:$AE$33,I$2) -> 11.68993 | J28: =I28*VLOOKUP($A28,'EU Ref Sc 2020 Other industries'!$A$5:$AE$33,J$2) -> 12.106699 | K28: =J28*VLOOKUP($A28,'EU Ref Sc 2020 Other industries'!$A$5:$AE$33,K$2) -> 12.523467 | L28: =K28*VLOOKUP($A28,'EU Ref Sc 2020 Other industries'!$A$5:$AE$33,L$2) -> 12.940235 | M28: =L28*VLOOKUP($A28,'EU Ref Sc 2020 Other industries'!$A$5:$AE$33,M$2) -> 13.357004 | ... AH28: =AG28*VLOOKUP($A28,'EU Ref Sc 2020 Other industries'!$A$5:$AE$33,AH$2) -> 13.360034 | AI28: =AH28 -> 13.360034 | AJ28: =AI28 -> 13.360034 | AK28: =AJ28 -> 13.360034 | AL28: =AK28 -> 13.360034 | AM28: =AL28 -> 13.360034 | AN28: =AM28 -> 13.360034 | AO28: =AN28 -> 13.360034 | AP28: =AO28 -> 13.360034 | ... AR28: =AQ28 -> 13.360034
A29: FR | B29: O | C29: FREINELCMC0O | D29: =A29&"IME"&B29 -> FRIMEO | E29: 48.7149 | F29: =E29*VLOOKUP($A29,'EU Ref Sc 2020 Other industries'!$A$5:$AE$33,F$2) -> 50.755956 | G29: =F29*VLOOKUP($A29,'EU Ref Sc 2020 Other industries'!$A$5:$AE$33,G$2) -> 52.797012 | H29: =G29*VLOOKUP($A29,'EU Ref Sc 2020 Other industries'!$A$5:$AE$33,H$2) -> 54.838068 | I29: =H29*VLOOKUP($A29,'EU Ref Sc 2020 Other industries'!$A$5:$AE$33,I$2) -> 56.879124 | J29: =I29*VLOOKUP($A29,'EU Ref Sc 2020 Other industries'!$A$5:$AE$33,J$2) -> 58.906973 | K29: =J29*VLOOKUP($A29,'EU Ref Sc 2020 Other industries'!$A$5:$AE$33,K$2) -> 60.934822 | L29: =K29*VLOOKUP($A29,'EU Ref Sc 2020 Other industries'!$A$5:$AE$33,L$2) -> 62.962671 | M29: =L29*VLOOKUP($A29,'EU Ref Sc 2020 Other industries'!$A$5:$AE$33,M$2) -> 64.99052 | ... AH29: =AG29*VLOOKUP($A29,'EU Ref Sc 2020 Other industries'!$A$5:$AE$33,AH$2) -> 65.005264 | AI29: =AH29 -> 65.005264 | AJ29: =AI29 -> 65.005264 | AK29: =AJ29 -> 65.005264 | AL29: =AK29 -> 65.005264 | AM29: =AL29 -> 65.005264 | AN29: =AM29 -> 65.005264 | AO29: =AN29 -> 65.005264 | AP29: =AO29 -> 65.005264 | ... AR29: =AQ29 -> 65.005264
... A44: SK | B44: O | C44: SKEINELCMC0O | D44: =A44&"IME"&B44 -> SKIMEO | E44: 5.6192 | F44: =E44*VLOOKUP($A44,'EU Ref Sc 2020 Other industries'!$A$5:$AE$33,F$2) -> 5.6486942 | G44: =F44*VLOOKUP($A44,'EU Ref Sc 2020 Other industries'!$A$5:$AE$33,G$2) -> 5.6781883 | H44: =G44*VLOOKUP($A44,'EU Ref Sc 2020 Other industries'!$A$5:$AE$33,H$2) -> 5.7076825 | I44: =H44*VLOOKUP($A44,'EU Ref Sc 2020 Other industries'!$A$5:$AE$33,I$2) -> 5.7371766 | J44: =I44*VLOOKUP($A44,'EU Ref Sc 2020 Other industries'!$A$5:$AE$33,J$2) -> 5.7400514 | K44: =J44*VLOOKUP($A44,'EU Ref Sc 2020 Other industries'!$A$5:$AE$33,K$2) -> 5.7429262 | L44: =K44*VLOOKUP($A44,'EU Ref Sc 2020 Other industries'!$A$5:$AE$33,L$2) -> 5.745801 | M44: =L44*VLOOKUP($A44,'EU Ref Sc 2020 Other industries'!$A$5:$AE$33,M$2) -> 5.7486758 | ... AH44: =AG44*VLOOKUP($A44,'EU Ref Sc 2020 Other industries'!$A$5:$AE$33,AH$2) -> 6.0108254 | AI44: =AH44 -> 6.0108254 | AJ44: =AI44 -> 6.0108254 | AK44: =AJ44 -> 6.0108254 | AL44: =AK44 -> 6.0108254 | AM44: =AL44 -> 6.0108254 | AN44: =AM44 -> 6.0108254 | AO44: =AN44 -> 6.0108254 | AP44: =AO44 -> 6.0108254 | ... AR44: =AQ44 -> 6.0108254
A45: AT | B45: N | C45: ATEINELCMC0N | D45: =A45&"IME"&B45 -> ATIMEN | E45: 2.7272 | F45: =E45*VLOOKUP($A45,'EU Ref Sc 2020 Energy intensive'!$A$5:$AE$33,F$2) -> 2.7476992 | G45: =F45*VLOOKUP($A45,'EU Ref Sc 2020 Energy intensive'!$A$5:$AE$33,G$2) -> 2.7681983 | H45: =G45*VLOOKUP($A45,'EU Ref Sc 2020 Energy intensive'!$A$5:$AE$33,H$2) -> 2.7886975 | I45: =H45*VLOOKUP($A45,'EU Ref Sc 2020 Energy intensive'!$A$5:$AE$33,I$2) -> 2.8091966 | J45: =I45*VLOOKUP($A45,'EU Ref Sc 2020 Energy intensive'!$A$5:$AE$33,J$2) -> 2.7872768 | K45: =J45*VLOOKUP($A45,'EU Ref Sc 2020 Energy intensive'!$A$5:$AE$33,K$2) -> 2.7653571 | L45: =K45*VLOOKUP($A45,'EU Ref Sc 2020 Energy intensive'!$A$5:$AE$33,L$2) -> 2.7434373 | M45: =L45*VLOOKUP($A45,'EU Ref Sc 2020 Energy intensive'!$A$5:$AE$33,M$2) -> 2.7215175 | ... AH45: =AG45*VLOOKUP($A45,'EU Ref Sc 2020 Energy intensive'!$A$5:$AE$33,AH$2) -> 2.3399282 | AI45: =AH45 -> 2.3399282 | AJ45: =AI45 -> 2.3399282 | AK45: =AJ45 -> 2.3399282 | AL45: =AK45 -> 2.3399282 | AM45: =AL45 -> 2.3399282 | AN45: =AM45 -> 2.3399282 | AO45: =AN45 -> 2.3399282 | AP45: =AO45 -> 2.3399282 | ... AR45: =AQ45 -> 2.3399282
A46: BE | B46: N | C46: BEEINELCMC0N | D46: =A46&"IME"&B46 -> BEIMEN | E46: 2.6334 | F46: =E46*VLOOKUP($A46,'EU Ref Sc 2020 Energy intensive'!$A$5:$AE$33,F$2) -> 2.7181002 | G46: =F46*VLOOKUP($A46,'EU Ref Sc 2020 Energy intensive'!$A$5:$AE$33,G$2) -> 2.8028004 | H46: =G46*VLOOKUP($A46,'EU Ref Sc 2020 Energy intensive'!$A$5:$AE$33,H$2) -> 2.8875006 | I46: =H46*VLOOKUP($A46,'EU Ref Sc 2020 Energy intensive'!$A$5:$AE$33,I$2) -> 2.9722008 | J46: =I46*VLOOKUP($A46,'EU Ref Sc 2020 Energy intensive'!$A$5:$AE$33,J$2) -> 3.0621309 | K46: =J46*VLOOKUP($A46,'EU Ref Sc 2020 Energy intensive'!$A$5:$AE$33,K$2) -> 3.152061 | L46: =K46*VLOOKUP($A46,'EU Ref Sc 2020 Energy intensive'!$A$5:$AE$33,L$2) -> 3.2419911 | M46: =L46*VLOOKUP($A46,'EU Ref Sc 2020 Energy intensive'!$A$5:$AE$33,M$2) -> 3.3319213 | ... AH46: =AG46*VLOOKUP($A46,'EU Ref Sc 2020 Energy intensive'!$A$5:$AE$33,AH$2) -> 3.2175055 | AI46: =AH46 -> 3.2175055 | AJ46: =AI46 -> 3.2175055 | AK46: =AJ46 -> 3.2175055 | AL46: =AK46 -> 3.2175055 | AM46: =AL46 -> 3.2175055 | AN46: =AM46 -> 3.2175055 | AO46: =AN46 -> 3.2175055 | AP46: =AO46 -> 3.2175055 | ... AR46: =AQ46 -> 3.2175055
A47: BG | B47: N | C47: BGEINELCMC0N | D47: =A47&"IME"&B47 -> BGIMEN | E47: 1.1172 | F47: =E47*VLOOKUP($A47,'EU Ref Sc 2020 Energy intensive'!$A$5:$AE$33,F$2) -> 1.1328995 | G47: =F47*VLOOKUP($A47,'EU Ref Sc 2020 Energy intensive'!$A$5:$AE$33,G$2) -> 1.148599 | H47: =G47*VLOOKUP($A47,'EU Ref Sc 2020 Energy intensive'!$A$5:$AE$33,H$2) -> 1.1642985 | I47: =H47*VLOOKUP($A47,'EU Ref Sc 2020 Energy intensive'!$A$5:$AE$33,I$2) -> 1.179998 | J47: =I47*VLOOKUP($A47,'EU Ref Sc 2020 Energy intensive'!$A$5:$AE$33,J$2) -> 1.1747792 | K47: =J47*VLOOKUP($A47,'EU Ref Sc 2020 Energy intensive'!$A$5:$AE$33,K$2) -> 1.1695604 | L47: =K47*VLOOKUP($A47,'EU Ref Sc 2020 Energy intensive'!$A$5:$AE$33,L$2) -> 1.1643416 | M47: =L47*VLOOKUP($A47,'EU Ref Sc 2020 Energy intensive'!$A$5:$AE$33,M$2) -> 1.1591228 | ... AH47: =AG47*VLOOKUP($A47,'EU Ref Sc 2020 Energy intensive'!$A$5:$AE$33,AH$2) -> 0.9789018 | AI47: =AH47 -> 0.9789018 | AJ47: =AI47 -> 0.9789018 | AK47: =AJ47 -> 0.9789018 | AL47: =AK47 -> 0.9789018 | AM47: =AL47 -> 0.9789018 | AN47: =AM47 -> 0.9789018 | AO47: =AN47 -> 0.9789018 | AP47: =AO47 -> 0.9789018 | ... AR47: =AQ47 -> 0.9789018
A48: CY | B48: N | C48: CYEINELCMC0N | D48: =A48&"IME"&B48 -> CYIMEN | E48: 0.2744 | F48: =E48*VLOOKUP($A48,'EU Ref Sc 2020 Energy intensive'!$A$5:$AE$33,F$2) -> 0.27765234 | G48: =F48*VLOOKUP($A48,'EU Ref Sc 2020 Energy intensive'!$A$5:$AE$33,G$2) -> 0.28090468 | H48: =G48*VLOOKUP($A48,'EU Ref Sc 2020 Energy intensive'!$A$5:$AE$33,H$2) -> 0.28415701 | I48: =H48*VLOOKUP($A48,'EU Ref Sc 2020 Energy intensive'!$A$5:$AE$33,I$2) -> 0.28740935 | J48: =I48*VLOOKUP($A48,'EU Ref Sc 2020 Energy intensive'!$A$5:$AE$33,J$2) -> 0.28251563 | K48: =J48*VLOOKUP($A48,'EU Ref Sc 2020 Energy intensive'!$A$5:$AE$33,K$2) -> 0.27762191 | L48: =K48*VLOOKUP($A48,'EU Ref Sc 2020 Energy intensive'!$A$5:$AE$33,L$2) -> 0.27272819 | M48: =L48*VLOOKUP($A48,'EU Ref Sc 2020 Energy intensive'!$A$5:$AE$33,M$2) -> 0.26783446 | ... AH48: =AG48*VLOOKUP($A48,'EU Ref Sc 2020 Energy intensive'!$A$5:$AE$33,AH$2) -> 0.28001389 | AI48: =AH48 -> 0.28001389 | AJ48: =AI48 -> 0.28001389 | AK48: =AJ48 -> 0.28001389 | AL48: =AK48 -> 0.28001389 | AM48: =AL48 -> 0.28001389 | AN48: =AM48 -> 0.28001389 | AO48: =AN48 -> 0.28001389 | AP48: =AO48 -> 0.28001389 | ... AR48: =AQ48 -> 0.28001389
A49: CZ | B49: N | C49: CZEINELCMC0N | D49: =A49&"IME"&B49 -> CZIMEN | E49: 2.7543 | F49: =E49*VLOOKUP($A49,'EU Ref Sc 2020 Energy intensive'!$A$5:$AE$33,F$2) -> 2.7610663 | G49: =F49*VLOOKUP($A49,'EU Ref Sc 2020 Energy intensive'!$A$5:$AE$33,G$2) -> 2.7678326 | H49: =G49*VLOOKUP($A49,'EU Ref Sc 2020 Energy intensive'!$A$5:$AE$33,H$2) -> 2.7745989 | I49: =H49*VLOOKUP($A49,'EU Ref Sc 2020 Energy intensive'!$A$5:$AE$33,I$2) -> 2.7813653 | J49: =I49*VLOOKUP($A49,'EU Ref Sc 2020 Energy intensive'!$A$5:$AE$33,J$2) -> 2.7291913 | K49: =J49*VLOOKUP($A49,'EU Ref Sc 2020 Energy intensive'!$A$5:$AE$33,K$2) -> 2.6770173 | L49: =K49*VLOOKUP($A49,'EU Ref Sc 2020 Energy intensive'!$A$5:$AE$33,L$2) -> 2.6248433 | M49: =L49*VLOOKUP($A49,'EU Ref Sc 2020 Energy intensive'!$A$5:$AE$33,M$2) -> 2.5726694 | ... AH49: =AG49*VLOOKUP($A49,'EU Ref Sc 2020 Energy intensive'!$A$5:$AE$33,AH$2) -> 2.1714193 | AI49: =AH49 -> 2.1714193 | AJ49: =AI49 -> 2.1714193 | AK49: =AJ49 -> 2.1714193 | AL49: =AK49 -> 2.1714193 | AM49: =AL49 -> 2.1714193 | AN49: =AM49 -> 2.1714193 | AO49: =AN49 -> 2.1714193 | AP49: =AO49 -> 2.1714193 | ... AR49: =AQ49 -> 2.1714193
A50: DE | B50: N | C50: DEEINELCMC0N | D50: =A50&"IME"&B50 -> DEIMEN | E50: 16.9558 | F50: =E50*VLOOKUP($A50,'EU Ref Sc 2020 Energy intensive'!$A$5:$AE$33,F$2) -> 17.063046 | G50: =F50*VLOOKUP($A50,'EU Ref Sc 2020 Energy intensive'!$A$5:$AE$33,G$2) -> 17.170292 | H50: =G50*VLOOKUP($A50,'EU Ref Sc 2020 Energy intensive'!$A$5:$AE$33,H$2) -> 17.277538 | I50: =H50*VLOOKUP($A50,'EU Ref Sc 2020 Energy intensive'!$A$5:$AE$33,I$2) -> 17.384784 | J50: =I50*VLOOKUP($A50,'EU Ref Sc 2020 Energy intensive'!$A$5:$AE$33,J$2) -> 17.171401 | K50: =J50*VLOOKUP($A50,'EU Ref Sc 2020 Energy intensive'!$A$5:$AE$33,K$2) -> 16.958018 | L50: =K50*VLOOKUP($A50,'EU Ref Sc 2020 Energy intensive'!$A$5:$AE$33,L$2) -> 16.744635 | M50: =L50*VLOOKUP($A50,'EU Ref Sc 2020 Energy intensive'!$A$5:$AE$33,M$2) -> 16.531251 | ... AH50: =AG50*VLOOKUP($A50,'EU Ref Sc 2020 Energy intensive'!$A$5:$AE$33,AH$2) -> 13.471402 | AI50: =AH50 -> 13.471402 | AJ50: =AI50 -> 13.471402 | AK50: =AJ50 -> 13.471402 | AL50: =AK50 -> 13.471402 | AM50: =AL50 -> 13.471402 | AN50: =AM50 -> 13.471402 | AO50: =AN50 -> 13.471402 | AP50: =AO50 -> 13.471402 | ... AR50: =AQ50 -> 13.471402
A51: DK | B51: N | C51: DKEINELCMC0N | D51: =A51&"IME"&B51 -> DKIMEN | E51: 1.0753 | F51: =E51*VLOOKUP($A51,'EU Ref Sc 2020 Energy intensive'!$A$5:$AE$33,F$2) -> 1.0943963 | G51: =F51*VLOOKUP($A51,'EU Ref Sc 2020 Energy intensive'!$A$5:$AE$33,G$2) -> 1.1134925 | H51: =G51*VLOOKUP($A51,'EU Ref Sc 2020 Energy intensive'!$A$5:$AE$33,H$2) -> 1.1325888 | I51: =H51*VLOOKUP($A51,'EU Ref Sc 2020 Energy intensive'!$A$5:$AE$33,I$2) -> 1.1516851 | J51: =I51*VLOOKUP($A51,'EU Ref Sc 2020 Energy intensive'!$A$5:$AE$33,J$2) -> 1.1563473 | K51: =J51*VLOOKUP($A51,'EU Ref Sc 2020 Energy intensive'!$A$5:$AE$33,K$2) -> 1.1610096 | L51: =K51*VLOOKUP($A51,'EU Ref Sc 2020 Energy intensive'!$A$5:$AE$33,L$2) -> 1.1656718 | M51: =L51*VLOOKUP($A51,'EU Ref Sc 2020 Energy intensive'!$A$5:$AE$33,M$2) -> 1.1703341 | ... AH51: =AG51*VLOOKUP($A51,'EU Ref Sc 2020 Energy intensive'!$A$5:$AE$33,AH$2) -> 1.1341421 | AI51: =AH51 -> 1.1341421 | AJ51: =AI51 -> 1.1341421 | AK51: =AJ51 -> 1.1341421 | AL51: =AK51 -> 1.1341421 | AM51: =AL51 -> 1.1341421 | AN51: =AM51 -> 1.1341421 | AO51: =AN51 -> 1.1341421 | AP51: =AO51 -> 1.1341421 | ... AR51: =AQ51 -> 1.1341421
A52: GR | B52: N | C52: GREINELCMC0N | D52: =A52&"IME"&B52 -> GRIMEN | E52: 2.2292 | F52: =E52*VLOOKUP($A52,'EU Ref Sc 2020 Energy intensive'!$A$5:$AE$33,F$2) -> 2.3094153 | G52: =F52*VLOOKUP($A52,'EU Ref Sc 2020 Energy intensive'!$A$5:$AE$33,G$2) -> 2.3896306 | H52: =G52*VLOOKUP($A52,'EU Ref Sc 2020 Energy intensive'!$A$5:$AE$33,H$2) -> 2.469846 | I52: =H52*VLOOKUP($A52,'EU Ref Sc 2020 Energy intensive'!$A$5:$AE$33,I$2) -> 2.5500613 | J52: =I52*VLOOKUP($A52,'EU Ref Sc 2020 Energy intensive'!$A$5:$AE$33,J$2) -> 2.5329114 | K52: =J52*VLOOKUP($A52,'EU Ref Sc 2020 Energy intensive'!$A$5:$AE$33,K$2) -> 2.5157614 | L52: =K52*VLOOKUP($A52,'EU Ref Sc 2020 Energy intensive'!$A$5:$AE$33,L$2) -> 2.4986115 | M52: =L52*VLOOKUP($A52,'EU Ref Sc 2020 Energy intensive'!$A$5:$AE$33,M$2) -> 2.4814616 | ... AH52: =AG52*VLOOKUP($A52,'EU Ref Sc 2020 Energy intensive'!$A$5:$AE$33,AH$2) -> 2.3104376 | AI52: =AH52 -> 2.3104376 | AJ52: =AI52 -> 2.3104376 | AK52: =AJ52 -> 2.3104376 | AL52: =AK52 -> 2.3104376 | AM52: =AL52 -> 2.3104376 | AN52: =AM52 -> 2.3104376 | AO52: =AN52 -> 2.3104376 | AP52: =AO52 -> 2.3104376 | ... AR52: =AQ52 -> 2.3104376
A53: ES | B53: N | C53: ESEINELCMC0N | D53: =A53&"IME"&B53 -> ESIMEN | E53: 8.6193 | F53: =E53*VLOOKUP($A53,'EU Ref Sc 2020 Energy intensive'!$A$5:$AE$33,F$2) -> 9.0156639 | G53: =F53*VLOOKUP($A53,'EU Ref Sc 2020 Energy intensive'!$A$5:$AE$33,G$2) -> 9.4120277 | H53: =G53*VLOOKUP($A53,'EU Ref Sc 2020 Energy intensive'!$A$5:$AE$33,H$2) -> 9.8083916 | I53: =H53*VLOOKUP($A53,'EU Ref Sc 2020 Energy intensive'!$A$5:$AE$33,I$2) -> 10.204755 | J53: =I53*VLOOKUP($A53,'EU Ref Sc 2020 Energy intensive'!$A$5:$AE$33,J$2) -> 10.255525 | K53: =J53*VLOOKUP($A53,'EU Ref Sc 2020 Energy intensive'!$A$5:$AE$33,K$2) -> 10.306294 | L53: =K53*VLOOKUP($A53,'EU Ref Sc 2020 Energy intensive'!$A$5:$AE$33,L$2) -> 10.357064 | M53: =L53*VLOOKUP($A53,'EU Ref Sc 2020 Energy intensive'!$A$5:$AE$33,M$2) -> 10.407833 | ... AH53: =AG53*VLOOKUP($A53,'EU Ref Sc 2020 Energy intensive'!$A$5:$AE$33,AH$2) -> 8.5564082 | AI53: =AH53 -> 8.5564082 | AJ53: =AI53 -> 8.5564082 | AK53: =AJ53 -> 8.5564082 | AL53: =AK53 -> 8.5564082 | AM53: =AL53 -> 8.5564082 | AN53: =AM53 -> 8.5564082 | AO53: =AN53 -> 8.5564082 | AP53: =AO53 -> 8.5564082 | ... AR53: =AQ53 -> 8.5564082
A54: FR | B54: N | C54: FREINELCMC0N | D54: =A54&"IME"&B54 -> FRIMEN | E54: 11.0428 | F54: =E54*VLOOKUP($A54,'EU Ref Sc 2020 Energy intensive'!$A$5:$AE$33,F$2) -> 11.55061 | G54: =F54*VLOOKUP($A54,'EU Ref Sc 2020 Energy intensive'!$A$5:$AE$33,G$2) -> 12.05842 | H54: =G54*VLOOKUP($A54,'EU Ref Sc 2020 Energy intensive'!$A$5:$AE$33,H$2) -> 12.56623 | I54: =H54*VLOOKUP($A54,'EU Ref Sc 2020 Energy intensive'!$A$5:$AE$33,I$2) -> 13.07404 | J54: =I54*VLOOKUP($A54,'EU Ref Sc 2020 Energy intensive'!$A$5:$AE$33,J$2) -> 13.139084 | K54: =J54*VLOOKUP($A54,'EU Ref Sc 2020 Energy intensive'!$A$5:$AE$33,K$2) -> 13.204129 | L54: =K54*VLOOKUP($A54,'EU Ref Sc 2020 Energy intensive'!$A$5:$AE$33,L$2) -> 13.269173 | M54: =L54*VLOOKUP($A54,'EU Ref Sc 2020 Energy intensive'!$A$5:$AE$33,M$2) -> 13.334217 | ... AH54: =AG54*VLOOKUP($A54,'EU Ref Sc 2020 Energy intensive'!$A$5:$AE$33,AH$2) -> 10.962225 | AI54: =AH54 -> 10.962225 | AJ54: =AI54 -> 10.962225 | AK54: =AJ54 -> 10.962225 | AL54: =AK54 -> 10.962225 | AM54: =AL54 -> 10.962225 | AN54: =AM54 -> 10.962225 | AO54: =AN54 -> 10.962225 | AP54: =AO54 -> 10.962225 | ... AR54: =AQ54 -> 10.962225
...

Sheet Useful energy - thermal
A1: Useful energy stats in PJ after aggregation of sectors (based on JRC-IDEES 2021)
A3: Country | B3: Sector | C3: TECHNOLOGY | D3: 2018 | E3: 2019 | F3: 2020 | G3: 2021
A4: AT | B4: I | C4: ATEINOILFC0I | D4: 0.033 | E4: 0.041 | F4: 0.0254 | G4: 0.0373
A5: AT | B5: I | C5: ATEINCOAFC0I | D5: 2.8024 | E5: 4.0938 | F5: 4.2838 | G5: 4.2633
A6: AT | B6: I | C6: ATEINCOAFCCI | D6: 0 | E6: 0 | F6: 0 | G6: 0
A7: AT | B7: I | C7: ATEINNGSFC0I | D7: 11.9996 | E7: 12.0262 | F7: 11.4296 | G7: 11.5473
A8: AT | B8: I | C8: ATEINNGSFCCI | D8: 0 | E8: 0 | F8: 0 | G8: 0
A9: AT | B9: I | C9: ATEINBIOFC0I | D9: 0.0061 | E9: 0.0053 | F9: 0.006 | G9: 0.0068
A10: AT | B10: I | C10: ATEINELCFC0I | D10: 5.449 | E10: 5.5274 | F10: 5.1102 | G10: 5.5114
A11: AT | B11: I | C11: ATEINHY2FC0I | D11: 0 | E11: 0 | F11: 0 | G11: 0
A12: AT | B12: I | C12: ATEINSTH000I | D12: 0 | E12: 0 | F12: 0 | G12: 0
A13: AT | B13: I | C13: ATEINHEA000I | D13: 1.9664 | E13: 1.9638 | F13: 1.9006 | G13: 2.1878
A14: AT | B14: C | C14: ATEINOILFC0C | D14: 0.2681 | E14: 0.2971 | F14: 0.3841 | G14: 0.2384
... A1263: SK | B1263: O | C1263: SKEINHEA000O | D1263: 0.3601 | E1263: 0.5284 | F1263: 0.476 | G1263: 0.5343

Sheet Thermal-Pivot
A3: Row Labels | B3: Sum of 2018 | C3: Sum of 2019 | D3: Sum of 2020 | E3: Sum of 2021
A4: AT | B4: 148.2729 | C4: 150.7148 | D4: 145.4666 | E4: 153.5145
A5: C | B5: 17.3979 | C5: 18.0991 | D5: 17.5031 | E5: 19.0304
A6: I | B6: 22.2565 | C6: 23.6575 | D6: 22.7556 | E6: 23.5539
A7: N | B7: 17.9814 | C7: 17.985 | D7: 19.3632 | E7: 20.3254
A8: O | B8: 40.8523 | C8: 38.8784 | D8: 37.2991 | E8: 39.8848
A9: P | B9: 49.7848 | C9: 52.0948 | D9: 48.5456 | E9: 50.72
A10: BE | B10: 197.6131 | C10: 190.4357 | D10: 185.8639 | E10: 197.8932
A11: C | B11: 71.0226 | C11: 67.0018 | D11: 68.1765 | E11: 73.1654
A12: F | B12: 26.452 | C12: 26.9865 | D12: 26.1318 | E12: 27.9618
A13: I | B13: 30.8031 | C13: 28.8149 | D13: 28.0213 | E13: 28.7512
A14: N | B14: 26.7666 | C14: 27.2541 | D14: 26.5814 | E14: 27.4779
A15: O | B15: 42.5688 | C15: 40.3784 | D15: 36.9529 | E15: 40.5369
... A157: Grand Total | B157: 4679.2679 | C157: 4629.258 | D157: 4478.8483 | E157: 4767.0706

Sheet Useful Thermal - Aggregate
A1: Useful energy stats in PJ after aggregation of sectors (based on JRC-IDEES 2021)
E2: 3 | F2: 4 | G2: 5 | H2: 6 | I2: 7 | J2: 8 | K2: 9 | L2: 10 | M2: 11 | N2: 12 | O2: 13 | P2: 14 | Q2: 15 | R2: 16 | S2: 17 | T2: 18 | U2: 19 | V2: 20 | W2: 21 | X2: 22 | Y2: 23 | Z2: 24 | AA2: 25 | AB2: 26 | AC2: 27 | AD2: 28 | AE2: 29 | AF2: 30 | AG2: 31 | AH2: 32 | AI2: 33 | AJ2: 34 | AK2: 35 | AL2: 36 | AM2: 37 | AN2: 38 | AO2: 39 | AP2: 40 | AQ2: 41
A3: Country | B3: Row Labels | C3: Fuel | D3: 2021 | E3: 2022 | F3: 2023 | G3: 2024 | H3: 2025 | I3: 2026 | J3: 2027 | K3: 2028 | L3: 2029 | M3: 2030 | N3: 2031 | O3: 2032 | P3: 2033 | Q3: 2034 | R3: 2035 | S3: 2036 | T3: 2037 | U3: 2038 | V3: 2039 | W3: 2040 | X3: 2041 | Y3: 2042 | Z3: 2043 | AA3: 2044 | AB3: 2045 | AC3: 2046 | AD3: 2047 | AE3: 2048 | AF3: 2049 | AG3: 2050 | AH3: 2051 | AI3: 2052 | AJ3: 2053 | AK3: 2054 | AL3: 2055 | AM3: 2056 | AN3: 2057 | AO3: 2058 | AP3: 2059 | AQ3: 2060
A4: EE | B4: W | C4: =A4&"IUE"&B4 -> EEIUEW | D4: 0.5 | E4: =D4*VLOOKUP($A4,'EU Ref Sc 2020 Other industries'!$A$5:$AE$33,E$2) -> 0.52094899 | F4: =E4*VLOOKUP($A4,'EU Ref Sc 2020 Other industries'!$A$5:$AE$33,F$2) -> 0.54189798 | G4: =F4*VLOOKUP($A4,'EU Ref Sc 2020 Other industries'!$A$5:$AE$33,G$2) -> 0.56284697 | H4: =G4*VLOOKUP($A4,'EU Ref Sc 2020 Other industries'!$A$5:$AE$33,H$2) -> 0.58379596 | I4: =H4*VLOOKUP($A4,'EU Ref Sc 2020 Other industries'!$A$5:$AE$33,I$2) -> 0.6046094 | J4: =I4*VLOOKUP($A4,'EU Ref Sc 2020 Other industries'!$A$5:$AE$33,J$2) -> 0.62542284 | K4: =J4*VLOOKUP($A4,'EU Ref Sc 2020 Other industries'!$A$5:$AE$33,K$2) -> 0.64623628 | L4: =K4*VLOOKUP($A4,'EU Ref Sc 2020 Other industries'!$A$5:$AE$33,L$2) -> 0.66704972 | ... AG4: =AF4*VLOOKUP($A4,'EU Ref Sc 2020 Other industries'!$A$5:$AE$33,AG$2) -> 0.66720104 | AH4: =AG4 -> 0.66720104 | AI4: =AH4 -> 0.66720104 | AJ4: =AI4 -> 0.66720104 | AK4: =AJ4 -> 0.66720104 | AL4: =AK4 -> 0.66720104 | AM4: =AL4 -> 0.66720104 | AN4: =AM4 -> 0.66720104 | AO4: =AN4 -> 0.66720104 | ... AQ4: =AP4 -> 0.66720104
A5: FI | B5: W | C5: =A5&"IUE"&B5 -> FIIUEW | D5: 7.9345 | E5: =D5*VLOOKUP($A5,'EU Ref Sc 2020 Other industries'!$A$5:$AE$33,E$2) -> 8.2669395 | F5: =E5*VLOOKUP($A5,'EU Ref Sc 2020 Other industries'!$A$5:$AE$33,F$2) -> 8.5993791 | G5: =F5*VLOOKUP($A5,'EU Ref Sc 2020 Other industries'!$A$5:$AE$33,G$2) -> 8.9318186 | H5: =G5*VLOOKUP($A5,'EU Ref Sc 2020 Other industries'!$A$5:$AE$33,H$2) -> 9.2642582 | I5: =H5*VLOOKUP($A5,'EU Ref Sc 2020 Other industries'!$A$5:$AE$33,I$2) -> 9.5945466 | J5: =I5*VLOOKUP($A5,'EU Ref Sc 2020 Other industries'!$A$5:$AE$33,J$2) -> 9.924835 | K5: =J5*VLOOKUP($A5,'EU Ref Sc 2020 Other industries'!$A$5:$AE$33,K$2) -> 10.255123 | L5: =K5*VLOOKUP($A5,'EU Ref Sc 2020 Other industries'!$A$5:$AE$33,L$2) -> 10.585412 | ... AG5: =AF5*VLOOKUP($A5,'EU Ref Sc 2020 Other industries'!$A$5:$AE$33,AG$2) -> 10.587813 | AH5: =AG5 -> 10.587813 | AI5: =AH5 -> 10.587813 | AJ5: =AI5 -> 10.587813 | AK5: =AJ5 -> 10.587813 | AL5: =AK5 -> 10.587813 | AM5: =AL5 -> 10.587813 | AN5: =AM5 -> 10.587813 | AO5: =AN5 -> 10.587813 | ... AQ5: =AP5 -> 10.587813
A6: LT | B6: W | C6: =A6&"IUE"&B6 -> LTIUEW | D6: 1.3488 | E6: =D6*VLOOKUP($A6,'EU Ref Sc 2020 Other industries'!$A$5:$AE$33,E$2) -> 1.3829323 | F6: =E6*VLOOKUP($A6,'EU Ref Sc 2020 Other industries'!$A$5:$AE$33,F$2) -> 1.4170646 | G6: =F6*VLOOKUP($A6,'EU Ref Sc 2020 Other industries'!$A$5:$AE$33,G$2) -> 1.451197 | H6: =G6*VLOOKUP($A6,'EU Ref Sc 2020 Other industries'!$A$5:$AE$33,H$2) -> 1.4853293 | I6: =H6*VLOOKUP($A6,'EU Ref Sc 2020 Other industries'!$A$5:$AE$33,I$2) -> 1.4840187 | J6: =I6*VLOOKUP($A6,'EU Ref Sc 2020 Other industries'!$A$5:$AE$33,J$2) -> 1.4827081 | K6: =J6*VLOOKUP($A6,'EU Ref Sc 2020 Other industries'!$A$5:$AE$33,K$2) -> 1.4813975 | L6: =K6*VLOOKUP($A6,'EU Ref Sc 2020 Other industries'!$A$5:$AE$33,L$2) -> 1.4800869 | ... AG6: =AF6*VLOOKUP($A6,'EU Ref Sc 2020 Other industries'!$A$5:$AE$33,AG$2) -> 1.5102369 | AH6: =AG6 -> 1.5102369 | AI6: =AH6 -> 1.5102369 | AJ6: =AI6 -> 1.5102369 | AK6: =AJ6 -> 1.5102369 | AL6: =AK6 -> 1.5102369 | AM6: =AL6 -> 1.5102369 | AN6: =AM6 -> 1.5102369 | AO6: =AN6 -> 1.5102369 | ... AQ6: =AP6 -> 1.5102369
A7: LV | B7: W | C7: =A7&"IUE"&B7 -> LVIUEW | D7: 7.9677 | E7: =D7*VLOOKUP($A7,'EU Ref Sc 2020 Other industries'!$A$5:$AE$33,E$2) -> 8.0734612 | F7: =E7*VLOOKUP($A7,'EU Ref Sc 2020 Other industries'!$A$5:$AE$33,F$2) -> 8.1792225 | G7: =F7*VLOOKUP($A7,'EU Ref Sc 2020 Other industries'!$A$5:$AE$33,G$2) -> 8.2849837 | H7: =G7*VLOOKUP($A7,'EU Ref Sc 2020 Other industries'!$A$5:$AE$33,H$2) -> 8.390745 | I7: =H7*VLOOKUP($A7,'EU Ref Sc 2020 Other industries'!$A$5:$AE$33,I$2) -> 8.3961378 | J7: =I7*VLOOKUP($A7,'EU Ref Sc 2020 Other industries'!$A$5:$AE$33,J$2) -> 8.4015307 | K7: =J7*VLOOKUP($A7,'EU Ref Sc 2020 Other industries'!$A$5:$AE$33,K$2) -> 8.4069235 | L7: =K7*VLOOKUP($A7,'EU Ref Sc 2020 Other industries'!$A$5:$AE$33,L$2) -> 8.4123163 | ... AG7: =AF7*VLOOKUP($A7,'EU Ref Sc 2020 Other industries'!$A$5:$AE$33,AG$2) -> 7.078175 | AH7: =AG7 -> 7.078175 | AI7: =AH7 -> 7.078175 | AJ7: =AI7 -> 7.078175 | AK7: =AJ7 -> 7.078175 | AL7: =AK7 -> 7.078175 | AM7: =AL7 -> 7.078175 | AN7: =AM7 -> 7.078175 | AO7: =AN7 -> 7.078175 | ... AQ7: =AP7 -> 7.078175
A8: AT | B8: P | C8: =A8&"IUE"&B8 -> ATIUEP | D8: 50.72 | E8: =D8*VLOOKUP($A8,'EU Ref Sc 2020 Energy intensive'!$A$5:$AE$33,E$2) -> 51.10124 | F8: =E8*VLOOKUP($A8,'EU Ref Sc 2020 Energy intensive'!$A$5:$AE$33,F$2) -> 51.48248 | G8: =F8*VLOOKUP($A8,'EU Ref Sc 2020 Energy intensive'!$A$5:$AE$33,G$2) -> 51.863719 | H8: =G8*VLOOKUP($A8,'EU Ref Sc 2020 Energy intensive'!$A$5:$AE$33,H$2) -> 52.244959 | I8: =H8*VLOOKUP($A8,'EU Ref Sc 2020 Energy intensive'!$A$5:$AE$33,I$2) -> 51.837299 | J8: =I8*VLOOKUP($A8,'EU Ref Sc 2020 Energy intensive'!$A$5:$AE$33,J$2) -> 51.429638 | K8: =J8*VLOOKUP($A8,'EU Ref Sc 2020 Energy intensive'!$A$5:$AE$33,K$2) -> 51.021978 | L8: =K8*VLOOKUP($A8,'EU Ref Sc 2020 Energy intensive'!$A$5:$AE$33,L$2) -> 50.614318 | ... AG8: =AF8*VLOOKUP($A8,'EU Ref Sc 2020 Energy intensive'!$A$5:$AE$33,AG$2) -> 43.517586 | AH8: =AG8 -> 43.517586 | AI8: =AH8 -> 43.517586 | AJ8: =AI8 -> 43.517586 | AK8: =AJ8 -> 43.517586 | AL8: =AK8 -> 43.517586 | AM8: =AL8 -> 43.517586 | AN8: =AM8 -> 43.517586 | AO8: =AN8 -> 43.517586 | ... AQ8: =AP8 -> 43.517586
A9: CZ | B9: P | C9: =A9&"IUE"&B9 -> CZIUEP | D9: 15.2526 | E9: =D9*VLOOKUP($A9,'EU Ref Sc 2020 Energy intensive'!$A$5:$AE$33,E$2) -> 15.29007 | F9: =E9*VLOOKUP($A9,'EU Ref Sc 2020 Energy intensive'!$A$5:$AE$33,F$2) -> 15.32754 | G9: =F9*VLOOKUP($A9,'EU Ref Sc 2020 Energy intensive'!$A$5:$AE$33,G$2) -> 15.36501 | H9: =G9*VLOOKUP($A9,'EU Ref Sc 2020 Energy intensive'!$A$5:$AE$33,H$2) -> 15.40248 | I9: =H9*VLOOKUP($A9,'EU Ref Sc 2020 Energy intensive'!$A$5:$AE$33,I$2) -> 15.113554 | J9: =I9*VLOOKUP($A9,'EU Ref Sc 2020 Energy intensive'!$A$5:$AE$33,J$2) -> 14.824628 | K9: =J9*VLOOKUP($A9,'EU Ref Sc 2020 Energy intensive'!$A$5:$AE$33,K$2) -> 14.535702 | L9: =K9*VLOOKUP($A9,'EU Ref Sc 2020 Energy intensive'!$A$5:$AE$33,L$2) -> 14.246777 | ... AG9: =AF9*VLOOKUP($A9,'EU Ref Sc 2020 Energy intensive'!$A$5:$AE$33,AG$2) -> 12.024758 | AH9: =AG9 -> 12.024758 | AI9: =AH9 -> 12.024758 | AJ9: =AI9 -> 12.024758 | AK9: =AJ9 -> 12.024758 | AL9: =AK9 -> 12.024758 | AM9: =AL9 -> 12.024758 | AN9: =AM9 -> 12.024758 | AO9: =AN9 -> 12.024758 | ... AQ9: =AP9 -> 12.024758
A10: DE | B10: P | C10: =A10&"IUE"&B10 -> DEIUEP | D10: 155.7442 | E10: =D10*VLOOKUP($A10,'EU Ref Sc 2020 Energy intensive'!$A$5:$AE$33,E$2) -> 156.72929 | F10: =E10*VLOOKUP($A10,'EU Ref Sc 2020 Energy intensive'!$A$5:$AE$33,F$2) -> 157.71438 | G10: =F10*VLOOKUP($A10,'EU Ref Sc 2020 Energy intensive'!$A$5:$AE$33,G$2) -> 158.69946 | H10: =G10*VLOOKUP($A10,'EU Ref Sc 2020 Energy intensive'!$A$5:$AE$33,H$2) -> 159.68455 | I10: =H10*VLOOKUP($A10,'EU Ref Sc 2020 Energy intensive'!$A$5:$AE$33,I$2) -> 157.72456 | J10: =I10*VLOOKUP($A10,'EU Ref Sc 2020 Energy intensive'!$A$5:$AE$33,J$2) -> 155.76457 | K10: =J10*VLOOKUP($A10,'EU Ref Sc 2020 Energy intensive'!$A$5:$AE$33,K$2) -> 153.80458 | L10: =K10*VLOOKUP($A10,'EU Ref Sc 2020 Energy intensive'!$A$5:$AE$33,L$2) -> 151.84459 | ... AG10: =AF10*VLOOKUP($A10,'EU Ref Sc 2020 Energy intensive'!$A$5:$AE$33,AG$2) -> 123.73894 | AH10: =AG10 -> 123.73894 | AI10: =AH10 -> 123.73894 | AJ10: =AI10 -> 123.73894 | AK10: =AJ10 -> 123.73894 | AL10: =AK10 -> 123.73894 | AM10: =AL10 -> 123.73894 | AN10: =AM10 -> 123.73894 | AO10: =AN10 -> 123.73894 | ... AQ10: =AP10 -> 123.73894
A11: EE | B11: P | C11: =A11&"IUE"&B11 -> EEIUEP | D11: 1.5654 | E11: =D11*VLOOKUP($A11,'EU Ref Sc 2020 Energy intensive'!$A$5:$AE$33,E$2) -> 1.6373859 | F11: =E11*VLOOKUP($A11,'EU Ref Sc 2020 Energy intensive'!$A$5:$AE$33,F$2) -> 1.7093718 | G11: =F11*VLOOKUP($A11,'EU Ref Sc 2020 Energy intensive'!$A$5:$AE$33,G$2) -> 1.7813577 | H11: =G11*VLOOKUP($A11,'EU Ref Sc 2020 Energy intensive'!$A$5:$AE$33,H$2) -> 1.8533436 | I11: =H11*VLOOKUP($A11,'EU Ref Sc 2020 Energy intensive'!$A$5:$AE$33,I$2) -> 1.8625641 | J11: =I11*VLOOKUP($A11,'EU Ref Sc 2020 Energy intensive'!$A$5:$AE$33,J$2) -> 1.8717846 | K11: =J11*VLOOKUP($A11,'EU Ref Sc 2020 Energy intensive'!$A$5:$AE$33,K$2) -> 1.8810051 | L11: =K11*VLOOKUP($A11,'EU Ref Sc 2020 Energy intensive'!$A$5:$AE$33,L$2) -> 1.8902256 | ... AG11: =AF11*VLOOKUP($A11,'EU Ref Sc 2020 Energy intensive'!$A$5:$AE$33,AG$2) -> 1.5539779 | AH11: =AG11 -> 1.5539779 | AI11: =AH11 -> 1.5539779 | AJ11: =AI11 -> 1.5539779 | AK11: =AJ11 -> 1.5539779 | AL11: =AK11 -> 1.5539779 | AM11: =AL11 -> 1.5539779 | AN11: =AM11 -> 1.5539779 | AO11: =AN11 -> 1.5539779 | ... AQ11: =AP11 -> 1.5539779
A12: FI | B12: P | C12: =A12&"IUE"&B12 -> FIIUEP | D12: 151.6995 | E12: =D12*VLOOKUP($A12,'EU Ref Sc 2020 Energy intensive'!$A$5:$AE$33,E$2) -> 158.6755 | F12: =E12*VLOOKUP($A12,'EU Ref Sc 2020 Energy intensive'!$A$5:$AE$33,F$2) -> 165.65149 | G12: =F12*VLOOKUP($A12,'EU Ref Sc 2020 Energy intensive'!$A$5:$AE$33,G$2) -> 172.62749 | H12: =G12*VLOOKUP($A12,'EU Ref Sc 2020 Energy intensive'!$A$5:$AE$33,H$2) -> 179.60348 | I12: =H12*VLOOKUP($A12,'EU Ref Sc 2020 Energy intensive'!$A$5:$AE$33,I$2) -> 180.49702 | J12: =I12*VLOOKUP($A12,'EU Ref Sc 2020 Energy intensive'!$A$5:$AE$33,J$2) -> 181.39056 | K12: =J12*VLOOKUP($A12,'EU Ref Sc 2020 Energy intensive'!$A$5:$AE$33,K$2) -> 182.2841 | L12: =K12*VLOOKUP($A12,'EU Ref Sc 2020 Energy intensive'!$A$5:$AE$33,L$2) -> 183.17764 | ... AG12: =AF12*VLOOKUP($A12,'EU Ref Sc 2020 Energy intensive'!$A$5:$AE$33,AG$2) -> 150.59261 | AH12: =AG12 -> 150.59261 | AI12: =AH12 -> 150.59261 | AJ12: =AI12 -> 150.59261 | AK12: =AJ12 -> 150.59261 | AL12: =AK12 -> 150.59261 | AM12: =AL12 -> 150.59261 | AN12: =AM12 -> 150.59261 | AO12: =AN12 -> 150.59261 | ... AQ12: =AP12 -> 150.59261
A13: FR | B13: P | C13: =A13&"IUE"&B13 -> FRIUEP | D13: 59.7343 | E13: =D13*VLOOKUP($A13,'EU Ref Sc 2020 Energy intensive'!$A$5:$AE$33,E$2) -> 62.481219 | F13: =E13*VLOOKUP($A13,'EU Ref Sc 2020 Energy intensive'!$A$5:$AE$33,F$2) -> 65.228138 | G13: =F13*VLOOKUP($A13,'EU Ref Sc 2020 Energy intensive'!$A$5:$AE$33,G$2) -> 67.975057 | H13: =G13*VLOOKUP($A13,'EU Ref Sc 2020 Energy intensive'!$A$5:$AE$33,H$2) -> 70.721976 | I13: =H13*VLOOKUP($A13,'EU Ref Sc 2020 Energy intensive'!$A$5:$AE$33,I$2) -> 71.073823 | J13: =I13*VLOOKUP($A13,'EU Ref Sc 2020 Energy intensive'!$A$5:$AE$33,J$2) -> 71.42567 | K13: =J13*VLOOKUP($A13,'EU Ref Sc 2020 Energy intensive'!$A$5:$AE$33,K$2) -> 71.777517 | L13: =K13*VLOOKUP($A13,'EU Ref Sc 2020 Energy intensive'!$A$5:$AE$33,L$2) -> 72.129364 | ... AG13: =AF13*VLOOKUP($A13,'EU Ref Sc 2020 Energy intensive'!$A$5:$AE$33,AG$2) -> 59.298441 | AH13: =AG13 -> 59.298441 | AI13: =AH13 -> 59.298441 | AJ13: =AI13 -> 59.298441 | AK13: =AJ13 -> 59.298441 | AL13: =AK13 -> 59.298441 | AM13: =AL13 -> 59.298441 | AN13: =AM13 -> 59.298441 | AO13: =AN13 -> 59.298441 | ... AQ13: =AP13 -> 59.298441
A14: HR | B14: P | C14: =A14&"IUE"&B14 -> HRIUEP | D14: 2.0081 | E14: =D14*VLOOKUP($A14,'EU Ref Sc 2020 Energy intensive'!$A$5:$AE$33,E$2) -> 2.0304845 | F14: =E14*VLOOKUP($A14,'EU Ref Sc 2020 Energy intensive'!$A$5:$AE$33,F$2) -> 2.0528689 | G14: =F14*VLOOKUP($A14,'EU Ref Sc 2020 Energy intensive'!$A$5:$AE$33,G$2) -> 2.0752534 | H14: =G14*VLOOKUP($A14,'EU Ref Sc 2020 Energy intensive'!$A$5:$AE$33,H$2) -> 2.0976378 | I14: =H14*VLOOKUP($A14,'EU Ref Sc 2020 Energy intensive'!$A$5:$AE$33,I$2) -> 2.0613852 | J14: =I14*VLOOKUP($A14,'EU Ref Sc 2020 Energy intensive'!$A$5:$AE$33,J$2) -> 2.0251325 | K14: =J14*VLOOKUP($A14,'EU Ref Sc 2020 Energy intensive'!$A$5:$AE$33,K$2) -> 1.9888799 | L14: =K14*VLOOKUP($A14,'EU Ref Sc 2020 Energy intensive'!$A$5:$AE$33,L$2) -> 1.9526272 | ... AG14: =AF14*VLOOKUP($A14,'EU Ref Sc 2020 Energy intensive'!$A$5:$AE$33,AG$2) -> 1.9437936 | AH14: =AG14 -> 1.9437936 | AI14: =AH14 -> 1.9437936 | AJ14: =AI14 -> 1.9437936 | AK14: =AJ14 -> 1.9437936 | AL14: =AK14 -> 1.9437936 | AM14: =AL14 -> 1.9437936 | AN14: =AM14 -> 1.9437936 | AO14: =AN14 -> 1.9437936 | ... AQ14: =AP14 -> 1.9437936
