Workbook

Sheet Country codes
A1: Country | B1: Country code
A2: Austria | B2: AT
A3: Belgium | B3: BE
A4: Bulgaria | B4: BG
A5: Cyprus | B5: CY
A6: Czechia | B6: CZ
A7: Germany | B7: DE
A8: Denmark | B8: DK
A9: Estonia | B9: EE
A10: Spain | B10: ES
A11: Finland | B11: FI
A12: France | B12: FR
... A28: Slovakia | B28: SK

Sheet Heavy trucks
A1: Source: JRC-IDEES 2021 (International & domestic)
A2: Freight activity (domestic and international) Gveh-km
B3: Country | C3: 2018 | D3: 2019 | E3: 2020 | F3: 2021 | G3: 2022 | H3: 2023 | I3: 2024 | J3: 2025 | K3: 2026 | L3: 2027 | M3: 2028 | N3: 2029 | O3: 2030 | P3: 2031 | Q3: 2032 | R3: 2033 | S3: 2034 | T3: 2035 | U3: 2036 | V3: 2037 | W3: 2038 | X3: 2039 | Y3: 2040 | Z3: 2041 | AA3: 2042 | AB3: 2043 | AC3: 2044 | AD3: 2045 | AE3: 2046 | AF3: 2047 | AG3: 2048 | AH3: 2049 | AI3: 2050 | AJ3: 2051 | AK3: 2052 | AL3: 2053 | AM3: 2054 | AN3: 2055 | AO3: 2056 | AP3: 2057 | AQ3: 2058 | AR3: 2059 | AS3: 2060 | AT3: 2061 | AU3: 2062 | AV3: 2063 | AW3: 2064 | AX3: 2065 | AY3: 2066 | AZ3: 2067 | BA3: 2068 | BB3: 2069 | BC3: 2070
A4: =LEFT(B4,2) -> AT | B4: ATEFTDSLHD00 | C4: 4.0861887 | D4: 4.1547379 | E4: 4.1314052 | F4: 4.3596899 | G4: =F4*('Road freight EU Ref'!H3/'Road freight EU Ref'!G3) -> 4.5415132 | H4: =G4*('Road freight EU Ref'!I3/'Road freight EU Ref'!H3) -> 4.7233366 | I4: =H4*('Road freight EU Ref'!J3/'Road freight EU Ref'!I3) -> 4.9051599 | J4: =I4*('Road freight EU Ref'!K3/'Road freight EU Ref'!J3) -> 5.0869833 | K4: =J4*('Road freight EU Ref'!L3/'Road freight EU Ref'!K3) -> 5.2119631 | L4: =K4*('Road freight EU Ref'!M3/'Road freight EU Ref'!L3) -> 5.3369429 | M4: =L4*('Road freight EU Ref'!N3/'Road freight EU Ref'!M3) -> 5.4619227 | N4: =M4*('Road freight EU Ref'!O3/'Road freight EU Ref'!N3) -> 5.5869025 | ... AI4: =AH4*('Road freight EU Ref'!AJ3/'Road freight EU Ref'!AI3) -> 6.8283113 | AJ4: =AI4 -> 6.8283113 | AK4: =AJ4 -> 6.8283113 | AL4: =AK4 -> 6.8283113 | AM4: =AL4 -> 6.8283113 | AN4: =AM4 -> 6.8283113 | AO4: =AN4 -> 6.8283113 | AP4: =AO4 -> 6.8283113 | AQ4: =AP4 -> 6.8283113 | ... BC4: =BB4 -> 6.8283113
A5: =LEFT(B5,2) -> BE | B5: BEEFTDSLHD00 | C5: 3.9293468 | D5: 4.1377003 | E5: 4.0378509 | F5: 4.2947537 | G5: =F5*('Road freight EU Ref'!H4/'Road freight EU Ref'!G4) -> 4.3950375 | H5: =G5*('Road freight EU Ref'!I4/'Road freight EU Ref'!H4) -> 4.4953212 | I5: =H5*('Road freight EU Ref'!J4/'Road freight EU Ref'!I4) -> 4.5956049 | J5: =I5*('Road freight EU Ref'!K4/'Road freight EU Ref'!J4) -> 4.6958886 | K5: =J5*('Road freight EU Ref'!L4/'Road freight EU Ref'!K4) -> 4.714066 | L5: =K5*('Road freight EU Ref'!M4/'Road freight EU Ref'!L4) -> 4.7322433 | M5: =L5*('Road freight EU Ref'!N4/'Road freight EU Ref'!M4) -> 4.7504207 | N5: =M5*('Road freight EU Ref'!O4/'Road freight EU Ref'!N4) -> 4.7685981 | ... AI5: =AH5*('Road freight EU Ref'!AJ4/'Road freight EU Ref'!AI4) -> 5.1547295 | AJ5: =AI5 -> 5.1547295 | AK5: =AJ5 -> 5.1547295 | AL5: =AK5 -> 5.1547295 | AM5: =AL5 -> 5.1547295 | AN5: =AM5 -> 5.1547295 | AO5: =AN5 -> 5.1547295 | AP5: =AO5 -> 5.1547295 | AQ5: =AP5 -> 5.1547295 | ... BC5: =BB5 -> 5.1547295
A6: =LEFT(B6,2) -> BG | B6: BGEFTDSLHD00 | C6: 1.0928171 | D6: 0.86381344 | E6: 1.0978791 | F6: 1.3228352 | G6: =F6*('Road freight EU Ref'!H5/'Road freight EU Ref'!G5) -> 1.3467504 | H6: =G6*('Road freight EU Ref'!I5/'Road freight EU Ref'!H5) -> 1.3706656 | I6: =H6*('Road freight EU Ref'!J5/'Road freight EU Ref'!I5) -> 1.3945808 | J6: =I6*('Road freight EU Ref'!K5/'Road freight EU Ref'!J5) -> 1.4184959 | K6: =J6*('Road freight EU Ref'!L5/'Road freight EU Ref'!K5) -> 1.4626075 | L6: =K6*('Road freight EU Ref'!M5/'Road freight EU Ref'!L5) -> 1.5067191 | M6: =L6*('Road freight EU Ref'!N5/'Road freight EU Ref'!M5) -> 1.5508307 | N6: =M6*('Road freight EU Ref'!O5/'Road freight EU Ref'!N5) -> 1.5949422 | ... AI6: =AH6*('Road freight EU Ref'!AJ5/'Road freight EU Ref'!AI5) -> 1.8786064 | AJ6: =AI6 -> 1.8786064 | AK6: =AJ6 -> 1.8786064 | AL6: =AK6 -> 1.8786064 | AM6: =AL6 -> 1.8786064 | AN6: =AM6 -> 1.8786064 | AO6: =AN6 -> 1.8786064 | AP6: =AO6 -> 1.8786064 | AQ6: =AP6 -> 1.8786064 | ... BC6: =BB6 -> 1.8786064
A7: =LEFT(B7,2) -> CY | B7: CYEFTDSLHD00 | C7: 0.111 | D7: 0.114 | E7: 0.083 | F7: 0.083 | G7: =F7*('Road freight EU Ref'!H6/'Road freight EU Ref'!G6) -> 0.084818438 | H7: =G7*('Road freight EU Ref'!I6/'Road freight EU Ref'!H6) -> 0.086636875 | I7: =H7*('Road freight EU Ref'!J6/'Road freight EU Ref'!I6) -> 0.088455313 | J7: =I7*('Road freight EU Ref'!K6/'Road freight EU Ref'!J6) -> 0.090273751 | K7: =J7*('Road freight EU Ref'!L6/'Road freight EU Ref'!K6) -> 0.0914129 | L7: =K7*('Road freight EU Ref'!M6/'Road freight EU Ref'!L6) -> 0.092552049 | M7: =L7*('Road freight EU Ref'!N6/'Road freight EU Ref'!M6) -> 0.093691198 | N7: =M7*('Road freight EU Ref'!O6/'Road freight EU Ref'!N6) -> 0.094830347 | ... AI7: =AH7*('Road freight EU Ref'!AJ6/'Road freight EU Ref'!AI6) -> 0.11409712 | AJ7: =AI7 -> 0.11409712 | AK7: =AJ7 -> 0.11409712 | AL7: =AK7 -> 0.11409712 | AM7: =AL7 -> 0.11409712 | AN7: =AM7 -> 0.11409712 | AO7: =AN7 -> 0.11409712 | AP7: =AO7 -> 0.11409712 | AQ7: =AP7 -> 0.11409712 | ... BC7: =BB7 -> 0.11409712
A8: =LEFT(B8,2) -> CZ | B8: CZEFTDSLHD00 | C8: 4.561191 | D8: 4.6554061 | E8: 5.162863 | F8: 5.6110286 | G8: =F8*('Road freight EU Ref'!H7/'Road freight EU Ref'!G7) -> 5.7690278 | H8: =G8*('Road freight EU Ref'!I7/'Road freight EU Ref'!H7) -> 5.9270269 | I8: =H8*('Road freight EU Ref'!J7/'Road freight EU Ref'!I7) -> 6.085026 | J8: =I8*('Road freight EU Ref'!K7/'Road freight EU Ref'!J7) -> 6.2430252 | K8: =J8*('Road freight EU Ref'!L7/'Road freight EU Ref'!K7) -> 6.3599086 | L8: =K8*('Road freight EU Ref'!M7/'Road freight EU Ref'!L7) -> 6.4767921 | M8: =L8*('Road freight EU Ref'!N7/'Road freight EU Ref'!M7) -> 6.5936755 | N8: =M8*('Road freight EU Ref'!O7/'Road freight EU Ref'!N7) -> 6.7105589 | ... AI8: =AH8*('Road freight EU Ref'!AJ7/'Road freight EU Ref'!AI7) -> 8.2080591 | AJ8: =AI8 -> 8.2080591 | AK8: =AJ8 -> 8.2080591 | AL8: =AK8 -> 8.2080591 | AM8: =AL8 -> 8.2080591 | AN8: =AM8 -> 8.2080591 | AO8: =AN8 -> 8.2080591 | AP8: =AO8 -> 8.2080591 | AQ8: =AP8 -> 8.2080591 | ... BC8: =BB8 -> 8.2080591
A9: =LEFT(B9,2) -> DE | B9: DEEFTDSLHD00 | C9: 40.056434 | D9: 40.965948 | E9: 40.88213 | F9: 41.734965 | G9: =F9*('Road freight EU Ref'!H8/'Road freight EU Ref'!G8) -> 42.867829 | H9: =G9*('Road freight EU Ref'!I8/'Road freight EU Ref'!H8) -> 44.000692 | I9: =H9*('Road freight EU Ref'!J8/'Road freight EU Ref'!I8) -> 45.133555 | J9: =I9*('Road freight EU Ref'!K8/'Road freight EU Ref'!J8) -> 46.266418 | K9: =J9*('Road freight EU Ref'!L8/'Road freight EU Ref'!K8) -> 47.16673 | L9: =K9*('Road freight EU Ref'!M8/'Road freight EU Ref'!L8) -> 48.067041 | M9: =L9*('Road freight EU Ref'!N8/'Road freight EU Ref'!M8) -> 48.967353 | N9: =M9*('Road freight EU Ref'!O8/'Road freight EU Ref'!N8) -> 49.867664 | ... AI9: =AH9*('Road freight EU Ref'!AJ8/'Road freight EU Ref'!AI8) -> 55.525699 | AJ9: =AI9 -> 55.525699 | AK9: =AJ9 -> 55.525699 | AL9: =AK9 -> 55.525699 | AM9: =AL9 -> 55.525699 | AN9: =AM9 -> 55.525699 | AO9: =AN9 -> 55.525699 | AP9: =AO9 -> 55.525699 | AQ9: =AP9 -> 55.525699 | ... BC9: =BB9 -> 55.525699
A10: =LEFT(B10,2) -> DK | B10: DKEFTDSLHD00 | C10: 1.7678092 | D10: 1.7943722 | E10: 1.8578289 | F10: 1.8936354 | G10: =F10*('Road freight EU Ref'!H9/'Road freight EU Ref'!G9) -> 1.955612 | H10: =G10*('Road freight EU Ref'!I9/'Road freight EU Ref'!H9) -> 2.0175886 | I10: =H10*('Road freight EU Ref'!J9/'Road freight EU Ref'!I9) -> 2.0795652 | J10: =I10*('Road freight EU Ref'!K9/'Road freight EU Ref'!J9) -> 2.1415419 | K10: =J10*('Road freight EU Ref'!L9/'Road freight EU Ref'!K9) -> 2.1618771 | L10: =K10*('Road freight EU Ref'!M9/'Road freight EU Ref'!L9) -> 2.1822122 | M10: =L10*('Road freight EU Ref'!N9/'Road freight EU Ref'!M9) -> 2.2025474 | N10: =M10*('Road freight EU Ref'!O9/'Road freight EU Ref'!N9) -> 2.2228826 | ... AI10: =AH10*('Road freight EU Ref'!AJ9/'Road freight EU Ref'!AI9) -> 2.5696831 | AJ10: =AI10 -> 2.5696831 | AK10: =AJ10 -> 2.5696831 | AL10: =AK10 -> 2.5696831 | AM10: =AL10 -> 2.5696831 | AN10: =AM10 -> 2.5696831 | AO10: =AN10 -> 2.5696831 | AP10: =AO10 -> 2.5696831 | AQ10: =AP10 -> 2.5696831 | ... BC10: =BB10 -> 2.5696831
A11: =LEFT(B11,2) -> EE | B11: EEEFTDSLHD00 | C11: 0.250812 | D11: 0.23991612 | E11: 0.22843208 | F11: 0.26964418 | G11: =F11*('Road freight EU Ref'!H10/'Road freight EU Ref'!G10) -> 0.27946107 | H11: =G11*('Road freight EU Ref'!I10/'Road freight EU Ref'!H10) -> 0.28927795 | I11: =H11*('Road freight EU Ref'!J10/'Road freight EU Ref'!I10) -> 0.29909483 | J11: =I11*('Road freight EU Ref'!K10/'Road freight EU Ref'!J10) -> 0.30891171 | K11: =J11*('Road freight EU Ref'!L10/'Road freight EU Ref'!K10) -> 0.3179538 | L11: =K11*('Road freight EU Ref'!M10/'Road freight EU Ref'!L10) -> 0.32699589 | M11: =L11*('Road freight EU Ref'!N10/'Road freight EU Ref'!M10) -> 0.33603799 | N11: =M11*('Road freight EU Ref'!O10/'Road freight EU Ref'!N10) -> 0.34508008 | ... AI11: =AH11*('Road freight EU Ref'!AJ10/'Road freight EU Ref'!AI10) -> 0.43917247 | AJ11: =AI11 -> 0.43917247 | AK11: =AJ11 -> 0.43917247 | AL11: =AK11 -> 0.43917247 | AM11: =AL11 -> 0.43917247 | AN11: =AM11 -> 0.43917247 | AO11: =AN11 -> 0.43917247 | AP11: =AO11 -> 0.43917247 | AQ11: =AP11 -> 0.43917247 | ... BC11: =BB11 -> 0.43917247
A12: =LEFT(B12,2) -> ES | B12: ESEFTDSLHD00 | C12: 17.526184 | D12: 18.343316 | E12: 17.876988 | F12: 19.654843 | G12: =F12*('Road freight EU Ref'!H11/'Road freight EU Ref'!G11) -> 20.122861 | H12: =G12*('Road freight EU Ref'!I11/'Road freight EU Ref'!H11) -> 20.590879 | I12: =H12*('Road freight EU Ref'!J11/'Road freight EU Ref'!I11) -> 21.058897 | J12: =I12*('Road freight EU Ref'!K11/'Road freight EU Ref'!J11) -> 21.526915 | K12: =J12*('Road freight EU Ref'!L11/'Road freight EU Ref'!K11) -> 21.74247 | L12: =K12*('Road freight EU Ref'!M11/'Road freight EU Ref'!L11) -> 21.958026 | M12: =L12*('Road freight EU Ref'!N11/'Road freight EU Ref'!M11) -> 22.173581 | N12: =M12*('Road freight EU Ref'!O11/'Road freight EU Ref'!N11) -> 22.389137 | ... AI12: =AH12*('Road freight EU Ref'!AJ11/'Road freight EU Ref'!AI11) -> 26.904947 | AJ12: =AI12 -> 26.904947 | AK12: =AJ12 -> 26.904947 | AL12: =AK12 -> 26.904947 | AM12: =AL12 -> 26.904947 | AN12: =AM12 -> 26.904947 | AO12: =AN12 -> 26.904947 | AP12: =AO12 -> 26.904947 | AQ12: =AP12 -> 26.904947 | ... BC12: =BB12 -> 26.904947
A13: =LEFT(B13,2) -> FI | B13: FIEFTDSLHD00 | C13: 1.9808451 | D13: 1.9719465 | E13: 1.9017718 | F13: 1.9521427 | G13: =F13*('Road freight EU Ref'!H12/'Road freight EU Ref'!G12) -> 2.0054605 | H13: =G13*('Road freight EU Ref'!I12/'Road freight EU Ref'!H12) -> 2.0587784 | I13: =H13*('Road freight EU Ref'!J12/'Road freight EU Ref'!I12) -> 2.1120962 | J13: =I13*('Road freight EU Ref'!K12/'Road freight EU Ref'!J12) -> 2.165414 | K13: =J13*('Road freight EU Ref'!L12/'Road freight EU Ref'!K12) -> 2.198611 | L13: =K13*('Road freight EU Ref'!M12/'Road freight EU Ref'!L12) -> 2.231808 | M13: =L13*('Road freight EU Ref'!N12/'Road freight EU Ref'!M12) -> 2.2650051 | N13: =M13*('Road freight EU Ref'!O12/'Road freight EU Ref'!N12) -> 2.2982021 | ... AI13: =AH13*('Road freight EU Ref'!AJ12/'Road freight EU Ref'!AI12) -> 2.4813482 | AJ13: =AI13 -> 2.4813482 | AK13: =AJ13 -> 2.4813482 | AL13: =AK13 -> 2.4813482 | AM13: =AL13 -> 2.4813482 | AN13: =AM13 -> 2.4813482 | AO13: =AN13 -> 2.4813482 | AP13: =AO13 -> 2.4813482 | AQ13: =AP13 -> 2.4813482 | ... BC13: =BB13 -> 2.4813482
A14: =LEFT(B14,2) -> FR | B14: FREFTDSLHD00 | C14: 21.193836 | D14: 21.864385 | E14: 21.240079 | F14: 22.264024 | G14: =F14*('Road freight EU Ref'!H13/'Road freight EU Ref'!G13) -> 22.575987 | H14: =G14*('Road freight EU Ref'!I13/'Road freight EU Ref'!H13) -> 22.88795 | I14: =H14*('Road freight EU Ref'!J13/'Road freight EU Ref'!I13) -> 23.199914 | J14: =I14*('Road freight EU Ref'!K13/'Road freight EU Ref'!J13) -> 23.511877 | K14: =J14*('Road freight EU Ref'!L13/'Road freight EU Ref'!K13) -> 23.790876 | L14: =K14*('Road freight EU Ref'!M13/'Road freight EU Ref'!L13) -> 24.069876 | M14: =L14*('Road freight EU Ref'!N13/'Road freight EU Ref'!M13) -> 24.348875 | N14: =M14*('Road freight EU Ref'!O13/'Road freight EU Ref'!N13) -> 24.627875 | ... AI14: =AH14*('Road freight EU Ref'!AJ13/'Road freight EU Ref'!AI13) -> 28.258581 | AJ14: =AI14 -> 28.258581 | AK14: =AJ14 -> 28.258581 | AL14: =AK14 -> 28.258581 | AM14: =AL14 -> 28.258581 | AN14: =AM14 -> 28.258581 | AO14: =AN14 -> 28.258581 | AP14: =AO14 -> 28.258581 | AQ14: =AP14 -> 28.258581 | ... BC14: =BB14 -> 28.258581
A15: =LEFT(B15,2) -> GR | B15: GREFTDSLHD00 | C15: 2.1296479 | D15: 2.0878062 | E15: 1.9161699 | F15: 2.190976 | G15: =F15*('Road freight EU Ref'!H14/'Road freight EU Ref'!G14) -> 2.254113 | H15: =G15*('Road freight EU Ref'!I14/'Road freight EU Ref'!H14) -> 2.3172501 | I15: =H15*('Road freight EU Ref'!J14/'Road freight EU Ref'!I14) -> 2.3803872 | J15: =I15*('Road freight EU Ref'!K14/'Road freight EU Ref'!J14) -> 2.4435242 | K15: =J15*('Road freight EU Ref'!L14/'Road freight EU Ref'!K14) -> 2.4592233 | L15: =K15*('Road freight EU Ref'!M14/'Road freight EU Ref'!L14) -> 2.4749224 | M15: =L15*('Road freight EU Ref'!N14/'Road freight EU Ref'!M14) -> 2.4906214 | N15: =M15*('Road freight EU Ref'!O14/'Road freight EU Ref'!N14) -> 2.5063205 | ... AI15: =AH15*('Road freight EU Ref'!AJ14/'Road freight EU Ref'!AI14) -> 2.8760642 | AJ15: =AI15 -> 2.8760642 | AK15: =AJ15 -> 2.8760642 | AL15: =AK15 -> 2.8760642 | AM15: =AL15 -> 2.8760642 | AN15: =AM15 -> 2.8760642 | AO15: =AN15 -> 2.8760642 | AP15: =AO15 -> 2.8760642 | AQ15: =AP15 -> 2.8760642 | ... BC15: =BB15 -> 2.8760642
... A30: =LEFT(B30,2) -> SK | B30: SKEFTDSLHD00 | C30: 2.1874532 | D30: 2.4285952 | E30: 2.3462528 | F30: 2.2794527 | G30: =F30*('Road freight EU Ref'!H29/'Road freight EU Ref'!G29) -> 2.3307614 | H30: =G30*('Road freight EU Ref'!I29/'Road freight EU Ref'!H29) -> 2.38207 | I30: =H30*('Road freight EU Ref'!J29/'Road freight EU Ref'!I29) -> 2.4333786 | J30: =I30*('Road freight EU Ref'!K29/'Road freight EU Ref'!J29) -> 2.4846873 | K30: =J30*('Road freight EU Ref'!L29/'Road freight EU Ref'!K29) -> 2.54837 | L30: =K30*('Road freight EU Ref'!M29/'Road freight EU Ref'!L29) -> 2.6120528 | M30: =L30*('Road freight EU Ref'!N29/'Road freight EU Ref'!M29) -> 2.6757356 | N30: =M30*('Road freight EU Ref'!O29/'Road freight EU Ref'!N29) -> 2.7394183 | ... AI30: =AH30*('Road freight EU Ref'!AJ29/'Road freight EU Ref'!AI29) -> 3.1658487 | AJ30: =AI30 -> 3.1658487 | AK30: =AJ30 -> 3.1658487 | AL30: =AK30 -> 3.1658487 | AM30: =AL30 -> 3.1658487 | AN30: =AM30 -> 3.1658487 | AO30: =AN30 -> 3.1658487 | AP30: =AO30 -> 3.1658487 | AQ30: =AP30 -> 3.1658487 | ... BC30: =BB30 -> 3.1658487

Sheet Light Commercial Vans
A1: Source: JRC-IDEES 2021 (International & domestic)
A2: Freight activity (domestic and international) Gveh-km
B3: Country | C3: 2018 | D3: 2019 | E3: 2020 | F3: 2021 | G3: 2022 | H3: 2023 | I3: 2024 | J3: 2025 | K3: 2026 | L3: 2027 | M3: 2028 | N3: 2029 | O3: 2030 | P3: 2031 | Q3: 2032 | R3: 2033 | S3: 2034 | T3: 2035 | U3: 2036 | V3: 2037 | W3: 2038 | X3: 2039 | Y3: 2040 | Z3: 2041 | AA3: 2042 | AB3: 2043 | AC3: 2044 | AD3: 2045 | AE3: 2046 | AF3: 2047 | AG3: 2048 | AH3: 2049 | AI3: 2050 | AJ3: 2051 | AK3: 2052 | AL3: 2053 | AM3: 2054 | AN3: 2055 | AO3: 2056 | AP3: 2057 | AQ3: 2058 | AR3: 2059 | AS3: 2060 | AT3: 2061 | AU3: 2062 | AV3: 2063 | AW3: 2064 | AX3: 2065 | AY3: 2066 | AZ3: 2067 | BA3: 2068 | BB3: 2069 | BC3: 2070
B4: AT | C4: 5.9205805 | D4: 6.1155232 | E4: 6.1927976 | F4: 6.5598192 | G4: =F4*('Road freight EU Ref'!H3/'Road freight EU Ref'!G3) -> 6.8334002 | H4: =G4*('Road freight EU Ref'!I3/'Road freight EU Ref'!H3) -> 7.1069812 | I4: =H4*('Road freight EU Ref'!J3/'Road freight EU Ref'!I3) -> 7.3805622 | J4: =I4*('Road freight EU Ref'!K3/'Road freight EU Ref'!J3) -> 7.6541432 | K4: =J4*('Road freight EU Ref'!L3/'Road freight EU Ref'!K3) -> 7.8421944 | L4: =K4*('Road freight EU Ref'!M3/'Road freight EU Ref'!L3) -> 8.0302456 | M4: =L4*('Road freight EU Ref'!N3/'Road freight EU Ref'!M3) -> 8.2182968 | N4: =M4*('Road freight EU Ref'!O3/'Road freight EU Ref'!N3) -> 8.406348 | ... AI4: =AH4*('Road freight EU Ref'!AJ3/'Road freight EU Ref'!AI3) -> 10.274237 | AJ4: =AI4 -> 10.274237 | AK4: =AJ4 -> 10.274237 | AL4: =AK4 -> 10.274237 | AM4: =AL4 -> 10.274237 | AN4: =AM4 -> 10.274237 | AO4: =AN4 -> 10.274237 | AP4: =AO4 -> 10.274237 | AQ4: =AP4 -> 10.274237 | ... BC4: =BB4 -> 10.274237
B5: BE | C5: 11.195743 | D5: 11.34766 | E5: 10.627549 | F5: 12.353805 | G5: =F5*('Road freight EU Ref'!H4/'Road freight EU Ref'!G4) -> 12.64227 | H5: =G5*('Road freight EU Ref'!I4/'Road freight EU Ref'!H4) -> 12.930735 | I5: =H5*('Road freight EU Ref'!J4/'Road freight EU Ref'!I4) -> 13.2192 | J5: =I5*('Road freight EU Ref'!K4/'Road freight EU Ref'!J4) -> 13.507665 | K5: =J5*('Road freight EU Ref'!L4/'Road freight EU Ref'!K4) -> 13.559952 | L5: =K5*('Road freight EU Ref'!M4/'Road freight EU Ref'!L4) -> 13.612239 | M5: =L5*('Road freight EU Ref'!N4/'Road freight EU Ref'!M4) -> 13.664526 | N5: =M5*('Road freight EU Ref'!O4/'Road freight EU Ref'!N4) -> 13.716813 | ... AI5: =AH5*('Road freight EU Ref'!AJ4/'Road freight EU Ref'!AI4) -> 14.827515 | AJ5: =AI5 -> 14.827515 | AK5: =AJ5 -> 14.827515 | AL5: =AK5 -> 14.827515 | AM5: =AL5 -> 14.827515 | AN5: =AM5 -> 14.827515 | AO5: =AN5 -> 14.827515 | AP5: =AO5 -> 14.827515 | AQ5: =AP5 -> 14.827515 | ... BC5: =BB5 -> 14.827515
B6: BG | C6: 2.4908733 | D6: 2.4459017 | E6: 2.3552496 | F6: 2.2599781 | G6: =F6*('Road freight EU Ref'!H5/'Road freight EU Ref'!G5) -> 2.3008356 | H6: =G6*('Road freight EU Ref'!I5/'Road freight EU Ref'!H5) -> 2.3416932 | I6: =H6*('Road freight EU Ref'!J5/'Road freight EU Ref'!I5) -> 2.3825507 | J6: =I6*('Road freight EU Ref'!K5/'Road freight EU Ref'!J5) -> 2.4234083 | K6: =J6*('Road freight EU Ref'!L5/'Road freight EU Ref'!K5) -> 2.49877 | L6: =K6*('Road freight EU Ref'!M5/'Road freight EU Ref'!L5) -> 2.5741318 | M6: =L6*('Road freight EU Ref'!N5/'Road freight EU Ref'!M5) -> 2.6494935 | N6: =M6*('Road freight EU Ref'!O5/'Road freight EU Ref'!N5) -> 2.7248553 | ... AI6: =AH6*('Road freight EU Ref'!AJ5/'Road freight EU Ref'!AI5) -> 3.209477 | AJ6: =AI6 -> 3.209477 | AK6: =AJ6 -> 3.209477 | AL6: =AK6 -> 3.209477 | AM6: =AL6 -> 3.209477 | AN6: =AM6 -> 3.209477 | AO6: =AN6 -> 3.209477 | AP6: =AO6 -> 3.209477 | AQ6: =AP6 -> 3.209477 | ... BC6: =BB6 -> 3.209477
B7: CY | C7: 1.5146746 | D7: 1.49279 | E7: 1.4463114 | F7: 1.4255472 | G7: =F7*('Road freight EU Ref'!H6/'Road freight EU Ref'!G6) -> 1.4567794 | H7: =G7*('Road freight EU Ref'!I6/'Road freight EU Ref'!H6) -> 1.4880115 | I7: =H7*('Road freight EU Ref'!J6/'Road freight EU Ref'!I6) -> 1.5192437 | J7: =I7*('Road freight EU Ref'!K6/'Road freight EU Ref'!J6) -> 1.5504758 | K7: =J7*('Road freight EU Ref'!L6/'Road freight EU Ref'!K6) -> 1.570041 | L7: =K7*('Road freight EU Ref'!M6/'Road freight EU Ref'!L6) -> 1.5896062 | M7: =L7*('Road freight EU Ref'!N6/'Road freight EU Ref'!M6) -> 1.6091714 | N7: =M7*('Road freight EU Ref'!O6/'Road freight EU Ref'!N6) -> 1.6287366 | ... AI7: =AH7*('Road freight EU Ref'!AJ6/'Road freight EU Ref'!AI6) -> 1.9596485 | AJ7: =AI7 -> 1.9596485 | AK7: =AJ7 -> 1.9596485 | AL7: =AK7 -> 1.9596485 | AM7: =AL7 -> 1.9596485 | AN7: =AM7 -> 1.9596485 | AO7: =AN7 -> 1.9596485 | AP7: =AO7 -> 1.9596485 | AQ7: =AP7 -> 1.9596485 | ... BC7: =BB7 -> 1.9596485
B8: CZ | C8: 6.5322269 | D8: 6.5730812 | E8: 6.3923407 | F8: 6.54226 | G8: =F8*('Road freight EU Ref'!H7/'Road freight EU Ref'!G7) -> 6.7264814 | H8: =G8*('Road freight EU Ref'!I7/'Road freight EU Ref'!H7) -> 6.9107028 | I8: =H8*('Road freight EU Ref'!J7/'Road freight EU Ref'!I7) -> 7.0949242 | J8: =I8*('Road freight EU Ref'!K7/'Road freight EU Ref'!J7) -> 7.2791456 | K8: =J8*('Road freight EU Ref'!L7/'Road freight EU Ref'!K7) -> 7.4154275 | L8: =K8*('Road freight EU Ref'!M7/'Road freight EU Ref'!L7) -> 7.5517095 | M8: =L8*('Road freight EU Ref'!N7/'Road freight EU Ref'!M7) -> 7.6879914 | N8: =M8*('Road freight EU Ref'!O7/'Road freight EU Ref'!N7) -> 7.8242733 | ... AI8: =AH8*('Road freight EU Ref'!AJ7/'Road freight EU Ref'!AI7) -> 9.5703053 | AJ8: =AI8 -> 9.5703053 | AK8: =AJ8 -> 9.5703053 | AL8: =AK8 -> 9.5703053 | AM8: =AL8 -> 9.5703053 | AN8: =AM8 -> 9.5703053 | AO8: =AN8 -> 9.5703053 | AP8: =AO8 -> 9.5703053 | AQ8: =AP8 -> 9.5703053 | ... BC8: =BB8 -> 9.5703053
B9: DE | C9: 42.432038 | D9: 43.881096 | E9: 42.948137 | F9: 45.016141 | G9: =F9*('Road freight EU Ref'!H8/'Road freight EU Ref'!G8) -> 46.238069 | H9: =G9*('Road freight EU Ref'!I8/'Road freight EU Ref'!H8) -> 47.459997 | I9: =H9*('Road freight EU Ref'!J8/'Road freight EU Ref'!I8) -> 48.681925 | J9: =I9*('Road freight EU Ref'!K8/'Road freight EU Ref'!J8) -> 49.903853 | K9: =J9*('Road freight EU Ref'!L8/'Road freight EU Ref'!K8) -> 50.874947 | L9: =K9*('Road freight EU Ref'!M8/'Road freight EU Ref'!L8) -> 51.84604 | M9: =L9*('Road freight EU Ref'!N8/'Road freight EU Ref'!M8) -> 52.817133 | N9: =M9*('Road freight EU Ref'!O8/'Road freight EU Ref'!N8) -> 53.788226 | ... AI9: =AH9*('Road freight EU Ref'!AJ8/'Road freight EU Ref'!AI8) -> 59.891093 | AJ9: =AI9 -> 59.891093 | AK9: =AJ9 -> 59.891093 | AL9: =AK9 -> 59.891093 | AM9: =AL9 -> 59.891093 | AN9: =AM9 -> 59.891093 | AO9: =AN9 -> 59.891093 | AP9: =AO9 -> 59.891093 | AQ9: =AP9 -> 59.891093 | ... BC9: =BB9 -> 59.891093
B10: DK | C10: 6.8860714 | D10: 6.6877842 | E10: 6.2055418 | F10: 6.3778432 | G10: =F10*('Road freight EU Ref'!H9/'Road freight EU Ref'!G9) -> 6.586583 | H10: =G10*('Road freight EU Ref'!I9/'Road freight EU Ref'!H9) -> 6.7953228 | I10: =H10*('Road freight EU Ref'!J9/'Road freight EU Ref'!I9) -> 7.0040626 | J10: =I10*('Road freight EU Ref'!K9/'Road freight EU Ref'!J9) -> 7.2128025 | K10: =J10*('Road freight EU Ref'!L9/'Road freight EU Ref'!K9) -> 7.2812923 | L10: =K10*('Road freight EU Ref'!M9/'Road freight EU Ref'!L9) -> 7.349782 | M10: =L10*('Road freight EU Ref'!N9/'Road freight EU Ref'!M9) -> 7.4182718 | N10: =M10*('Road freight EU Ref'!O9/'Road freight EU Ref'!N9) -> 7.4867616 | ... AI10: =AH10*('Road freight EU Ref'!AJ9/'Road freight EU Ref'!AI9) -> 8.6548 | AJ10: =AI10 -> 8.6548 | AK10: =AJ10 -> 8.6548 | AL10: =AK10 -> 8.6548 | AM10: =AL10 -> 8.6548 | AN10: =AM10 -> 8.6548 | AO10: =AN10 -> 8.6548 | AP10: =AO10 -> 8.6548 | AQ10: =AP10 -> 8.6548 | ... BC10: =BB10 -> 8.6548
B11: EE | C11: 1.0705855 | D11: 1.1850081 | E11: 1.2203085 | F11: 1.2994433 | G11: =F11*('Road freight EU Ref'!H10/'Road freight EU Ref'!G10) -> 1.3467519 | H11: =G11*('Road freight EU Ref'!I10/'Road freight EU Ref'!H10) -> 1.3940604 | I11: =H11*('Road freight EU Ref'!J10/'Road freight EU Ref'!I10) -> 1.441369 | J11: =I11*('Road freight EU Ref'!K10/'Road freight EU Ref'!J10) -> 1.4886776 | K11: =J11*('Road freight EU Ref'!L10/'Road freight EU Ref'!K10) -> 1.5322523 | L11: =K11*('Road freight EU Ref'!M10/'Road freight EU Ref'!L10) -> 1.5758271 | M11: =L11*('Road freight EU Ref'!N10/'Road freight EU Ref'!M10) -> 1.6194019 | N11: =M11*('Road freight EU Ref'!O10/'Road freight EU Ref'!N10) -> 1.6629767 | ... AI11: =AH11*('Road freight EU Ref'!AJ10/'Road freight EU Ref'!AI10) -> 2.1164177 | AJ11: =AI11 -> 2.1164177 | AK11: =AJ11 -> 2.1164177 | AL11: =AK11 -> 2.1164177 | AM11: =AL11 -> 2.1164177 | AN11: =AM11 -> 2.1164177 | AO11: =AN11 -> 2.1164177 | AP11: =AO11 -> 2.1164177 | AQ11: =AP11 -> 2.1164177 | ... BC11: =BB11 -> 2.1164177
B12: ES | C12: 27.662577 | D12: 27.913473 | E12: 18.443174 | F12: 26.948141 | G12: =F12*('Road freight EU Ref'!H11/'Road freight EU Ref'!G11) -> 27.589826 | H12: =G12*('Road freight EU Ref'!I11/'Road freight EU Ref'!H11) -> 28.23151 | I12: =H12*('Road freight EU Ref'!J11/'Road freight EU Ref'!I11) -> 28.873195 | J12: =I12*('Road freight EU Ref'!K11/'Road freight EU Ref'!J11) -> 29.51488 | K12: =J12*('Road freight EU Ref'!L11/'Road freight EU Ref'!K11) -> 29.810421 | L12: =K12*('Road freight EU Ref'!M11/'Road freight EU Ref'!L11) -> 30.105962 | M12: =L12*('Road freight EU Ref'!N11/'Road freight EU Ref'!M11) -> 30.401504 | N12: =M12*('Road freight EU Ref'!O11/'Road freight EU Ref'!N11) -> 30.697045 | ... AI12: =AH12*('Road freight EU Ref'!AJ11/'Road freight EU Ref'!AI11) -> 36.888531 | AJ12: =AI12 -> 36.888531 | AK12: =AJ12 -> 36.888531 | AL12: =AK12 -> 36.888531 | AM12: =AL12 -> 36.888531 | AN12: =AM12 -> 36.888531 | AO12: =AN12 -> 36.888531 | AP12: =AO12 -> 36.888531 | AQ12: =AP12 -> 36.888531 | ... BC12: =BB12 -> 36.888531
B13: FI | C13: 6.9369398 | D13: 7.1382441 | E13: 7.1396677 | F13: 7.4577104 | G13: =F13*('Road freight EU Ref'!H12/'Road freight EU Ref'!G12) -> 7.6613988 | H13: =G13*('Road freight EU Ref'!I12/'Road freight EU Ref'!H12) -> 7.8650872 | I13: =H13*('Road freight EU Ref'!J12/'Road freight EU Ref'!I12) -> 8.0687756 | J13: =I13*('Road freight EU Ref'!K12/'Road freight EU Ref'!J12) -> 8.272464 | K13: =J13*('Road freight EU Ref'!L12/'Road freight EU Ref'!K12) -> 8.3992855 | L13: =K13*('Road freight EU Ref'!M12/'Road freight EU Ref'!L12) -> 8.5261071 | M13: =L13*('Road freight EU Ref'!N12/'Road freight EU Ref'!M12) -> 8.6529287 | N13: =M13*('Road freight EU Ref'!O12/'Road freight EU Ref'!N12) -> 8.7797502 | ... AI13: =AH13*('Road freight EU Ref'!AJ12/'Road freight EU Ref'!AI12) -> 9.4794177 | AJ13: =AI13 -> 9.4794177 | AK13: =AJ13 -> 9.4794177 | AL13: =AK13 -> 9.4794177 | AM13: =AL13 -> 9.4794177 | AN13: =AM13 -> 9.4794177 | AO13: =AN13 -> 9.4794177 | AP13: =AO13 -> 9.4794177 | AQ13: =AP13 -> 9.4794177 | ... BC13: =BB13 -> 9.4794177
B14: FR | C14: 75.422041 | D14: 76.188551 | E14: 66.504985 | F14: 76.180214 | G14: =F14*('Road freight EU Ref'!H13/'Road freight EU Ref'!G13) -> 77.24765 | H14: =G14*('Road freight EU Ref'!I13/'Road freight EU Ref'!H13) -> 78.315087 | I14: =H14*('Road freight EU Ref'!J13/'Road freight EU Ref'!I13) -> 79.382523 | J14: =I14*('Road freight EU Ref'!K13/'Road freight EU Ref'!J13) -> 80.44996 | K14: =J14*('Road freight EU Ref'!L13/'Road freight EU Ref'!K13) -> 81.404605 | L14: =K14*('Road freight EU Ref'!M13/'Road freight EU Ref'!L13) -> 82.35925 | M14: =L14*('Road freight EU Ref'!N13/'Road freight EU Ref'!M13) -> 83.313896 | N14: =M14*('Road freight EU Ref'!O13/'Road freight EU Ref'!N13) -> 84.268541 | ... AI14: =AH14*('Road freight EU Ref'!AJ13/'Road freight EU Ref'!AI13) -> 96.691631 | AJ14: =AI14 -> 96.691631 | AK14: =AJ14 -> 96.691631 | AL14: =AK14 -> 96.691631 | AM14: =AL14 -> 96.691631 | AN14: =AM14 -> 96.691631 | AO14: =AN14 -> 96.691631 | AP14: =AO14 -> 96.691631 | AQ14: =AP14 -> 96.691631 | ... BC14: =BB14 -> 96.691631
B15: GR | C15: 8.4057201 | D15: 8.5680985 | E15: 7.4596459 | F15: 8.2218643 | G15: =F15*('Road freight EU Ref'!H14/'Road freight EU Ref'!G14) -> 8.4587927 | H15: =G15*('Road freight EU Ref'!I14/'Road freight EU Ref'!H14) -> 8.6957211 | I15: =H15*('Road freight EU Ref'!J14/'Road freight EU Ref'!I14) -> 8.9326495 | J15: =I15*('Road freight EU Ref'!K14/'Road freight EU Ref'!J14) -> 9.1695779 | K15: =J15*('Road freight EU Ref'!L14/'Road freight EU Ref'!K14) -> 9.2284902 | L15: =K15*('Road freight EU Ref'!M14/'Road freight EU Ref'!L14) -> 9.2874025 | M15: =L15*('Road freight EU Ref'!N14/'Road freight EU Ref'!M14) -> 9.3463149 | N15: =M15*('Road freight EU Ref'!O14/'Road freight EU Ref'!N14) -> 9.4052272 | ... AI15: =AH15*('Road freight EU Ref'!AJ14/'Road freight EU Ref'!AI14) -> 10.792729 | AJ15: =AI15 -> 10.792729 | AK15: =AJ15 -> 10.792729 | AL15: =AK15 -> 10.792729 | AM15: =AL15 -> 10.792729 | AN15: =AM15 -> 10.792729 | AO15: =AN15 -> 10.792729 | AP15: =AO15 -> 10.792729 | AQ15: =AP15 -> 10.792729 | ... BC15: =BB15 -> 10.792729
... B30: SK | C30: 2.5924092 | D30: 2.5852686 | E30: 2.6301302 | F30: 2.6719811 | G30: =F30*('Road freight EU Ref'!H29/'Road freight EU Ref'!G29) -> 2.7321253 | H30: =G30*('Road freight EU Ref'!I29/'Road freight EU Ref'!H29) -> 2.7922694 | I30: =H30*('Road freight EU Ref'!J29/'Road freight EU Ref'!I29) -> 2.8524135 | J30: =I30*('Road freight EU Ref'!K29/'Road freight EU Ref'!J29) -> 2.9125577 | K30: =J30*('Road freight EU Ref'!L29/'Road freight EU Ref'!K29) -> 2.9872068 | L30: =K30*('Road freight EU Ref'!M29/'Road freight EU Ref'!L29) -> 3.0618559 | M30: =L30*('Road freight EU Ref'!N29/'Road freight EU Ref'!M29) -> 3.136505 | N30: =M30*('Road freight EU Ref'!O29/'Road freight EU Ref'!N29) -> 3.2111541 | ... AI30: =AH30*('Road freight EU Ref'!AJ29/'Road freight EU Ref'!AI29) -> 3.7110171 | AJ30: =AI30 -> 3.7110171 | AK30: =AJ30 -> 3.7110171 | AL30: =AK30 -> 3.7110171 | AM30: =AL30 -> 3.7110171 | AN30: =AM30 -> 3.7110171 | AO30: =AN30 -> 3.7110171 | AP30: =AO30 -> 3.7110171 | AQ30: =AP30 -> 3.7110171 | ... BC30: =BB30 -> 3.7110171
A33: Source: JRC-IDEES 2021 (International & domestic)
A34: Freight activity (domestic and international) Gtkm
A35: Country | B35: TECHNOLOGY | C35: 2018 | D35: 2019 | E35: 2020 | F35: 2021
A36: =LEFT(B36,2) -> AT | B36: ATEFTGSLLC00 | C36: 0.27390541 | D36: 0.27479011 | E36: 0.26844355 | F36: 0.26910843
A37: =LEFT(B37,2) -> AT | B37: ATEFTDSLLC00 | C37: 5.6012872 | D37: 5.7901954 | E37: 5.8665027 | F37: 6.201103
A38: =LEFT(B38,2) -> AT | B38: ATEFTNGSLC00 | C38: 0.018850432 | D38: 0.018228548 | E38: 0.016575004 | F38: 0.015754719
A39: =LEFT(B39,2) -> AT | B39: ATEFTGSLLCHB | C39: 0 | D39: 0 | E39: 0.000138224 | F39: 0.000441262
A40: =LEFT(B40,2) -> AT | B40: ATEFTDSLLCHB | C40: 0 | D40: 2.83e-05 | E40: 0.000335496 | F40: 0.003767521
A41: =LEFT(B41,2) -> AT | B41: ATEFTDSLLCPH | C41: 0 | D41: 0 | E41: 0 | F41: 0
A42: =LEFT(B42,2) -> AT | B42: ATEFTELCLCBT | C42: 0.02653738 | D42: 0.032280762 | E42: 0.04080261 | F42: 0.069644245
A43: =LEFT(B43,2) -> AT | B43: ATEFTHY2LCFC | C43: 0 | D43: 0 | E43: 0 | F43: 0
A44: =LEFT(B44,2) -> BG | B44: BGEFTGSLLC00 | C44: 0.16857757 | D44: 0.17714856 | E44: 0.18079942 | F44: 0.18674012
A45: =LEFT(B45,2) -> BG | B45: BGEFTDSLLC00 | C45: 2.3196747 | D45: 2.2648756 | E45: 2.1696756 | F45: 2.067703
A46: =LEFT(B46,2) -> BG | B46: BGEFTNGSLC00 | C46: 0.002057087 | D46: 0.003109477 | E46: 0.003928144 | F46: 0.004608442
A47: =LEFT(B47,2) -> BG | B47: BGEFTGSLLCHB | C47: 0 | D47: 0 | E47: 0 | F47: 0
... A251: =LEFT(B251,2) -> SE | B251: SEEFTHY2LCFC | C251: 0 | D251: 0 | E251: 0 | F251: 0

Sheet Road freight EU Ref
A1: Source: interpolation from EU Reference Scenario 2020 projections
A2: Country | B2: YEAR | F2: 2020 | G2: 2021 | H2: 2022 | I2: 2023 | J2: 2024 | K2: 2025 | L2: 2026 | M2: 2027 | N2: 2028 | O2: 2029 | P2: 2030 | Q2: 2031 | R2: 2032 | S2: 2033 | T2: 2034 | U2: 2035 | V2: 2036 | W2: 2037 | X2: 2038 | Y2: 2039 | Z2: 2040 | AA2: 2041 | AB2: 2042 | AC2: 2043 | AD2: 2044 | AE2: 2045 | AF2: 2046 | AG2: 2047 | AH2: 2048 | AI2: 2049 | AJ2: 2050 | AK2: '20-'30 | AL2: '30-'50
A3: =VLOOKUP(B3,'Country codes'!$A$1:$B$28,2,FALSE) -> AT | B3: Austria | C3: Reference Scenario 2020 (REF2020) | D3: Freight transport activity (Gtkm) | E3: Heavy goods and light commercial vehicles | F3: 45.79919 | G3: =F3+(($K3-$F3)/5) -> 47.792399 | H3: =G3+(($K3-$F3)/5) -> 49.785609 | I3: =H3+(($K3-$F3)/5) -> 51.778818 | J3: =I3+(($K3-$F3)/5) -> 53.772027 | K3: 55.765237 | L3: =K3+(($P3-$K3)/5) -> 57.135308 | M3: =L3+(($P3-$K3)/5) -> 58.505379 | N3: =M3+(($P3-$K3)/5) -> 59.87545 | O3: =N3+(($P3-$K3)/5) -> 61.245521 | P3: 62.615592 | Q3: =P3+(($U3-$P3)/5) -> 63.474945 | R3: =Q3+(($U3-$P3)/5) -> 64.334298 | S3: =R3+(($U3-$P3)/5) -> 65.193651 | T3: =S3+(($U3-$P3)/5) -> 66.053004 | U3: 66.912357 | V3: =U3+(($Z3-$U3)/5) -> 67.684325 | W3: =V3+(($Z3-$U3)/5) -> 68.456293 | X3: =W3+(($Z3-$U3)/5) -> 69.228261 | Y3: =X3+(($Z3-$U3)/5) -> 70.000229 | Z3: 70.772197 | AA3: =Z3+(($AE3-$Z3)/5) -> 71.312958 | AB3: =AA3+(($AE3-$Z3)/5) -> 71.85372 | AC3: =AB3+(($AE3-$Z3)/5) -> 72.394481 | AD3: =AC3+(($AE3-$Z3)/5) -> 72.935243 | AE3: 73.476004 | AF3: =AE3+(($AJ3-$AE3)/5) -> 73.751657 | AG3: =AF3+(($AJ3-$AE3)/5) -> 74.027309 | AH3: =AG3+(($AJ3-$AE3)/5) -> 74.302961 | AI3: =AH3+(($AJ3-$AE3)/5) -> 74.578613 | AJ3: 74.854265 | AK3: 3.1768986 | AL3: 0.8966398
A4: =VLOOKUP(B4,'Country codes'!$A$1:$B$28,2,FALSE) -> BE | B4: Belgium | C4: Reference Scenario 2020 (REF2020) | D4: Freight transport activity (Gtkm) | E4: Heavy goods and light commercial vehicles | F4: 52.095418 | G4: =F4+(($K4-$F4)/5) -> 53.340944 | H4: =G4+(($K4-$F4)/5) -> 54.58647 | I4: =H4+(($K4-$F4)/5) -> 55.831996 | J4: =I4+(($K4-$F4)/5) -> 57.077522 | K4: 58.323048 | L4: =K4+(($P4-$K4)/5) -> 58.548812 | M4: =L4+(($P4-$K4)/5) -> 58.774575 | N4: =M4+(($P4-$K4)/5) -> 59.000338 | O4: =N4+(($P4-$K4)/5) -> 59.226102 | P4: 59.451865 | Q4: =P4+(($U4-$P4)/5) -> 59.599975 | R4: =Q4+(($U4-$P4)/5) -> 59.748085 | S4: =R4+(($U4-$P4)/5) -> 59.896195 | T4: =S4+(($U4-$P4)/5) -> 60.044305 | U4: 60.192415 | V4: =U4+(($Z4-$U4)/5) -> 60.427684 | W4: =V4+(($Z4-$U4)/5) -> 60.662952 | X4: =W4+(($Z4-$U4)/5) -> 60.89822 | Y4: =X4+(($Z4-$U4)/5) -> 61.133489 | Z4: 61.368757 | AA4: =Z4+(($AE4-$Z4)/5) -> 61.64927 | AB4: =AA4+(($AE4-$Z4)/5) -> 61.929782 | AC4: =AB4+(($AE4-$Z4)/5) -> 62.210295 | AD4: =AC4+(($AE4-$Z4)/5) -> 62.490808 | AE4: 62.771321 | AF4: =AE4+(($AJ4-$AE4)/5) -> 63.021429 | AG4: =AF4+(($AJ4-$AE4)/5) -> 63.271537 | AH4: =AG4+(($AJ4-$AE4)/5) -> 63.521646 | AI4: =AH4+(($AJ4-$AE4)/5) -> 63.771754 | AJ4: 64.021863 | AK4: 1.3296624 | AL4: 0.37097459
A5: =VLOOKUP(B5,'Country codes'!$A$1:$B$28,2,FALSE) -> BG | B5: Bulgaria | C5: Reference Scenario 2020 (REF2020) | D5: Freight transport activity (Gtkm) | E5: Heavy goods and light commercial vehicles | F5: 12.036113 | G5: =F5+(($K5-$F5)/5) -> 12.257717 | H5: =G5+(($K5-$F5)/5) -> 12.479321 | I5: =H5+(($K5-$F5)/5) -> 12.700925 | J5: =I5+(($K5-$F5)/5) -> 12.922529 | K5: 13.144133 | L5: =K5+(($P5-$K5)/5) -> 13.552882 | M5: =L5+(($P5-$K5)/5) -> 13.96163 | N5: =M5+(($P5-$K5)/5) -> 14.370379 | O5: =N5+(($P5-$K5)/5) -> 14.779128 | P5: 15.187876 | Q5: =P5+(($U5-$P5)/5) -> 15.220915 | R5: =Q5+(($U5-$P5)/5) -> 15.253954 | S5: =R5+(($U5-$P5)/5) -> 15.286992 | T5: =S5+(($U5-$P5)/5) -> 15.320031 | U5: 15.353069 | V5: =U5+(($Z5-$U5)/5) -> 15.510458 | W5: =V5+(($Z5-$U5)/5) -> 15.667847 | X5: =W5+(($Z5-$U5)/5) -> 15.825236 | Y5: =X5+(($Z5-$U5)/5) -> 15.982625 | Z5: 16.140013 | AA5: =Z5+(($AE5-$Z5)/5) -> 16.228995 | AB5: =AA5+(($AE5-$Z5)/5) -> 16.317976 | AC5: =AB5+(($AE5-$Z5)/5) -> 16.406958 | AD5: =AC5+(($AE5-$Z5)/5) -> 16.495939 | AE5: 16.584921 | AF5: =AE5+(($AJ5-$AE5)/5) -> 16.749462 | AG5: =AF5+(($AJ5-$AE5)/5) -> 16.914004 | AH5: =AG5+(($AJ5-$AE5)/5) -> 17.078546 | AI5: =AH5+(($AJ5-$AE5)/5) -> 17.243087 | AJ5: 17.407629 | AK5: 2.3531187 | AL5: 0.68438668
A6: =VLOOKUP(B6,'Country codes'!$A$1:$B$28,2,FALSE) -> CY | B6: Cyprus | C6: Reference Scenario 2020 (REF2020) | D6: Freight transport activity (Gtkm) | E6: Heavy goods and light commercial vehicles | F6: 0.84646221 | G6: =F6+(($K6-$F6)/5) -> 0.86542266 | H6: =G6+(($K6-$F6)/5) -> 0.88438311 | I6: =H6+(($K6-$F6)/5) -> 0.90334356 | J6: =I6+(($K6-$F6)/5) -> 0.92230401 | K6: 0.94126445 | L6: =K6+(($P6-$K6)/5) -> 0.95314211 | M6: =L6+(($P6-$K6)/5) -> 0.96501977 | N6: =M6+(($P6-$K6)/5) -> 0.97689742 | O6: =N6+(($P6-$K6)/5) -> 0.98877508 | P6: 1.0006527 | Q6: =P6+(($U6-$P6)/5) -> 1.0131006 | R6: =Q6+(($U6-$P6)/5) -> 1.0255484 | S6: =R6+(($U6-$P6)/5) -> 1.0379963 | T6: =S6+(($U6-$P6)/5) -> 1.0504442 | U6: 1.062892 | V6: =U6+(($Z6-$U6)/5) -> 1.0747221 | W6: =V6+(($Z6-$U6)/5) -> 1.0865522 | X6: =W6+(($Z6-$U6)/5) -> 1.0983823 | Y6: =X6+(($Z6-$U6)/5) -> 1.1102124 | Z6: 1.1220425 | AA6: =Z6+(($AE6-$Z6)/5) -> 1.1286176 | AB6: =AA6+(($AE6-$Z6)/5) -> 1.1351928 | AC6: =AB6+(($AE6-$Z6)/5) -> 1.1417679 | AD6: =AC6+(($AE6-$Z6)/5) -> 1.1483431 | AE6: 1.1549182 | AF6: =AE6+(($AJ6-$AE6)/5) -> 1.1618677 | AG6: =AF6+(($AJ6-$AE6)/5) -> 1.1688171 | AH6: =AG6+(($AJ6-$AE6)/5) -> 1.1757666 | AI6: =AH6+(($AJ6-$AE6)/5) -> 1.182716 | AJ6: 1.1896654 | AK6: 1.6875025 | AL6: 0.86885084
A7: =VLOOKUP(B7,'Country codes'!$A$1:$B$28,2,FALSE) -> CZ | B7: Czechia | C7: Reference Scenario 2020 (REF2020) | D7: Freight transport activity (Gtkm) | E7: Heavy goods and light commercial vehicles | F7: 42.557559 | G7: =F7+(($K7-$F7)/5) -> 43.790645 | H7: =G7+(($K7-$F7)/5) -> 45.023732 | I7: =H7+(($K7-$F7)/5) -> 46.256819 | J7: =I7+(($K7-$F7)/5) -> 47.489905 | K7: 48.722992 | L7: =K7+(($P7-$K7)/5) -> 49.635196 | M7: =L7+(($P7-$K7)/5) -> 50.547399 | N7: =M7+(($P7-$K7)/5) -> 51.459603 | O7: =N7+(($P7-$K7)/5) -> 52.371807 | P7: 53.284011 | Q7: =P7+(($U7-$P7)/5) -> 53.842354 | R7: =Q7+(($U7-$P7)/5) -> 54.400698 | S7: =R7+(($U7-$P7)/5) -> 54.959041 | T7: =S7+(($U7-$P7)/5) -> 55.517385 | U7: 56.075729 | V7: =U7+(($Z7-$U7)/5) -> 56.754182 | W7: =V7+(($Z7-$U7)/5) -> 57.432635 | X7: =W7+(($Z7-$U7)/5) -> 58.111089 | Y7: =X7+(($Z7-$U7)/5) -> 58.789542 | Z7: 59.467996 | AA7: =Z7+(($AE7-$Z7)/5) -> 59.906091 | AB7: =AA7+(($AE7-$Z7)/5) -> 60.344187 | AC7: =AB7+(($AE7-$Z7)/5) -> 60.782282 | AD7: =AC7+(($AE7-$Z7)/5) -> 61.220378 | AE7: 61.658474 | AF7: =AE7+(($AJ7-$AE7)/5) -> 62.138555 | AG7: =AF7+(($AJ7-$AE7)/5) -> 62.618636 | AH7: =AG7+(($AJ7-$AE7)/5) -> 63.098717 | AI7: =AH7+(($AJ7-$AE7)/5) -> 63.578798 | AJ7: 64.058879 | AK7: 2.2732413 | AL7: 0.92508444
A8: =VLOOKUP(B8,'Country codes'!$A$1:$B$28,2,FALSE) -> DE | B8: Germany | C8: Reference Scenario 2020 (REF2020) | D8: Freight transport activity (Gtkm) | E8: Heavy goods and light commercial vehicles | F8: 455.99438 | G8: =F8+(($K8-$F8)/5) -> 468.71735 | H8: =G8+(($K8-$F8)/5) -> 481.44031 | I8: =H8+(($K8-$F8)/5) -> 494.16328 | J8: =I8+(($K8-$F8)/5) -> 506.88625 | K8: 519.60922 | L8: =K8+(($P8-$K8)/5) -> 529.72044 | M8: =L8+(($P8-$K8)/5) -> 539.83167 | N8: =M8+(($P8-$K8)/5) -> 549.94289 | O8: =N8+(($P8-$K8)/5) -> 560.05411 | P8: 570.16534 | Q8: =P8+(($U8-$P8)/5) -> 573.64314 | R8: =Q8+(($U8-$P8)/5) -> 577.12094 | S8: =R8+(($U8-$P8)/5) -> 580.59874 | T8: =S8+(($U8-$P8)/5) -> 584.07655 | U8: 587.55435 | V8: =U8+(($Z8-$U8)/5) -> 591.47117 | W8: =V8+(($Z8-$U8)/5) -> 595.388 | X8: =W8+(($Z8-$U8)/5) -> 599.30483 | Y8: =X8+(($Z8-$U8)/5) -> 603.22166 | Z8: 607.13848 | AA8: =Z8+(($AE8-$Z8)/5) -> 608.7614 | AB8: =AA8+(($AE8-$Z8)/5) -> 610.38431 | AC8: =AB8+(($AE8-$Z8)/5) -> 612.00723 | AD8: =AC8+(($AE8-$Z8)/5) -> 613.63014 | AE8: 615.25306 | AF8: =AE8+(($AJ8-$AE8)/5) -> 616.92213 | AG8: =AF8+(($AJ8-$AE8)/5) -> 618.5912 | AH8: =AG8+(($AJ8-$AE8)/5) -> 620.26027 | AI8: =AH8+(($AJ8-$AE8)/5) -> 621.92934 | AJ8: 623.59841 | AK8: 2.2596101 | AL8: 0.44890563
A9: =VLOOKUP(B9,'Country codes'!$A$1:$B$28,2,FALSE) -> DK | B9: Denmark | C9: Reference Scenario 2020 (REF2020) | D9: Freight transport activity (Gtkm) | E9: Heavy goods and light commercial vehicles | F9: 20.812907 | G9: =F9+(($K9-$F9)/5) -> 21.517139 | H9: =G9+(($K9-$F9)/5) -> 22.221372 | I9: =H9+(($K9-$F9)/5) -> 22.925604 | J9: =I9+(($K9-$F9)/5) -> 23.629837 | K9: 24.334069 | L9: =K9+(($P9-$K9)/5) -> 24.565135 | M9: =L9+(($P9-$K9)/5) -> 24.796202 | N9: =M9+(($P9-$K9)/5) -> 25.027268 | O9: =N9+(($P9-$K9)/5) -> 25.258334 | P9: 25.4894 | Q9: =P9+(($U9-$P9)/5) -> 25.703227 | R9: =Q9+(($U9-$P9)/5) -> 25.917053 | S9: =R9+(($U9-$P9)/5) -> 26.130879 | T9: =S9+(($U9-$P9)/5) -> 26.344705 | U9: 26.558531 | V9: =U9+(($Z9-$U9)/5) -> 26.773252 | W9: =V9+(($Z9-$U9)/5) -> 26.987974 | X9: =W9+(($Z9-$U9)/5) -> 27.202695 | Y9: =X9+(($Z9-$U9)/5) -> 27.417416 | Z9: 27.632137 | AA9: =Z9+(($AE9-$Z9)/5) -> 27.788749 | AB9: =AA9+(($AE9-$Z9)/5) -> 27.945361 | AC9: =AB9+(($AE9-$Z9)/5) -> 28.101973 | AD9: =AC9+(($AE9-$Z9)/5) -> 28.258584 | AE9: 28.415196 | AF9: =AE9+(($AJ9-$AE9)/5) -> 28.571954 | AG9: =AF9+(($AJ9-$AE9)/5) -> 28.728711 | AH9: =AG9+(($AJ9-$AE9)/5) -> 28.885469 | AI9: =AH9+(($AJ9-$AE9)/5) -> 29.042226 | AJ9: 29.198984 | AK9: 2.0475747 | AL9: 0.68166888
A10: =VLOOKUP(B10,'Country codes'!$A$1:$B$28,2,FALSE) -> EE | B10: Estonia | C10: Reference Scenario 2020 (REF2020) | D10: Freight transport activity (Gtkm) | E10: Heavy goods and light commercial vehicles | F10: 2.9266825 | G10: =F10+(($K10-$F10)/5) -> 3.0372594 | H10: =G10+(($K10-$F10)/5) -> 3.1478363 | I10: =H10+(($K10-$F10)/5) -> 3.2584131 | J10: =I10+(($K10-$F10)/5) -> 3.36899 | K10: 3.4795669 | L10: =K10+(($P10-$K10)/5) -> 3.5814166 | M10: =L10+(($P10-$K10)/5) -> 3.6832663 | N10: =M10+(($P10-$K10)/5) -> 3.785116 | O10: =N10+(($P10-$K10)/5) -> 3.8869657 | P10: 3.9888154 | Q10: =P10+(($U10-$P10)/5) -> 4.0562579 | R10: =Q10+(($U10-$P10)/5) -> 4.1237004 | S10: =R10+(($U10-$P10)/5) -> 4.1911429 | T10: =S10+(($U10-$P10)/5) -> 4.2585854 | U10: 4.3260279 | V10: =U10+(($Z10-$U10)/5) -> 4.3889735 | W10: =V10+(($Z10-$U10)/5) -> 4.4519191 | X10: =W10+(($Z10-$U10)/5) -> 4.5148647 | Y10: =X10+(($Z10-$U10)/5) -> 4.5778103 | Z10: 4.6407559 | AA10: =Z10+(($AE10-$Z10)/5) -> 4.6700283 | AB10: =AA10+(($AE10-$Z10)/5) -> 4.6993008 | AC10: =AB10+(($AE10-$Z10)/5) -> 4.7285733 | AD10: =AC10+(($AE10-$Z10)/5) -> 4.7578458 | AE10: 4.7871183 | AF10: =AE10+(($AJ10-$AE10)/5) -> 4.8190582 | AG10: =AF10+(($AJ10-$AE10)/5) -> 4.8509982 | AH10: =AG10+(($AJ10-$AE10)/5) -> 4.8829381 | AI10: =AH10+(($AJ10-$AE10)/5) -> 4.914878 | AJ10: 4.9468179 | AK10: 3.14468 | AL10: 1.0820636
A11: =VLOOKUP(B11,'Country codes'!$A$1:$B$28,2,FALSE) -> ES | B11: Spain | C11: Reference Scenario 2020 (REF2020) | D11: Freight transport activity (Gtkm) | E11: Heavy goods and light commercial vehicles | F11: 197.52574 | G11: =F11+(($K11-$F11)/5) -> 202.34392 | H11: =G11+(($K11-$F11)/5) -> 207.1621 | I11: =H11+(($K11-$F11)/5) -> 211.98028 | J11: =I11+(($K11-$F11)/5) -> 216.79847 | K11: 221.61665 | L11: =K11+(($P11-$K11)/5) -> 223.83576 | M11: =L11+(($P11-$K11)/5) -> 226.05487 | N11: =M11+(($P11-$K11)/5) -> 228.27399 | O11: =N11+(($P11-$K11)/5) -> 230.4931 | P11: 232.71222 | Q11: =P11+(($U11-$P11)/5) -> 234.85462 | R11: =Q11+(($U11-$P11)/5) -> 236.99702 | S11: =R11+(($U11-$P11)/5) -> 239.13942 | T11: =S11+(($U11-$P11)/5) -> 241.28182 | U11: 243.42421 | V11: =U11+(($Z11-$U11)/5) -> 245.72242 | W11: =V11+(($Z11-$U11)/5) -> 248.02063 | X11: =W11+(($Z11-$U11)/5) -> 250.31883 | Y11: =X11+(($Z11-$U11)/5) -> 252.61704 | Z11: 254.91525 | AA11: =Z11+(($AE11-$Z11)/5) -> 257.10899 | AB11: =AA11+(($AE11-$Z11)/5) -> 259.30273 | AC11: =AB11+(($AE11-$Z11)/5) -> 261.49647 | AD11: =AC11+(($AE11-$Z11)/5) -> 263.69021 | AE11: 265.88395 | AF11: =AE11+(($AJ11-$AE11)/5) -> 268.10371 | AG11: =AF11+(($AJ11-$AE11)/5) -> 270.32347 | AH11: =AG11+(($AJ11-$AE11)/5) -> 272.54323 | AI11: =AH11+(($AJ11-$AE11)/5) -> 274.76299 | AJ11: 276.98275 | AK11: 1.6528473 | AL11: 0.87456545
A12: =VLOOKUP(B12,'Country codes'!$A$1:$B$28,2,FALSE) -> FI | B12: Finland | C12: Reference Scenario 2020 (REF2020) | D12: Freight transport activity (Gtkm) | E12: Heavy goods and light commercial vehicles | F12: 27.143517 | G12: =F12+(($K12-$F12)/5) -> 27.90569 | H12: =G12+(($K12-$F12)/5) -> 28.667863 | I12: =H12+(($K12-$F12)/5) -> 29.430036 | J12: =I12+(($K12-$F12)/5) -> 30.192209 | K12: 30.954382 | L12: =K12+(($P12-$K12)/5) -> 31.42893 | M12: =L12+(($P12-$K12)/5) -> 31.903478 | N12: =M12+(($P12-$K12)/5) -> 32.378026 | O12: =N12+(($P12-$K12)/5) -> 32.852574 | P12: 33.327123 | Q12: =P12+(($U12-$P12)/5) -> 33.544842 | R12: =Q12+(($U12-$P12)/5) -> 33.762561 | S12: =R12+(($U12-$P12)/5) -> 33.980281 | T12: =S12+(($U12-$P12)/5) -> 34.198 | U12: 34.415719 | V12: =U12+(($Z12-$U12)/5) -> 34.515823 | W12: =V12+(($Z12-$U12)/5) -> 34.615927 | X12: =W12+(($Z12-$U12)/5) -> 34.71603 | Y12: =X12+(($Z12-$U12)/5) -> 34.816134 | Z12: 34.916237 | AA12: =Z12+(($AE12-$Z12)/5) -> 34.956334 | AB12: =AA12+(($AE12-$Z12)/5) -> 34.996431 | AC12: =AB12+(($AE12-$Z12)/5) -> 35.036529 | AD12: =AC12+(($AE12-$Z12)/5) -> 35.076626 | AE12: 35.116723 | AF12: =AE12+(($AJ12-$AE12)/5) -> 35.187504 | AG12: =AF12+(($AJ12-$AE12)/5) -> 35.258286 | AH12: =AG12+(($AJ12-$AE12)/5) -> 35.329067 | AI12: =AH12+(($AJ12-$AE12)/5) -> 35.399849 | AJ12: 35.470631 | AK12: 2.0735384 | AL12: 0.31215362
A13: =VLOOKUP(B13,'Country codes'!$A$1:$B$28,2,FALSE) -> FR | B13: France | C13: Reference Scenario 2020 (REF2020) | D13: Freight transport activity (Gtkm) | E13: Heavy goods and light commercial vehicles | F13: 282.88421 | G13: =F13+(($K13-$F13)/5) -> 286.90431 | H13: =G13+(($K13-$F13)/5) -> 290.92441 | I13: =H13+(($K13-$F13)/5) -> 294.94451 | J13: =I13+(($K13-$F13)/5) -> 298.96461 | K13: 302.98471 | L13: =K13+(($P13-$K13)/5) -> 306.58003 | M13: =L13+(($P13-$K13)/5) -> 310.17534 | N13: =M13+(($P13-$K13)/5) -> 313.77066 | O13: =N13+(($P13-$K13)/5) -> 317.36597 | P13: 320.96129 | Q13: =P13+(($U13-$P13)/5) -> 322.81492 | R13: =Q13+(($U13-$P13)/5) -> 324.66856 | S13: =R13+(($U13-$P13)/5) -> 326.52219 | T13: =S13+(($U13-$P13)/5) -> 328.37583 | U13: 330.22946 | V13: =U13+(($Z13-$U13)/5) -> 332.87028 | W13: =V13+(($Z13-$U13)/5) -> 335.5111 | X13: =W13+(($Z13-$U13)/5) -> 338.15193 | Y13: =X13+(($Z13-$U13)/5) -> 340.79275 | Z13: 343.43357 | AA13: =Z13+(($AE13-$Z13)/5) -> 345.57096 | AB13: =AA13+(($AE13-$Z13)/5) -> 347.70835 | AC13: =AB13+(($AE13-$Z13)/5) -> 349.84574 | AD13: =AC13+(($AE13-$Z13)/5) -> 351.98313 | AE13: 354.12052 | AF13: =AE13+(($AJ13-$AE13)/5) -> 356.127 | AG13: =AF13+(($AJ13-$AE13)/5) -> 358.13347 | AH13: =AG13+(($AJ13-$AE13)/5) -> 360.13995 | AI13: =AH13+(($AJ13-$AE13)/5) -> 362.14642 | AJ13: 364.1529 | AK13: 1.2708359 | AL13: 0.63326328
A14: =VLOOKUP(B14,'Country codes'!$A$1:$B$28,2,FALSE) -> GR | B14: Greece | C14: Reference Scenario 2020 (REF2020) | D14: Freight transport activity (Gtkm) | E14: Heavy goods and light commercial vehicles | F14: 20.869395 | G14: =F14+(($K14-$F14)/5) -> 21.48863 | H14: =G14+(($K14-$F14)/5) -> 22.107865 | I14: =H14+(($K14-$F14)/5) -> 22.7271 | J14: =I14+(($K14-$F14)/5) -> 23.346335 | K14: 23.96557 | L14: =K14+(($P14-$K14)/5) -> 24.119543 | M14: =L14+(($P14-$K14)/5) -> 24.273516 | N14: =M14+(($P14-$K14)/5) -> 24.427489 | O14: =N14+(($P14-$K14)/5) -> 24.581462 | P14: 24.735436 | Q14: =P14+(($U14-$P14)/5) -> 24.940137 | R14: =Q14+(($U14-$P14)/5) -> 25.144839 | S14: =R14+(($U14-$P14)/5) -> 25.349541 | T14: =S14+(($U14-$P14)/5) -> 25.554243 | U14: 25.758945 | V14: =U14+(($Z14-$U14)/5) -> 25.915471 | W14: =V14+(($Z14-$U14)/5) -> 26.071996 | X14: =W14+(($Z14-$U14)/5) -> 26.228521 | Y14: =X14+(($Z14-$U14)/5) -> 26.385046 | Z14: 26.541571 | AA14: =Z14+(($AE14-$Z14)/5) -> 26.708321 | AB14: =AA14+(($AE14-$Z14)/5) -> 26.87507 | AC14: =AB14+(($AE14-$Z14)/5) -> 27.041819 | AD14: =AC14+(($AE14-$Z14)/5) -> 27.208569 | AE14: 27.375318 | AF14: =AE14+(($AJ14-$AE14)/5) -> 27.541821 | AG14: =AF14+(($AJ14-$AE14)/5) -> 27.708323 | AH14: =AG14+(($AJ14-$AE14)/5) -> 27.874826 | AI14: =AH14+(($AJ14-$AE14)/5) -> 28.041329 | AJ14: 28.207831 | AK14: 1.7140554 | AL14: 0.65897571
... A29: =VLOOKUP(B29,'Country codes'!$A$1:$B$28,2,FALSE) -> SK | B29: Slovakia | C29: Reference Scenario 2020 (REF2020) | D29: Freight transport activity (Gtkm) | E29: Heavy goods and light commercial vehicles | F29: 16.812718 | G29: =F29+(($K29-$F29)/5) -> 17.199874 | H29: =G29+(($K29-$F29)/5) -> 17.587029 | I29: =H29+(($K29-$F29)/5) -> 17.974184 | J29: =I29+(($K29-$F29)/5) -> 18.361339 | K29: 18.748494 | L29: =K29+(($P29-$K29)/5) -> 19.22902 | M29: =L29+(($P29-$K29)/5) -> 19.709546 | N29: =M29+(($P29-$K29)/5) -> 20.190071 | O29: =N29+(($P29-$K29)/5) -> 20.670597 | P29: 21.151122 | Q29: =P29+(($U29-$P29)/5) -> 21.308522 | R29: =Q29+(($U29-$P29)/5) -> 21.465922 | S29: =R29+(($U29-$P29)/5) -> 21.623322 | T29: =S29+(($U29-$P29)/5) -> 21.780722 | U29: 21.938122 | V29: =U29+(($Z29-$U29)/5) -> 22.143611 | W29: =V29+(($Z29-$U29)/5) -> 22.3491 | X29: =W29+(($Z29-$U29)/5) -> 22.554589 | Y29: =X29+(($Z29-$U29)/5) -> 22.760078 | Z29: 22.965567 | AA29: =Z29+(($AE29-$Z29)/5) -> 23.059275 | AB29: =AA29+(($AE29-$Z29)/5) -> 23.152982 | AC29: =AB29+(($AE29-$Z29)/5) -> 23.246689 | AD29: =AC29+(($AE29-$Z29)/5) -> 23.340396 | AE29: 23.434103 | AF29: =AE29+(($AJ29-$AE29)/5) -> 23.524938 | AG29: =AF29+(($AJ29-$AE29)/5) -> 23.615772 | AH29: =AG29+(($AJ29-$AE29)/5) -> 23.706607 | AI29: =AH29+(($AJ29-$AE29)/5) -> 23.797442 | AJ29: 23.888277 | AK29: 2.3221244 | AL29: 0.61032924

Sheet Buses
A1: Source: JRC-IDEES 2021
A2: Passenger activity (Gveh-km)
A3: Country | B3: TECHNOLOGY | C3: 2018 | D3: 2019 | E3: 2020 | F3: 2021
A4: =LEFT(B4,2) -> AT | B4: ATEPTDSLBU00 | C4: 0.51227979 | D4: 0.4976535 | E4: 0.49218877 | F4: 0.49387697
A5: =LEFT(B5,2) -> AT | B5: ATEPTNGSBU00 | C5: 0.023128851 | D5: 0.027212244 | E5: 0.031127052 | F5: 0.029470323
A6: =LEFT(B6,2) -> AT | B6: ATEPTELCBUBT | C6: 0.006313745 | D6: 0.006593865 | E6: 0.007011688 | F6: 0.007126069
A7: =LEFT(B7,2) -> AT | B7: ATEPTHY2BUFC | C7: 0 | D7: 0 | E7: 0 | F7: 0
A8: =LEFT(B8,2) -> BG | B8: BGEPTDSLBU00 | C8: 0.34783841 | D8: 0.3753783 | E8: 0.369968 | F8: 0.36091178
A9: =LEFT(B9,2) -> BG | B9: BGEPTNGSBU00 | C9: 0.05956304 | D9: 0.073603094 | E9: 0.076506662 | F9: 0.083180567
A10: =LEFT(B10,2) -> BG | B10: BGEPTELCBUBT | C10: 0.020198548 | D10: 0.020095552 | E10: 0.01902302 | F10: 0.021324236
A11: =LEFT(B11,2) -> BG | B11: BGEPTHY2BUFC | C11: 0 | D11: 0 | E11: 0 | F11: 0
A12: =LEFT(B12,2) -> BE | B12: BEEPTDSLBU00 | C12: 0.62088967 | D12: 0.62654122 | E12: 0.62292579 | F12: 0.6183094
A13: =LEFT(B13,2) -> BE | B13: BEEPTNGSBU00 | C13: 0.000205187 | D13: 0.000415118 | E13: 0.000811354 | F13: 0.004991624
A14: =LEFT(B14,2) -> BE | B14: BEEPTELCBUBT | C14: 0.000863269 | D14: 0.002425183 | E14: 0.002959021 | F14: 0.00369885
A15: =LEFT(B15,2) -> BE | B15: BEEPTHY2BUFC | C15: 0 | D15: 0 | E15: 0 | F15: 0
... A111: =LEFT(B111,2) -> SE | B111: SEEPTHY2BUFC | C111: 0 | D111: 0 | E111: 0 | F111: 0
A113: Demand projections (Gveh-km)
A114: Country | B114: 2018 | C114: 2019 | D114: 2020 | E114: 2021 | F114: 2022 | G114: 2023 | H114: 2024 | I114: 2025 | J114: 2026 | K114: 2027 | L114: 2028 | M114: 2029 | N114: 2030 | O114: 2031 | P114: 2032 | Q114: 2033 | R114: 2034 | S114: 2035 | T114: 2036 | U114: 2037 | V114: 2038 | W114: 2039 | X114: 2040 | Y114: 2041 | Z114: 2042 | AA114: 2043 | AB114: 2044 | AC114: 2045 | AD114: 2046 | AE114: 2047 | AF114: 2048 | AG114: 2049 | AH114: 2050 | AI114: 2051 | AJ114: 2052 | AK114: 2053 | AL114: 2054 | AM114: 2055 | AN114: 2056 | AO114: 2057 | AP114: 2058 | AQ114: 2059 | AR114: 2060 | AS114: 2061 | AT114: 2062 | AU114: 2063 | AV114: 2064 | AW114: 2065 | AX114: 2066 | AY114: 2067 | AZ114: 2068 | BA114: 2069 | BB114: 2070
A115: AT | B115: 0.54172239 | C115: 0.53145961 | D115: 0.53032751 | E115: 0.53047336 | F115: =E115*('Buses EU Ref'!H3/'Buses EU Ref'!G3) -> 0.57387465 | G115: =F115*('Buses EU Ref'!I3/'Buses EU Ref'!H3) -> 0.61727593 | H115: =G115*('Buses EU Ref'!J3/'Buses EU Ref'!I3) -> 0.66067721 | I115: =H115*('Buses EU Ref'!K3/'Buses EU Ref'!J3) -> 0.7040785 | J115: =I115*('Buses EU Ref'!L3/'Buses EU Ref'!K3) -> 0.70587997 | K115: =J115*('Buses EU Ref'!M3/'Buses EU Ref'!L3) -> 0.70768145 | L115: =K115*('Buses EU Ref'!N3/'Buses EU Ref'!M3) -> 0.70948292 | M115: =L115*('Buses EU Ref'!O3/'Buses EU Ref'!N3) -> 0.7112844 | ... AH115: =AG115*('Buses EU Ref'!AJ3/'Buses EU Ref'!AI3) -> 0.81862279 | AI115: =AH115 -> 0.81862279 | AJ115: =AI115 -> 0.81862279 | AK115: =AJ115 -> 0.81862279 | AL115: =AK115 -> 0.81862279 | AM115: =AL115 -> 0.81862279 | AN115: =AM115 -> 0.81862279 | AO115: =AN115 -> 0.81862279 | AP115: =AO115 -> 0.81862279 | ... BB115: =BA115 -> 0.81862279
A116: BE | B116: 0.62195813 | C116: 0.62938152 | D116: 0.62669617 | E116: 0.62699987 | F116: =E116*('Buses EU Ref'!H4/'Buses EU Ref'!G4) -> 0.69325478 | G116: =F116*('Buses EU Ref'!I4/'Buses EU Ref'!H4) -> 0.75950968 | H116: =G116*('Buses EU Ref'!J4/'Buses EU Ref'!I4) -> 0.82576459 | I116: =H116*('Buses EU Ref'!K4/'Buses EU Ref'!J4) -> 0.89201949 | J116: =I116*('Buses EU Ref'!L4/'Buses EU Ref'!K4) -> 0.89326696 | K116: =J116*('Buses EU Ref'!M4/'Buses EU Ref'!L4) -> 0.89451443 | L116: =K116*('Buses EU Ref'!N4/'Buses EU Ref'!M4) -> 0.8957619 | M116: =L116*('Buses EU Ref'!O4/'Buses EU Ref'!N4) -> 0.89700937 | ... AH116: =AG116*('Buses EU Ref'!AJ4/'Buses EU Ref'!AI4) -> 0.90624279 | AI116: =AH116 -> 0.90624279 | AJ116: =AI116 -> 0.90624279 | AK116: =AJ116 -> 0.90624279 | AL116: =AK116 -> 0.90624279 | AM116: =AL116 -> 0.90624279 | AN116: =AM116 -> 0.90624279 | AO116: =AN116 -> 0.90624279 | AP116: =AO116 -> 0.90624279 | ... BB116: =BA116 -> 0.90624279
A117: BG | B117: 0.4276 | C117: 0.46907695 | D117: 0.46549768 | E117: 0.46541658 | F117: =E117*('Buses EU Ref'!H5/'Buses EU Ref'!G5) -> 0.49155169 | G117: =F117*('Buses EU Ref'!I5/'Buses EU Ref'!H5) -> 0.51768679 | H117: =G117*('Buses EU Ref'!J5/'Buses EU Ref'!I5) -> 0.5438219 | I117: =H117*('Buses EU Ref'!K5/'Buses EU Ref'!J5) -> 0.56995701 | J117: =I117*('Buses EU Ref'!L5/'Buses EU Ref'!K5) -> 0.57057864 | K117: =J117*('Buses EU Ref'!M5/'Buses EU Ref'!L5) -> 0.57120027 | L117: =K117*('Buses EU Ref'!N5/'Buses EU Ref'!M5) -> 0.5718219 | M117: =L117*('Buses EU Ref'!O5/'Buses EU Ref'!N5) -> 0.57244354 | ... AH117: =AG117*('Buses EU Ref'!AJ5/'Buses EU Ref'!AI5) -> 0.61787046 | AI117: =AH117 -> 0.61787046 | AJ117: =AI117 -> 0.61787046 | AK117: =AJ117 -> 0.61787046 | AL117: =AK117 -> 0.61787046 | AM117: =AL117 -> 0.61787046 | AN117: =AM117 -> 0.61787046 | AO117: =AN117 -> 0.61787046 | AP117: =AO117 -> 0.61787046 | ... BB117: =BA117 -> 0.61787046
A118: CY | B118: 0.17582359 | C118: 0.17722448 | D118: 0.13977593 | E118: 0.14785343 | F118: =E118*('Buses EU Ref'!H6/'Buses EU Ref'!G6) -> 0.15993009 | G118: =F118*('Buses EU Ref'!I6/'Buses EU Ref'!H6) -> 0.17200675 | H118: =G118*('Buses EU Ref'!J6/'Buses EU Ref'!I6) -> 0.18408341 | I118: =H118*('Buses EU Ref'!K6/'Buses EU Ref'!J6) -> 0.19616007 | J118: =I118*('Buses EU Ref'!L6/'Buses EU Ref'!K6) -> 0.19745607 | K118: =J118*('Buses EU Ref'!M6/'Buses EU Ref'!L6) -> 0.19875207 | L118: =K118*('Buses EU Ref'!N6/'Buses EU Ref'!M6) -> 0.20004807 | M118: =L118*('Buses EU Ref'!O6/'Buses EU Ref'!N6) -> 0.20134407 | ... AH118: =AG118*('Buses EU Ref'!AJ6/'Buses EU Ref'!AI6) -> 0.23425605 | AI118: =AH118 -> 0.23425605 | AJ118: =AI118 -> 0.23425605 | AK118: =AJ118 -> 0.23425605 | AL118: =AK118 -> 0.23425605 | AM118: =AL118 -> 0.23425605 | AN118: =AM118 -> 0.23425605 | AO118: =AN118 -> 0.23425605 | AP118: =AO118 -> 0.23425605 | ... BB118: =BA118 -> 0.23425605
A119: CZ | B119: 0.79712938 | C119: 0.78979705 | D119: 0.57409015 | E119: 0.54562353 | F119: =E119*('Buses EU Ref'!H7/'Buses EU Ref'!G7) -> 0.57961135 | G119: =F119*('Buses EU Ref'!I7/'Buses EU Ref'!H7) -> 0.61359918 | H119: =G119*('Buses EU Ref'!J7/'Buses EU Ref'!I7) -> 0.64758701 | I119: =H119*('Buses EU Ref'!K7/'Buses EU Ref'!J7) -> 0.68157483 | J119: =I119*('Buses EU Ref'!L7/'Buses EU Ref'!K7) -> 0.70244992 | K119: =J119*('Buses EU Ref'!M7/'Buses EU Ref'!L7) -> 0.723325 | L119: =K119*('Buses EU Ref'!N7/'Buses EU Ref'!M7) -> 0.74420009 | M119: =L119*('Buses EU Ref'!O7/'Buses EU Ref'!N7) -> 0.76507517 | ... AH119: =AG119*('Buses EU Ref'!AJ7/'Buses EU Ref'!AI7) -> 0.89714202 | AI119: =AH119 -> 0.89714202 | AJ119: =AI119 -> 0.89714202 | AK119: =AJ119 -> 0.89714202 | AL119: =AK119 -> 0.89714202 | AM119: =AL119 -> 0.89714202 | AN119: =AM119 -> 0.89714202 | AO119: =AN119 -> 0.89714202 | AP119: =AO119 -> 0.89714202 | ... BB119: =BA119 -> 0.89714202
A120: DE | B120: 4.4866265 | C120: 4.5406648 | D120: 4.1645687 | E120: 4.0295828 | F120: =E120*('Buses EU Ref'!H8/'Buses EU Ref'!G8) -> 4.2133886 | G120: =F120*('Buses EU Ref'!I8/'Buses EU Ref'!H8) -> 4.3971944 | H120: =G120*('Buses EU Ref'!J8/'Buses EU Ref'!I8) -> 4.5810002 | I120: =H120*('Buses EU Ref'!K8/'Buses EU Ref'!J8) -> 4.7648061 | J120: =I120*('Buses EU Ref'!L8/'Buses EU Ref'!K8) -> 4.8348933 | K120: =J120*('Buses EU Ref'!M8/'Buses EU Ref'!L8) -> 4.9049805 | L120: =K120*('Buses EU Ref'!N8/'Buses EU Ref'!M8) -> 4.9750677 | M120: =L120*('Buses EU Ref'!O8/'Buses EU Ref'!N8) -> 5.045155 | ... AH120: =AG120*('Buses EU Ref'!AJ8/'Buses EU Ref'!AI8) -> 5.412748 | AI120: =AH120 -> 5.412748 | AJ120: =AI120 -> 5.412748 | AK120: =AJ120 -> 5.412748 | AL120: =AK120 -> 5.412748 | AM120: =AL120 -> 5.412748 | AN120: =AM120 -> 5.412748 | AO120: =AN120 -> 5.412748 | AP120: =AO120 -> 5.412748 | ... BB120: =BA120 -> 5.412748
A121: DK | B121: 0.64081167 | C121: 0.62356825 | D121: 0.6212858 | E121: 0.62202461 | F121: =E121*('Buses EU Ref'!H9/'Buses EU Ref'!G9) -> 0.63702843 | G121: =F121*('Buses EU Ref'!I9/'Buses EU Ref'!H9) -> 0.65203224 | H121: =G121*('Buses EU Ref'!J9/'Buses EU Ref'!I9) -> 0.66703605 | I121: =H121*('Buses EU Ref'!K9/'Buses EU Ref'!J9) -> 0.68203986 | J121: =I121*('Buses EU Ref'!L9/'Buses EU Ref'!K9) -> 0.69068365 | K121: =J121*('Buses EU Ref'!M9/'Buses EU Ref'!L9) -> 0.69932744 | L121: =K121*('Buses EU Ref'!N9/'Buses EU Ref'!M9) -> 0.70797123 | M121: =L121*('Buses EU Ref'!O9/'Buses EU Ref'!N9) -> 0.71661502 | ... AH121: =AG121*('Buses EU Ref'!AJ9/'Buses EU Ref'!AI9) -> 0.77260961 | AI121: =AH121 -> 0.77260961 | AJ121: =AI121 -> 0.77260961 | AK121: =AJ121 -> 0.77260961 | AL121: =AK121 -> 0.77260961 | AM121: =AL121 -> 0.77260961 | AN121: =AM121 -> 0.77260961 | AO121: =AN121 -> 0.77260961 | AP121: =AO121 -> 0.77260961 | ... BB121: =BA121 -> 0.77260961
A122: EE | B122: 0.21559333 | C122: 0.20325151 | D122: 0.19839553 | E122: 0.21217453 | F122: =E122*('Buses EU Ref'!H10/'Buses EU Ref'!G10) -> 0.22018027 | G122: =F122*('Buses EU Ref'!I10/'Buses EU Ref'!H10) -> 0.228186 | H122: =G122*('Buses EU Ref'!J10/'Buses EU Ref'!I10) -> 0.23619173 | I122: =H122*('Buses EU Ref'!K10/'Buses EU Ref'!J10) -> 0.24419747 | J122: =I122*('Buses EU Ref'!L10/'Buses EU Ref'!K10) -> 0.24959929 | K122: =J122*('Buses EU Ref'!M10/'Buses EU Ref'!L10) -> 0.25500112 | L122: =K122*('Buses EU Ref'!N10/'Buses EU Ref'!M10) -> 0.26040294 | M122: =L122*('Buses EU Ref'!O10/'Buses EU Ref'!N10) -> 0.26580477 | ... AH122: =AG122*('Buses EU Ref'!AJ10/'Buses EU Ref'!AI10) -> 0.31045444 | AI122: =AH122 -> 0.31045444 | AJ122: =AI122 -> 0.31045444 | AK122: =AJ122 -> 0.31045444 | AL122: =AK122 -> 0.31045444 | AM122: =AL122 -> 0.31045444 | AN122: =AM122 -> 0.31045444 | AO122: =AN122 -> 0.31045444 | AP122: =AO122 -> 0.31045444 | ... BB122: =BA122 -> 0.31045444
A123: ES | B123: 1.3405842 | C123: 1.3750381 | D123: 0.90654227 | E123: 1.1623225 | F123: =E123*('Buses EU Ref'!H11/'Buses EU Ref'!G11) -> 1.4194913 | G123: =F123*('Buses EU Ref'!I11/'Buses EU Ref'!H11) -> 1.6766601 | H123: =G123*('Buses EU Ref'!J11/'Buses EU Ref'!I11) -> 1.9338288 | I123: =H123*('Buses EU Ref'!K11/'Buses EU Ref'!J11) -> 2.1909976 | J123: =I123*('Buses EU Ref'!L11/'Buses EU Ref'!K11) -> 2.2081739 | K123: =J123*('Buses EU Ref'!M11/'Buses EU Ref'!L11) -> 2.2253503 | L123: =K123*('Buses EU Ref'!N11/'Buses EU Ref'!M11) -> 2.2425267 | M123: =L123*('Buses EU Ref'!O11/'Buses EU Ref'!N11) -> 2.259703 | ... AH123: =AG123*('Buses EU Ref'!AJ11/'Buses EU Ref'!AI11) -> 2.7276048 | AI123: =AH123 -> 2.7276048 | AJ123: =AI123 -> 2.7276048 | AK123: =AJ123 -> 2.7276048 | AL123: =AK123 -> 2.7276048 | AM123: =AL123 -> 2.7276048 | AN123: =AM123 -> 2.7276048 | AO123: =AN123 -> 2.7276048 | AP123: =AO123 -> 2.7276048 | ... BB123: =BA123 -> 2.7276048
A124: FI | B124: 0.61455769 | C124: 0.60153873 | D124: 0.52346109 | E124: 0.46140681 | F124: =E124*('Buses EU Ref'!H12/'Buses EU Ref'!G12) -> 0.47609449 | G124: =F124*('Buses EU Ref'!I12/'Buses EU Ref'!H12) -> 0.49078217 | H124: =G124*('Buses EU Ref'!J12/'Buses EU Ref'!I12) -> 0.50546984 | I124: =H124*('Buses EU Ref'!K12/'Buses EU Ref'!J12) -> 0.52015752 | J124: =I124*('Buses EU Ref'!L12/'Buses EU Ref'!K12) -> 0.52538696 | K124: =J124*('Buses EU Ref'!M12/'Buses EU Ref'!L12) -> 0.5306164 | L124: =K124*('Buses EU Ref'!N12/'Buses EU Ref'!M12) -> 0.53584585 | M124: =L124*('Buses EU Ref'!O12/'Buses EU Ref'!N12) -> 0.54107529 | ... AH124: =AG124*('Buses EU Ref'!AJ12/'Buses EU Ref'!AI12) -> 0.57380366 | AI124: =AH124 -> 0.57380366 | AJ124: =AI124 -> 0.57380366 | AK124: =AJ124 -> 0.57380366 | AL124: =AK124 -> 0.57380366 | AM124: =AL124 -> 0.57380366 | AN124: =AM124 -> 0.57380366 | AO124: =AN124 -> 0.57380366 | AP124: =AO124 -> 0.57380366 | ... BB124: =BA124 -> 0.57380366
