Workbook

Sheet crop_codes
A1: Crop Name | B1: GAEZ_name | C1: Code | F1: Crop Name | G1: Crop Code | H1: Countries | K1: Crop | L1: Code | M1: Energy content (MJ/kg of residue) | P1: Crop_code | R1: PJ/Million tonnes | S1: Assumptions
A2: Alfalfa | B2: Alfalfa | C2: ALF | E2: =G2 -> ALM | F2: Almonds, in shell | G2: ALM | H2: Cyprus, Portugal, Spain | K2: Maize | L2: MAI | M2: 33.73199 | P2: ALM | Q2: =VLOOKUP(P2,$E$2:$F$43,2,FALSE) -> Almonds, in shell | R2: =M19 -> 12.8 | S2: Assumed coffee
A3: Arecanut | B3: Arecanut | C3: ARE | E3: =G3 -> APP | F3: Apples | G3: APP | H3: Hungary, Luxembourg, Slovenia | K3: Rice | L3: RIC | M3: 13.074398 | P3: APP | Q3: =VLOOKUP(P3,$E$2:$F$43,2,FALSE) -> Apples | R3: =10 -> 10 | S3: RPR: 0.5, SAF:1, LHV (20MJ/kg) | T3: Cichy et al. (BioResources | U3: 2024)
A4: Bananas | B4: Banana | C4: BAN | E4: =G4 -> BRL | F4: Barley | G4: BRL | H4: Austria, Belgium, Bulgaria, Croatia, Cyprus, Czechia, Denmark, Estonia, Finland, France , Germany, Greece, Hungary, Ireland , Italy, Latvia, Lithuania, Luxembourg, Netherlands, Poland, Romania, Slovakia, Slovenia, Spain, Sweden | K4: Sorghum | L4: SOR | M4: 30.58 | P4: BRL | Q4: =VLOOKUP(P4,$E$2:$F$43,2,FALSE) -> Barley | R4: =VLOOKUP(P4,$L$2:$M$39,2,FALSE) -> 19.72875 | S4: BEPMAT
A5: Barley | B5: Barley | C5: BRL | E5: =G5 -> BRO | F5: Broad beans and horse beans, dry | G5: BRO | H5: Denmark, Estonia, Finland, Ireland , Latvia, Lithuania, Sweden | K5: Millet | L5: MLT | M5: 39.914 | P5: BRO | Q5: =VLOOKUP(P5,$E$2:$F$43,2,FALSE) -> Broad beans and horse beans, dry | R5: =M28 -> 7.68 | S5: Assumed Lettuce
A6: Beans, dry | B6: Phaseolus bean | C6: BEA | E6: =G6 -> BUC | F6: Buckwheat | G6: BUC | H6: Lithuania | K6: Wheat | L6: WHE | M6: 6.28923 | P6: CAB | Q6: =VLOOKUP(P6,$E$2:$F$43,2,FALSE) -> Cabbages | R6: =M28 -> 7.68 | S6: Assumed Lettuce
A7: BMX | B7: BMX | C7: BMX | E7: =G7 -> CAB | F7: Cabbages | G7: CAB | H7: Ireland | K7: Cassava | L7: CAS | M7: 6.7947257 | P7: CAR | Q7: =VLOOKUP(P7,$E$2:$F$43,2,FALSE) -> Carrots and turnips | R7: =M11 -> 6.366 | S7: Assumed potatoes
A8: Buckwheat | B8: Buckwheat | C8: BUC | E8: =G8 -> CAR | F8: Carrots and turnips | G8: CAR | H8: Ireland , Netherlands | K8: Cocoyam | L8: YAM | M8: 1.6976 | P8: CAU | Q8: =VLOOKUP(P8,$E$2:$F$43,2,FALSE) -> Cauliflowers and broccoli | R8: =M28 -> 7.68 | S8: Assumed Lettuce
A9: Cabbages | B9: Cabbage | C9: CAB | E9: =G9 -> CAU | F9: Cauliflowers and broccoli | G9: CAU | H9: Ireland | K9: Sweet potato | L9: POT | M9: 5.0928 | P9: CER | Q9: =VLOOKUP(P9,$E$2:$F$43,2,FALSE) -> Cereals n.e.c. | R9: =VLOOKUP(P9,$L$2:$M$39,2,FALSE) -> 8.0856 | S9: BEPMAT
A10: Cardamom | B10: Cardamom | C10: CRD | E10: =G10 -> CER | F10: Cereals n.e.c. | G10: CER | H10: Latvia, Lithuania, Slovenia | K10: Yam | L10: YAM | M10: 1.6976 | P10: CHE | Q10: =VLOOKUP(P10,$E$2:$F$43,2,FALSE) -> #N/A | R10: =M26 -> 5.28747 | S10: Assuned Rapeseed
A11: Carrots and turnips | B11: Carrot | C11: CAR | E11: =G11 -> FLX | F11: Flax, raw or retted | G11: FLX | H11: Belgium | K11: Potatoes | L11: POT | M11: 6.366 | P11: FLX | Q11: =VLOOKUP(P11,$E$2:$F$43,2,FALSE) -> Flax, raw or retted | R11: =M6 -> 6.28923 | S11: Assumed Wheat
A12: Cassava, fresh | B12: Cassava | C12: CAS | E12: =G12 -> GRE | F12: Green corn (maize) | G12: GRE | H12: Croatia | K12: Groundnuts | L12: OTN | M12: 47.85612 | P12: GRE | Q12: =VLOOKUP(P12,$E$2:$F$43,2,FALSE) -> Green corn (maize) | R12: =M2 -> 33.73199 | S12: Assumed Maize
A13: Cereals n.e.c. | B13: Cereals | C13: CER | E13: =G13 -> GRP | F13: Grapes | G13: GRP | H13: Austria, Bulgaria, Croatia, Cyprus, France , Germany, Greece, Hungary, Italy, Luxembourg, Malta, Portugal, Romania, Slovenia, Spain | K13: Palm oil | L13: OTO | M13: 36.48882 | P13: GRP | Q13: =VLOOKUP(P13,$E$2:$F$43,2,FALSE) -> Grapes | R13: =M27 -> 7.092 | S13: Assumed Olives
A14: Chick peas, dry | B14: Chickpea | C14: CHI | E14: =G14 -> LEM | F14: Lemons and limes | G14: LEM | H14: Cyprus | K14: Beans(In Pulses) | L14: OTP | M14: 30.95 | P14: LET | Q14: =VLOOKUP(P14,$E$2:$F$43,2,FALSE) -> Lettuce and chicory | R14: =M28 -> 7.68 | S14: BEPMAT
A15: Cocoa beans | B15: Cocoa | C15: COC | E15: =G15 -> LET | F15: Lettuce and chicory | G15: LET | H15: Belgium, Netherlands | K15: Soybean | L15: SOY | M15: 52.704 | P15: MAI | Q15: =VLOOKUP(P15,$E$2:$F$43,2,FALSE) -> Maize (corn) | R15: =VLOOKUP(P15,$L$2:$M$39,2,FALSE) -> 33.73199 | S15: BEPMAT
A16: Coconuts, in shell | B16: Coconut | C16: CON | E16: =G16 -> MAI | F16: Maize (corn) | G16: MAI | H16: Austria, Belgium, Bulgaria, Croatia, Czechia, France , Germany, Greece, Hungary, Italy, Netherlands, Poland, Portugal, Romania, Slovakia, Slovenia, Spain | K16: Banana | L16: BAN | M16: 73.5255 | P16: MIX | Q16: =VLOOKUP(P16,$E$2:$F$43,2,FALSE) -> Mixed grain | R16: =M32 -> 8.0856 | S16: Assumed other cereals
A17: Coffee, green | B17: Coffee | C17: COF | E17: =G17 -> MIX | F17: Mixed grain | G17: MIX | H17: Denmark, Finland, Poland | K17: Plantain(With Bananas) | L17: BAN | M17: 40.6288 | P17: OAT | Q17: =VLOOKUP(P17,$E$2:$F$43,2,FALSE) -> Oats | R17: =M32 -> 8.0856 | S17: Assumed other cereals
A18: Cow peas, dry | B18: Cowpea | C18: COW | E18: =G18 -> MOS | F18: Minor Oil Seeds | G18: MOS | H18: Austria | K18: Sugar Cane | L18: SGC | M18: 5.6523 | P18: OLI | Q18: =VLOOKUP(P18,$E$2:$F$43,2,FALSE) -> Olives | R18: =VLOOKUP(P18,$L$2:$M$39,2,FALSE) -> 7.092 | S18: BEPMAT
A19: Dryland rice | B19: Dryland rice | C19: RCD | E19: =G19 -> OAT | F19: Oats | G19: OAT | H19: Czechia, Denmark, Estonia, Finland, Germany, Greece, Ireland , Italy, Latvia, Lithuania, Luxembourg, Poland, Portugal, Romania, Slovakia, Spain, Sweden | K19: Coffee | L19: COF | M19: 12.8 | P19: ONI | Q19: =VLOOKUP(P19,$E$2:$F$43,2,FALSE) -> Onions and shallots, dry (excluding dehydrated) | R19: =M25 -> 1.23849 | S19: Assumed sugarbewet
A20: Flax, processed but not spun | B20: Flax | C20: FLA | E20: =G20 -> OLI | F20: Olives | G20: OLI | H20: Croatia, Cyprus, Greece, Italy, Portugal, Spain | K20: Cocoa | L20: COC | M20: 15.48 | P20: ORA | Q20: =VLOOKUP(P20,$E$2:$F$43,2,FALSE) -> Oranges | R20: =10 -> 10 | S20: Asumed apples
A21: Foxtail millet | B21: Foxtail millet | C21: MTF | E21: =G21 -> ONI | F21: Onions and shallots, dry (excluding dehydrated) | G21: ONI | H21: Netherlands | K21: Cotton | L21: OTH | M21: 33.39 | P21: OTH | Q21: =VLOOKUP(P21,$E$2:$F$43,2,FALSE) -> All other crops | R21: =VLOOKUP(P21,$L$2:$M$39,2,FALSE) -> 33.39 | S21: BEPMAT
A22: Fruits | B22: Fruits | C22: FRU | E22: =G22 -> ORA | F22: Oranges | G22: ORA | H22: Cyprus | K22: Barley | L22: BRL | M22: 19.72875 | P22: OTN | Q22: =VLOOKUP(P22,$E$2:$F$43,2,FALSE) -> Chestnuts, in shell | R22: =VLOOKUP(P22,$L$2:$M$39,2,FALSE) -> 47.85612 | S22: BEPMAT
A23: Gram | B23: Gram | C23: GRM | E23: =G23 -> OTH | F23: All other crops | G23: OTH | H23: Austria, Belgium, Bulgaria, Croatia, Cyprus, Czechia, Denmark, Estonia, Finland, France , Germany, Greece, Hungary, Ireland , Italy, Latvia, Lithuania, Luxembourg, Malta, Netherlands, Poland, Portugal, Romania, Slovakia, Slovenia, Spain, Sweden | K23: Tobacco | L23: OTH | M23: 11.592 | P23: OTO | Q23: =VLOOKUP(P23,$E$2:$F$43,2,FALSE) -> Other oil seeds, n.e.c. | R23: =VLOOKUP(P23,$L$2:$M$39,2,FALSE) -> 36.48882 | S23: BEPMAT
A24: Groundnuts, excluding shelled | B24: Groundnut | C24: GRO | E24: =G24 -> OTN | F24: Chestnuts, in shell | G24: OTN | H24: Portugal | K24: Sunflower | L24: SUN | M24: 21.3 | P24: OTP | Q24: =VLOOKUP(P24,$E$2:$F$43,2,FALSE) -> Other pulses n.e.c. | R24: =VLOOKUP(P24,$L$2:$M$39,2,FALSE) -> 30.95 | S24: BEPMAT
A25: Jatropha | B25: Jatropha | C25: JAT | E25: =G25 -> OTN | F25: Other nuts (excluding wild edible nuts and groundnuts), in shell, n.e.c. | G25: OTN | H25: Portugal | K25: Sugarbeet | L25: SUG | M25: 1.23849 | P25: PEA | Q25: =VLOOKUP(P25,$E$2:$F$43,2,FALSE) -> Peas, dry | R25: =10 -> 10 | S25: Apples
A26: Maize (corn) | B26: Maize | C26: MZE | E26: =G26 -> OTO | F26: Other oil seeds, n.e.c. | G26: OTO | H26: Czechia, Estonia, Slovenia | K26: Rapeseed | L26: RAP | M26: 5.28747 | P26: PER | Q26: =VLOOKUP(P26,$E$2:$F$43,2,FALSE) -> Pears | R26: 10 | S26: Apples
A27: Miscanthus | B27: Miscanthus | C27: MIS | E27: =G27 -> OTP | F27: Other pulses n.e.c. | G27: OTP | H27: Bulgaria, Greece, Spain | K27: Olives | L27: OLI | M27: 7.092 | P27: POT | Q27: =VLOOKUP(P27,$E$2:$F$43,2,FALSE) -> Potatoes | R27: =VLOOKUP(P27,$L$2:$M$39,2,FALSE) -> 5.0928 | S27: BEPMAT
A28: Oats | B28: Oat | C28: OAT | E28: =G28 -> PEA | F28: Peas, dry | G28: PEA | H28: Bulgaria, Czechia, Estonia, France , Latvia, Lithuania, Luxembourg, Sweden | K28: Lettuce | L28: OTH | M28: 7.68 | P28: RAP | Q28: =VLOOKUP(P28,$E$2:$F$43,2,FALSE) -> Rape or colza seed | R28: =VLOOKUP(P28,$L$2:$M$39,2,FALSE) -> 5.28747 | S28: BEPMAT
A29: Oil palm fruit | B29: Oil palm | C29: OIL | E29: =G29 -> PEA | F29: Peas, green | G29: PEA | H29: Belgium | K29: Tomatoes | L29: TOM | M29: 4.11 | P29: RIC | Q29: =VLOOKUP(P29,$E$2:$F$43,2,FALSE) -> Rice | R29: =VLOOKUP(P29,$L$2:$M$39,2,FALSE) -> 13.074398 | S29: BEPMAT
A30: Olives | B30: Olive | C30: OLI | E30: =G30 -> PER | F30: Pears | G30: PER | H30: Netherlands | K30: Green peppers | L30: OTH | M30: 2.7 | P30: RYE | Q30: =VLOOKUP(P30,$E$2:$F$43,2,FALSE) -> Rye | R30: =R36 -> 6.28923 | S30: Assumed wheat
A31: Onions and shallots | B31: Onion | C31: ONI | E31: =G31 -> POT | F31: Potatoes | G31: POT | H31: Belgium, Bulgaria, Cyprus, Denmark, Estonia, Finland, France , Germany, Ireland , Latvia, Luxembourg, Malta, Netherlands, Poland, Romania, Slovenia, Sweden | K31: Red Peppers | L31: OTH | M31: 2.7 | P31: SEE | Q31: =VLOOKUP(P31,$E$2:$F$43,2,FALSE) -> Seed cotton, unginned | R31: =M21 -> 33.39 | S31: Cotton
A32: Other citrus fruit, n.e.c. | B32: Citrus | C32: CIT | E32: =G32 -> RAP | F32: Rape or colza seed | G32: RAP | H32: Austria, Belgium, Bulgaria, Croatia, Czechia, Denmark, Estonia, Finland, France , Germany, Hungary, Ireland , Latvia, Lithuania, Luxembourg, Poland, Romania, Slovakia, Slovenia, Sweden | K32: Other Cereals | L32: CER | M32: 8.0856 | P32: SOY | Q32: =VLOOKUP(P32,$E$2:$F$43,2,FALSE) -> Soya beans | R32: =VLOOKUP(P32,$L$2:$M$39,2,FALSE) -> 52.704 | S32: BEPMAT
A33: Other sugar crops n.e.c. | B33: Sugar beet | C33: SUG | E33: =G33 -> RIC | F33: Rice | G33: RIC | H33: Italy, Portugal | K33: Rest of Crops | L33: OTH | M33: 0 | P33: SUG | Q33: =VLOOKUP(P33,$E$2:$F$43,2,FALSE) -> Sugar beet | R33: =VLOOKUP(P33,$L$2:$M$39,2,FALSE) -> 1.23849 | S33: BEPMAT
A34: Pears | B34: Pearl millet | C34: MTP | E34: =G34 -> RYE | F34: Rye | G34: RYE | H34: Austria, Czechia, Denmark, Estonia, Finland, Germany, Hungary, Latvia, Lithuania, Luxembourg, Poland, Slovakia, Sweden | K34: Fodder Crops | L34: OTH | M34: 0 | P34: SUN | Q34: =VLOOKUP(P34,$E$2:$F$43,2,FALSE) -> Sunflower seed | R34: =VLOOKUP(P34,$L$2:$M$39,2,FALSE) -> 21.3 | S34: BEPMAT
A35: Peas, dry | B35: Dry pea | C35: PEA | E35: =G35 -> SEE | F35: Seed cotton, unginned | G35: SEE | H35: Greece | K35: Tur | L35: OTP | M35: 17.651 | P35: TAN | Q35: =VLOOKUP(P35,$E$2:$F$43,2,FALSE) -> Tangerines, mandarins, clementines | R35: 10 | S35: Assumed apples
A36: Pigeon peas, dry | B36: Pigeonpea | C36: PIG | E36: =G36 -> SHR | F36: Shrubland | G36: SHR | H36: Malta | K36: Lentils | L36: OTP | M36: 10.0206 | P36: WHE | Q36: =VLOOKUP(P36,$E$2:$F$43,2,FALSE) -> Wheat | R36: =VLOOKUP(P36,$L$2:$M$39,2,FALSE) -> 6.28923 | S36: BEPMAT
A37: Potatoes | B37: White potato | C37: PTW | E37: =G37 -> SOY | F37: Soya beans | G37: SOY | H37: Austria, Croatia, Hungary, Italy, Romania, Slovakia | K37: Gaur | L37: OTP | M37: 6.0876
A38: Rape or colza seed | B38: Rapeseed | C38: RAP | E38: =G38 -> STR | F38: Strawberries | G38: STR | H38: Finland | K38: Gram | L38: OTP | M38: 6.69636
A39: Reed | B39: Reed canary grass | C39: REE | E39: =G39 -> SUG | F39: Sugar beet | G39: SUG | H39: Austria, Belgium, Czechia, Denmark, France , Germany, Netherlands, Poland, Slovakia, Sweden | K39: Fruits and Nuts | L39: OTH | M39: 0
A40: Rubber | B40: Rubber | C40: RUB | E40: =G40 -> SUN | F40: Sunflower seed | G40: SUN | H40: Bulgaria, Croatia, France , Greece, Hungary, Italy, Romania, Slovakia, Spain
...

Sheet Crop_residue_biomass potential
A1: Crop_code | B1: Crop | C1: Residue Production potential (PJ/Million tonnes)
A2: ALM | B2: =VLOOKUP(A2,crop_codes!$E$2:$F$43,2,FALSE) -> Almonds, in shell | C2: 12.8
A3: APP | B3: =VLOOKUP(A3,crop_codes!$E$2:$F$43,2,FALSE) -> Apples | C3: 10
A4: BRL | B4: =VLOOKUP(A4,crop_codes!$E$2:$F$43,2,FALSE) -> Barley | C4: 19.729
A5: BRO | B5: =VLOOKUP(A5,crop_codes!$E$2:$F$43,2,FALSE) -> Broad beans and horse beans, dry | C5: 7.68
A6: CAB | B6: =VLOOKUP(A6,crop_codes!$E$2:$F$43,2,FALSE) -> Cabbages | C6: 7.68
A7: CAR | B7: =VLOOKUP(A7,crop_codes!$E$2:$F$43,2,FALSE) -> Carrots and turnips | C7: 6.366
A8: CAU | B8: =VLOOKUP(A8,crop_codes!$E$2:$F$43,2,FALSE) -> Cauliflowers and broccoli | C8: 7.68
A9: CER | B9: =VLOOKUP(A9,crop_codes!$E$2:$F$43,2,FALSE) -> Cereals n.e.c. | C9: 8.086
A10: FLX | B10: =VLOOKUP(A10,crop_codes!$E$2:$F$43,2,FALSE) -> Flax, raw or retted | C10: 6.289
A11: GRE | B11: =VLOOKUP(A11,crop_codes!$E$2:$F$43,2,FALSE) -> Green corn (maize) | C11: 33.732
A12: GRP | B12: =VLOOKUP(A12,crop_codes!$E$2:$F$43,2,FALSE) -> Grapes | C12: 7.092
A13: LET | B13: =VLOOKUP(A13,crop_codes!$E$2:$F$43,2,FALSE) -> Lettuce and chicory | C13: 7.68
... A35: WHE | B35: =VLOOKUP(A35,crop_codes!$E$2:$F$43,2,FALSE) -> Wheat | C35: 6.289

Sheet crop_residues_BEPMAT
A1: Biomass Energy Potential Mapping and Analysis Tool (BEPMAT)
A2: Source: https://zenodo.org/records/10881926
A3: Crop | B3: Residue Type | C3: RPR | D3: SAF | E3: LHV (MJ/kg) | F3: Weighted LHV
A4: Maize | B4: Stalk | C4: 2 | D4: 0.8 | E4: 16.3 | F4: =C4*D4*E4 -> 26.08
A5: Maize | B5: Cob | C5: 0.273 | D5: 1 | E5: 16.63 | F5: =C5*D5*E5 -> 4.53999
A6: Maize | B6: Husk | C6: 0.2 | D6: 1 | E6: 15.56 | F6: =C6*D6*E6 -> 3.112
A7: Rice | B7: Straw | C7: 1.757 | D7: 0.684 | E7: 8.83 | F7: =C7*D7*E7 -> 10.611788
A8: Rice | B8: Husk | C8: 0.23 | D8: 0.83 | E8: 12.9 | F8: =C8*D8*E8 -> 2.46261
A9: Sorghum | B9: Straw | C9: 1.25 | D9: 0.8 | E9: 12.38 | F9: =C9*D9*E9 -> 12.38
A10: Sorghum | B10: Husk | C10: 1.4 | D10: 1 | E10: 13 | F10: =C10*D10*E10 -> 18.2
A11: Millet | B11: Straw | C11: 1.4 | D11: 1 | E11: 13 | F11: =C11*D11*E11 -> 18.2
A12: Millet | B12: Stalk | C12: 1.75 | D12: 0.8 | E12: 15.51 | F12: =C12*D12*E12 -> 21.714
A13: Wheat | B13: Straw | C13: 1.2 | D13: 0.29 | E13: 15.6 | F13: =C13*D13*E13 -> 5.4288
A14: Wheat | B14: Husk | C14: 0.23 | D14: 0.29 | E14: 12.9 | F14: =C14*D14*E14 -> 0.86043
A15: Cassava | B15: Stalk | C15: 0.062 | D15: 0.407 | E15: 16.99 | F15: =C15*D15*E15 -> 0.42872566
... A61: Fruits and Nuts | B61: pruning | C61: 0 | D61: 0 | E61: 0 | F61: =C61*D61*E61 -> 0

Sheet Intermediate calculation
A1: Crop | B1: Code | C1: Energy content (MJ/kg of residue)
A2: Maize | B2: MAI | C2: =SUMIF(crop_residues_BEPMAT!A4:A61,'Intermediate calculation'!A2,crop_residues_BEPMAT!F4:F61) -> 33.73199
A3: Rice | B3: RIC | C3: =SUMIF(crop_residues_BEPMAT!A5:A62,'Intermediate calculation'!A3,crop_residues_BEPMAT!F5:F62) -> 13.074398
A4: Sorghum | B4: =VLOOKUP(A4,crop_codes!$A$2:$C$58,3,FALSE) -> SOR | C4: =SUMIF(crop_residues_BEPMAT!A6:A63,'Intermediate calculation'!A4,crop_residues_BEPMAT!F6:F63) -> 30.58
A5: Millet | B5: =VLOOKUP(A5,crop_codes!$A$2:$C$58,3,FALSE) -> MLT | C5: =SUMIF(crop_residues_BEPMAT!A7:A64,'Intermediate calculation'!A5,crop_residues_BEPMAT!F7:F64) -> 39.914
A6: Wheat | B6: =VLOOKUP(A6,crop_codes!$A$2:$C$58,3,FALSE) -> WHE | C6: =SUMIF(crop_residues_BEPMAT!A8:A65,'Intermediate calculation'!A6,crop_residues_BEPMAT!F8:F65) -> 6.28923
A7: Cassava | C7: =SUMIF(crop_residues_BEPMAT!A9:A66,'Intermediate calculation'!A7,crop_residues_BEPMAT!F9:F66) -> 6.7947257
A8: Cocoyam | C8: =SUMIF(crop_residues_BEPMAT!A10:A67,'Intermediate calculation'!A8,crop_residues_BEPMAT!F10:F67) -> 1.6976
A9: Sweet potato | C9: =SUMIF(crop_residues_BEPMAT!A11:A68,'Intermediate calculation'!A9,crop_residues_BEPMAT!F11:F68) -> 5.0928
A10: Yam | C10: =SUMIF(crop_residues_BEPMAT!A12:A69,'Intermediate calculation'!A10,crop_residues_BEPMAT!F12:F69) -> 1.6976
A11: Potatoes | B11: POT | C11: =SUMIF(crop_residues_BEPMAT!A13:A70,'Intermediate calculation'!A11,crop_residues_BEPMAT!F13:F70) -> 6.366
A12: Groundnuts | B12: OTN | C12: =SUMIF(crop_residues_BEPMAT!A14:A71,'Intermediate calculation'!A12,crop_residues_BEPMAT!F14:F71) -> 47.85612
A13: Palm oil | B13: =VLOOKUP(A13,crop_codes!$A$2:$C$58,3,FALSE) -> #N/A | C13: =SUMIF(crop_residues_BEPMAT!A15:A72,'Intermediate calculation'!A13,crop_residues_BEPMAT!F15:F72) -> 36.48882
A14: Beans(In Pulses) | B14: =VLOOKUP(A14,crop_codes!$A$2:$C$58,3,FALSE) -> #N/A | C14: =SUMIF(crop_residues_BEPMAT!A16:A73,'Intermediate calculation'!A14,crop_residues_BEPMAT!F16:F73) -> 30.95
A15: Soybean | B15: =VLOOKUP(A15,crop_codes!$A$2:$C$58,3,FALSE) -> #N/A | C15: =SUMIF(crop_residues_BEPMAT!A17:A74,'Intermediate calculation'!A15,crop_residues_BEPMAT!F17:F74) -> 52.704
A16: Banana | B16: =VLOOKUP(A16,crop_codes!$A$2:$C$58,3,FALSE) -> #N/A | C16: =SUMIF(crop_residues_BEPMAT!A18:A75,'Intermediate calculation'!A16,crop_residues_BEPMAT!F18:F75) -> 73.5255
A17: Plantain(With Bananas) | B17: =VLOOKUP(A17,crop_codes!$A$2:$C$58,3,FALSE) -> #N/A | C17: =SUMIF(crop_residues_BEPMAT!A19:A76,'Intermediate calculation'!A17,crop_residues_BEPMAT!F19:F76) -> 40.6288
A18: Sugar Cane | B18: =VLOOKUP(A18,crop_codes!$A$2:$C$58,3,FALSE) -> SGC | C18: =SUMIF(crop_residues_BEPMAT!A20:A77,'Intermediate calculation'!A18,crop_residues_BEPMAT!F20:F77) -> 5.6523
A19: Coffee | B19: =VLOOKUP(A19,crop_codes!$A$2:$C$58,3,FALSE) -> #N/A | C19: =SUMIF(crop_residues_BEPMAT!A21:A78,'Intermediate calculation'!A19,crop_residues_BEPMAT!F21:F78) -> 12.8
A20: Cocoa | B20: =VLOOKUP(A20,crop_codes!$A$2:$C$58,3,FALSE) -> #N/A | C20: =SUMIF(crop_residues_BEPMAT!A22:A79,'Intermediate calculation'!A20,crop_residues_BEPMAT!F22:F79) -> 15.48
A21: Cotton | B21: =VLOOKUP(A21,crop_codes!$A$2:$C$58,3,FALSE) -> #N/A | C21: =SUMIF(crop_residues_BEPMAT!A23:A80,'Intermediate calculation'!A21,crop_residues_BEPMAT!F23:F80) -> 33.39
A22: Barley | B22: =VLOOKUP(A22,crop_codes!$A$2:$C$58,3,FALSE) -> BRL | C22: =SUMIF(crop_residues_BEPMAT!A24:A81,'Intermediate calculation'!A22,crop_residues_BEPMAT!F24:F81) -> 19.72875
A23: Tobacco | B23: =VLOOKUP(A23,crop_codes!$A$2:$C$58,3,FALSE) -> #N/A | C23: =SUMIF(crop_residues_BEPMAT!A25:A82,'Intermediate calculation'!A23,crop_residues_BEPMAT!F25:F82) -> 11.592
A24: Sunflower | B24: =VLOOKUP(A24,crop_codes!$A$2:$C$58,3,FALSE) -> #N/A | C24: =SUMIF(crop_residues_BEPMAT!A26:A83,'Intermediate calculation'!A24,crop_residues_BEPMAT!F26:F83) -> 21.3
... A39: Fruits and Nuts | B39: =VLOOKUP(A39,crop_codes!$A$2:$C$58,3,FALSE) -> #N/A | C39: =SUMIF(crop_residues_BEPMAT!A41:A98,'Intermediate calculation'!A39,crop_residues_BEPMAT!F41:F98) -> 0

Sheet Non BEPMAT sources
A1: Crop / Residue | B1: RPR (Residue-to-Product Ratio) | C1: SAF (Surplus Availability Fraction) | D1: LHV (MJ/kg, dry basis) | E1: Weighted LHV value | F1: Sources / Notes
A2: Wheat straw | B2: 1.8 | C2: 0.35 | D2: 13.7 | E2: =D2*C2*B2 -> 8.631 | F2: Noori et al. (EJ-Eng, 2024); typical EU cereal straw RPR, LHV range 13–15MJ/kg
A3: Barley straw | B3: 1.3 | C3: 0.375 | D3: 13.97 | E3: =D3*C3*B3 -> 6.810375 | F3: Noori et al. (EJ-Eng, 2024); similar to wheat straw range
A4: Maize (corn) stover | B4: 2 | C4: 0.375 | D4: 13.22 | E4: =D4*C4*B4 -> 9.915 | F4: Noori et al. (EJ-Eng, 2024); maize stalks LHV 13–14MJ/kg
A5: Rice straw | B5: 1.5 | C5: 0.375 | D5: 12.81 | E5: =D5*C5*B5 -> 7.205625 | F5: Noori et al. (EJ-Eng, 2024); rice stalks ~12.8MJ/kg
A6: Olive pruning residues | C6: 0.475 | D6: 19.86 | E6: =D6*C6*B6 -> 0 | F6: MDPI (2024) 'Lignocellulosic Residues from Fruit Trees'; PMC8198515 'Pyrolysis of Pruning Residues'
A7: Fruit tree pruning residues (apple, pear, etc.) | B7: 0.5 | C7: 1 | D7: 20 | E7: =D7*C7*B7 -> 10 | F7: Cichy etal. (BioResources, 2024) 'Fuel properties of woody biomass from pruning operations in fruit orchards'
