Workbook

Sheet Comparison with GWSP
A1: Comparison of freshwater withdrawals from this research and Flörke et al., per country
A2: Country | B2: GWSP [assumed that freshwater used at all power plants] | D2: Research results
B3: Year | C3: Water withdrawals [m3] | D3: Year | E3: Median freshwater withdrawals [m3]
A4: Afghanistan | B4: 2005 | C4: 20661765 | D4: 2015 | E4: 265
A5: Albania | B5: 2005 | C5: 8745004 | D5: 2015 | E5: 0
A6: Algeria | B6: 2005 | C6: 2779516644 | D6: 2015 | E6: 8032546
A7: Angola | B7: 2005 | C7: 51409804 | D7: 2015 | E7: 0
A8: Argentina | B8: 2005 | C8: 6086315585 | D8: 2015 | E8: 2666335488
A9: Armenia | B9: 2005 | C9: 530738804 | D9: 2015 | E9: 20061133
A10: Australia | B10: 2005 | C10: 421944746 | D10: 2015 | E10: 2329541106
A11: Austria | B11: 2005 | C11: 1825402760 | D11: 2015 | E11: 1121264300
A12: Azerbaijan | B12: 2005 | C12: 2032530711 | D12: 2015 | E12: 588706116
A13: Bahamas | B13: 2005 | C13: 245637562 | D13: 2015 | E13: 0
A14: Bahrain | B14: 2005 | C14: 743058912 | D14: 2015 | E14: 0
A15: Bangladesh | B15: 2005 | C15: 2008335283 | D15: 2015 | E15: 1346434015
... A35: Cuba | B35: 2005 | C35: 1853545853 | D35: 2015 | E35: 189585106
A36: Cyprus | B36: 2005 | D36: 2015 | E36: 0
A37: Czech Republic | B37: 2005 | C37: 416898051 | D37: 2015 | E37: 244942977
A38: Denmark | B38: 2005 | C38: 56717667 | D38: 2015 | E38: 350
A39: Djibouti | B39: 2005 | C39: 31799994 | D39: 2015 | E39: 0
A40: Dominican Republic | B40: 2005 | C40: 1024333431 | D40: 2015 | E40: 1705171
A41: Ecuador | B41: 2005 | C41: 756724049 | D41: 2015 | E41: 153023428
A42: Egypt | B42: 2005 | C42: 7703022788 | D42: 2015 | E42: 2854460794
A43: El Salvador | B43: 2005 | C43: 218669993 | D43: 2015 | E43: 4574
A44: Eritrea | B44: 2005 | C44: 35775011 | D44: 2015 | E44: 0
A45: Estonia | B45: 2005 | C45: 1254709854 | D45: 2015 | E45: 5768
A46: Finland | B46: 2005 | C46: 173998994 | D46: 2015 | E46: 521489469
A47: France | B47: 2005 | C47: 18529544480 | D47: 2015 | E47: 11090787083
A48: Gabon | B48: 2005 | C48: 99242455 | D48: 2015 | E48: 0
... A61: Ireland | B61: 2005 | C61: 277032008 | D61: 2015 | E61: 312402
A62: Israel | B62: 2005 | D62: 2015 | E62: 7420163
A63: Italy | B63: 2005 | C63: 9335534709 | D63: 2015 | E63: 1447433634
A64: Jamaica | B64: 2005 | C64: 779110408 | D64: 2015 | E64: 0
A65: Japan | B65: 2005 | C65: 4741354 | D65: 2015 | E65: 2826967500
A66: Jordan | B66: 2005 | C66: 618234009 | D66: 2015 | E66: 1504628
A67: Kazakhstan | B67: 2005 | C67: 4186178936 | D67: 2015 | E67: 1187833243
A68: Kenya | B68: 2005 | C68: 184630082 | D68: 2015 | E68: 143527
A69: Korea Democratic People's Republic | B69: 2005 | C69: 953320807 | D69: 2015 | E69: 1437074338
A70: Korea Republic | B70: 2005 | C70: 7812119026 | D70: 2015 | E70: 1119657419
A71: Kuwait | B71: 2005 | C71: 2681970443 | D71: 2015 | E71: 0
...

Sheet Metadata
A1: Source | B1: https://www.nature.com/articles/s41560-019-0501-4
A2: Lohrmann, A., Farfan, J., Caldera, U. et al. Global scenarios for significant water use reduction in thermal power plants based on cooling water demand estimation using satellite imagery. Nat Energy 4, 1040–1048 (2019). https://doi.org/10.1038/s41560-019-0501-4

Sheet water_abstraction_EU_EEA
A1: Downloaded from: https://www.eea.europa.eu/en/analysis/indicators/water-abstraction-by-source-and/water-abstraction-by-economic-sector
A3: Sources | B3: https://www.eea.europa.eu/en/datahub/datahubitem-view/a4324714-784a-4763-b8b9-b8939ead87fe?activeAccordion=1092906 | C3: European Environment Agency (EEA) | D3: Waterbase - Water Quantity, 2023
A5: Geographical coverage | B5: Cyprus, Portugal, Spain, Malta, Denmark, Iceland, Switzerland, Sweden, Netherlands, Austria, Belgium, Germany, Luxembourg, Ireland, TÃ¼rkiye, France, Liechtenstein, Slovakia, Czechia, Norway, Italy, Slovenia, Montenegro, Croatia, Bosnia and Herzegovina, Greece, Estonia, Latvia, Lithuania, Serbia, Finland, North Macedonia, Hungary, Bulgaria, Albania, Poland, Romania, Kosovo (UNSCR 1244/99)
A7: Agriculture | B7: Construction | C7: Electricity cooling | D7: Manufacturing | E7: Mining and Quarrying | F7: Public water supply | G7: Year | H7: ï»¿Country
F8: Country | I8: Year | J8: water abstraction (MCM)
A9: 1198.1 | G9: 2000 | H9: Bulgaria
A10: 876.8 | G10: 2001 | H10: Bulgaria
A11: 754 | G11: 2002 | H11: Bulgaria
A12: 1106.3 | G12: 2003 | H12: Bulgaria
A13: 909.9 | G13: 2004 | H13: Bulgaria
A14: 711.5 | G14: 2005 | H14: Bulgaria
A15: 886.5 | G15: 2006 | H15: Bulgaria
A16: 1025.1 | G16: 2007 | H16: Bulgaria
A17: 1019.5 | G17: 2008 | H17: Bulgaria
A18: 1006.4 | G18: 2009 | H18: Bulgaria
A19: 948.6 | G19: 2010 | H19: Bulgaria
A20: 1059.4 | G20: 2011 | H20: Bulgaria
... A31: 771.1 | G31: 2022 | H31: Bulgaria
A32: 2.1 | F32: 2000 | G32: Bulgaria
A33: 1.3 | F33: 2001 | G33: Bulgaria
A34: 2.2 | F34: 2002 | G34: Bulgaria
A35: 2.6 | F35: 2003 | G35: Bulgaria
A36: 1.7 | F36: 2004 | G36: Bulgaria
A37: 0 | F37: 2005 | G37: Bulgaria
A38: 0 | F38: 2006 | G38: Bulgaria
A39: 0 | F39: 2007 | G39: Bulgaria
A40: 0 | F40: 2008 | G40: Bulgaria
A41: 0 | F41: 2009 | G41: Bulgaria
A42: 0 | F42: 2010 | G42: Bulgaria
A43: 0 | F43: 2011 | G43: Bulgaria
... A54: 0 | F54: 2022 | G54: Bulgaria
A55: 3227.9 | E55: 2000 | F55: Bulgaria | I55: =E55 -> 2000 | J55: =A55 -> 3227.9
A56: 3467.2 | E56: 2001 | F56: Bulgaria | I56: =E56 -> 2001 | J56: =A56 -> 3467.2
A57: 4388.6 | E57: 2002 | F57: Bulgaria | I57: =E57 -> 2002 | J57: =A57 -> 4388.6
A58: 4082.7 | E58: 2003 | F58: Bulgaria | I58: =E58 -> 2003 | J58: =A58 -> 4082.7
A59: 3804.2 | E59: 2004 | F59: Bulgaria | I59: =E59 -> 2004 | J59: =A59 -> 3804.2
A60: 3780.3 | E60: 2005 | F60: Bulgaria | I60: =E60 -> 2005 | J60: =A60 -> 3780.3
A61: 4153.7 | E61: 2006 | F61: Bulgaria | I61: =E61 -> 2006 | J61: =A61 -> 4153.7
A62: 3492.8 | E62: 2007 | F62: Bulgaria | I62: =E62 -> 2007 | J62: =A62 -> 3492.8
A63: 3741.1 | E63: 2008 | F63: Bulgaria | I63: =E63 -> 2008 | J63: =A63 -> 3741.1
...

Sheet Water demand per country_Nature
A1: The values listed in the table represent median values of water consumption and water withdrawal. The numbers highlighted in red show the values that belong to the global ten highest water demand in the specific category. The underlined numbers in red represent the highest values of all countries in each category. The table shows the values of water consumption and water withdrawal (on fresh- and aggregated-water levels) for 148 countries in the world. For the remaining countries, which are not included in this list, no thermal power plants exceeding 50 MW were found, and/ or there is no reported information on the capacity factors of power generation facilities of these specific countries. The category ‘Ratio Capacity Potentially Seawater Cooled’ is the outcome of the GIS analysis and shows the share of the cumulated active thermal power plant capacity of the country located within 20 km from the coastline. In other words, it displays the share of cumulated country’s capacity which is potentially seawater-cooled.

Sheet cooling water_Nature_EU27_sort
A1: Country | B1: ISO 3166-2 Country Codes | C1: Active Capacity, [MW] | D1: Ratio Capacity Potentially Seawater Cooled | E1: Freshwater Consumption, [m3] | F1: Aggregated Water Consumption, [m3] | G1: Freshwater Withdrawal, [m3] | H1: Aggregated Water Withdrawal, [m3] | I1: Share (consumption/Withdrawal) | J1: actual withdrawal (MCM) | K1: Actual consumption (MCM)
A2: Afghanistan | B2: af | C2: 100 | D2: 0 | E2: 265.28 | F2: 265.28 | G2: 265.28 | H2: 265.28
A3: Albania | B3: al | C3: 97 | D3: 1 | E3: 0 | F3: 9327.96 | G3: 0 | H3: 1061522.1
A4: Algeria | B4: dz | C4: 14368.8 | D4: 0.68 | E4: 6444718.8 | F4: 6725831.9 | G4: 8032545.6 | H4: 8313658.6
A5: Angola | B5: ao | C5: 404 | D5: 1 | E5: 0 | F5: 2218845.6 | G5: 0 | H5: 70487518
A6: Argentina | B6: ar | C6: 19098.41 | D6: 0.41 | E6: 60712581 | F6: 1.3933845e+08 | G6: 2.6663355e+09 | H6: 3.1175355e+09
A7: Armenia | B7: am | C7: 2257.9 | D7: 0 | E7: 13186843 | F7: 13186843 | G7: 20061133 | H7: 20061133
A8: Australia | B8: au | C8: 45749.68 | D8: 0.35 | E8: 2.5527838e+08 | F8: 3.7824788e+08 | G8: 2.3295411e+09 | H8: 2.4869056e+09
A9: Austria | B9: at | C9: 7483.4 | D9: 0 | E9: 23716478 | F9: 23716478 | G9: 1.1212643e+09 | H9: 1.1212643e+09 | I9: =F9/H9 -> 0.02115155 | J9: =H9/1000000 -> 1121.2643 | K9: =F9/1000000 -> 23.716478
A10: Azerbaijan | B10: az | C10: 6183.9 | D10: 0.23 | E10: 5101961.8 | F10: 6570539.1 | G10: 5.8870612e+08 | H10: 6.2495352e+08
A11: Bahamas | B11: bs | C11: 403.8 | D11: 1 | E11: 0 | F11: 1377194.4 | G11: 0 | H11: 97288757
A12: Bahrain | B12: bh | C12: 5394 | D12: 1 | E12: 0 | F12: 18215139 | G12: 0 | H12: 5.5263173e+08
A13: Bangladesh | B13: bd | C13: 8177.7 | D13: 0.08 | E13: 64002987 | F13: 70266996 | G13: 1.346434e+09 | H13: 1.5176137e+09
A14: Barbados | B14: bb | C14: 285.4 | D14: 1 | E14: 0 | F14: 2837642.5 | G14: 0 | H14: 4132789.2
A15: Belarus | B15: by | C15: 8596.01 | D15: 0 | E15: 57177919 | F15: 57177919 | G15: 1.7036455e+09 | H15: 1.7036455e+09
A16: Belgium | B16: be | C16: 12111 | D16: 0.35 | E16: 69115202 | F16: 1.1558558e+08 | G16: 1.7268328e+08 | H16: 2.4649062e+08 | I16: =F16/H16 -> 0.46892487 | J16: =H16/1000000 -> 246.49062 | K16: =F16/1000000 -> 115.58558
A17: Bolivia | B17: bo | C17: 1129.18 | D17: 0 | E17: 2620947.2 | F17: 2620947.2 | G17: 3258512.5 | H17: 3258512.5
A18: Bosnia and Herzegovina | B18: ba | C18: 1765 | D18: 0 | E18: 19313083 | F18: 19313083 | G18: 23667599 | H18: 23667599
A19: Botswana | B19: bw | C19: 742 | D19: 0 | E19: 7904411.5 | F19: 7904411.5 | G19: 9711867.4 | H19: 9711867.4
A20: Brazil | B20: br | C20: 24349.72 | D20: 0.62 | E20: 50134440 | F20: 1.3082694e+08 | G20: 3.7313451e+08 | H20: 3.714445e+09
A21: Brunei Darussalam | B21: bn | C21: 876 | D21: 1 | E21: 0 | F21: 9712876.8 | G21: 0 | H21: 13883654
A22: Bulgaria | B22: bg | C22: 8007.18 | D22: 0.03 | E22: 58187097 | F22: 59269782 | G22: 2.8452455e+09 | H22: 2.8468223e+09 | I22: =F22/H22 -> 0.020819628 | J22: =H22/1000000 -> 2846.8223 | K22: =F22/1000000 -> 59.269782
A23: Cambodia | B23: kh | C23: 100 | D23: 1 | E23: 0 | F23: 355974.66 | G23: 0 | H23: 85333111
A24: Cameroon | B24: cm | C24: 449.5 | D24: 0.87 | E24: 1595.67 | F24: 17210.1 | G24: 1595.67 | H24: 17210.1
A25: Canada | B25: ca | C25: 47303.06 | D25: 0.15 | E25: 1.7104704e+08 | F25: 1.8722997e+08 | G25: 2.18769e+10 | H25: 2.3663638e+10
A26: Cayman Islands | B26: ky | C26: 52.75 | D26: 1 | E26: 0 | F26: 152390.31 | G26: 0 | H26: 22223587
A27: Chile | B27: cl | C27: 11566.44 | D27: 0.77 | E27: 5177369 | F27: 25069583 | G27: 1.3147937e+08 | H27: 2.8990398e+09
A28: China | B28: cn | C28: 922340.2 | D28: 0.22 | E28: 5.6156242e+09 | F28: 6.3498105e+09 | G28: 42115058588 | H28: 5.6473869e+10
A29: Colombia | B29: co | C29: 6847 | D29: 0.4 | E29: 16813846 | F29: 25342441 | G29: 5.0253518e+08 | H29: 9.6526029e+08
A30: Congo Republic | B30: cd | C30: 292.2 | D30: 1 | E30: 0 | F30: 2529760.6 | G30: 0 | H30: 3162200.8
A31: Costa Rica | B31: cr | C31: 431 | D31: 1 | E31: 0 | F31: 414318.69 | G31: 0 | H31: 59410315
A32: Croatia | B32: hr | C32: 1895.8 | D32: 0.34 | E32: 499631.38 | F32: 1425337 | G32: 35851622 | H32: 2.5082512e+08 | I32: =F32/H32 -> 0.0056825927 | J32: =H32/1000000 -> 250.82512 | K32: =F32/1000000 -> 1.425337
A33: Cuba | B33: cu | C33: 4346.2 | D33: 0.9 | E33: 1300012.1 | F33: 12587584 | G33: 1.8958511e+08 | H33: 1778894907
A34: Cyprus | B34: cy | C34: 1375.3 | D34: 1 | E34: 0 | F34: 1129823.6 | G34: 0 | H34: 1.4018908e+08 | I34: =F34/H34 -> 0.0080592841 | J34: =H34/1000000 -> 140.18908 | K34: =F34/1000000 -> 1.1298236
A35: Czech Republic | B35: cz | C35: 15424.62 | D35: 0 | E35: 1.4213857e+08 | F35: 1.4213857e+08 | G35: 2.4494298e+08 | H35: 2.4494298e+08 | I35: =F35/H35 -> 0.58029249 | J35: =H35/1000000 -> 244.94298 | K35: =F35/1000000 -> 142.13857
A36: Denmark | B36: dk | C36: 6792.79 | D36: 0.99 | E36: 350.04 | F36: 4924215.4 | G36: 350.04 | H36: 1.1442831e+09 | I36: =F36/H36 -> 0.0043033191 | J36: =H36/1000000 -> 1144.2831 | K36: =F36/1000000 -> 4.9242154
A37: Djibouti | B37: dj | C37: 82 | D37: 1 | E37: 0 | F37: 1772098.8 | G37: 0 | H37: 2580913.9
A38: Dominican Republic | B38: do | C38: 4293.8 | D38: 0.86 | E38: 1203727 | F38: 48284253 | G38: 1705170.6 | H38: 5.5908543e+08
A39: Ecuador | B39: ec | C39: 1902.9 | D39: 0.78 | E39: 2793030 | F39: 9006769.7 | G39: 1.5302343e+08 | H39: 4.2708606e+08
A40: Egypt | B40: eg | C40: 27241.41 | D40: 0.4 | E40: 27746369 | F40: 1.1098548e+08 | G40: 2.8544608e+09 | H40: 1.1417843e+10
...

Sheet cooling water_calculation_Eu27
T1: OSeMOSYS inputs
A2: Country | B2: ISO 3166-2 Country Codes | C2: Active Capacity, [MW] | D2: Ratio Capacity Potentially Seawater Cooled | E2: Freshwater Consumption, [m3] | F2: Aggregated Water Consumption, [m3] | G2: Freshwater Withdrawal, [m3] | H2: Aggregated Water Withdrawal, [m3] | I2: Share (consumption/Withdrawal) | J2: Share (release/Withdrawal) | K2: Average water withdrawal (MCM) | L2: Average water consumption (MCM) | M2: Total thermal electricity generation (2018) PJ | N2: Total thermal electricity generation (2021) PJ | O2: Total Water withdrawal for cooling (MCM)-2018 | P2: Total Water withdrawal for cooling (MCM)-2021 | Q2: Total Water release after cooling (MCM)-2018 | R2: Total Water release after cooling (MCM)-2021 | T2: IAR (XXWPWR) for all thermal power plants (2018) BCM/PJ | U2: IAR (XXWPWR) for all thermal power plants (2021) BCM/PJ | V2: OAR (XXWSUR) for all thermal power plants (2018) BCM/PJ | W2: OAR (XXWRUN) for all thermal power plants (2021) BCM/PJ | X2: IAR FUEL (input) | Y2: Value (BCM/PJ) | Z2: OAR Fuel (Output) | AA2: Value (BCM/PJ)
A3: Austria | B3: AT | C3: 7483.4 | D3: 0 | E3: 23716478 | F3: 23716478 | G3: 1.1212643e+09 | H3: 1.1212643e+09 | I3: 0.02115155 | J3: =1-I3 -> 0.97884845 | K3: 1121.2643 | L3: 23.716478 | M3: 71.639258 | N3: 67.240764 | O3: {=INDEX(water_abstraction_EU_EEA!$J$55:$J$4515, MATCH(1, (water_abstraction_EU_EEA!$F$55:$F$4515=$A3)*(water_abstraction_EU_EEA!$I$55:$I$4515=2018), 0))} -> 1171.6 | P3: {=INDEX(water_abstraction_EU_EEA!$J$55:$J$4515, MATCH(1, (water_abstraction_EU_EEA!$F$55:$F$4515=$A3)*(water_abstraction_EU_EEA!$I$55:$I$4515=2021), 0))} -> 1495.1 | Q3: =O3*$J3 -> 1146.8188 | R3: =P3*$J3 -> 1463.4763 | S3: =P3-R3 -> 31.623682 | T3: =O3/(1000*M3) -> 0.016354161 | U3: =P3/(1000*N3) -> 0.022235024 | V3: =Q3/(1000*M3) -> 0.016008246 | W3: =R3/(1000*N3) -> 0.021764719 | X3: =B3&"WPWR" -> ATWPWR | Y3: =ROUND(U3,5) -> 0.02224 | Z3: =B3&"WRUN" -> ATWRUN | AA3: =ROUND(W3,5) -> 0.02176
A4: Belgium | B4: BE | C4: 12111 | D4: 0.35 | E4: 69115202 | F4: 1.1558558e+08 | G4: 1.7268328e+08 | H4: 2.4649062e+08 | I4: 0.46892487 | J4: =1-I4 -> 0.53107513 | K4: 246.49062 | L4: 115.58558 | M4: 222.36336 | N4: 291.61188 | O4: {=INDEX(water_abstraction_EU_EEA!$J$55:$J$4515, MATCH(1, (water_abstraction_EU_EEA!$F$55:$F$4515=$A4)*(water_abstraction_EU_EEA!$I$55:$I$4515=2018), 0))} -> 2239.7 | P4: {=INDEX(water_abstraction_EU_EEA!$J$55:$J$4515, MATCH(1, (water_abstraction_EU_EEA!$F$55:$F$4515=$A4)*(water_abstraction_EU_EEA!$I$55:$I$4515=2021), 0))} -> 2256.5 | Q4: =O4*$J4 -> 1189.449 | R4: =P4*$J4 -> 1198.371 | S4: =P4-R4 -> 1058.129 | T4: =O4/(1000*M4) -> 0.010072253 | U4: =P4/(1000*N4) -> 0.0077380249 | V4: =Q4/(1000*M4) -> 0.005349123 | W4: =R4/(1000*N4) -> 0.0041094726 | X4: =B4&"WPWR" -> BEWPWR | Y4: =ROUND(U4,5) -> 0.00774 | Z4: =B4&"WRUN" -> BEWRUN | AA4: =ROUND(W4,5) -> 0.00411
A5: Bulgaria | B5: BG | C5: 8007.18 | D5: 0.03 | E5: 58187097 | F5: 59269782 | G5: 2.8452455e+09 | H5: 2.8468223e+09 | I5: 0.020819628 | J5: =1-I5 -> 0.97918037 | K5: 2846.8223 | L5: 59.269782 | M5: 139.43437 | N5: 142.4358 | O5: {=INDEX(water_abstraction_EU_EEA!$J$55:$J$4515, MATCH(1, (water_abstraction_EU_EEA!$F$55:$F$4515=$A5)*(water_abstraction_EU_EEA!$I$55:$I$4515=2018), 0))} -> 3607.7 | P5: {=INDEX(water_abstraction_EU_EEA!$J$55:$J$4515, MATCH(1, (water_abstraction_EU_EEA!$F$55:$F$4515=$A5)*(water_abstraction_EU_EEA!$I$55:$I$4515=2021), 0))} -> 3471.7 | Q5: =O5*$J5 -> 3532.589 | R5: =P5*$J5 -> 3399.4205 | S5: =P5-R5 -> 72.279503 | T5: =O5/(1000*M5) -> 0.025873821 | U5: =P5/(1000*N5) -> 0.024373787 | V5: =Q5/(1000*M5) -> 0.025335138 | W5: =R5/(1000*N5) -> 0.023866334 | X5: =B5&"WPWR" -> BGWPWR | Y5: =ROUND(U5,5) -> 0.02437 | Z5: =B5&"WRUN" -> BGWRUN | AA5: =ROUND(W5,5) -> 0.02387
A6: Croatia | B6: HR | C6: 1895.8 | D6: 0.34 | E6: 499631.38 | F6: 1425337 | G6: 35851622 | H6: 2.5082512e+08 | I6: 0.0056825927 | J6: =1-I6 -> 0.99431741 | K6: 250.82512 | L6: 1.425337 | M6: 15.9642 | N6: 20.45268 | O6: {=INDEX(water_abstraction_EU_EEA!$J$55:$J$4515, MATCH(1, (water_abstraction_EU_EEA!$F$55:$F$4515=$A6)*(water_abstraction_EU_EEA!$I$55:$I$4515=2018), 0))} -> 165 | P6: {=INDEX(water_abstraction_EU_EEA!$J$55:$J$4515, MATCH(1, (water_abstraction_EU_EEA!$F$55:$F$4515=$A6)*(water_abstraction_EU_EEA!$I$55:$I$4515=2021), 0))} -> 167.3 | Q6: =O6*$J6 -> 164.06237 | R6: =P6*$J6 -> 166.3493 | S6: =P6-R6 -> 0.95069776 | T6: =O6/(1000*M6) -> 0.010335626 | U6: =P6/(1000*N6) -> 0.0081798571 | V6: =Q6/(1000*M6) -> 0.010276893 | W6: =R6/(1000*N6) -> 0.0081333743 | X6: =B6&"WPWR" -> HRWPWR | Y6: =ROUND(U6,5) -> 0.00818 | Z6: =B6&"WRUN" -> HRWRUN | AA6: =ROUND(W6,5) -> 0.00813
A7: Cyprus | B7: CY | C7: 1375.3 | D7: 1 | E7: 0 | F7: 1129823.6 | G7: 0 | H7: 1.4018908e+08 | I7: 0.0080592841 | J7: =1-I7 -> 0.99194072 | K7: 140.18908 | L7: 1.1298236 | M7: 16.704122 | N7: 15.856585 | O7: {=INDEX(water_abstraction_EU_EEA!$J$55:$J$4515, MATCH(1, (water_abstraction_EU_EEA!$F$55:$F$4515=$A7)*(water_abstraction_EU_EEA!$I$55:$I$4515=2018), 0))} -> 0 | P7: {=INDEX(water_abstraction_EU_EEA!$J$55:$J$4515, MATCH(1, (water_abstraction_EU_EEA!$F$55:$F$4515=$A7)*(water_abstraction_EU_EEA!$I$55:$I$4515=2021), 0))} -> 14.8 | Q7: =O7*$J7 -> 0 | R7: =P7*$J7 -> 14.680723 | S7: =P7-R7 -> 0.11927741 | T7: =O7/(1000*M7) -> 0 | U7: =P7/(1000*N7) -> 0.00093336616 | V7: =Q7/(1000*M7) -> 0 | W7: =R7/(1000*N7) -> 0.00092584389 | X7: =B7&"WPWR" -> CYWPWR | Y7: =ROUND(U7,5) -> 0.00093 | Z7: =B7&"WRUN" -> CYWRUN | AA7: =ROUND(W7,5) -> 0.00093
A8: Czechia | B8: CZ | C8: 15424.62 | D8: 0 | E8: 1.4213857e+08 | F8: 1.4213857e+08 | G8: 2.4494298e+08 | H8: 2.4494298e+08 | I8: 0.58029249 | J8: =1-I8 -> 0.41970751 | K8: 244.94298 | L8: 142.13857 | M8: 296.13361 | N8: 282.26907 | O8: {=INDEX(water_abstraction_EU_EEA!$J$55:$J$4515, MATCH(1, (water_abstraction_EU_EEA!$F$55:$F$4515=$A8)*(water_abstraction_EU_EEA!$I$55:$I$4515=2018), 0))} -> 408.6 | P8: {=INDEX(water_abstraction_EU_EEA!$J$55:$J$4515, MATCH(1, (water_abstraction_EU_EEA!$F$55:$F$4515=$A8)*(water_abstraction_EU_EEA!$I$55:$I$4515=2021), 0))} -> 264.5 | Q8: =O8*$J8 -> 171.49249 | R8: =P8*$J8 -> 111.01264 | S8: =P8-R8 -> 153.48736 | T8: =O8/(1000*M8) -> 0.0013797826 | U8: =P8/(1000*N8) -> 0.00093704919 | V8: =Q8/(1000*M8) -> 0.00057910512 | W8: =R8/(1000*N8) -> 0.00039328659 | X8: =B8&"WPWR" -> CZWPWR | Y8: =ROUND(U8,5) -> 0.00094 | Z8: =B8&"WRUN" -> CZWRUN | AA8: =ROUND(W8,5) -> 0.00039
A9: Denmark | B9: DK | C9: 6792.79 | D9: 0.99 | E9: 350.04 | F9: 4924215.4 | G9: 350.04 | H9: 1.1442831e+09 | I9: 0.0043033191 | J9: =1-I9 -> 0.99569668 | K9: 1144.2831 | L9: 4.9242154 | M9: 55.799903 | N9: 56.415366 | O9: {=INDEX(water_abstraction_EU_EEA!$J$55:$J$4515, MATCH(1, (water_abstraction_EU_EEA!$F$55:$F$4515=$A9)*(water_abstraction_EU_EEA!$I$55:$I$4515=2018), 0))} -> 2.9 | P9: {=INDEX(water_abstraction_EU_EEA!$J$55:$J$4515, MATCH(1, (water_abstraction_EU_EEA!$F$55:$F$4515=$A9)*(water_abstraction_EU_EEA!$I$55:$I$4515=2021), 0))} -> 3.5 | Q9: =O9*$J9 -> 2.8875204 | R9: =P9*$J9 -> 3.4849384 | S9: =P9-R9 -> 0.015061617 | T9: =O9/(1000*M9) -> 5.1971417e-05 | U9: =P9/(1000*N9) -> 6.2039835e-05 | V9: =Q9/(1000*M9) -> 5.1747767e-05 | W9: =R9/(1000*N9) -> 6.1772858e-05 | X9: =B9&"WPWR" -> DKWPWR | Y9: =ROUND(U9,5) -> 6e-05 | Z9: =B9&"WRUN" -> DKWRUN | AA9: =ROUND(W9,5) -> 6e-05
A10: Estonia | B10: EE | C10: 3170 | D10: 0.92 | E10: 5767.74 | F10: 9138249.2 | G10: 5767.74 | H10: 1.330857e+09 | I10: 0.0068664398 | J10: =1-I10 -> 0.99313356 | K10: 1330.857 | L10: 9.1382492 | M10: 42.056528 | N10: 21.94124 | O10: {=INDEX(water_abstraction_EU_EEA!$J$55:$J$4515, MATCH(1, (water_abstraction_EU_EEA!$F$55:$F$4515=$A10)*(water_abstraction_EU_EEA!$I$55:$I$4515=2018), 0))} -> 1306.6 | P10: {=INDEX(water_abstraction_EU_EEA!$J$55:$J$4515, MATCH(1, (water_abstraction_EU_EEA!$F$55:$F$4515=$A10)*(water_abstraction_EU_EEA!$I$55:$I$4515=2021), 0))} -> 681.7 | Q10: =O10*$J10 -> 1297.6283 | R10: =P10*$J10 -> 677.01915 | S10: =P10-R10 -> 4.680852 | T10: =O10/(1000*M10) -> 0.031067709 | U10: =P10/(1000*N10) -> 0.031069346 | V10: =Q10/(1000*M10) -> 0.030854385 | W10: =R10/(1000*N10) -> 0.030856011 | X10: =B10&"WPWR" -> EEWPWR | Y10: =ROUND(U10,5) -> 0.03107 | Z10: =B10&"WRUN" -> EEWRUN | AA10: =ROUND(W10,5) -> 0.03086
A11: Finland | B11: FI | C11: 8975.6 | D11: 0.82 | E11: 2561794.4 | F11: 35049678 | G11: 5.2148947e+08 | H11: 6.3332954e+09 | I11: 0.0055341928 | J11: =1-I11 -> 0.99446581 | K11: 6333.2954 | L11: 35.049678 | M11: 182.7072 | N11: 170.172 | O11: {=INDEX(water_abstraction_EU_EEA!$J$55:$J$4515, MATCH(1, (water_abstraction_EU_EEA!$F$55:$F$4515=$A11)*(water_abstraction_EU_EEA!$I$55:$I$4515=2018), 0))} -> 472.3 | P11: {=INDEX(water_abstraction_EU_EEA!$J$55:$J$4515, MATCH(1, (water_abstraction_EU_EEA!$F$55:$F$4515=$A11)*(water_abstraction_EU_EEA!$I$55:$I$4515=2021), 0))} -> 405.4 | Q11: =O11*$J11 -> 469.6862 | R11: =P11*$J11 -> 403.15644 | S11: =P11-R11 -> 2.2435617 | T11: =O11/(1000*M11) -> 0.0025850103 | U11: =P11/(1000*N11) -> 0.0023822956 | V11: =Q11/(1000*M11) -> 0.0025707044 | W11: =R11/(1000*N11) -> 0.0023691115 | X11: =B11&"WPWR" -> FIWPWR | Y11: =ROUND(U11,5) -> 0.00238 | Z11: =B11&"WRUN" -> FIWRUN | AA11: =ROUND(W11,5) -> 0.00237
A12: France | B12: FR | C12: 87125.9 | D12: 0.32 | E12: 6.9845234e+08 | F12: 1.0669693e+09 | G12: 1.1090787e+10 | H12: 1.1876136e+10 | I12: 0.089841447 | J12: =1-I12 -> 0.91015855 | K12: 11876.136 | L12: 1066.9693 | M12: 1693.8877 | N12: 1575.1115 | O12: {=INDEX(water_abstraction_EU_EEA!$J$55:$J$4515, MATCH(1, (water_abstraction_EU_EEA!$F$55:$F$4515=$A12)*(water_abstraction_EU_EEA!$I$55:$I$4515=2018), 0))} -> 16045.3 | P12: {=INDEX(water_abstraction_EU_EEA!$J$55:$J$4515, MATCH(1, (water_abstraction_EU_EEA!$F$55:$F$4515=$A12)*(water_abstraction_EU_EEA!$I$55:$I$4515=2021), 0))} -> 14368.4 | Q12: =O12*$J12 -> 14603.767 | R12: =P12*$J12 -> 13077.522 | S12: =P12-R12 -> 1290.8778 | T12: =O12/(1000*M12) -> 0.0094724699 | U12: =P12/(1000*N12) -> 0.0091221481 | V12: =Q12/(1000*M12) -> 0.0086214495 | W12: =R12/(1000*N12) -> 0.0083026011 | X12: =B12&"WPWR" -> FRWPWR | Y12: =ROUND(U12,5) -> 0.00912 | Z12: =B12&"WRUN" -> FRWRUN | AA12: =ROUND(W12,5) -> 0.0083
A13: Germany | B13: DE | C13: 95461.91 | D13: 0.06 | E13: 6.6758175e+08 | F13: 7.2567486e+08 | G13: 2.9603915e+09 | H13: 3.0443249e+09 | I13: 0.23836972 | J13: =1-I13 -> 0.76163028 | K13: 3044.3249 | L13: 725.67486 | M13: 1661.22 | N13: 1444.7455 | O13: {=INDEX(water_abstraction_EU_EEA!$J$55:$J$4515, MATCH(1, (water_abstraction_EU_EEA!$F$55:$F$4515=$A13)*(water_abstraction_EU_EEA!$I$55:$I$4515=2018), 0))} -> 9285.8 | P13: {=INDEX(water_abstraction_EU_EEA!$J$55:$J$4515, MATCH(1, (water_abstraction_EU_EEA!$F$55:$F$4515=$A13)*(water_abstraction_EU_EEA!$I$55:$I$4515=2021), 0))} -> 13321.6 | Q13: =O13*$J13 -> 7072.3465 | R13: =P13*$J13 -> 10146.134 | S13: =P13-R13 -> 3175.466 | T13: =O13/(1000*M13) -> 0.0055897473 | U13: =P13/(1000*N13) -> 0.0092207242 | V13: =Q13/(1000*M13) -> 0.0042573208 | W13: =R13/(1000*N13) -> 0.0070227828 | X13: =B13&"WPWR" -> DEWPWR | Y13: =ROUND(U13,5) -> 0.00922 | Z13: =B13&"WRUN" -> DEWRUN | AA13: =ROUND(W13,5) -> 0.00702
A14: Greece | B14: GR | C14: 12787.98 | D14: 0.53 | E14: 39192582 | F14: 46116852 | G14: 48026877 | H14: 6.5238789e+08 | I14: 0.070689313 | J14: =1-I14 -> 0.92931069 | K14: 652.38789 | L14: 46.116852 | M14: 134.6831 | N14: 118.87103 | O14: {=INDEX(water_abstraction_EU_EEA!$J$55:$J$4515, MATCH(1, (water_abstraction_EU_EEA!$F$55:$F$4515=$A14)*(water_abstraction_EU_EEA!$I$55:$I$4515=2018), 0))} -> 0 | P14: {=INDEX(water_abstraction_EU_EEA!$J$55:$J$4515, MATCH(1, (water_abstraction_EU_EEA!$F$55:$F$4515=$A14)*(water_abstraction_EU_EEA!$I$55:$I$4515=2021), 0))} -> 0 | Q14: =O14*$J14 -> 0 | R14: =P14*$J14 -> 0 | S14: =P14-R14 -> 0 | T14: =O14/(1000*M14) -> 0 | U14: 0.009705834 | V14: =Q14/(1000*M14) -> 0 | W14: 0.00870738 | X14: =B14&"WPWR" -> GRWPWR | Y14: =ROUND(U14,5) -> 0.00971 | Z14: =B14&"WRUN" -> GRWRUN | AA14: =ROUND(W14,5) -> 0.00871
A15: Hungary | B15: HU | C15: 4122.3 | D15: 0 | E15: 20737927 | F15: 20737927 | G15: 2.9369982e+08 | H15: 2.9369982e+08 | I15: 0.070609262 | J15: =1-I15 -> 0.92939074 | K15: 293.69982 | L15: 20.737927 | M15: 109.6488 | N15: 112.64868 | O15: {=INDEX(water_abstraction_EU_EEA!$J$55:$J$4515, MATCH(1, (water_abstraction_EU_EEA!$F$55:$F$4515=$A15)*(water_abstraction_EU_EEA!$I$55:$I$4515=2018), 0))} -> 3352.6 | P15: {=INDEX(water_abstraction_EU_EEA!$J$55:$J$4515, MATCH(1, (water_abstraction_EU_EEA!$F$55:$F$4515=$A15)*(water_abstraction_EU_EEA!$I$55:$I$4515=2021), 0))} -> 3586.7 | Q15: =O15*$J15 -> 3115.8754 | R15: =P15*$J15 -> 3333.4458 | S15: =P15-R15 -> 253.25424 | T15: =O15/(1000*M15) -> 0.030575802 | U15: =P15/(1000*N15) -> 0.031839698 | V15: =Q15/(1000*M15) -> 0.028416867 | W15: =R15/(1000*N15) -> 0.029591521 | X15: =B15&"WPWR" -> HUWPWR | Y15: =ROUND(U15,5) -> 0.03184 | Z15: =B15&"WRUN" -> HUWRUN | AA15: =ROUND(W15,5) -> 0.02959
A16: Ireland | B16: IE | C16: 6160 | D16: 0.9 | E16: 225237.29 | F16: 3338917.9 | G16: 312402.17 | H16: 6.0143871e+08 | I16: 0.0055515513 | J16: =1-I16 -> 0.99444845 | K16: 601.43871 | L16: 3.3389179 | M16: 77.564538 | N16: 75.485066 | O16: {=INDEX(water_abstraction_EU_EEA!$J$55:$J$4515, MATCH(1, (water_abstraction_EU_EEA!$F$55:$F$4515=$A16)*(water_abstraction_EU_EEA!$I$55:$I$4515=2018), 0))} -> 359.2 | P16: {=INDEX(water_abstraction_EU_EEA!$J$55:$J$4515, MATCH(1, (water_abstraction_EU_EEA!$F$55:$F$4515=$A16)*(water_abstraction_EU_EEA!$I$55:$I$4515=2021), 0))} -> 359.2 | Q16: =O16*$J16 -> 357.20588 | R16: =P16*$J16 -> 357.20588 | S16: =P16-R16 -> 1.9941172 | T16: =O16/(1000*M16) -> 0.0046309823 | U16: =P16/(1000*N16) -> 0.0047585571 | V16: =Q16/(1000*M16) -> 0.0046052731 | W16: =R16/(1000*N16) -> 0.0047321397 | X16: =B16&"WPWR" -> IEWPWR | Y16: =ROUND(U16,5) -> 0.00476 | Z16: =B16&"WRUN" -> IEWRUN | AA16: =ROUND(W16,5) -> 0.00473
A17: Italy | B17: IT | C17: 77799.1 | D17: 0.63 | E17: 24310220 | F17: 55811991 | G17: 1.4474336e+09 | H17: 3.6724707e+09 | I17: 0.015197396 | J17: =1-I17 -> 0.9848026 | K17: 3672.4707 | L17: 55.811991 | M17: 691.66377 | N17: 680.87606 | O17: {=INDEX(water_abstraction_EU_EEA!$J$55:$J$4515, MATCH(1, (water_abstraction_EU_EEA!$F$55:$F$4515=$A17)*(water_abstraction_EU_EEA!$I$55:$I$4515=2018), 0))} -> 0 | P17: {=INDEX(water_abstraction_EU_EEA!$J$55:$J$4515, MATCH(1, (water_abstraction_EU_EEA!$F$55:$F$4515=$A17)*(water_abstraction_EU_EEA!$I$55:$I$4515=2021), 0))} -> 4594.2 | Q17: =O17*$J17 -> 0 | R17: =P17*$J17 -> 4524.3801 | S17: =P17-R17 -> 69.819876 | T17: =O17/(1000*M17) -> 0 | U17: =P17/(1000*N17) -> 0.0067474835 | V17: =Q17/(1000*M17) -> 0 | W17: =R17/(1000*N17) -> 0.0066449393 | X17: =B17&"WPWR" -> ITWPWR | Y17: =ROUND(U17,5) -> 0.00675 | Z17: =B17&"WRUN" -> ITWRUN | AA17: =ROUND(W17,5) -> 0.00664
A18: Latvia | B18: LA | C18: 894 | D18: 1 | E18: 0 | F18: 4140867.9 | G18: 0 | H18: 5818242 | I18: 0.71170432 | J18: =1-I18 -> 0.28829568 | K18: 5.818242 | L18: 4.1408679 | M18: 15.011982 | N18: 10.764691 | O18: {=INDEX(water_abstraction_EU_EEA!$J$55:$J$4515, MATCH(1, (water_abstraction_EU_EEA!$F$55:$F$4515=$A18)*(water_abstraction_EU_EEA!$I$55:$I$4515=2018), 0))} -> 2.5 | P18: {=INDEX(water_abstraction_EU_EEA!$J$55:$J$4515, MATCH(1, (water_abstraction_EU_EEA!$F$55:$F$4515=$A18)*(water_abstraction_EU_EEA!$I$55:$I$4515=2021), 0))} -> 2.6 | Q18: =O18*$J18 -> 0.72073921 | R18: =P18*$J18 -> 0.74956878 | S18: =P18-R18 -> 1.8504312 | T18: =O18/(1000*M18) -> 0.00016653364 | U18: =P18/(1000*N18) -> 0.00024153038 | V18: =Q18/(1000*M18) -> 4.8010929e-05 | W18: =R18/(1000*N18) -> 6.9632167e-05 | X18: =B18&"WPWR" -> LAWPWR | Y18: =ROUND(U18,5) -> 0.00024 | Z18: =B18&"WRUN" -> LAWRUN | AA18: =ROUND(W18,5) -> 7e-05
A19: Lithuania | B19: LT | C19: 3063 | D19: 0.06 | E19: 12094164 | F19: 13713976 | G19: 7.9605667e+08 | H19: 7.9841579e+08 | I19: 0.017176484 | J19: =1-I19 -> 0.98282352 | K19: 798.41579 | L19: 13.713976 | M19: 3.92112 | N19: 8.06292 | O19: {=INDEX(water_abstraction_EU_EEA!$J$55:$J$4515, MATCH(1, (water_abstraction_EU_EEA!$F$55:$F$4515=$A19)*(water_abstraction_EU_EEA!$I$55:$I$4515=2018), 0))} -> 15.4 | P19: {=INDEX(water_abstraction_EU_EEA!$J$55:$J$4515, MATCH(1, (water_abstraction_EU_EEA!$F$55:$F$4515=$A19)*(water_abstraction_EU_EEA!$I$55:$I$4515=2021), 0))} -> 87.5 | Q19: =O19*$J19 -> 15.135482 | R19: =P19*$J19 -> 85.997058 | S19: =P19-R19 -> 1.5029423 | T19: =O19/(1000*M19) -> 0.0039274493 | U19: =P19/(1000*N19) -> 0.010852148 | V19: =Q19/(1000*M19) -> 0.0038599895 | W19: =R19/(1000*N19) -> 0.010665746 | X19: =B19&"WPWR" -> LTWPWR | Y19: =ROUND(U19,5) -> 0.01085 | Z19: =B19&"WRUN" -> LTWRUN | AA19: =ROUND(W19,5) -> 0.01067
A20: Luxembourg | B20: LU | C20: 376.4 | D20: 0 | E20: 9692.95 | F20: 9692.95 | G20: 9692.95 | H20: 9692.95 | I20: 1 | J20: =1-I20 -> 0 | K20: 0.00969295 | L20: 0.00969295 | M20: 1.76265 | N20: 2.2741776 | O20: {=INDEX(water_abstraction_EU_EEA!$J$55:$J$4515, MATCH(1, (water_abstraction_EU_EEA!$F$55:$F$4515=$A20)*(water_abstraction_EU_EEA!$I$55:$I$4515=2018), 0))} -> 0 | P20: {=INDEX(water_abstraction_EU_EEA!$J$55:$J$4515, MATCH(1, (water_abstraction_EU_EEA!$F$55:$F$4515=$A20)*(water_abstraction_EU_EEA!$I$55:$I$4515=2021), 0))} -> 0 | Q20: =O20*$J20 -> 0 | R20: =P20*$J20 -> 0 | S20: =P20-R20 -> 0 | T20: =O20/(1000*M20) -> 0 | U20: 0.009705834 | V20: =Q20/(1000*M20) -> 0 | W20: 0.00870738 | X20: =B20&"WPWR" -> LUWPWR | Y20: =ROUND(U20,5) -> 0.00971 | Z20: =B20&"WRUN" -> LUWRUN | AA20: =ROUND(W20,5) -> 0.00871
A21: Malta | B21: MT | C21: 452.8 | D21: 1 | E21: 0 | F21: 349499.67 | G21: 0 | H21: 49648347 | I21: 0.0070395026 | J21: =1-I21 -> 0.9929605 | K21: 49.648347 | L21: 0.34949967 | M21: 6.3807876 | N21: 7.0525836 | O21: {=INDEX(water_abstraction_EU_EEA!$J$55:$J$4515, MATCH(1, (water_abstraction_EU_EEA!$F$55:$F$4515=$A21)*(water_abstraction_EU_EEA!$I$55:$I$4515=2018), 0))} -> 0 | P21: {=INDEX(water_abstraction_EU_EEA!$J$55:$J$4515, MATCH(1, (water_abstraction_EU_EEA!$F$55:$F$4515=$A21)*(water_abstraction_EU_EEA!$I$55:$I$4515=2021), 0))} -> 0 | Q21: =O21*$J21 -> 0 | R21: =P21*$J21 -> 0 | S21: =P21-R21 -> 0 | T21: =O21/(1000*M21) -> 0 | U21: 0.009705834 | V21: =Q21/(1000*M21) -> 0 | W21: 0.00870738 | X21: =B21&"WPWR" -> MTWPWR | Y21: =ROUND(U21,5) -> 0.00971 | Z21: =B21&"WRUN" -> MTWRUN | AA21: =ROUND(W21,5) -> 0.00871
A22: Netherlands | B22: NL | C22: 26194.88 | D22: 0.81 | E22: 16600822 | F22: 63062636 | G22: 7.4583504e+08 | H22: 7.5910792e+09 | I22: 0.0083074665 | J22: =1-I22 -> 0.99169253 | K22: 7591.0792 | L22: 63.062636 | M22: 358.12729 | N22: 331.67912 | O22: {=INDEX(water_abstraction_EU_EEA!$J$55:$J$4515, MATCH(1, (water_abstraction_EU_EEA!$F$55:$F$4515=$A22)*(water_abstraction_EU_EEA!$I$55:$I$4515=2018), 0))} -> 3369.9 | P22: {=INDEX(water_abstraction_EU_EEA!$J$55:$J$4515, MATCH(1, (water_abstraction_EU_EEA!$F$55:$F$4515=$A22)*(water_abstraction_EU_EEA!$I$55:$I$4515=2021), 0))} -> 3183.3 | Q22: =O22*$J22 -> 3341.9047 | R22: =P22*$J22 -> 3156.8548 | S22: =P22-R22 -> 26.445158 | T22: =O22/(1000*M22) -> 0.0094097826 | U22: =P22/(1000*N22) -> 0.0095975292 | V22: =Q22/(1000*M22) -> 0.0093316112 | W22: =R22/(1000*N22) -> 0.009517798 | X22: =B22&"WPWR" -> NLWPWR | Y22: =ROUND(U22,5) -> 0.0096 | Z22: =B22&"WRUN" -> NLWRUN | AA22: =ROUND(W22,5) -> 0.00952
A23: Poland | B23: PL | C23: 30588.2 | D23: 0.01 | E23: 2.055814e+08 | F23: 2.068407e+08 | G23: 3.449279e+09 | H23: 3.5492217e+09 | I23: 0.058277764 | J23: =1-I23 -> 0.94172224 | K23: 3549.2217 | L23: 206.8407 | M23: 555.94044 | N23: 562.60272 | O23: {=INDEX(water_abstraction_EU_EEA!$J$55:$J$4515, MATCH(1, (water_abstraction_EU_EEA!$F$55:$F$4515=$A23)*(water_abstraction_EU_EEA!$I$55:$I$4515=2018), 0))} -> 5741.1 | P23: {=INDEX(water_abstraction_EU_EEA!$J$55:$J$4515, MATCH(1, (water_abstraction_EU_EEA!$F$55:$F$4515=$A23)*(water_abstraction_EU_EEA!$I$55:$I$4515=2021), 0))} -> 5216 | Q23: =O23*$J23 -> 5406.5215 | R23: =P23*$J23 -> 4912.0232 | S23: =P23-R23 -> 303.97681 | T23: =O23/(1000*M23) -> 0.010326826 | U23: =P23/(1000*N23) -> 0.0092711958 | V23: =Q23/(1000*M23) -> 0.0097250013 | W23: =R23/(1000*N23) -> 0.0087308912 | X23: =B23&"WPWR" -> PLWPWR | Y23: =ROUND(U23,5) -> 0.00927 | Z23: =B23&"WRUN" -> PLWRUN | AA23: =ROUND(W23,5) -> 0.00873
A24: Portugal | B24: PT | C24: 6707.21 | D24: 0.78 | E24: 10611165 | F24: 32221285 | G24: 13040957 | H24: 39823465 | I24: 0.80910301 | J24: =1-I24 -> 0.19089699 | K24: 39.823465 | L24: 32.221285 | M24: 115.75784 | N24: 78.816978 | O24: {=INDEX(water_abstraction_EU_EEA!$J$55:$J$4515, MATCH(1, (water_abstraction_EU_EEA!$F$55:$F$4515=$A24)*(water_abstraction_EU_EEA!$I$55:$I$4515=2018), 0))} -> 835.8 | P24: {=INDEX(water_abstraction_EU_EEA!$J$55:$J$4515, MATCH(1, (water_abstraction_EU_EEA!$F$55:$F$4515=$A24)*(water_abstraction_EU_EEA!$I$55:$I$4515=2021), 0))} -> 786.9 | Q24: =O24*$J24 -> 159.55171 | R24: =P24*$J24 -> 150.21684 | S24: =P24-R24 -> 636.68316 | T24: =O24/(1000*M24) -> 0.0072202454 | U24: =P24/(1000*N24) -> 0.0099838895 | V24: =Q24/(1000*M24) -> 0.0013783231 | W24: =R24/(1000*N24) -> 0.0019058945 | X24: =B24&"WPWR" -> PTWPWR | Y24: =ROUND(U24,5) -> 0.00998 | Z24: =B24&"WRUN" -> PTWRUN | AA24: =ROUND(W24,5) -> 0.00191
A25: Romania | B25: RO | C25: 12162.75 | D25: 0.01 | E25: 77961483 | F25: 78125427 | G25: 2.0067747e+09 | H25: 2.0306832e+09 | I25: 0.038472484 | J25: =1-I25 -> 0.96152752 | K25: 2030.6832 | L25: 78.125427 | M25: 139.26928 | N25: 120.40688 | O25: {=INDEX(water_abstraction_EU_EEA!$J$55:$J$4515, MATCH(1, (water_abstraction_EU_EEA!$F$55:$F$4515=$A25)*(water_abstraction_EU_EEA!$I$55:$I$4515=2018), 0))} -> 681.3 | P25: {=INDEX(water_abstraction_EU_EEA!$J$55:$J$4515, MATCH(1, (water_abstraction_EU_EEA!$F$55:$F$4515=$A25)*(water_abstraction_EU_EEA!$I$55:$I$4515=2021), 0))} -> 566 | Q25: =O25*$J25 -> 655.0887 | R25: =P25*$J25 -> 544.22457 | S25: =P25-R25 -> 21.775426 | T25: =O25/(1000*M25) -> 0.0048919617 | U25: =P25/(1000*N25) -> 0.004700728 | V25: =Q25/(1000*M25) -> 0.0047037558 | W25: =R25/(1000*N25) -> 0.0045198793 | X25: =B25&"WPWR" -> ROWPWR | Y25: =ROUND(U25,5) -> 0.0047 | Z25: =B25&"WRUN" -> ROWRUN | AA25: =ROUND(W25,5) -> 0.00452
A26: Slovakia | B26: SK | C26: 4140.91 | D26: 0 | E26: 47607037 | F26: 47607037 | G26: 1.2545167e+08 | H26: 1.2545167e+08 | I26: 0.37948507 | J26: =1-I26 -> 0.62051493 | K26: 125.45167 | L26: 47.607037 | M26: 80.586 | N26: 89.0244 | O26: {=INDEX(water_abstraction_EU_EEA!$J$55:$J$4515, MATCH(1, (water_abstraction_EU_EEA!$F$55:$F$4515=$A26)*(water_abstraction_EU_EEA!$I$55:$I$4515=2018), 0))} -> 57.2 | P26: {=INDEX(water_abstraction_EU_EEA!$J$55:$J$4515, MATCH(1, (water_abstraction_EU_EEA!$F$55:$F$4515=$A26)*(water_abstraction_EU_EEA!$I$55:$I$4515=2021), 0))} -> 50.4 | Q26: =O26*$J26 -> 35.493454 | R26: =P26*$J26 -> 31.273953 | S26: =P26-R26 -> 19.126047 | T26: =O26/(1000*M26) -> 0.00070980071 | U26: =P26/(1000*N26) -> 0.00056613692 | V26: =Q26/(1000*M26) -> 0.00044044194 | W26: =R26/(1000*N26) -> 0.00035129642 | X26: =B26&"WPWR" -> SKWPWR | Y26: =ROUND(U26,5) -> 0.00057 | Z26: =B26&"WRUN" -> SKWRUN | AA26: =ROUND(W26,5) -> 0.00035
A27: Slovenia | B27: SI | C27: 1938 | D27: 0 | E27: 22523114 | F27: 22523114 | G27: 1.4336859e+08 | H27: 1.4336859e+08 | I27: 0.15709936 | J27: =1-I27 -> 0.84290064 | K27: 143.36859 | L27: 22.523114 | M27: 40.222656 | N27: 37.516136 | O27: {=INDEX(water_abstraction_EU_EEA!$J$55:$J$4515, MATCH(1, (water_abstraction_EU_EEA!$F$55:$F$4515=$A27)*(water_abstraction_EU_EEA!$I$55:$I$4515=2018), 0))} -> 742.3 | P27: {=INDEX(water_abstraction_EU_EEA!$J$55:$J$4515, MATCH(1, (water_abstraction_EU_EEA!$F$55:$F$4515=$A27)*(water_abstraction_EU_EEA!$I$55:$I$4515=2021), 0))} -> 717.1 | Q27: =O27*$J27 -> 625.68514 | R27: =P27*$J27 -> 604.44405 | S27: =P27-R27 -> 112.65595 | T27: =O27/(1000*M27) -> 0.018454773 | U27: =P27/(1000*N27) -> 0.019114442 | V27: =Q27/(1000*M27) -> 0.01555554 | W27: =R27/(1000*N27) -> 0.016111575 | X27: =B27&"WPWR" -> SIWPWR | Y27: =ROUND(U27,5) -> 0.01911 | Z27: =B27&"WRUN" -> SIWRUN | AA27: =ROUND(W27,5) -> 0.01611
A28: Spain | B28: ES | C28: 51735.54 | D28: 0.55 | E28: 2.1485488e+08 | F28: 321553527 | G28: 3.2570807e+09 | H28: 4.0477533e+09 | I28: 0.079440002 | J28: =1-I28 -> 0.92056 | K28: 4047.7533 | L28: 321.55353 | M28: 626.094 | N28: 547.2252 | O28: {=INDEX(water_abstraction_EU_EEA!$J$55:$J$4515, MATCH(1, (water_abstraction_EU_EEA!$F$55:$F$4515=$A28)*(water_abstraction_EU_EEA!$I$55:$I$4515=2018), 0))} -> 5450 | P28: {=INDEX(water_abstraction_EU_EEA!$J$55:$J$4515, MATCH(1, (water_abstraction_EU_EEA!$F$55:$F$4515=$A28)*(water_abstraction_EU_EEA!$I$55:$I$4515=2021), 0))} -> 4682.7 | Q28: =O28*$J28 -> 5017.052 | R28: =P28*$J28 -> 4310.7063 | S28: =P28-R28 -> 371.9937 | T28: =O28/(1000*M28) -> 0.0087047632 | U28: =P28/(1000*N28) -> 0.0085571717 | V28: =Q28/(1000*M28) -> 0.0080132568 | W28: =R28/(1000*N28) -> 0.00787739 | X28: =B28&"WPWR" -> ESWPWR | Y28: =ROUND(U28,5) -> 0.00856 | Z28: =B28&"WRUN" -> ESWRUN | AA28: =ROUND(W28,5) -> 0.00788
A29: Sweden | B29: SE | C29: 14115.77 | D29: 0.98 | E29: 378909.91 | F29: 68701421 | G29: 89680441 | H29: 1.1408101e+10 | I29: 0.0060221609 | J29: =1-I29 -> 0.99397784 | K29: 11408.101 | L29: 68.701421 | M29: 302.832 | N29: 248.7672 | O29: {=INDEX(water_abstraction_EU_EEA!$J$55:$J$4515, MATCH(1, (water_abstraction_EU_EEA!$F$55:$F$4515=$A29)*(water_abstraction_EU_EEA!$I$55:$I$4515=2018), 0))} -> 81.8 | P29: {=INDEX(water_abstraction_EU_EEA!$J$55:$J$4515, MATCH(1, (water_abstraction_EU_EEA!$F$55:$F$4515=$A29)*(water_abstraction_EU_EEA!$I$55:$I$4515=2021), 0))} -> 113.4 | Q29: =O29*$J29 -> 81.307387 | R29: =P29*$J29 -> 112.71709 | S29: =P29-R29 -> 0.68291305 | T29: =O29/(1000*M29) -> 0.00027011676 | U29: =P29/(1000*N29) -> 0.00045584788 | V29: =Q29/(1000*M29) -> 0.00026849008 | W29: =R29/(1000*N29) -> 0.00045310269 | X29: =B29&"WPWR" -> SEWPWR | Y29: =ROUND(U29,5) -> 0.00046 | Z29: =B29&"WRUN" -> SEWRUN | AA29: =ROUND(W29,5) -> 0.00045

Sheet Sheet2
A1: Country | B1: Thermal electricity generation (PJ) | C1: Water withdrawal (MCM) | D1: Wate consumption (MCM) | E1: country | F1: ratio
A2: Austria | B2: 67.240764 | C2: 1495.1 | E2: =A2 -> Austria | F2: =C2/B2 -> 22.235024
A3: Belgium | B3: 291.61188 | C3: 2256.5 | E3: =A3 -> Belgium | F3: =C3/B3 -> 7.7380249
A4: Bulgaria | B4: 142.4358 | C4: 3471.7 | E4: =A4 -> Bulgaria | F4: =C4/B4 -> 24.373787
A5: Croatia | B5: 20.45268 | C5: 167.3 | E5: =A5 -> Croatia | F5: =C5/B5 -> 8.1798571
A6: Cyprus | B6: 15.856585 | C6: 14.8 | E6: =A6 -> Cyprus | F6: =C6/B6 -> 0.93336616
A7: Czechia | B7: 282.26907 | C7: 264.5 | E7: =A7 -> Czechia | F7: =C7/B7 -> 0.93704919
A8: Denmark | B8: 56.415366 | C8: 3.5 | E8: =A8 -> Denmark | F8: =C8/B8 -> 0.062039835
A9: Estonia | B9: 21.94124 | C9: 681.7 | E9: =A9 -> Estonia | F9: =C9/B9 -> 31.069346
A10: Finland | B10: 170.172 | C10: 405.4 | E10: =A10 -> Finland | F10: =C10/B10 -> 2.3822956
A11: France | B11: 1575.1115 | C11: 14368.4 | E11: =A11 -> France | F11: =C11/B11 -> 9.1221481
A12: Germany | B12: 1444.7455 | C12: 13321.6 | E12: =A12 -> Germany | F12: =C12/B12 -> 9.2207242
A13: Greece | B13: 118.87103 | C13: 0 | E13: =A13 -> Greece | F13: =C13/B13 -> 0
... A28: Sweden | B28: 248.7672 | C28: 113.4 | E28: =A28 -> Sweden | F28: =C28/B28 -> 0.45584788

Sheet Country code
A1: Country | B1: ISO2
A2: Austria | B2: AT
A3: Belgium | B3: BE
A4: Bulgaria | B4: BG
A5: Cyprus | B5: CY
A6: Czechia | B6: CZ
A7: Germany | B7: DE
A8: Denmark | B8: DK
A9: Spain | B9: ES
A10: Estonia | B10: EE
A11: Finland | B11: FI
A12: France | B12: FR
... A29: Europe | B29: EU

Sheet Water consumption per river
A1: River Name | B1: Main Final Country | C1: Ocean | D1: Continent | E1: Annual Water Consumption of Power Generation Facilities (median values), [m3]
E2: 2015 | F2: 2020 | G2: 2025 | H2: 2030 | I2: 2035 | J2: 2040 | K2: 2045 | L2: 2050
A3: Alabama | B3: United States | C3: Atlantic | D3: Americas | E3: 28085161 | F3: 6542770 | G3: 2050368 | H3: 1415845 | I3: 473460 | J3: 0 | K3: 0 | L3: 0
A4: Aldan | B4: Russia | C4: Arctic | D4: Europe | E4: 59688 | F4: 0 | G4: 0 | H4: 0 | I4: 0 | J4: 0 | K4: 0 | L4: 0
A5: Allegheny | B5: United States | C5: Atlantic | D5: Americas | E5: 6365046 | F5: 7452612 | G5: 4006870 | H5: 2600404 | I5: 1003172 | J5: 0 | K5: 0 | L5: 0
A6: Allier | B6: France | C6: Atlantic | D6: Europe | E6: 3788 | F6: 13 | G6: 694 | H6: 4166 | I6: 4991 | J6: 4998 | K6: 0 | L6: 0
A7: Altamaha | B7: United States | C7: Atlantic | D7: Americas | E7: 37237091 | F7: 0 | G7: 0 | H7: 0 | I7: 0 | J7: 0 | K7: 0 | L7: 0
A8: Amazonas | B8: Brazil | C8: Atlantic | D8: Americas | E8: 2875449 | F8: 0 | G8: 0 | H8: 0 | I8: 0 | J8: 0 | K8: 0 | L8: 0
A9: Amu Darya | B9: Uzbekistan | C9: Inland Sea | D9: Asia-Pacific | E9: 9997466 | F9: 0 | G9: 0 | H9: 0 | I9: 0 | J9: 0 | K9: 0 | L9: 0
A10: Amur | B10: Russia | C10: Pacific | D10: Europe | E10: 8033484 | F10: 5543220 | G10: 0 | H10: 0 | I10: 0 | J10: 0 | K10: 0 | L10: 0
A11: Angara | B11: Russia | C11: Arctic | D11: Europe | E11: 15009186 | F11: 5446431 | G11: 93143 | H11: 12032 | I11: 18482 | J11: 30579 | K11: 28900 | L11: 0
A12: Arkansas | B12: United States | C12: Atlantic | D12: Americas | E12: 77779377 | F12: 33568191 | G12: 439753 | H12: 488064 | I12: 472961 | J12: 240826 | K12: 523384 | L12: 0
A13: Assiniboine | B13: Canada | C13: Arctic | D13: Americas | E13: 2899138 | F13: 263807 | G13: 293064 | H13: 288409 | I13: 292369 | J13: 0 | K13: 0 | L13: 0
A14: Athabasca | B14: Canada | C14: Arctic | D14: Americas | E14: 2867106 | F14: 481499 | G14: 534898 | H14: 526403 | I14: 374121 | J14: 61688 | K14: 0 | L14: 0
... A353: Zhang | B353: China | C353: Pacific | D353: Asia-Pacific | E353: 4325083 | F353: 718371 | G353: 64250 | H353: 34758 | I353: 11903 | J353: 5410 | K353: 1 | L353: 0

Sheet Water withdrawal per river
A1: River Name | B1: Main Final Country | C1: Ocean | D1: Continent | E1: Annual Water Withdrawal of Power Generation Facilities (median values), [m3]
E2: 2015 | F2: 2020 | G2: 2025 | H2: 2030 | I2: 2035 | J2: 2040 | K2: 2045 | L2: 2050
A3: Alabama | B3: United States | C3: Atlantic | D3: Americas | E3: 1483557666 | F3: 140854268 | G3: 50954183 | H3: 35187693 | I3: 588938 | J3: 0 | K3: 0 | L3: 0
A4: Aldan | B4: Russia | C4: Arctic | D4: Europe | E4: 8704550 | F4: 0 | G4: 0 | H4: 0 | I4: 0 | J4: 0 | K4: 0 | L4: 0
A5: Allegheny | B5: United States | C5: Atlantic | D5: Americas | E5: 321116636 | F5: 9446192 | G5: 5040699 | H5: 3274492 | I5: 1235929 | J5: 0 | K5: 0 | L5: 0
A6: Allier | B6: France | C6: Atlantic | D6: Europe | E6: 3788 | F6: 13 | G6: 694 | H6: 4166 | I6: 4991 | J6: 4998 | K6: 0 | L6: 0
A7: Altamaha | B7: United States | C7: Atlantic | D7: Americas | E7: 61008984 | F7: 0 | G7: 0 | H7: 0 | I7: 0 | J7: 0 | K7: 0 | L7: 0
A8: Amazonas | B8: Brazil | C8: Atlantic | D8: Americas | E8: 84054364 | F8: 0 | G8: 0 | H8: 0 | I8: 0 | J8: 0 | K8: 0 | L8: 0
A9: Amu Darya | B9: Uzbekistan | C9: Inland Sea | D9: Asia-Pacific | E9: 14560474 | F9: 0 | G9: 0 | H9: 0 | I9: 0 | J9: 0 | K9: 0 | L9: 0
A10: Amur | B10: Russia | C10: Pacific | D10: Europe | E10: 123811434 | F10: 6793049 | G10: 0 | H10: 0 | I10: 0 | J10: 0 | K10: 0 | L10: 0
A11: Angara | B11: Russia | C11: Arctic | D11: Europe | E11: 398858781 | F11: 6674437 | G11: 114144 | H11: 14745 | I11: 22649 | J11: 37474 | K11: 35416 | L11: 0
A12: Arkansas | B12: United States | C12: Atlantic | D12: Americas | E12: 661266370 | F12: 41908789 | G12: 582731 | H12: 643457 | I12: 625166 | J12: 340567 | K12: 740121 | L12: 0
A13: Assiniboine | B13: Canada | C13: Arctic | D13: Americas | E13: 3856439 | F13: 384213 | G13: 426823 | H13: 420044 | I13: 425810 | J13: 0 | K13: 0 | L13: 0
A14: Athabasca | B14: Canada | C14: Arctic | D14: Americas | E14: 5823938 | F14: 661149 | G14: 734471 | H14: 722806 | I14: 534374 | J14: 76656 | K14: 0 | L14: 0
... A353: Zhang | B353: China | C353: Pacific | D353: Asia-Pacific | E353: 5292183 | F353: 879000 | G353: 78617 | H353: 42530 | I353: 14564 | J353: 6619 | K353: 1 | L353: 0

Sheet Water demand per river-info
A1: The tables show the development of annual water consumption by power plants from 351 major global rivers. The presented results are the median values of the outcomes of the ‘Best Policies Scenario’ applied for the river-level, and are presented for 5-year intervals. On the river-level, it is expected that the vast majority of new gas-fired power plant capacities installed during the transition period will be seawater-cooled. For that reason, no specific water consumption or water withdrawals by power plants is expected in the year 2050 if the ‘Best Policies Scenario’ will be fully implemented. According to the ‘Best Policies Scenario’ estimation, the amount of gas-fired thermal power plants projected for commissioning is expected to be negligible, this assumption will be of high importance for the coastal regions with high freshwater scarcity, such as, for instance, Pakistan and India. The category ‘Main final country’ defines the country which in 2015 used the largest amount of water from the specific river for cooling purposes in the power generation processes. The category ‘Continent’ describes the geographical location of the river (Africa, Americas, Asia-Pacific or Europe). The category ‘Ocean’ describes the large body of water which the specific river belongs to. The subcategory ‘Inland sea’ in the category ‘Ocean’ describes the situation when the river does not reach the ocean by any means. The red color is used to highlight ten world rivers facing the highest projected water consumption for the specific time periods.

Sheet Sensitivity of country cons.
A1: Algeria | B1: Min | C1: Min-Estimate | D1: Estimate | E1: P_Estimate | F1: Estimate-Q1 | G1: Q1 | H1: Q1-Q3 | I1: Q3 | J1: Q3-Max | K1: Max
B2: 6,73E+06 | C2: 0,00 % | D2: 6,73E+06 | E2: 88,57 % | F2: 0,00 % | G2: 6,73E+06 | H2: 0,00 % | I2: 1,13E+07 | J2: 11,43 % | K2: 1,13E+07
A3: Argentina | B3: Min | C3: Min-Estimate | D3: Estimate | E3: P_Estimate | F3: Estimate-Q1 | G3: Q1 | H3: Q1-Q3 | I3: Q3 | J3: Q3-Max | K3: Max
B4: 1,39E+08 | C4: 0,00 % | D4: 1,39E+08 | E4: 100,00 % | F4: 0,00 % | G4: 1,39E+08 | H4: 0,00 % | I4: 1,39E+08 | J4: 0,00 % | K4: 1,39E+08
A5: Australia | B5: Min | C5: Min-Q1 | D5: Q1 | E5: Q1-Estimate | F5: Estimate | G5: P_Estimate | H5: Estimate-Q3 | I5: Q3 | J5: Q3-Max | K5: Max
B6: 3,71E+08 | C6: 2,30 % | D6: 3,73E+08 | E6: 36,18 % | F6: 3,78E+08 | G6: 47,70 % | H6: 0,00 % | I6: 3,78E+08 | J6: 13,82 % | K6: 3,81E+08
A7: Austria | B7: Min | C7: Min-Estimate | D7: Estimate | E7: P_Estimate | F7: Estimate-Q1 | G7: Q1 | H7: Q1-Q3 | I7: Q3 | J7: Q3-Max | K7: Max
B8: 2,37E+07 | C8: 0,00 % | D8: 2,37E+07 | E8: 42,86 % | F8: 0,00 % | G8: 2,40E+07 | H8: 14,29 % | I8: 2,54E+07 | J8: 42,86 % | K8: 2,55E+07
A9: Belgium | B9: Min | C9: Min-Estimate | D9: Estimate | E9: P_Estimate | F9: Estimate-Q1 | G9: Q1 | H9: Q1-Q3 | I9: Q3 | J9: Q3-Max | K9: Max
B10: 1,16E+08 | C10: 0,00 % | D10: 1,16E+08 | E10: 100,00 % | F10: 0,00 % | G10: 1,16E+08 | H10: 0,00 % | I10: 1,16E+08 | J10: 0,00 % | K10: 1,16E+08
A11: Brazil | B11: Min | C11: Min-Q1 | D11: Q1 | E11: Q1-Estimate | F11: Estimate | G11: P_Estimate | H11: Estimate-Q3 | I11: Q3 | J11: Q3-Max | K11: Max
B12: 1,26E+08 | C12: 53,07 % | D12: 1,29E+08 | E12: 9,43 % | F12: 1,31E+08 | G12: 17,11 % | H12: 6,58 % | I12: 1,31E+08 | J12: 13,82 % | K12: 1,39E+08
A13: Bulgaria | B13: Min | C13: Min-Q1 | D13: Q1 | E13: Q1-Q3 | F13: Q3 | G13: Q3-Estimate | H13: Estimate | I13: P_Estimate | J13: Estimate-Max | K13: Max
B14: 5,31E+07 | C14: 0,00 % | D14: 5,31E+07 | E14: 8,33 % | F14: 5,93E+07 | G14: 0,00 % | H14: 5,93E+07 | I14: 91,67 % | J14: 0,00 % | K14: 5,93E+07
A15: Canada | B15: Min | C15: Min-Q1 | D15: Q1 | E15: Q1-Estimate | F15: Estimate | G15: P_Estimate | H15: Estimate-Q3 | I15: Q3 | J15: Q3-Max | K15: Max
B16: 1,83E+08 | C16: 17,62 % | D16: 1,86E+08 | E16: 10,71 % | F16: 1,87E+08 | G16: 24,07 % | H16: 38,35 % | I16: 2,00E+08 | J16: 9,24 % | K16: 2,15E+08
A17: Chile | B17: Min | C17: Min-Q1 | D17: Q1 | E17: Q1-Estimate | F17: Estimate | G17: P_Estimate | H17: Estimate-Q3 | I17: Q3 | J17: Q3-Max | K17: Max
B18: 2,44E+07 | C18: 52,26 % | D18: 2,49E+07 | E18: 6,04 % | F18: 2,51E+07 | G18: 12,07 % | H18: 21,06 % | I18: 2,57E+07 | J18: 8,57 % | K18: 2,63E+07
A19: China | B19: Min | C19: Min-Q1 | D19: Q1 | E19: Q1-Estimate | F19: Estimate | G19: P_Estimate | H19: Estimate-Q3 | I19: Q3 | J19: Q3-Max | K19: Max
B20: 4,78E+09 | C20: 6,22 % | D20: 5,05E+09 | E20: 14,41 % | F20: 6,35E+09 | G20: 32,08 % | H20: 14,21 % | I20: 6,38E+09 | J20: 33,08 % | K20: 7,40E+09
A21: Colombia | B21: Min | C21: Min-Q1 | D21: Q1 | E21: Q1-Q3 | F21: Q3 | G21: Q3-Estimate | H21: Estimate | I21: P_Estimate | J21: Estimate-Max | K21: Max
B22: 2,29E+07 | C22: 0,00 % | D22: 2,29E+07 | E22: 33,33 % | F22: 2,53E+07 | G22: 0,00E+00 | H22: 2,53E+07 | I22: 66,67 % | J22: 0,00E+00 | K22: 2,53E+07
A23: Czech Republic | B23: Min | C23: Min-Q1 | D23: Q1 | E23: Q1-Estimate | F23: Estimate | G23: P_Estimate | H23: Estimate-Q3 | I23: Q3 | J23: Q3-Max | K23: Max
B24: 1,38E+08 | C24: 3,03 % | D24: 1,39E+08 | E24: 4,24 % | F24: 1,42E+08 | G24: 18,18 % | H24: 18,79 % | I24: 1,43E+08 | J24: 55,76 % | K24: 1,46E+08
A25: Denmark | B25: Min | C25: Min-Q1 | D25: Q1 | E25: Q1-Q3 | F25: Q3 | G25: Q3-Estimate | H25: Estimate | I25: P_Estimate | J25: Estimate-Max | K25: Max
B26: 4,90E+06 | C26: 0,00 % | D26: 4,90E+06 | E26: 20,00 % | F26: 4,92E+06 | G26: 0,00 % | H26: 4,92E+06 | I26: 80,00 % | J26: 0,00 % | K26: 4,92E+06
A27: Egypt | B27: Min | C27: Min-Q1 | D27: Q1 | E27: Q1-Estimate | F27: Estimate | G27: P_Estimate | H27: Estimate-Q3 | I27: Q3 | J27: Q3-Max | K27: Max
B28: 1,10E+08 | C28: 22,22 % | D28: 1,11E+08 | E28: 17,78 % | F28: 1,11E+08 | G28: 51,11 % | H28: 0,00 % | I28: 1,11E+08 | J28: 8,89 % | K28: 1,12E+08
A29: Finland | B29: Min | C29: Min-Estimate | D29: Estimate | E29: P_Estimate | F29: Estimate-Q1 | G29: Q1 | H29: Q1-Q3 | I29: Q3 | J29: Q3-Max | K29: Max
B30: 3,50E+07 | C30: 0,00 % | D30: 3,50E+07 | E30: 100,00 % | F30: 0,00E+00 | G30: 3,50E+07 | H30: 0,00E+00 | I30: 3,50E+07 | J30: 0,00 % | K30: 3,50E+07
A31: France | B31: Min | C31: Min-Estimate | D31: Estimate | E31: P_Estimate | F31: Estimate-Q1 | G31: Q1 | H31: Q1-Q3 | I31: Q3 | J31: Q3-Max | K31: Max
B32: 1,07E+09 | C32: 0,00 % | D32: 1,07E+09 | E32: 18,37 % | F32: 15,31 % | G32: 1,07E+09 | H32: 58,16 % | I32: 1,07E+09 | J32: 8,16 % | K32: 1,08E+09
A33: Germany | B33: Min | C33: Min-Q1 | D33: Q1 | E33: Q1-Estimate | F33: Estimate | G33: P_Estimate | H33: Estimate-Q3 | I33: Q3 | J33: Q3-Max | K33: Max
B34: 7,22E+08 | C34: 10,40 % | D34: 7,25E+08 | E34: 35,60 % | F34: 7,26E+08 | G34: 24,00 % | H34: 0,00 % | I34: 7,26E+08 | J34: 30,00 % | K34: 7,30E+08
A35: Greece | B35: Min | C35: Min-Estimate | D35: Estimate | E35: P_Estimate | F35: Estimate-Q1 | G35: Q1 | H35: Q1-Q3 | I35: Q3 | J35: Q3-Max | K35: Max
B36: 4,61E+07 | C36: 0,00 % | D36: 4,61E+07 | E36: 100,00 % | F36: 0,00 % | G36: 4,61E+07 | H36: 0,00 % | I36: 4,61E+07 | J36: 0,00 % | K36: 4,61E+07
A37: India | B37: Min | C37: Min-Estimate | D37: Estimate | E37: P_Estimate | F37: Estimate-Q1 | G37: Q1 | H37: Q1-Q3 | I37: Q3 | J37: Q3-Max | K37: Max
B38: 2,00E+09 | C38: 0,00 % | D38: 2,00E+09 | E38: 100,00 % | F38: 0,00 % | G38: 2,00E+09 | H38: 0,00 % | I38: 2,00E+09 | J38: 0,00 % | K38: 2,00E+09
A39: Indonesia | B39: Min | C39: Min-Q1 | D39: Q1 | E39: Q1-Estimate | F39: Estimate | G39: P_Estimate | H39: Estimate-Q3 | I39: Q3 | J39: Q3-Max | K39: Max
B40: 1,39E+08 | C40: 4,17 % | D40: 1,42E+08 | E40: 0,00 % | F40: 1,49E+08 | G40: 50,00 % | H40: 0,00 % | I40: 1,73E+08 | J40: 45,83 % | K40: 1,81E+08
...

Sheet Sensitivity of country withd.
A1: Algeria | B1: Min | C1: Min-Estimate | D1: Estimate | E1: P_Estimate | F1: Estimate-Q1 | G1: Q1 | H1: Q1-Q3 | I1: Q3 | J1: Q3-Max | K1: Max
B2: 8,31E+06 | C2: 0,00 % | D2: 8,31E+06 | E2: 88,57 % | F2: 0,00 % | G2: 8,31E+06 | H2: 0,00 % | I2: 1,41E+07 | J2: 11,43 % | K2: 1,41E+07
A3: Argentina | B3: Min | C3: Min-Estimate | D3: Estimate | E3: P_Estimate | F3: Estimate-Q1 | G3: Q1 | H3: Q1-Q3 | I3: Q3 | J3: Q3-Max | K3: Max
B4: 3,12E+09 | C4: 0,00 % | D4: 3,12E+09 | E4: 100,00 % | F4: 0,00 % | G4: 3,12E+09 | H4: 0,00 % | I4: 3,12E+09 | J4: 0,00 % | K4: 3,12E+09
A5: Australia | B5: Min | C5: Min-Estimate | D5: Estimate | E5: P_Estimate | F5: Estimate-Q1 | G5: Q1 | H5: Q1-Q3 | I5: Q3 | J5: Q3-Max | K5: Max
B6: 2,48E+09 | C6: 20,39 % | D6: 2,49E+09 | E6: 47,70 % | F6: 0,00 % | G6: 2,49E+09 | H6: 25,33 % | I6: 2,75E+09 | J6: 6,58 % | K6: 2,86E+09
A7: Austria | B7: Min | C7: Min-Q1 | D7: Q1 | E7: Q1-Estimate | F7: Estimate | G7: P_Estimate | H7: Estimate-Q3 | I7: Q3 | J7: Q3-Max | K7: Max
B8: 9,81E+08 | C8: 14,29 % | D8: 1,02E+09 | E8: 28,57 % | F8: 1,12E+09 | G8: 42,86 % | H8: 0,00 % | I8: 1,27E+09 | J8: 14,29 % | K8: 1,42E+09
A9: Belgium | B9: Min | C9: Min-Estimate | D9: Estimate | E9: P_Estimate | F9: Estimate-Q1 | G9: Q1 | H9: Q1-Q3 | I9: Q3 | J9: Q3-Max | K9: Max
B10: 2,46E+08 | C10: 0,00 % | D10: 2,46E+08 | E10: 100,00 % | F10: 0,00 % | G10: 2,46E+08 | H10: 0,00 % | I10: 2,46E+08 | J10: 0,00 % | K10: 2,46E+08
A11: Brazil | B11: Min | C11: Min-Estimate | D11: Estimate | E11: P_Estimate | F11: Estimate-Q1 | G11: Q1 | H11: Q1-Q3 | I11: Q3 | J11: Q3-Max | K11: Max
B12: 3,71E+09 | C12: 46,05 % | D12: 3,71E+09 | E12: 17,11 % | F12: 0,00 % | G12: 3,72E+09 | H12: 28,73 % | I12: 3,77E+09 | J12: 8,11 % | K12: 3,84E+09
A13: Bulgaria | B13: Min | C13: Min-Estimate | D13: Estimate | E13: P_Estimate | F13: Estimate-Q1 | G13: Q1 | H13: Q1-Q3 | I13: Q3 | J13: Q3-Max | K13: Max
B14: 2,85E+09 | C14: 0,00 % | D14: 2,85E+09 | E14: 91,67 % | F14: 0,00 % | G14: 2,85E+09 | H14: 0,00 % | I14: 3,29E+09 | J14: 8,33 % | K14: 3,29E+09
A15: Canada | B15: Min | C15: Min-Q1 | D15: Q1 | E15: Q1-Q3 | F15: Q3 | G15: Q3-Estimate | H15: Estimate | I15: P_Estimate | J15: Estimate-Max | K15: Max
B16: 2,28E+10 | C16: 10,64 % | D16: 2,33E+10 | E16: 16,54 % | F16: 2,37E+10 | G16: 10,87 % | H16: 2,37E+10 | I16: 24,07 % | J16: 37,89 % | K16: 2,40E+10
A17: Chile | B17: Min | C17: Min-Q1 | D17: Q1 | E17: Q1-Q3 | F17: Q3 | G17: Q3-Estimate | H17: Estimate | I17: P_Estimate | J17: Estimate-Max | K17: Max
B18: 2,80E+09 | C18: 3,98 % | D18: 2,80E+09 | E18: 52,67 % | F18: 2,86E+09 | G18: 14,68 % | H18: 2,90E+09 | I18: 12,07 % | J18: 16,60 % | K18: 2,91E+09
A19: China | B19: Min | C19: Min-Estimate | D19: Estimate | E19: P_Estimate | F19: Estimate-Q1 | G19: Q1 | H19: Q1-Q3 | I19: Q3 | J19: Q3-Max | K19: Max
B20: 5,45E+10 | C20: 7,73 % | D20: 5,65E+10 | E20: 32,08 % | F20: 0,00 % | G20: 5,65E+10 | H20: 51,54 % | I20: 1,21E+11 | J20: 8,66 % | K20: 1,44E+11
A21: Colombia | B21: Min | C21: Min-Estimate | D21: Estimate | E21: P_Estimate | F21: Estimate-Q1 | G21: Q1 | H21: Q1-Q3 | I21: Q3 | J21: Q3-Max | K21: Max
B22: 9,65E+08 | C22: 0,00 % | D22: 9,65E+08 | E22: 66,67 % | F22: 0,00 % | G22: 9,65E+08 | H22: 0,00 % | I22: 1,14E+09 | J22: 33,33 % | K22: 1,14E+09
A23: Czech Republic | B23: Min | C23: Min-Q1 | D23: Q1 | E23: Q1-Estimate | F23: Estimate | G23: P_Estimate | H23: Estimate-Q3 | I23: Q3 | J23: Q3-Max | K23: Max
B24: 2,40E+08 | C24: 3,03 % | D24: 2,45E+08 | E24: 0,61 % | F24: 2,45E+08 | G24: 18,18 % | H24: 75,15 % | I24: 3,87E+08 | J24: 3,03 % | K24: 5,28E+08
A25: Denmark | B25: Min | C25: Min-Q1 | D25: Q1 | E25: Q1-Q3 | F25: Q3 | G25: Q3-Estimate | H25: Estimate | I25: P_Estimate | J25: Estimate-Max | K25: Max
B26: 1,13E+09 | C26: 0,00 % | D26: 1,13E+09 | E26: 20,00 % | F26: 1,14E+09 | G26: 0,00 % | H26: 1,14E+09 | I26: 80,00 % | J26: 0,00 % | K26: 1,14E+09
A27: Egypt | B27: Min | C27: Min-Q1 | D27: Q1 | E27: Q1-Q3 | F27: Q3 | G27: Q3-Estimate | H27: Estimate | I27: P_Estimate | J27: Estimate-Max | K27: Max
B28: 1,13E+10 | C28: 26,67 % | D28: 1,13E+10 | E28: 11,11 % | F28: 1,14E+10 | G28: 13,33 % | H28: 1,14E+10 | I28: 48,89 % | J28: 0,00 % | K28: 1,14E+10
A29: Finland | B29: Min | C29: Min-Estimate | D29: Estimate | E29: P_Estimate | F29: Estimate-Q1 | G29: Q1 | H29: Q1-Q3 | I29: Q3 | J29: Q3-Max | K29: Max
B30: 6,33E+09 | C30: 0,00 % | D30: 6,33E+09 | E30: 100,00 % | F30: 0,00 % | G30: 6,33E+09 | H30: 0,00 % | I30: 6,33E+09 | J30: 0,00 % | K30: 6,33E+09
A31: France | B31: Min | C31: Min-Estimate | D31: Estimate | E31: P_Estimate | F31: Estimate-Q1 | G31: Q1 | H31: Q1-Q3 | I31: Q3 | J31: Q3-Max | K31: Max
B32: 1,19E+10 | C32: 5,10 % | D32: 1,19E+10 | E32: 18,37 % | F32: 0,00 % | G32: 1,19E+10 | H32: 26,53 % | I32: 1,20E+10 | J32: 50,00 % | K32: 1,23E+10
A33: Germany | B33: Min | C33: Min-Estimate | D33: Estimate | E33: P_Estimate | F33: Estimate-Q1 | G33: Q1 | H33: Q1-Q3 | I33: Q3 | J33: Q3-Max | K33: Max
B34: 3,04E+09 | C34: 8,13 % | D34: 3,04E+09 | E34: 24,00 % | F34: 2,80 % | G34: 3,05E+09 | H34: 47,33 % | I34: 3,13E+09 | J34: 17,73 % | K34: 3,35E+09
A35: Greece | B35: Min | C35: Min-Estimate | D35: Estimate | E35: P_Estimate | F35: Estimate-Q1 | G35: Q1 | H35: Q1-Q3 | I35: Q3 | J35: Q3-Max | K35: Max
B36: 6,52E+08 | C36: 0,00 % | D36: 6,52E+08 | E36: 100,00 % | F36: 0,00 % | G36: 6,52E+08 | H36: 0,00 % | I36: 6,52E+08 | J36: 0,00 % | K36: 6,52E+08
A37: India | B37: Min | C37: Min-Estimate | D37: Estimate | E37: P_Estimate | F37: Estimate-Q1 | G37: Q1 | H37: Q1-Q3 | I37: Q3 | J37: Q3-Max | K37: Max
B38: 8,33E+09 | C38: 0,00 % | D38: 8,33E+09 | E38: 100,00 % | F38: 0,00 % | G38: 8,33E+09 | H38: 0,00 % | I38: 8,33E+09 | J38: 0,00 % | K38: 8,33E+09
A39: Indonesia | B39: Min | C39: Min-Q1 | D39: Q1 | E39: Q1-Estimate | F39: Estimate | G39: P_Estimate | H39: Estimate-Q3 | I39: Q3 | J39: Q3-Max | K39: Max
B40: 1,52E+10 | C40: 4,17 % | D40: 1,52E+10 | E40: 0,00 % | F40: 1,52E+10 | G40: 50,00 % | H40: 0,00 % | I40: 1,52E+10 | J40: 45,83 % | K40: 1,52E+10
...

Sheet Sensitivity of country-info
