Workbook

Sheet GHG data from Eurostat
A1: Data extracted on 23/09/2025 14:52:11 from [ESTAT]
A2: Dataset: | B2: Greenhouse gas emissions by source sector [env_air_gge__custom_18145251]
A3: Last updated: | B3: 08/05/2025 23:00
A4: Source | B4: https://ec.europa.eu/eurostat/databrowser/product/page/env_air_gge__custom_18145251
A5: Time frequency | B5: Annual | DV5: =DU11/(77/3) -> -2.3009692
A6: Unit of measure | B6: Million tonnes
A8: TIME | B8: TIME | C8: 2018 | D8: 2018 | E8: 2018 | F8: 2018 | G8: 2018 | H8: 2018 | I8: 2018 | J8: 2018 | K8: 2018 | L8: 2018 | M8: 2018 | N8: 2018 | O8: 2018 | P8: 2018 | Q8: 2018 | R8: 2018 | S8: 2018 | T8: 2018 | U8: 2018 | V8: 2018 | W8: 2018 | X8: 2018 | Y8: 2018 | Z8: 2018 | AA8: 2018 | AB8: 2018 | AC8: 2018 | AD8: 2018 | AE8: 2018 | AF8: 2018 | AG8: 2018 | AH8: 2018 | AI8: 2018 | AJ8: 2018 | AK8: 2018 | AL8: 2018 | AM8: 2018 | AN8: 2018 | AO8: 2018 | AP8: 2018 | AQ8: 2018 | AR8: 2018 | AS8: 2018 | AT8: 2018 | AU8: 2018 | AV8: 2018 | AW8: 2018 | AX8: 2018 | AY8: 2018 | AZ8: 2018 | BA8: 2018 | BB8: 2018 | BC8: 2018 | BD8: 2018 | BE8: 2018 | BF8: 2018 | BG8: 2018 | BH8: 2018 | BI8: 2018 | BJ8: 2018 | BK8: 2018 | BL8: 2018 | BM8: 2018 | BN8: 2018 | BO8: 2018 | BP8: 2018 | BQ8: 2018 | BR8: 2018 | BS8: 2018 | BT8: 2018 | BU8: 2018 | BV8: 2018 | BW8: 2018 | BX8: 2018 | BY8: 2018 | BZ8: 2018 | CA8: 2018 | CB8: 2018 | CC8: 2018 | CD8: 2018 | CE8: 2018 | CF8: 2018 | CG8: 2018 | CH8: 2018 | CI8: 2018 | CJ8: 2018 | CK8: 2018 | CL8: 2018 | CM8: 2018 | CN8: 2018 | CO8: 2018 | CP8: 2018 | CQ8: 2018 | CR8: 2018 | CS8: 2018 | CT8: 2018 | CU8: 2018 | CV8: 2018 | CW8: 2018 | CX8: 2018 | CY8: 2018 | CZ8: 2018 | DA8: 2018 | DB8: 2018 | DC8: 2018 | DD8: 2018 | DE8: 2018 | DF8: 2018 | DG8: 2018 | DH8: 2018 | DI8: 2018 | DJ8: 2018 | DK8: 2018 | DL8: 2018 | DM8: 2018 | DN8: 2018 | DO8: 2018 | DP8: 2018 | DQ8: 2018 | DR8: 2018 | DS8: 2018 | DT8: 2018 | DU8: 2018 | DV8: 2018 | DW8: 2018 | DX8: 2018 | DY8: 2018 | DZ8: 2018 | EA8: 2018 | EB8: 2018 | EC8: 2018 | ED8: 2018 | EE8: 2018 | EF8: 2018 | EG8: 2018 | EH8: 2018 | EI8: 2018 | EJ8: 2018 | EK8: 2018 | EL8: 2018 | EM8: 2018 | EN8: 2018 | EO8: 2018 | EP8: 2018 | EQ8: 2018 | ER8: 2018 | ES8: 2018 | ET8: 2018 | EU8: 2018 | EV8: 2018 | EW8: 2018 | EX8: 2018 | EY8: 2018 | EZ8: 2018 | FA8: 2018 | FB8: 2018 | FC8: 2018 | FD8: 2018 | FE8: 2018 | FF8: 2018 | FG8: 2018 | FH8: 2018 | FI8: 2018 | FJ8: 2018 | FK8: 2018 | FL8: 2018
A9: SRC_CRF (Labels) | B9: SRC_CRF (Labels) | C9: Total (excluding memo items) | D9: Total (excluding LULUCF and memo items) | E9: Energy | F9: Fuel combustion - sectoral approach | G9: Fuel combustion in energy industries | H9: Fuel combustion in public electricity and heat production | I9: Fuel combustion in petroleum refining | J9: Fuel combustion in manufacture of solid fuels and other energy industries | K9: Fuel combustion in manufacturing industries and construction | L9: Fuel combustion in manufacture of iron and steel | M9: Fuel combustion in manufacture of non-ferrous metals | N9: Fuel combustion in manufacture of chemicals | O9: Fuel combustion in manufacture of pulp, paper and printing | P9: Fuel combustion in manufacture of food, beverages and tobacco | Q9: Fuel combustion in manufacture of non-metallic mineral products | R9: Fuel combustion in other manufacturing industries and construction | S9: Fuel combustion in transport | T9: Fuel combustion in domestic aviation | U9: Fuel combustion in road transport | V9: Fuel combustion in cars | W9: Fuel combustion in light duty trucks | X9: Fuel combustion in heavy duty trucks and buses | Y9: Fuel combustion in motorcycles | Z9: Fuel combustion in other road transportation | AA9: Fuel combustion in railways | AB9: Fuel combustion in domestic navigation | AC9: Fuel combustion in other transport | AD9: Other fuel combustion sectors | AE9: Fuel combustion in commercial and institutional sector | AF9: Fuel combustion by households | AG9: Fuel combustion in agriculture, forestry and fishing | AH9: Other fuel combustion sectors n.e.c. | AI9: Stationary fuel combustion sectors n.e.c. | AJ9: Mobile fuel combustion sectors n.e.c. | AK9: Fuels - fugitive emissions | AL9: Solid fuels - fugitive emissions | AM9: Oil, natural gas and other energy production - fugitive emissions | AN9: Transport and storage of CO2 (memo item) | AO9: International bunkers (memo item) | AP9: International aviation (memo item) | AQ9: International navigation (memo item) | AR9: Multilateral operations (memo item) | AS9: Biomass - CO2 emissions (memo item) | AT9: Industrial processes and product use | AU9: Mineral industry | AV9: Cement production | AW9: Lime production | AX9: Glass production | AY9: Other process uses of carbonates | AZ9: Chemical industry | BA9: Ammonia production | BB9: Nitric acid production | BC9: Adipic acid production | BD9: Caprolactam, glyoxal and glyoxylic acid production | BE9: Carbide production | BF9: Titanium dioxide production | BG9: Soda ash production | BH9: Petrochemical and carbon black production | BI9: Fluorochemical production | BJ9: Other chemical industry | BK9: Metal industry | BL9: Iron and steel production | BM9: Ferroalloys production | BN9: Aluminium production | BO9: Magnesium production | BP9: Lead production | BQ9: Zinc production | BR9: Other metal industry | BS9: Non-energy products from fuels and solvent use | BT9: Lubricant use | BU9: Paraffin wax use | BV9: Other non-energy product use | BW9: Electronics industry | BX9: Integrated circuit or semiconductor production | BY9: TFT flat panel display production | BZ9: Photovoltaic | CA9: Heat transfer fluid | CB9: Other electronics industry | CC9: Product uses as substitutes for ozone depleting substances | CD9: Refrigeration and air conditioning | CE9: Foam blowing agent use | CF9: Fire protection | CG9: Aerosol use | CH9: Solvent use | CI9: Other applications of substitutes for ozone depleting substances | CJ9: Other product manufacture and use | CK9: Other industrial process and product use | CL9: Agriculture | CM9: Enteric fermentation | CN9: Enteric fermentation of cattle | CO9: Enteric fermentation of sheep | CP9: Enteric fermentation of swine | CQ9: Enteric fermentation of other livestock | CR9: Manure management | CS9: Cattle manure management | CT9: Sheep manure management | CU9: Swine manure management | CV9: Other livestock manure management | CW9: Manure management - indirect N2O emissions | CX9: Rice cultivation | CY9: Irrigated rice cultivation | CZ9: Rainfed rice cultivation | DA9: Deep water rice cultivation | DB9: Other rice cultivation | DC9: Managed agricultural soils | DD9: Managed agricultural soils - direct N2O emissions | DE9: Managed agricultural soils - indirect N2O emissions | DF9: Prescribed burning of savannas | DG9: Field burning of agricultural residues | DH9: Field burning of cereals residues | DI9: Field burning of pulses residues | DJ9: Field burning of tubers and roots residues | DK9: Field burning of sugar cane residues | DL9: Field burning of other agricultural residues | DM9: Liming | DN9: Urea application | DO9: Other carbon-containing fertilizers | DP9: Other agriculture | DQ9: Land use, land use change, and forestry (LULUCF) | DR9: Forest land | DS9: Drainage and rewetting and other management of organic and mineral soils related to forest land - emissions and removals | DT9: Unconverted forest land | DU9: Land converted to forest land | DV9: Cropland | DW9: Drainage and rewetting and other management of organic and mineral soils related to cropland - emissions and removals | DX9: Unconverted cropland | DY9: Land converted to cropland | DZ9: Grassland | EA9: Drainage and rewetting and other management of organic and mineral soils related to grassland - emissions and removals | EB9: Unconverted grassland | EC9: Land converted to grassland | ED9: Wetlands | EE9: Drainage and rewetting and other management of organic and mineral soils related to wetlands - emissions and removals | EF9: Unconverted wetlands | EG9: Land converted to wetlands | EH9: Settlements | EI9: Biomass burning in settlements | EJ9: Unconverted settlements | EK9: Land converted to settlements | EL9: Other land | EM9: Land converted to other land | EN9: Nitrogen mineralization and immobilization in other land - direct N2O emissions | EO9: Biomass burning on other land | EP9: Harvested wood products | EQ9: Other land use, land use change, and forestry | ER9: Waste management | ES9: Solid waste disposal | ET9: Managed waste disposal sites | EU9: Unmanaged waste disposal sites | EV9: Uncategorized waste disposal sites | EW9: Biological treatment of solid waste | EX9: Waste composting | EY9: Anaerobic digestion at biogas facilities | EZ9: Incineration and open burning of waste | FA9: Waste incineration | FB9: Open burning of waste | FC9: Wastewater treatment and discharge | FD9: Domestic wastewater | FE9: Industrial wastewater | FF9: Other wastewater | FG9: Other disposal | FH9: Long-term storage of carbon in waste disposal sites | FI9: Annual change in total long-term carbon storage | FJ9: Annual change in total long-term carbon storage in harvested wood products HWP waste | FK9: Other sectors | FL9: Indirect CO2
A10: GEO (Labels) | B10: AIRPOL (Labels)
A11: European Union - 27 countries (from 2020) | B11: Greenhouse gases (CO2, N2O in CO2 equivalent, CH4 in CO2 equivalent, HFC in CO2 equivalent, PFC in CO2 equivalent, SF6 in CO2 equivalent, NF3 in CO2 equivalent) | C11: 3546.7562 | D11: 3749.8848 | E11: 2901.9674 | F11: 2827.4781 | G11: 1024.275 | H11: 883.98896 | I11: 99.74929 | J11: 40.53672 | K11: 429.8956 | L11: 82.5444 | M11: 8.56619 | N11: 61.07187 | O11: 23.66615 | P11: 36.71103 | Q11: 87.15395 | R11: 128.12606 | S11: 830.88806 | T11: 14.63443 | U11: 787.80671 | V11: 483.14698 | W11: 85.94433 | X11: 209.12552 | Y11: 9.47814 | Z11: 0.11174 | AA11: 4.12842 | AB11: 18.13082 | AC11: 6.18768 | AD11: 536.69507 | AE11: 124.31231 | AF11: 333.72367 | AG11: 78.65909 | AH11: 5.72439 | AI11: 3.51383 | AJ11: 2.21056 | AK11: 74.4893 | AL11: 34.93627 | AM11: 39.55303 | AN11: 0 | AO11: 267.43165 | AP11: 130.06639 | AQ11: 137.36526 | AR11: 0.00217 | AS11: 561.67781 | AT11: 344.12963 | AU11: 106.59063 | AV11: 73.60795 | AW11: 18.5787 | AX11: 3.96086 | AY11: 10.44311 | AZ11: 66.65341 | BA11: 20.81548 | BB11: 3.02226 | BC11: 0.37172 | BD11: 1.70305 | BE11: 0.27703 | BF11: 0.12046 | BG11: 2.05793 | BH11: 16.71342 | BI11: 3.47706 | BJ11: 18.095 | BK11: 78.77322 | BL11: 69.7986 | BM11: 3.05819 | BN11: 3.754 | BO11: 0.12104 | BP11: 0.20094 | BQ11: 1.06083 | BR11: 0.32875 | BS11: 6.61387 | BT11: 2.30567 | BU11: 1.07888 | BV11: 3.22933 | BW11: 0.7835 | BX11: 0.76063 | BY11: 0 | BZ11: 3e-05 | CA11: 0.02284 | CB11: 0 | CC11: 75.21695 | CD11: 67.91084 | CE11: 2.04566 | CF11: 2.41731 | CG11: 2.62128 | CH11: 0.04518 | CI11: 0.17667 | CJ11: 9.15656 | CK11: 0.3415 | CL11: 386.08819 | CM11: 185.93478 | CN11: 158.85769 | CO11: 16.14197 | CP11: 4.54657 | CQ11: 6.38857 | CR11: 66.44227 | CS11: 31.036 | CT11: 1.37362 | CU11: 22.48916 | CV11: 4.29403 | CW11: 7.24946 | CX11: 2.9223 | CY11: 2.9223 | CZ11: 0 | DA11: 0 | DB11: 0 | DC11: 118.49519 | DD11: 93.46896 | DE11: 25.02623 | DF11: 0 | DG11: 0.54327 | DH11: 0.48322 | DI11: 0.00034 | DJ11: 0.00475 | DK11: 0.00181 | DL11: 0.05315 | DM11: 4.97771 | DN11: 4.2564 | DO11: 0.86711 | DP11: 1.64915 | DQ11: -203.12861 | DR11: -267.38612 | DS11: 7.58122 | DT11: -208.32791 | DU11: -59.05821 | DV11: 39.13098 | DW11: 1.78059 | DX11: 15.4884 | DY11: 23.64259 | DZ11: 11.65156 | EA11: 5.51196 | EB11: 30.67121 | EC11: -19.01964 | ED11: 24.86138 | EE11: 10.77777 | EF11: 21.84214 | EG11: 3.01925 | EH11: 26.3348 | EI11: 0.68597 | EJ11: 2.21738 | EK11: 24.11742 | EL11: 1.82741 | EM11: 1.82741 | EN11: 0.04108 | EO11: 0.00021 | EP11: -40.06697 | EQ11: 0.29734 | ER11: 113.8402 | ES11: 77.58205 | ET11: 66.09506 | EU11: 11.2358 | EV11: 0.2512 | EW11: 6.17586 | EX11: 4.60494 | EY11: 1.57092 | EZ11: 3.30646 | FA11: 2.24792 | FB11: 1.05854 | FC11: 26.71748 | FD11: 20.04334 | FE11: 6.54876 | FF11: 0.12537 | FG11: 0.05835 | FH11: 222.14316 | FI11: 2.05176 | FJ11: 1.10372 | FK11: 0 | FL11: 3.85936
A12: European Union - 27 countries (from 2020) | B12: Carbon dioxide | C12: 2834.9584 | D12: 3062.558 | E12: 2798.7461 | F12: 2776.5611 | G12: 1014.7493 | H12: 875.24583 | I12: 99.37231 | J12: 40.13113 | K12: 424.17884 | L12: 82.121 | M12: 8.53411 | N12: 60.37409 | O12: 22.95184 | P12: 36.05229 | Q12: 86.02125 | R12: 126.10576 | S12: 821.90026 | T12: 14.51178 | U12: 779.48748 | V12: 478.52112 | W12: 85.20997 | X12: 206.49319 | Y12: 9.16725 | Z12: 0.09596 | AA12: 3.92405 | AB12: 17.83857 | AC12: 6.13837 | AD12: 510.05847 | AE12: 122.94424 | AF12: 313.79036 | AG12: 73.32387 | AH12: 5.67429 | AI12: 3.49116 | AJ12: 2.18313 | AK12: 22.18497 | AL12: 4.05147 | AM12: 18.1335 | AN12: 0 | AO12: 265.04024 | AP12: 129.0563 | AQ12: 135.98394 | AR12: 0.00216 | AS12: 561.67781 | AT12: 247.66218 | AU12: 106.59063 | AV12: 73.60795 | AW12: 18.5787 | AX12: 3.96086 | AY12: 10.44311 | AZ12: 56.31751 | BA12: 20.81198 | BB12: 0 | BC12: 0.02295 | BD12: 0 | BE12: 0.26535 | BF12: 0.12046 | BG12: 2.05793 | BH12: 15.47588 | BI12: 0 | BJ12: 17.56295 | BK12: 77.8964 | BL12: 69.62138 | BM12: 3.03604 | BN12: 3.27211 | BO12: 0 | BP12: 0.20094 | BQ12: 1.06083 | BR12: 0.25423 | BS12: 6.60807 | BT12: 2.30208 | BU12: 1.07717 | BV12: 3.22882 | BW12: 0 | BX12: 0 | BY12: 0 | BZ12: 0 | CA12: 0 | CB12: 0 | CC12: 0 | CD12: 0 | CE12: 0 | CF12: 0 | CG12: 0 | CH12: 0 | CI12: 0 | CJ12: 0.12584 | CK12: 0.12374 | CL12: 10.10122 | CM12: 0 | CN12: 0 | CO12: 0 | CP12: 0 | CQ12: 0 | CR12: 0 | CS12: 0 | CT12: 0 | CU12: 0 | CV12: 0 | CW12: 0 | CX12: 0 | CY12: 0 | CZ12: 0 | DA12: 0 | DB12: 0 | DC12: 0 | DD12: 0 | DE12: 0 | DF12: 0 | DG12: 0 | DH12: 0 | DI12: 0 | DJ12: 0 | DK12: 0 | DL12: 0 | DM12: 4.97771 | DN12: 4.2564 | DO12: 0.86711 | DP12: 0 | DQ12: -227.59964 | DR12: -274.15581 | DS12: 1.77141 | DT12: -214.59319 | DU12: -59.56262 | DV12: 36.84788 | DW12: 1.10478 | DX12: 14.7557 | DY12: 22.09218 | DZ12: 8.45294 | EA12: 2.87656 | EB12: 27.92706 | EC12: -19.47412 | ED12: 16.21766 | EE12: 2.28375 | EF12: 13.46314 | EG12: 2.75453 | EH12: 23.27141 | EI12: 0.54455 | EJ12: 2.02489 | EK12: 21.24652 | EL12: 1.78089 | EM12: 1.78089 | EN12: 0 | EO12: 0 | EP12: -40.06697 | EQ12: 0.05236 | ER12: 2.18919 | ES12: 0 | ET12: 0 | EU12: 0 | EV12: 0 | EW12: 0 | EX12: 0 | EY12: 0 | EZ12: 2.17127 | FA12: 2.13594 | FB12: 0.03533 | FC12: 0 | FD12: 0 | FE12: 0 | FF12: 0 | FG12: 0.01792 | FH12: 222.14316 | FI12: 2.05176 | FJ12: 1.10372 | FK12: 0 | FL12: 3.85936
A13: European Union - 27 countries (from 2020) | B13: Methane | C13: 15.47622 | D13: 14.96245 | E13: 2.83951 | F13: 0.97254 | G13: 0.12997 | H13: 0.12004 | I13: 0.00267 | J13: 0.00727 | K13: 0.08642 | L13: 0.0054 | M13: 0.00055 | N13: 0.01845 | O13: 0.01032 | P13: 0.01793 | Q13: 0.01034 | R13: 0.02318 | S13: 0.04696 | T13: 0.00029 | U13: 0.04314 | V13: 0.02618 | W13: 0.00188 | X13: 0.00548 | Y13: 0.00952 | Z13: 8e-05 | AA13: 0.00027 | AB13: 0.00279 | AC13: 0.00047 | AD13: 0.7088 | AE13: 0.02857 | AF13: 0.59862 | AG13: 0.0816 | AH13: 0.00039 | AI13: 0.00028 | AJ13: 0.00012 | AK13: 1.86696 | AL13: 1.10302 | AM13: 0.76394 | AN13: 0 | AO13: 0.01049 | AP13: 0.00087 | AQ13: 0.00962 | AR13: 0 | AS13: 0 | AT13: 0.05982 | AU13: 0 | AV13: 0 | AW13: 0 | AX13: 0 | AY13: 0 | AZ13: 0.04895 | BA13: 0.00011 | BB13: 0 | BC13: 0 | BD13: 0 | BE13: 0.00042 | BF13: 0 | BG13: 0 | BH13: 0.0442 | BI13: 0 | BJ13: 0.00423 | BK13: 0.00712 | BL13: 0.00633 | BM13: 0.00079 | BN13: 0 | BO13: 0 | BP13: 0 | BQ13: 0 | BR13: 0 | BS13: 5e-05 | BT13: 2e-05 | BU13: 1e-05 | BV13: 2e-05 | BW13: 0 | BX13: 0 | BY13: 0 | BZ13: 0 | CA13: 0 | CB13: 0 | CC13: 0 | CD13: 0 | CE13: 0 | CF13: 0 | CG13: 0 | CH13: 0 | CI13: 0 | CJ13: 0.00337 | CK13: 0.00033 | CL13: 8.50202 | CM13: 6.64053 | CN13: 5.67349 | CO13: 0.5765 | CP13: 0.16238 | CQ13: 0.22816 | CR13: 1.68964 | CS13: 0.83075 | CT13: 0.0299 | CU13: 0.7392 | CV13: 0.08978 | CW13: 0 | CX13: 0.10437 | CY13: 0.10437 | CZ13: 0 | DA13: 0 | DB13: 0 | DC13: 0 | DD13: 0 | DE13: 0 | DF13: 0 | DG13: 0.01512 | DH13: 0.01355 | DI13: 1e-05 | DJ13: 0.00012 | DK13: 5e-05 | DL13: 0.00139 | DM13: 0 | DN13: 0 | DO13: 0 | DP13: 0.05237 | DQ13: 0.51377 | DR13: 0.0683 | DS13: 0.05453 | DT13: 0.06629 | DU13: 0.00201 | DV13: 0.03119 | DW13: 0.02414 | DX13: 0.02462 | DY13: 0.00657 | DZ13: 0.10122 | EA13: 0.09195 | EB13: 0.09198 | EC13: 0.00924 | ED13: 0.29835 | EE13: 0.29623 | EF13: 0.29196 | EG13: 0.00639 | EH13: 0.00595 | EI13: 0.00497 | EJ13: 0.00421 | EK13: 0.00175 | EL13: 1e-05 | EM13: 1e-05 | EN13: 0 | EO13: 1e-05 | EP13: 0 | EQ13: 0.00875 | ER13: 3.56111 | ES13: 2.77079 | ET13: 2.36054 | EU13: 0.40128 | EV13: 0.00897 | EW13: 0.15558 | EX13: 0.1021 | EY13: 0.05348 | EZ13: 0.02277 | FA13: 0.0007 | FB13: 0.02207 | FC13: 0.6116 | FD13: 0.40709 | FE13: 0.20163 | FF13: 0.00287 | FG13: 0.00036 | FH13: 0 | FI13: 0 | FJ13: 0 | FK13: 0 | FL13: 0
A14: European Union - 27 countries (from 2020) | B14: Nitrous oxide | C14: 0.72326 | D14: 0.6852 | E14: 0.08949 | F14: 0.08938 | G14: 0.02221 | H14: 0.02031 | I14: 0.00114 | J14: 0.00076 | K14: 0.01244 | L14: 0.00103 | M14: 6e-05 | N14: 0.00068 | O14: 0.0016 | P14: 0.00059 | Q14: 0.00318 | R14: 0.00517 | S14: 0.02895 | T14: 0.00043 | U14: 0.02683 | V14: 0.01469 | W14: 0.00257 | X14: 0.00935 | Y14: 0.00017 | Z14: 5e-05 | AA14: 0.00074 | AB14: 0.00081 | AC14: 0.00014 | AD14: 0.02562 | AE14: 0.00214 | AF14: 0.01197 | AG14: 0.01151 | AH14: 0.00015 | AI14: 6e-05 | AJ14: 9e-05 | AK14: 0.00011 | AL14: 0 | AM14: 0.00011 | AN14: 0 | AO14: 0.00792 | AP14: 0.00372 | AQ14: 0.0042 | AR14: 0 | AS14: 0 | AT14: 0.03016 | AU14: 0 | AV14: 0 | AW14: 0 | AX14: 0 | AY14: 0 | AZ14: 0.02071 | BA14: 0 | BB14: 0.0114 | BC14: 0.00132 | BD14: 0.00643 | BE14: 0 | BF14: 0 | BG14: 0 | BH14: 0 | BI14: 0 | BJ14: 0.00156 | BK14: 6e-05 | BL14: 0 | BM14: 0 | BN14: 0 | BO14: 0 | BP14: 0 | BQ14: 0 | BR14: 6e-05 | BS14: 2e-05 | BT14: 1e-05 | BU14: 0 | BV14: 0 | BW14: 0 | BX14: 0 | BY14: 0 | BZ14: 0 | CA14: 0 | CB14: 0 | CC14: 0 | CD14: 0 | CE14: 0 | CF14: 0 | CG14: 0 | CH14: 0 | CI14: 0 | CJ14: 0.00909 | CK14: 0.00029 | CL14: 0.52049 | CM14: 0 | CN14: 0 | CO14: 0 | CP14: 0 | CQ14: 0 | CR14: 0.0722 | CS14: 0.02934 | CT14: 0.00202 | CU14: 0.00676 | CV14: 0.00672 | CW14: 0.02736 | CX14: 0 | CY14: 0 | CZ14: 0 | DA14: 0 | DB14: 0 | DC14: 0.44715 | DD14: 0.35271 | DE14: 0.09444 | DF14: 0 | DG14: 0.00045 | DH14: 0.00039 | DI14: 0 | DJ14: 1e-05 | DK14: 0 | DL14: 5e-05 | DM14: 0 | DN14: 0 | DO14: 0 | DP14: 0.00069 | DQ14: 0.03806 | DR14: 0.01833 | DS14: 0.01616 | DT14: 0.01664 | DU14: 0.00169 | DV14: 0.00532 | DW14: 0 | DX14: 0.00016 | DY14: 0.00516 | DZ14: 0.00138 | EA14: 0.00023 | EB14: 0.00064 | EC14: 0.00074 | ED14: 0.00109 | EE14: 0.00075 | EF14: 0.00077 | EG14: 0.00032 | EH14: 0.01093 | EI14: 1e-05 | EJ14: 0.00028 | EK14: 0.01065 | EL14: 0.00017 | EM14: 0.00017 | EN14: 0.00016 | EO14: 0 | EP14: 0 | EQ14: 0 | ER14: 0.04506 | ES14: 0 | ET14: 0 | EU14: 0 | EV14: 0 | EW14: 0.00687 | EX14: 0.00659 | EY14: 0.00028 | EZ14: 0.00188 | FA14: 0.00035 | FB14: 0.00153 | FC14: 0.0362 | FD14: 0.03262 | FE14: 0.00341 | FF14: 0.00017 | FG14: 0.00011 | FH14: 0 | FI14: 0 | FJ14: 0 | FK14: 0 | FL14: 0
A15: Belgium | B15: Greenhouse gases (CO2, N2O in CO2 equivalent, CH4 in CO2 equivalent, HFC in CO2 equivalent, PFC in CO2 equivalent, SF6 in CO2 equivalent, NF3 in CO2 equivalent) | C15: 116.74231 | D15: 117.36547 | E15: 85.62322 | F15: 84.89881 | G15: 19.5846 | H15: 14.85926 | I15: 4.56903 | J15: 0.15631 | K15: 14.19772 | L15: 1.34545 | M15: 0.44542 | N15: 3.92328 | O15: 0.52501 | P15: 2.43329 | Q15: 3.52446 | R15: 2.00082 | S15: 26.3005 | T15: 0.01328 | U15: 25.34982 | V15: 14.4094 | W15: 3.13299 | X15: 7.65009 | Y15: 0.15662 | Z15: 0.00072 | AA15: 0.08441 | AB15: 0.45337 | AC15: 0.39963 | AD15: 24.70043 | AE15: 5.87501 | AF15: 16.39613 | AG15: 2.42929 | AH15: 0.11556 | AI15: 0 | AJ15: 0.11556 | AK15: 0.72441 | AL15: 0.04559 | AM15: 0.67882 | AN15: 0 | AO15: 35.6868 | AP15: 5.18309 | AQ15: 30.50371 | AR15: 0 | AS15: 12.26092 | AT15: 21.24173 | AU15: 4.44056 | AV15: 2.53438 | AW15: 1.56296 | AX15: 0.15779 | AY15: 0.18543 | AZ15: 9.40629 | BA15: 1.14573 | BB15: 0.22569 | BC15: 0 | BD15: 0.47605 | BE15: 0 | BF15: 0.06895 | BG15: 0 | BH15: 3.85169 | BI15: 1.4832 | BJ15: 2.15499 | BK15: 4.25313 | BL15: 4.14106 | BM15: 0 | BN15: 0 | BO15: 0 | BP15: 0 | BQ15: 0.0093 | BR15: 0.10277 | BS15: 0.13077 | BT15: 0.08912 | BU15: 0.0102 | BV15: 0.03145 | BW15: 0.01954 | BX15: 0.01943 | BY15: 0 | BZ15: 0 | CA15: 0.00011 | CB15: 0 | CC15: 2.8226 | CD15: 2.71017 | CE15: 0.0542 | CF15: 0.01241 | CG15: 0.04582 | CH15: 0 | CI15: 0 | CJ15: 0.14442 | CK15: 0.02441 | CL15: 9.01028 | CM15: 4.53326 | CN15: 4.19159 | CO15: 0.0221 | CP15: 0.26645 | CQ15: 0.05312 | CR15: 1.81442 | CS15: 0.93695 | CT15: 0.00132 | CU15: 0.63903 | CV15: 0.05793 | CW15: 0.17918 | CX15: 0 | CY15: 0 | CZ15: 0 | DA15: 0 | DB15: 0 | DC15: 2.48554 | DD15: 1.75086 | DE15: 0.73469 | DF15: 0 | DG15: 0 | DH15: 0 | DI15: 0 | DJ15: 0 | DK15: 0 | DL15: 0 | DM15: 0.13171 | DN15: 0.04535 | DO15: 0 | DP15: 0 | DQ15: -0.62316 | DR15: -2.00717 | DS15: 0 | DT15: -1.45014 | DU15: -0.55704 | DV15: 0.84705 | DW15: 0 | DX15: 0.34124 | DY15: 0.50581 | DZ15: 0.10501 | EA15: 0 | EB15: 0.11387 | EC15: -0.00886 | ED15: 0.00835 | EE15: 0 | EF15: 0 | EG15: 0.00835 | EH15: 0.51325 | EI15: 0 | EJ15: 0 | EK15: 0.51325 | EL15: 0 | EM15: 0 | EN15: 0 | EO15: 0 | EP15: -0.08964 | EQ15: 0 | ER15: 1.49025 | ES15: 0.78505 | ET15: 0.78505 | EU15: 0 | EV15: 0 | EW15: 0.04925 | EX15: 0.04925 | EY15: 0 | EZ15: 0.28742 | FA15: 0.28742 | FB15: 0 | FC15: 0.36853 | FD15: 0.36853 | FE15: 0 | FF15: 0 | FG15: 0 | FH15: 0 | FI15: 0 | FJ15: 0 | FK15: 0 | FL15: 0
A16: Belgium | B16: Carbon dioxide | C16: 99.57864 | D16: 100.25637 | E16: 83.8041 | F16: 83.68286 | G16: 19.41713 | H16: 14.76301 | I16: 4.5021 | J16: 0.15202 | K16: 13.98247 | L16: 1.26527 | M16: 0.44401 | N16: 3.88446 | O16: 0.51131 | P16: 2.41903 | Q16: 3.4908 | R16: 1.9676 | S16: 26.03299 | T16: 0.01126 | U16: 25.0938 | V16: 14.29503 | W16: 3.11079 | X16: 7.53426 | Y16: 0.153 | Z16: 0.00072 | AA16: 0.08208 | AB16: 0.44976 | AC16: 0.39609 | AD16: 24.13593 | AE16: 5.82258 | AF16: 16.05657 | AG16: 2.25679 | AH16: 0.11433 | AI16: 0 | AJ16: 0.11433 | AK16: 0.12125 | AL16: 0 | AM16: 0.12125 | AN16: 0 | AO16: 35.43363 | AP16: 5.14421 | AQ16: 30.28942 | AR16: 0 | AS16: 12.26092 | AT16: 15.98795 | AU16: 4.44056 | AV16: 2.53438 | AW16: 1.56296 | AX16: 0.15779 | AY16: 0.18543 | AZ16: 7.15829 | BA16: 1.14572 | BB16: 0 | BC16: 0 | BD16: 0 | BE16: 0 | BF16: 0.06895 | BG16: 0 | BH16: 3.85169 | BI16: 0 | BJ16: 2.09192 | BK16: 4.23392 | BL16: 4.12185 | BM16: 0 | BN16: 0 | BO16: 0 | BP16: 0 | BQ16: 0.0093 | BR16: 0.10277 | BS16: 0.13077 | BT16: 0.08912 | BU16: 0.0102 | BV16: 0.03145 | BW16: 0 | BX16: 0 | BY16: 0 | BZ16: 0 | CA16: 0 | CB16: 0 | CC16: 0 | CD16: 0 | CE16: 0 | CF16: 0 | CG16: 0 | CH16: 0 | CI16: 0 | CJ16: 0 | CK16: 0.02441 | CL16: 0.17706 | CM16: 0 | CN16: 0 | CO16: 0 | CP16: 0 | CQ16: 0 | CR16: 0 | CS16: 0 | CT16: 0 | CU16: 0 | CV16: 0 | CW16: 0 | CX16: 0 | CY16: 0 | CZ16: 0 | DA16: 0 | DB16: 0 | DC16: 0 | DD16: 0 | DE16: 0 | DF16: 0 | DG16: 0 | DH16: 0 | DI16: 0 | DJ16: 0 | DK16: 0 | DL16: 0 | DM16: 0.13171 | DN16: 0.04535 | DO16: 0 | DP16: 0 | DQ16: -0.67774 | DR16: -2.00718 | DS16: 0 | DT16: -1.45014 | DU16: -0.55705 | DV16: 0.81463 | DW16: 0 | DX16: 0.34124 | DY16: 0.47339 | DZ16: 0.10337 | EA16: 0 | EB16: 0.11387 | EC16: -0.0105 | ED16: 0.00816 | EE16: 0 | EF16: 0 | EG16: 0.00816 | EH16: 0.49292 | EI16: 0 | EJ16: 0 | EK16: 0.49292 | EL16: 0 | EM16: 0 | EN16: 0 | EO16: 0 | EP16: -0.08964 | EQ16: 0 | ER16: 0.28726 | ES16: 0 | ET16: 0 | EU16: 0 | EV16: 0 | EW16: 0 | EX16: 0 | EY16: 0 | EZ16: 0.28726 | FA16: 0.28726 | FB16: 0 | FC16: 0 | FD16: 0 | FE16: 0 | FF16: 0 | FG16: 0 | FH16: 0 | FI16: 0 | FJ16: 0 | FK16: 0 | FL16: 0
A17: Belgium | B17: Methane | C17: 0.29348 | D17: 0.29348 | E17: 0.04152 | F17: 0.01998 | G17: 0.00102 | H17: 0.00087 | I17: 0 | J17: 0.00015 | K17: 0.00181 | L17: 4e-05 | M17: 2e-05 | N17: 0.00062 | O17: 0.00016 | P17: 0.00037 | Q17: 0.00024 | R17: 0.00036 | S17: 0.00061 | T17: 0 | U17: 0.00058 | V17: 0.00037 | W17: 1e-05 | X17: 0.0001 | Y17: 0.0001 | Z17: 0 | AA17: 1e-05 | AB17: 2e-05 | AC17: 1e-05 | AD17: 0.01653 | AE17: 0.00119 | AF17: 0.01035 | AG17: 0.00499 | AH17: 1e-05 | AI17: 0 | AJ17: 1e-05 | AK17: 0.02154 | AL17: 0.00163 | AM17: 0.01991 | AN17: 0 | AO17: 0.00023 | AP17: 3e-05 | AQ17: 0.0002 | AR17: 0 | AS17: 0 | AT17: 0.00164 | AU17: 0 | AV17: 0 | AW17: 0 | AX17: 0 | AY17: 0 | AZ17: 0.00095 | BA17: 0 | BB17: 0 | BC17: 0 | BD17: 0 | BE17: 0 | BF17: 0 | BG17: 0 | BH17: 0 | BI17: 0 | BJ17: 0.00095 | BK17: 0.00069 | BL17: 0.00069 | BM17: 0 | BN17: 0 | BO17: 0 | BP17: 0 | BQ17: 0 | BR17: 0 | BS17: 0 | BT17: 0 | BU17: 0 | BV17: 0 | BW17: 0 | BX17: 0 | BY17: 0 | BZ17: 0 | CA17: 0 | CB17: 0 | CC17: 0 | CD17: 0 | CE17: 0 | CF17: 0 | CG17: 0 | CH17: 0 | CI17: 0 | CJ17: 0 | CK17: 0 | CL17: 0.21166 | CM17: 0.1619 | CN17: 0.1497 | CO17: 0.00079 | CP17: 0.00952 | CQ17: 0.0019 | CR17: 0.04976 | CS17: 0.02695 | CT17: 2e-05 | CU17: 0.0214 | CV17: 0.00139 | CW17: 0 | CX17: 0 | CY17: 0 | CZ17: 0 | DA17: 0 | DB17: 0 | DC17: 0 | DD17: 0 | DE17: 0 | DF17: 0 | DG17: 0 | DH17: 0 | DI17: 0 | DJ17: 0 | DK17: 0 | DL17: 0 | DM17: 0 | DN17: 0 | DO17: 0 | DP17: 0 | DQ17: 0 | DR17: 0 | DS17: 0 | DT17: 0 | DU17: 0 | DV17: 0 | DW17: 0 | DX17: 0 | DY17: 0 | DZ17: 0 | EA17: 0 | EB17: 0 | EC17: 0 | ED17: 0 | EE17: 0 | EF17: 0 | EG17: 0 | EH17: 0 | EI17: 0 | EJ17: 0 | EK17: 0 | EL17: 0 | EM17: 0 | EN17: 0 | EO17: 0 | EP17: 0 | EQ17: 0 | ER17: 0.03867 | ES17: 0.02804 | ET17: 0.02804 | EU17: 0 | EV17: 0 | EW17: 0.0008 | EX17: 0.0008 | EY17: 0 | EZ17: 0 | FA17: 0 | FB17: 0 | FC17: 0.00983 | FD17: 0.00983 | FE17: 0 | FF17: 0 | FG17: 0 | FH17: 0 | FI17: 0 | FJ17: 0 | FK17: 0 | FL17: 0
A18: Belgium | B18: Nitrous oxide | C18: 0.0171 | D18: 0.01689 | E18: 0.00248 | F18: 0.00248 | G18: 0.00052 | H18: 0.00027 | I18: 0.00025 | J18: 0 | K18: 0.00062 | L18: 0.0003 | M18: 0 | N18: 8e-05 | O18: 3e-05 | P18: 2e-05 | Q18: 0.0001 | R18: 9e-05 | S18: 0.00094 | T18: 1e-05 | U18: 0.0009 | V18: 0.00039 | W18: 8e-05 | X18: 0.00043 | Y18: 0 | Z18: 0 | AA18: 1e-05 | AB18: 1e-05 | AC18: 1e-05 | AD18: 0.00038 | AE18: 7e-05 | AF18: 0.00019 | AG18: 0.00012 | AH18: 0 | AI18: 0 | AJ18: 0 | AK18: 0 | AL18: 0 | AM18: 0 | AN18: 0 | AO18: 0.00093 | AP18: 0.00014 | AQ18: 0.00079 | AR18: 0 | AS18: 0 | AT18: 0.00299 | AU18: 0 | AV18: 0 | AW18: 0 | AX18: 0 | AY18: 0 | AZ18: 0.00279 | BA18: 0 | BB18: 0.00085 | BC18: 0 | BD18: 0.0018 | BE18: 0 | BF18: 0 | BG18: 0 | BH18: 0 | BI18: 0 | BJ18: 0.00014 | BK18: 0 | BL18: 0 | BM18: 0 | BN18: 0 | BO18: 0 | BP18: 0 | BQ18: 0 | BR18: 0 | BS18: 0 | BT18: 0 | BU18: 0 | BV18: 0 | BW18: 0 | BX18: 0 | BY18: 0 | BZ18: 0 | CA18: 0 | CB18: 0 | CC18: 0 | CD18: 0 | CE18: 0 | CF18: 0 | CG18: 0 | CH18: 0 | CI18: 0 | CJ18: 0.0002 | CK18: 0 | CL18: 0.01097 | CM18: 0 | CN18: 0 | CO18: 0 | CP18: 0 | CQ18: 0 | CR18: 0.00159 | CS18: 0.00069 | CT18: 0 | CU18: 0.00015 | CV18: 7e-05 | CW18: 0.00068 | CX18: 0 | CY18: 0 | CZ18: 0 | DA18: 0 | DB18: 0 | DC18: 0.00938 | DD18: 0.00661 | DE18: 0.00277 | DF18: 0 | DG18: 0 | DH18: 0 | DI18: 0 | DJ18: 0 | DK18: 0 | DL18: 0 | DM18: 0 | DN18: 0 | DO18: 0 | DP18: 0 | DQ18: 0.00021 | DR18: 0 | DS18: 0 | DT18: 0 | DU18: 0 | DV18: 0.00012 | DW18: 0 | DX18: 0 | DY18: 0.00012 | DZ18: 1e-05 | EA18: 0 | EB18: 0 | EC18: 1e-05 | ED18: 0 | EE18: 0 | EF18: 0 | EG18: 0 | EH18: 8e-05 | EI18: 0 | EJ18: 0 | EK18: 8e-05 | EL18: 0 | EM18: 0 | EN18: 0 | EO18: 0 | EP18: 0 | EQ18: 0 | ER18: 0.00045 | ES18: 0 | ET18: 0 | EU18: 0 | EV18: 0 | EW18: 0.0001 | EX18: 0.0001 | EY18: 0 | EZ18: 0 | FA18: 0 | FB18: 0 | FC18: 0.00035 | FD18: 0.00035 | FE18: 0 | FF18: 0 | FG18: 0 | FH18: 0 | FI18: 0 | FJ18: 0 | FK18: 0 | FL18: 0
A19: Bulgaria | B19: Greenhouse gases (CO2, N2O in CO2 equivalent, CH4 in CO2 equivalent, HFC in CO2 equivalent, PFC in CO2 equivalent, SF6 in CO2 equivalent, NF3 in CO2 equivalent) | C19: 45.78733 | D19: 55.29483 | E19: 41.34467 | F19: 39.35926 | G19: 23.53676 | H19: 22.70951 | I19: 0.82155 | J19: 0.00571 | K19: 4.27356 | L19: 0.12983 | M19: 0.20554 | N19: 1.54373 | O19: 0.11634 | P19: 0.24068 | Q19: 1.15243 | R19: 0.88502 | S19: 9.65324 | T19: 0.02214 | U19: 9.26844 | V19: 5.77248 | W19: 1.41008 | X19: 2.05418 | Y19: 0.03169 | Z19: 0 | AA19: 0.03781 | AB19: 0.00514 | AC19: 0.31972 | AD19: 1.86456 | AE19: 0.35335 | AF19: 1.00962 | AG19: 0.50159 | AH19: 0.03113 | AI19: 0 | AJ19: 0.03113 | AK19: 1.98541 | AL19: 1.03688 | AM19: 0.94853 | AN19: 0 | AO19: 1.0779 | AP19: 0.81855 | AQ19: 0.25935 | AR19: 0 | AS19: 7.57611 | AT19: 4.89006 | AU19: 2.47852 | AV19: 1.2235 | AW19: 0.25172 | AX19: 0.0794 | AY19: 0.9239 | AZ19: 1.44277 | BA19: 0.784 | BB19: 0.10283 | BC19: 0 | BD19: 0 | BE19: 0.00515 | BF19: 0 | BG19: 0.55078 | BH19: 0 | BI19: 0 | BJ19: 0 | BK19: 0.18611 | BL19: 0.03538 | BM19: 0 | BN19: 0 | BO19: 0 | BP19: 0.00878 | BQ19: 0.14195 | BR19: 0 | BS19: 0.0154 | BT19: 0.01148 | BU19: 0.00056 | BV19: 0.00336 | BW19: 0 | BX19: 0 | BY19: 0 | BZ19: 0 | CA19: 0 | CB19: 0 | CC19: 0.71895 | CD19: 0.68437 | CE19: 0.01454 | CF19: 0.00775 | CG19: 0.01229 | CH19: 0 | CI19: 0 | CJ19: 0.04831 | CK19: 0 | CL19: 5.87969 | CM19: 1.64191 | CN19: 1.2535 | CO19: 0.27634 | CP19: 0.0262 | CQ19: 0.08587 | CR19: 0.61381 | CS19: 0.32798 | CT19: 0.02176 | CU19: 0.07809 | CV19: 0.08263 | CW19: 0.10335 | CX19: 0.111 | CY19: 0.111 | CZ19: 0 | DA19: 0 | DB19: 0 | DC19: 3.39971 | DD19: 2.67169 | DE19: 0.72802 | DF19: 0 | DG19: 0.03713 | DH19: 0.02829 | DI19: 7e-05 | DJ19: 9e-05 | DK19: 0 | DL19: 0.00869 | DM19: 0.02477 | DN19: 0.05137 | DO19: 0 | DP19: 0 | DQ19: -9.5075 | DR19: -8.5277 | DS19: 0 | DT19: -8.23711 | DU19: -0.29059 | DV19: 0.81902 | DW19: 0 | DX19: 0.34255 | DY19: 0.47647 | DZ19: -0.82747 | EA19: 0 | EB19: 0.10067 | EC19: -0.92814 | ED19: 0.09966 | EE19: 0 | EF19: 0 | EG19: 0.09966 | EH19: 0.16168 | EI19: 0 | EJ19: 0 | EK19: 0.16168 | EL19: 0 | EM19: 0 | EN19: 0 | EO19: 0 | EP19: -1.23269 | EQ19: 0 | ER19: 3.11221 | ES19: 2.46074 | ET19: 1.18049 | EU19: 1.28025 | EV19: 0 | EW19: 0.01007 | EX19: 0.01 | EY19: 7e-05 | EZ19: 0.00723 | FA19: 0.00723 | FB19: 0 | FC19: 0.63418 | FD19: 0.39921 | FE19: 0.23496 | FF19: 0 | FG19: 0 | FH19: 0 | FI19: 0 | FJ19: 0 | FK19: 0 | FL19: 0.0682
A20: Bulgaria | B20: Carbon dioxide | C20: 33.95589 | D20: 43.57152 | E20: 39.38132 | F20: 38.66987 | G20: 23.41659 | H20: 22.59028 | I20: 0.82062 | J20: 0.00569 | K20: 4.23177 | L20: 0.1297 | M20: 0.20498 | N20: 1.53858 | O20: 0.10678 | P20: 0.23842 | Q20: 1.14557 | R20: 0.86774 | S20: 9.54507 | T20: 0.02197 | U20: 9.16435 | V20: 5.70543 | W20: 1.39932 | X20: 2.02918 | Y20: 0.03042 | Z20: 0 | AA20: 0.03425 | AB20: 0.00509 | AC20: 0.3194 | AD20: 1.44553 | AE20: 0.31417 | AF20: 0.67411 | AG20: 0.45725 | AH20: 0.0309 | AI20: 0 | AJ20: 0.0309 | AK20: 0.71145 | AL20: 0.02501 | AM20: 0.68644 | AN20: 0 | AO20: 1.06937 | AP20: 0.81251 | AQ20: 0.25687 | AR20: 0 | AS20: 7.57611 | AT20: 4.0391 | AU20: 2.47852 | AV20: 1.2235 | AW20: 0.25172 | AX20: 0.0794 | AY20: 0.9239 | AZ20: 1.33993 | BA20: 0.784 | BB20: 0 | BC20: 0 | BD20: 0 | BE20: 0.00515 | BF20: 0 | BG20: 0.55078 | BH20: 0 | BI20: 0 | BJ20: 0 | BK20: 0.18611 | BL20: 0.03538 | BM20: 0 | BN20: 0 | BO20: 0 | BP20: 0.00878 | BQ20: 0.14195 | BR20: 0 | BS20: 0.0154 | BT20: 0.01148 | BU20: 0.00056 | BV20: 0.00336 | BW20: 0 | BX20: 0 | BY20: 0 | BZ20: 0 | CA20: 0 | CB20: 0 | CC20: 0 | CD20: 0 | CE20: 0 | CF20: 0 | CG20: 0 | CH20: 0 | CI20: 0 | CJ20: 0.01913 | CK20: 0 | CL20: 0.07614 | CM20: 0 | CN20: 0 | CO20: 0 | CP20: 0 | CQ20: 0 | CR20: 0 | CS20: 0 | CT20: 0 | CU20: 0 | CV20: 0 | CW20: 0 | CX20: 0 | CY20: 0 | CZ20: 0 | DA20: 0 | DB20: 0 | DC20: 0 | DD20: 0 | DE20: 0 | DF20: 0 | DG20: 0 | DH20: 0 | DI20: 0 | DJ20: 0 | DK20: 0 | DL20: 0 | DM20: 0.02477 | DN20: 0.05137 | DO20: 0 | DP20: 0 | DQ20: -9.61563 | DR20: -8.53597 | DS20: 0 | DT20: -8.24276 | DU20: -0.29321 | DV20: 0.75963 | DW20: 0 | DX20: 0.34255 | DY20: 0.41709 | DZ20: -0.84279 | EA20: 0 | EB20: 0.08534 | EC20: -0.92814 | ED20: 0.08759 | EE20: 0 | EF20: 0 | EG20: 0.08759 | EH20: 0.1486 | EI20: 0 | EJ20: 0 | EK20: 0.1486 | EL20: 0 | EM20: 0 | EN20: 0 | EO20: 0 | EP20: -1.23269 | EQ20: 0 | ER20: 0.00677 | ES20: 0 | ET20: 0 | EU20: 0 | EV20: 0 | EW20: 0 | EX20: 0 | EY20: 0 | EZ20: 0.00677 | FA20: 0.00677 | FB20: 0 | FC20: 0 | FD20: 0 | FE20: 0 | FF20: 0 | FG20: 0 | FH20: 0 | FI20: 0 | FJ20: 0 | FK20: 0 | FL20: 0.0682
A21: Bulgaria | B21: Methane | C21: 0.24232 | D21: 0.24219 | E21: 0.0598 | F21: 0.01433 | G21: 0.00073 | H21: 0.00072 | I21: 2e-05 | J21: 0 | K21: 0.00054 | L21: 0 | M21: 1e-05 | N21: 7e-05 | O21: 0.00015 | P21: 4e-05 | Q21: 0.00011 | R21: 0.00017 | S21: 0.00089 | T21: 0 | U21: 0.00088 | V21: 0.0006 | W21: 3e-05 | X21: 0.00022 | Y21: 4e-05 | Z21: 0 | AA21: 0 | AB21: 0 | AC21: 1e-05 | AD21: 0.01216 | AE21: 0.00124 | AF21: 0.01074 | AG21: 0.00019 | AH21: 0 | AI21: 0 | AJ21: 0 | AK21: 0.04547 | AL21: 0.03614 | AM21: 0.00933 | AN21: 0 | AO21: 3e-05 | AP21: 1e-05 | AQ21: 2e-05 | AR21: 0 | AS21: 0 | AT21: 0 | AU21: 0 | AV21: 0 | AW21: 0 | AX21: 0 | AY21: 0 | AZ21: 0 | BA21: 0 | BB21: 0 | BC21: 0 | BD21: 0 | BE21: 0 | BF21: 0 | BG21: 0 | BH21: 0 | BI21: 0 | BJ21: 0 | BK21: 0 | BL21: 0 | BM21: 0 | BN21: 0 | BO21: 0 | BP21: 0 | BQ21: 0 | BR21: 0 | BS21: 0 | BT21: 0 | BU21: 0 | BV21: 0 | BW21: 0 | BX21: 0 | BY21: 0 | BZ21: 0 | CA21: 0 | CB21: 0 | CC21: 0 | CD21: 0 | CE21: 0 | CF21: 0 | CG21: 0 | CH21: 0 | CI21: 0 | CJ21: 0 | CK21: 0 | CL21: 0.07634 | CM21: 0.05864 | CN21: 0.04477 | CO21: 0.00987 | CP21: 0.00094 | CQ21: 0.00307 | CR21: 0.01265 | CS21: 0.0091 | CT21: 0.00029 | CU21: 0.00274 | CV21: 0.00052 | CW21: 0 | CX21: 0.00396 | CY21: 0.00396 | CZ21: 0 | DA21: 0 | DB21: 0 | DC21: 0 | DD21: 0 | DE21: 0 | DF21: 0 | DG21: 0.00109 | DH21: 0.00088 | DI21: 0 | DJ21: 0 | DK21: 0 | DL21: 0.0002 | DM21: 0 | DN21: 0 | DO21: 0 | DP21: 0 | DQ21: 0.00014 | DR21: 0.00014 | DS21: 0 | DT21: 0.00013 | DU21: 0 | DV21: 0 | DW21: 0 | DX21: 0 | DY21: 0 | DZ21: 0 | EA21: 0 | EB21: 0 | EC21: 0 | ED21: 0 | EE21: 0 | EF21: 0 | EG21: 0 | EH21: 0 | EI21: 0 | EJ21: 0 | EK21: 0 | EL21: 0 | EM21: 0 | EN21: 0 | EO21: 0 | EP21: 0 | EQ21: 0 | ER21: 0.10604 | ES21: 0.08788 | ET21: 0.04216 | EU21: 0.04572 | EV21: 0 | EW21: 0.00023 | EX21: 0.00023 | EY21: 0 | EZ21: 0 | FA21: 0 | FB21: 0 | FC21: 0.01793 | FD21: 0.00954 | FE21: 0.00839 | FF21: 0 | FG21: 0 | FH21: 0 | FI21: 0 | FJ21: 0 | FK21: 0 | FL21: 0
A22: Bulgaria | B22: Nitrous oxide | C22: 0.01626 | D22: 0.01587 | E22: 0.00109 | F22: 0.00109 | G22: 0.00038 | H22: 0.00037 | I22: 0 | J22: 0 | K22: 0.0001 | L22: 0 | M22: 0 | N22: 1e-05 | O22: 2e-05 | P22: 0 | Q22: 1e-05 | R22: 5e-05 | S22: 0.00031 | T22: 0 | U22: 0.0003 | V22: 0.00019 | W22: 4e-05 | X22: 7e-05 | Y22: 0 | Z22: 0 | AA22: 1e-05 | AB22: 0 | AC22: 0 | AD22: 0.0003 | AE22: 2e-05 | AF22: 0.00013 | AG22: 0.00015 | AH22: 0 | AI22: 0 | AJ22: 0 | AK22: 0 | AL22: 0 | AM22: 0 | AN22: 0 | AO22: 3e-05 | AP22: 2e-05 | AQ22: 1e-05 | AR22: 0 | AS22: 0 | AT22: 0.00043 | AU22: 0 | AV22: 0 | AW22: 0 | AX22: 0 | AY22: 0 | AZ22: 0.00039 | BA22: 0 | BB22: 0.00039 | BC22: 0 | BD22: 0 | BE22: 0 | BF22: 0 | BG22: 0 | BH22: 0 | BI22: 0 | BJ22: 0 | BK22: 0 | BL22: 0 | BM22: 0 | BN22: 0 | BO22: 0 | BP22: 0 | BQ22: 0 | BR22: 0 | BS22: 0 | BT22: 0 | BU22: 0 | BV22: 0 | BW22: 0 | BX22: 0 | BY22: 0 | BZ22: 0 | CA22: 0 | CB22: 0 | CC22: 0 | CD22: 0 | CE22: 0 | CF22: 0 | CG22: 0 | CH22: 0 | CI22: 0 | CJ22: 4e-05 | CK22: 0 | CL22: 0.01383 | CM22: 0 | CN22: 0 | CO22: 0 | CP22: 0 | CQ22: 0 | CR22: 0.00098 | CS22: 0.00028 | CT22: 5e-05 | CU22: 0 | CV22: 0.00026 | CW22: 0.00039 | CX22: 0 | CY22: 0 | CZ22: 0 | DA22: 0 | DB22: 0 | DC22: 0.01283 | DD22: 0.01008 | DE22: 0.00275 | DF22: 0 | DG22: 3e-05 | DH22: 1e-05 | DI22: 0 | DJ22: 0 | DK22: 0 | DL22: 1e-05 | DM22: 0 | DN22: 0 | DO22: 0 | DP22: 0 | DQ22: 0.00039 | DR22: 2e-05 | DS22: 0 | DT22: 1e-05 | DU22: 1e-05 | DV22: 0.00022 | DW22: 0 | DX22: 0 | DY22: 0.00022 | DZ22: 6e-05 | EA22: 0 | EB22: 6e-05 | EC22: 0 | ED22: 5e-05 | EE22: 0 | EF22: 0 | EG22: 5e-05 | EH22: 5e-05 | EI22: 0 | EJ22: 0 | EK22: 5e-05 | EL22: 0 | EM22: 0 | EN22: 0 | EO22: 0 | EP22: 0 | EQ22: 0 | ER22: 0.00051 | ES22: 0 | ET22: 0 | EU22: 0 | EV22: 0 | EW22: 1e-05 | EX22: 1e-05 | EY22: 0 | EZ22: 0 | FA22: 0 | FB22: 0 | FC22: 0.0005 | FD22: 0.0005 | FE22: 0 | FF22: 0 | FG22: 0 | FH22: 0 | FI22: 0 | FJ22: 0 | FK22: 0 | FL22: 0
... A130: Norway | B130: Nitrous oxide | C130: 0.00935 | D130: 0.00843 | E130: 0.00078 | F130: 0.00077 | G130: 0.0001 | H130: 7e-05 | I130: 0 | J130: 3e-05 | K130: 0.00012 | L130: 0 | M130: 0 | N130: 1e-05 | O130: 2e-05 | P130: 0 | Q130: 2e-05 | R130: 7e-05 | S130: 0.00043 | T130: 4e-05 | U130: 0.00033 | V130: 0.00015 | W130: 5e-05 | X130: 0.00012 | Y130: 0 | Z130: 0 | AA130: 2e-05 | AB130: 4e-05 | AC130: 0 | AD130: 0.00012 | AE130: 4e-05 | AF130: 4e-05 | AG130: 3e-05 | AH130: 1e-05 | AI130: 0 | AJ130: 1e-05 | AK130: 1e-05 | AL130: 0 | AM130: 1e-05 | AN130: 0 | AO130: 0.00022 | AP130: 0.00012 | AQ130: 0.00011 | AR130: 0 | AS130: 0 | AT130: 0.00096 | AU130: 0 | AV130: 0 | AW130: 0 | AX130: 0 | AY130: 0 | AZ130: 0.00088 | BA130: 0 | BB130: 0.00067 | BC130: 0 | BD130: 0 | BE130: 0 | BF130: 0 | BG130: 0 | BH130: 0 | BI130: 0 | BJ130: 0.00021 | BK130: 1e-05 | BL130: 0 | BM130: 0 | BN130: 0 | BO130: 0 | BP130: 0 | BQ130: 0 | BR130: 1e-05 | BS130: 0 | BT130: 0 | BU130: 0 | BV130: 0 | BW130: 0 | BX130: 0 | BY130: 0 | BZ130: 0 | CA130: 0 | CB130: 0 | CC130: 0 | CD130: 0 | CE130: 0 | CF130: 0 | CG130: 0 | CH130: 0 | CI130: 0 | CJ130: 6e-05 | CK130: 0 | CL130: 0.00649 | CM130: 0 | CN130: 0 | CO130: 0 | CP130: 0 | CQ130: 0 | CR130: 0.00064 | CS130: 0.00027 | CT130: 3e-05 | CU130: 1e-05 | CV130: 6e-05 | CW130: 0.00027 | CX130: 0 | CY130: 0 | CZ130: 0 | DA130: 0 | DB130: 0 | DC130: 0.00585 | DD130: 0.00474 | DE130: 0.00111 | DF130: 0 | DG130: 0 | DH130: 0 | DI130: 0 | DJ130: 0 | DK130: 0 | DL130: 0 | DM130: 0 | DN130: 0 | DO130: 0 | DP130: 0 | DQ130: 0.00092 | DR130: 0.0006 | DS130: 0.00057 | DT130: 0.00059 | DU130: 1e-05 | DV130: 3e-05 | DW130: 0 | DX130: 0 | DY130: 3e-05 | DZ130: 2e-05 | EA130: 0 | EB130: 2e-05 | EC130: 0 | ED130: 0.00012 | EE130: 0.00012 | EF130: 0.00011 | EG130: 0 | EH130: 0.00016 | EI130: 0 | EJ130: 7e-05 | EK130: 8e-05 | EL130: 0 | EM130: 0 | EN130: 0 | EO130: 0 | EP130: 0 | EQ130: 0 | ER130: 0.0002 | ES130: 0 | ET130: 0 | EU130: 0 | EV130: 0 | EW130: 3e-05 | EX130: 3e-05 | EY130: 1e-05 | EZ130: 1e-05 | FA130: 1e-05 | FB130: 0 | FC130: 0.00016 | FD130: 0.00015 | FE130: 1e-05 | FF130: 0 | FG130: 0 | FH130: 0 | FI130: 0 | FJ130: 0 | FK130: 0 | FL130: 0
A132: Special value
A133: 0 | B133: not available

Sheet GHG_by country_by emission
U2: Total Livestock Emissions CO2e & CO2 (million tonnes), CH4 & N2O (Thousand tonnes) | Z2: Livestock Emissions CO2e & CO2 (million tonnes/million LSUs), CH4 & N2O (Thousand tonnes/million LSUs) | AE2: Rounded (4 digit) Livestock Emissions CO2e & CO2 (million tonnes/million LSUs), CH4 & N2O (Thousand tonnes/million LSUs) | AX2: CO2e & CO2 (million tonnes/1000 sq km), CH4 & N2O (Thousand tonnes/1000 sq km) | BD2: Rounded (4 digit) CO2e & CO2 (million tonnes/1000 sq km), CH4 & N2O (Thousand tonnes/1000 sq km) | BJ2: Exogenous emissions
A3: Units (Million Livestock Units) Million LSUs | B3: Units (Million Livestock Units) Million LSUs | I3: Units (Million Livestock Units) Million LSUs | M3: Enteric fermentation (Million tonnes) | Q3: Manure (Million Tonnes) | AL3: Area (1000 sq km) | AR3: GHG from EU (million tonnes)
A4: Countries | B4: Pigs | C4: Bovines | D4: Poultry | E4: Sheep and goat | G4: Geography | H4: Emission | I4: Pigs | J4: Bovines | K4: Poultry | L4: Sheep and goat | M4: Pigs | N4: Bovines | O4: Poultry | P4: Sheep and goat | Q4: Pigs | R4: Bovines | S4: Poultry | T4: Sheep and goat | U4: Pigs | V4: Bovines | W4: Poultry | X4: Sheep and goat | Z4: Pigs | AA4: Bovines | AB4: Poultry | AC4: Sheep and goat | AE4: Pigs | AF4: Bovines | AG4: Poultry | AH4: Sheep and goat | AJ4: Geography | AK4: Emission | AL4: Cropland | AM4: Forest | AN4: Grasslands | AO4: Wetlands | AP4: Shrubland | AR4: Cropland | AS4: Forest | AT4: Grasslands | AU4: Wetlands | AV4: Shrubland | AX4: Cropland | AY4: Forest | AZ4: Grasslands | BA4: Wetlands | BB4: Shrubland | BD4: Cropland | BE4: Forest | BF4: Grasslands | BG4: Wetlands | BH4: Shrubland | BJ4: =AJ4 -> Geography | BK4: =AK4 -> Emission | BL4: Harvested Woodstock
A5: European Union - 27 countries (from 2020) | B5: 43.055568 | C5: 77.8401 | D5: 92.451 | E5: 7.5202 | G5: European Union - 27 countries (from 2020) | H5: CO2e | I5: =VLOOKUP($G5,$A$5:$E$32,2,FALSE) -> 43.055568 | J5: =VLOOKUP($G5,$A$5:$E$32,3,FALSE) -> 77.8401 | K5: =VLOOKUP($G5,$A$5:$E$32,4,FALSE) -> 92.451 | L5: =VLOOKUP($G5,$A$5:$E$32,5,FALSE) -> 7.5202 | M5: ='GHG data from Eurostat'!CP11 -> 4.54657 | N5: ='GHG data from Eurostat'!CN11 -> 158.85769 | O5: ='GHG data from Eurostat'!CQ11 -> 6.38857 | P5: ='GHG data from Eurostat'!CO11 -> 16.14197 | Q5: ='GHG data from Eurostat'!CU11 -> 22.48916 | R5: =IFERROR(('GHG data from Eurostat'!CS11+'GHG data from Eurostat'!CW11),0) -> 38.28546 | S5: ='GHG data from Eurostat'!CV11 -> 4.29403 | T5: ='GHG data from Eurostat'!CT11 -> 1.37362 | U5: =Q5+M5 -> 27.03573 | V5: =R5+N5 -> 197.14315 | W5: =S5+O5 -> 10.6826 | X5: =T5+P5 -> 17.51559 | Y5: =SUM(U5:X5) -> 252.37707 | Z5: =(M5+Q5)/I5 -> 0.62792645 | AA5: =(N5+R5)/J5 -> 2.5326683 | AB5: =(O5+S5)/K5 -> 0.11554878 | AC5: =(P5+T5)/L5 -> 2.3291389 | AE5: =ROUND(Z5,3) -> 0.628 | AF5: =ROUND(AA5,3) -> 2.533 | AG5: =ROUND(AB5,3) -> 0.116 | AH5: =ROUND(AC5,3) -> 2.329 | AJ5: European Union - 27 countries (from 2020) | AK5: CO2e | AL5: =VLOOKUP($AJ5,Landcover!$A$3:$K$30,5,FALSE)/1000 -> 998.508 | AM5: =VLOOKUP($AJ5,Landcover!$A$3:$K$30,6,FALSE)/1000 -> 1695.726 | AN5: =VLOOKUP($AJ5,Landcover!$A$3:$K$30,8,FALSE)/1000 -> 717.135 | AO5: =VLOOKUP($AJ5,Landcover!$A$3:$K$30,11,FALSE)/1000 -> 71.643 | AP5: =VLOOKUP($AJ5,Landcover!$A$3:$K$30,7,FALSE)/1000 -> 235.533 | AR5: =SUM('GHG data from Eurostat'!CX11,'GHG data from Eurostat'!DC11,'GHG data from Eurostat'!DG11,'GHG data from Eurostat'!DM11,'GHG data from Eurostat'!DP11,'GHG data from Eurostat'!DV11) -> 167.7186 | AS5: ='GHG data from Eurostat'!DS11+'GHG data from Eurostat'!DT11 -> -200.74669 | AT5: ='GHG data from Eurostat'!EA11+'GHG data from Eurostat'!EB11 -> 36.18317 | AU5: ='GHG data from Eurostat'!ED11 -> 24.86138 | AV5: ='GHG data from Eurostat'!EL11 -> 1.82741 | AW5: =SUM(AR5:AV5) -> 29.84387 | AX5: =AR5/AL5 -> 0.16796921 | AY5: =AS5/AM5 -> -0.11838392 | AZ5: =AT5/AN5 -> 0.050455172 | BA5: =AU5/AO5 -> 0.34701757 | BB5: =AV5/AP5 -> 0.0077586156 | BD5: =ROUND(AX5,4) -> 0.168 | BE5: =ROUND(AY5,4) -> -0.1184 | BF5: =ROUND(AZ5,4) -> 0.0505 | BG5: =ROUND(BA5,4) -> 0.347 | BH5: =ROUND(BB5,4) -> 0.0078 | BJ5: =AJ5 -> European Union - 27 countries (from 2020) | BK5: **CO2e | BL5: ='GHG data from Eurostat'!EP11 -> -40.06697
A6: Belgium | B6: 1.862739 | C6: 2.39809 | D6: 4.281 | E6: 0.015591 | G6: European Union - 27 countries (from 2020) | H6: CO2 | I6: =VLOOKUP($G6,$A$5:$E$32,2,FALSE) -> 43.055568 | J6: =VLOOKUP($G6,$A$5:$E$32,3,FALSE) -> 77.8401 | K6: =VLOOKUP($G6,$A$5:$E$32,4,FALSE) -> 92.451 | L6: =VLOOKUP($G6,$A$5:$E$32,5,FALSE) -> 7.5202 | M6: ='GHG data from Eurostat'!CP12 -> 0 | N6: ='GHG data from Eurostat'!CN12 -> 0 | O6: ='GHG data from Eurostat'!CQ12 -> 0 | P6: ='GHG data from Eurostat'!CO12 -> 0 | Q6: ='GHG data from Eurostat'!CU12 -> 0 | R6: =IFERROR(('GHG data from Eurostat'!CS12+'GHG data from Eurostat'!CW12),0) -> 0 | S6: ='GHG data from Eurostat'!CV12 -> 0 | T6: ='GHG data from Eurostat'!CT12 -> 0 | U6: =Q6+M6 -> 0 | V6: =R6+N6 -> 0 | W6: =S6+O6 -> 0 | X6: =T6+P6 -> 0 | Y6: =SUM(U6:X6) -> 0 | Z6: =(M6+Q6)/I6 -> 0 | AA6: =(N6+R6)/J6 -> 0 | AB6: =(O6+S6)/K6 -> 0 | AC6: =(P6+T6)/L6 -> 0 | AE6: =ROUND(Z6,3) -> 0 | AF6: =ROUND(AA6,3) -> 0 | AG6: =ROUND(AB6,3) -> 0 | AH6: =ROUND(AC6,3) -> 0 | AJ6: European Union - 27 countries (from 2020) | AK6: CO2 | AL6: =VLOOKUP($AJ6,Landcover!$A$3:$K$30,5,FALSE)/1000 -> 998.508 | AM6: =VLOOKUP($AJ6,Landcover!$A$3:$K$30,6,FALSE)/1000 -> 1695.726 | AN6: =VLOOKUP($AJ6,Landcover!$A$3:$K$30,8,FALSE)/1000 -> 717.135 | AO6: =VLOOKUP($AJ6,Landcover!$A$3:$K$30,11,FALSE)/1000 -> 71.643 | AP6: =VLOOKUP($AJ6,Landcover!$A$3:$K$30,7,FALSE)/1000 -> 235.533 | AR6: =SUM('GHG data from Eurostat'!CX12,'GHG data from Eurostat'!DC12,'GHG data from Eurostat'!DG12,'GHG data from Eurostat'!DM12,'GHG data from Eurostat'!DP12,'GHG data from Eurostat'!DV12) -> 41.82559 | AS6: ='GHG data from Eurostat'!DS12+'GHG data from Eurostat'!DT12 -> -212.82178 | AT6: ='GHG data from Eurostat'!EA12+'GHG data from Eurostat'!EB12 -> 30.80362 | AU6: ='GHG data from Eurostat'!ED12 -> 16.21766 | AV6: ='GHG data from Eurostat'!EL12 -> 1.78089 | AW6: =SUM(AR6:AV6) -> -122.19402 | AX6: =AR6/AL6 -> 0.041888087 | AY6: =AS6/AM6 -> -0.12550482 | AZ6: =AT6/AN6 -> 0.042953726 | BA6: =AU6/AO6 -> 0.22636768 | BB6: =AV6/AP6 -> 0.0075611061 | BD6: =ROUND(AX6,4) -> 0.0419 | BE6: =ROUND(AY6,4) -> -0.1255 | BF6: =ROUND(AZ6,4) -> 0.043 | BG6: =ROUND(BA6,4) -> 0.2264 | BH6: =ROUND(BB6,4) -> 0.0076 | BJ6: =AJ6 -> European Union - 27 countries (from 2020) | BK6: **CO2 | BL6: ='GHG data from Eurostat'!EP12 -> -40.06697
A7: Bulgaria | B7: 0.196365 | C7: 0.54212 | D7: 0.844 | E7: 0.162177 | G7: European Union - 27 countries (from 2020) | H7: CH4 | I7: =VLOOKUP($G7,$A$5:$E$32,2,FALSE) -> 43.055568 | J7: =VLOOKUP($G7,$A$5:$E$32,3,FALSE) -> 77.8401 | K7: =VLOOKUP($G7,$A$5:$E$32,4,FALSE) -> 92.451 | L7: =VLOOKUP($G7,$A$5:$E$32,5,FALSE) -> 7.5202 | M7: ='GHG data from Eurostat'!CP13 -> 0.16238 | N7: ='GHG data from Eurostat'!CN13 -> 5.67349 | O7: ='GHG data from Eurostat'!CQ13 -> 0.22816 | P7: ='GHG data from Eurostat'!CO13 -> 0.5765 | Q7: ='GHG data from Eurostat'!CU13 -> 0.7392 | R7: =IFERROR(('GHG data from Eurostat'!CS13+'GHG data from Eurostat'!CW13),0) -> 0.83075 | S7: ='GHG data from Eurostat'!CV13 -> 0.08978 | T7: ='GHG data from Eurostat'!CT13 -> 0.0299 | U7: =(Q7+M7)*1000 -> 901.58 | V7: =(R7+N7)*1000 -> 6504.24 | W7: =(S7+O7)*1000 -> 317.94 | X7: =(T7+P7)*1000 -> 606.4 | Y7: =SUM(U7:X7) -> 8330.16 | Z7: =IFERROR((M7+Q7)*1000/I7,0) -> 20.939917 | AA7: =IFERROR((N7+R7)*1000/J7,0) -> 83.558988 | AB7: =IFERROR((O7+S7)*1000/K7,0) -> 3.4390109 | AC7: =IFERROR((P7+T7)*1000/L7,0) -> 80.636153 | AE7: =ROUND(Z7,3) -> 20.94 | AF7: =ROUND(AA7,3) -> 83.559 | AG7: =ROUND(AB7,3) -> 3.439 | AH7: =ROUND(AC7,3) -> 80.636 | AJ7: European Union - 27 countries (from 2020) | AK7: CH4 | AL7: =VLOOKUP($AJ7,Landcover!$A$3:$K$30,5,FALSE)/1000 -> 998.508 | AM7: =VLOOKUP($AJ7,Landcover!$A$3:$K$30,6,FALSE)/1000 -> 1695.726 | AN7: =VLOOKUP($AJ7,Landcover!$A$3:$K$30,8,FALSE)/1000 -> 717.135 | AO7: =VLOOKUP($AJ7,Landcover!$A$3:$K$30,11,FALSE)/1000 -> 71.643 | AP7: =VLOOKUP($AJ7,Landcover!$A$3:$K$30,7,FALSE)/1000 -> 235.533 | AR7: =SUM('GHG data from Eurostat'!CX13,'GHG data from Eurostat'!DC13,'GHG data from Eurostat'!DG13,'GHG data from Eurostat'!DM13,'GHG data from Eurostat'!DP13,'GHG data from Eurostat'!DV13) -> 0.20305 | AS7: ='GHG data from Eurostat'!DS13+'GHG data from Eurostat'!DT13 -> 0.12082 | AT7: ='GHG data from Eurostat'!EA13+'GHG data from Eurostat'!EB13 -> 0.18393 | AU7: ='GHG data from Eurostat'!ED13 -> 0.29835 | AV7: ='GHG data from Eurostat'!EL13 -> 1e-05 | AW7: =SUM(AR7:AV7) -> 0.80616 | AX7: =IFERROR(AR7*1000/AL7,0) -> 0.2033534 | AY7: =IFERROR(AS7*1000/AM7,0) -> 0.071249718 | AZ7: =IFERROR(AT7*1000/AN7,0) -> 0.25647891 | BA7: =IFERROR(AU7*1000/AO7,0) -> 4.1643985 | BB7: =IFERROR(AV7*1000/AP7,0) -> 4.2456896e-05 | BD7: =ROUND(AX7,4) -> 0.2034 | BE7: =ROUND(AY7,4) -> 0.0712 | BF7: =ROUND(AZ7,4) -> 0.2565 | BG7: =ROUND(BA7,4) -> 4.1644 | BH7: =ROUND(BB7,4) -> 0 | BJ7: =AJ7 -> European Union - 27 countries (from 2020) | BK7: **CH4 | BL7: ='GHG data from Eurostat'!EP13 -> 0
A8: Czechia | B8: 0.452274 | C8: 1.36524 | D8: 1.694 | E8: 0.024228 | G8: European Union - 27 countries (from 2020) | H8: N2O | I8: =VLOOKUP($G8,$A$5:$E$32,2,FALSE) -> 43.055568 | J8: =VLOOKUP($G8,$A$5:$E$32,3,FALSE) -> 77.8401 | K8: =VLOOKUP($G8,$A$5:$E$32,4,FALSE) -> 92.451 | L8: =VLOOKUP($G8,$A$5:$E$32,5,FALSE) -> 7.5202 | M8: ='GHG data from Eurostat'!CP14 -> 0 | N8: ='GHG data from Eurostat'!CN14 -> 0 | O8: ='GHG data from Eurostat'!CQ14 -> 0 | P8: ='GHG data from Eurostat'!CO14 -> 0 | Q8: ='GHG data from Eurostat'!CU14 -> 0.00676 | R8: =IFERROR(('GHG data from Eurostat'!CS14+'GHG data from Eurostat'!CW14),0) -> 0.0567 | S8: ='GHG data from Eurostat'!CV14 -> 0.00672 | T8: ='GHG data from Eurostat'!CT14 -> 0.00202 | U8: =(Q8+M8)*1000 -> 6.76 | V8: =(R8+N8)*1000 -> 56.7 | W8: =(S8+O8)*1000 -> 6.72 | X8: =(T8+P8)*1000 -> 2.02 | Y8: =SUM(U8:X8) -> 72.2 | Z8: =IFERROR((M8+Q8)*1000/I8,0) -> 0.15700641 | AA8: =IFERROR((N8+R8)*1000/J8,0) -> 0.72841633 | AB8: =IFERROR((O8+S8)*1000/K8,0) -> 0.072687153 | AC8: =IFERROR((P8+T8)*1000/L8,0) -> 0.26860988 | AE8: =ROUND(Z8,3) -> 0.157 | AF8: =ROUND(AA8,3) -> 0.728 | AG8: =ROUND(AB8,3) -> 0.073 | AH8: =ROUND(AC8,3) -> 0.269 | AJ8: European Union - 27 countries (from 2020) | AK8: N2O | AL8: =VLOOKUP($AJ8,Landcover!$A$3:$K$30,5,FALSE)/1000 -> 998.508 | AM8: =VLOOKUP($AJ8,Landcover!$A$3:$K$30,6,FALSE)/1000 -> 1695.726 | AN8: =VLOOKUP($AJ8,Landcover!$A$3:$K$30,8,FALSE)/1000 -> 717.135 | AO8: =VLOOKUP($AJ8,Landcover!$A$3:$K$30,11,FALSE)/1000 -> 71.643 | AP8: =VLOOKUP($AJ8,Landcover!$A$3:$K$30,7,FALSE)/1000 -> 235.533 | AR8: =SUM('GHG data from Eurostat'!CX14,'GHG data from Eurostat'!DC14,'GHG data from Eurostat'!DG14,'GHG data from Eurostat'!DM14,'GHG data from Eurostat'!DP14,'GHG data from Eurostat'!DV14) -> 0.45361 | AS8: ='GHG data from Eurostat'!DS14+'GHG data from Eurostat'!DT14 -> 0.0328 | AT8: ='GHG data from Eurostat'!EA14+'GHG data from Eurostat'!EB14 -> 0.00087 | AU8: ='GHG data from Eurostat'!ED14 -> 0.00109 | AV8: ='GHG data from Eurostat'!EL14 -> 0.00017 | AW8: =SUM(AR8:AV8) -> 0.48854 | AX8: =IFERROR(AR8*1000/AL8,0) -> 0.4542878 | AY8: =IFERROR(AS8*1000/AM8,0) -> 0.019342748 | AZ8: =IFERROR(AT8*1000/AN8,0) -> 0.0012131607 | BA8: =IFERROR(AU8*1000/AO8,0) -> 0.015214327 | BB8: =IFERROR(AV8*1000/AP8,0) -> 0.00072176723 | BD8: =ROUND(AX8,4) -> 0.4543 | BE8: =ROUND(AY8,4) -> 0.0193 | BF8: =ROUND(AZ8,4) -> 0.0012 | BG8: =ROUND(BA8,4) -> 0.0152 | BH8: =ROUND(BB8,4) -> 0.0007 | BJ8: =AJ8 -> European Union - 27 countries (from 2020) | BK8: **N2O | BL8: ='GHG data from Eurostat'!EP14 -> 0
A9: Denmark | B9: 3.7926 | C9: 1.53 | D9: 1.458 | E9: 0.015681 | G9: Belgium | H9: CO2e | I9: =VLOOKUP($G9,$A$5:$E$32,2,FALSE) -> 1.862739 | J9: =VLOOKUP($G9,$A$5:$E$32,3,FALSE) -> 2.39809 | K9: =VLOOKUP($G9,$A$5:$E$32,4,FALSE) -> 4.281 | L9: =VLOOKUP($G9,$A$5:$E$32,5,FALSE) -> 0.015591 | M9: ='GHG data from Eurostat'!CP15 -> 0.26645 | N9: ='GHG data from Eurostat'!CN15 -> 4.19159 | O9: ='GHG data from Eurostat'!CQ15 -> 0.05312 | P9: ='GHG data from Eurostat'!CO15 -> 0.0221 | Q9: ='GHG data from Eurostat'!CU15 -> 0.63903 | R9: =IFERROR(('GHG data from Eurostat'!CS15+'GHG data from Eurostat'!CW15),0) -> 1.11613 | S9: ='GHG data from Eurostat'!CV15 -> 0.05793 | T9: ='GHG data from Eurostat'!CT15 -> 0.00132 | U9: =Q9+M9 -> 0.90548 | V9: =R9+N9 -> 5.30772 | W9: =S9+O9 -> 0.11105 | X9: =T9+P9 -> 0.02342 | Y9: =SUM(U9:X9) -> 6.34767 | Z9: =(M9+Q9)/I9 -> 0.48610138 | AA9: =(N9+R9)/J9 -> 2.2133114 | AB9: =(O9+S9)/K9 -> 0.025940201 | AC9: =(P9+T9)/L9 -> 1.5021487 | AE9: =ROUND(Z9,3) -> 0.486 | AF9: =ROUND(AA9,3) -> 2.213 | AG9: =ROUND(AB9,3) -> 0.026 | AH9: =ROUND(AC9,3) -> 1.502 | AJ9: Belgium | AK9: CO2e | AL9: =VLOOKUP($AJ9,Landcover!$A$3:$K$30,5,FALSE)/1000 -> 8.914 | AM9: =VLOOKUP($AJ9,Landcover!$A$3:$K$30,6,FALSE)/1000 -> 8.113 | AN9: =VLOOKUP($AJ9,Landcover!$A$3:$K$30,8,FALSE)/1000 -> 8.633 | AO9: =VLOOKUP($AJ9,Landcover!$A$3:$K$30,11,FALSE)/1000 -> 0.139 | AP9: =VLOOKUP($AJ9,Landcover!$A$3:$K$30,7,FALSE)/1000 -> 0.39 | AR9: =SUM('GHG data from Eurostat'!CX15,'GHG data from Eurostat'!DC15,'GHG data from Eurostat'!DG15,'GHG data from Eurostat'!DM15,'GHG data from Eurostat'!DP15,'GHG data from Eurostat'!DV15) -> 3.4643 | AS9: ='GHG data from Eurostat'!DS15+'GHG data from Eurostat'!DT15 -> -1.45014 | AT9: ='GHG data from Eurostat'!EA15+'GHG data from Eurostat'!EB15 -> 0.11387 | AU9: ='GHG data from Eurostat'!ED15 -> 0.00835 | AV9: ='GHG data from Eurostat'!EL15 -> 0 | AW9: =SUM(AR9:AV9) -> 2.13638 | AX9: =AR9/AL9 -> 0.38863585 | AY9: =AS9/AM9 -> -0.17874276 | AZ9: =AT9/AN9 -> 0.013190085 | BA9: =AU9/AO9 -> 0.060071942 | BB9: =AV9/AP9 -> 0 | BD9: =ROUND(AX9,4) -> 0.3886 | BE9: =ROUND(AY9,4) -> -0.1787 | BF9: =ROUND(AZ9,4) -> 0.0132 | BG9: =ROUND(BA9,4) -> 0.0601 | BH9: =ROUND(BB9,4) -> 0 | BJ9: =AJ9 -> Belgium | BK9: **CO2e | BL9: ='GHG data from Eurostat'!EP15 -> -0.08964
A10: Germany | B10: 7.93362 | C10: 11.94909 | D10: 9.935 | E10: 0.17159 | G10: Belgium | H10: CO2 | I10: =VLOOKUP($G10,$A$5:$E$32,2,FALSE) -> 1.862739 | J10: =VLOOKUP($G10,$A$5:$E$32,3,FALSE) -> 2.39809 | K10: =VLOOKUP($G10,$A$5:$E$32,4,FALSE) -> 4.281 | L10: =VLOOKUP($G10,$A$5:$E$32,5,FALSE) -> 0.015591 | M10: ='GHG data from Eurostat'!CP16 -> 0 | N10: ='GHG data from Eurostat'!CN16 -> 0 | O10: ='GHG data from Eurostat'!CQ16 -> 0 | P10: ='GHG data from Eurostat'!CO16 -> 0 | Q10: ='GHG data from Eurostat'!CU16 -> 0 | R10: =IFERROR(('GHG data from Eurostat'!CS16+'GHG data from Eurostat'!CW16),0) -> 0 | S10: ='GHG data from Eurostat'!CV16 -> 0 | T10: ='GHG data from Eurostat'!CT16 -> 0 | U10: =Q10+M10 -> 0 | V10: =R10+N10 -> 0 | W10: =S10+O10 -> 0 | X10: =T10+P10 -> 0 | Y10: =SUM(U10:X10) -> 0 | Z10: =(M10+Q10)/I10 -> 0 | AA10: =(N10+R10)/J10 -> 0 | AB10: =(O10+S10)/K10 -> 0 | AC10: =(P10+T10)/L10 -> 0 | AE10: =ROUND(Z10,3) -> 0 | AF10: =ROUND(AA10,3) -> 0 | AG10: =ROUND(AB10,3) -> 0 | AH10: =ROUND(AC10,3) -> 0 | AJ10: Belgium | AK10: CO2 | AL10: =VLOOKUP($AJ10,Landcover!$A$3:$K$30,5,FALSE)/1000 -> 8.914 | AM10: =VLOOKUP($AJ10,Landcover!$A$3:$K$30,6,FALSE)/1000 -> 8.113 | AN10: =VLOOKUP($AJ10,Landcover!$A$3:$K$30,8,FALSE)/1000 -> 8.633 | AO10: =VLOOKUP($AJ10,Landcover!$A$3:$K$30,11,FALSE)/1000 -> 0.139 | AP10: =VLOOKUP($AJ10,Landcover!$A$3:$K$30,7,FALSE)/1000 -> 0.39 | AR10: =SUM('GHG data from Eurostat'!CX16,'GHG data from Eurostat'!DC16,'GHG data from Eurostat'!DG16,'GHG data from Eurostat'!DM16,'GHG data from Eurostat'!DP16,'GHG data from Eurostat'!DV16) -> 0.94634 | AS10: ='GHG data from Eurostat'!DS16+'GHG data from Eurostat'!DT16 -> -1.45014 | AT10: ='GHG data from Eurostat'!EA16+'GHG data from Eurostat'!EB16 -> 0.11387 | AU10: ='GHG data from Eurostat'!ED16 -> 0.00816 | AV10: ='GHG data from Eurostat'!EL16 -> 0 | AW10: =SUM(AR10:AV10) -> -0.38177 | AX10: =AR10/AL10 -> 0.10616334 | AY10: =AS10/AM10 -> -0.17874276 | AZ10: =AT10/AN10 -> 0.013190085 | BA10: =AU10/AO10 -> 0.058705036 | BB10: =AV10/AP10 -> 0 | BD10: =ROUND(AX10,4) -> 0.1062 | BE10: =ROUND(AY10,4) -> -0.1787 | BF10: =ROUND(AZ10,4) -> 0.0132 | BG10: =ROUND(BA10,4) -> 0.0587 | BH10: =ROUND(BB10,4) -> 0 | BJ10: =AJ10 -> Belgium | BK10: **CO2 | BL10: ='GHG data from Eurostat'!EP16 -> -0.08964
A11: Estonia | B11: 0.08712 | C11: 0.2519 | D11: 0.341 | E11: 0.00783 | G11: Belgium | H11: CH4 | I11: =VLOOKUP($G11,$A$5:$E$32,2,FALSE) -> 1.862739 | J11: =VLOOKUP($G11,$A$5:$E$32,3,FALSE) -> 2.39809 | K11: =VLOOKUP($G11,$A$5:$E$32,4,FALSE) -> 4.281 | L11: =VLOOKUP($G11,$A$5:$E$32,5,FALSE) -> 0.015591 | M11: ='GHG data from Eurostat'!CP17 -> 0.00952 | N11: ='GHG data from Eurostat'!CN17 -> 0.1497 | O11: ='GHG data from Eurostat'!CQ17 -> 0.0019 | P11: ='GHG data from Eurostat'!CO17 -> 0.00079 | Q11: ='GHG data from Eurostat'!CU17 -> 0.0214 | R11: =IFERROR(('GHG data from Eurostat'!CS17+'GHG data from Eurostat'!CW17),0) -> 0.02695 | S11: ='GHG data from Eurostat'!CV17 -> 0.00139 | T11: ='GHG data from Eurostat'!CT17 -> 2e-05 | U11: =(Q11+M11)*1000 -> 30.92 | V11: =(R11+N11)*1000 -> 176.65 | W11: =(S11+O11)*1000 -> 3.29 | X11: =(T11+P11)*1000 -> 0.81 | Y11: =SUM(U11:X11) -> 211.67 | Z11: =IFERROR((M11+Q11)*1000/I11,0) -> 16.599212 | AA11: =IFERROR((N11+R11)*1000/J11,0) -> 73.66279 | AB11: =IFERROR((O11+S11)*1000/K11,0) -> 0.76851203 | AC11: =IFERROR((P11+T11)*1000/L11,0) -> 51.95305 | AE11: =ROUND(Z11,3) -> 16.599 | AF11: =ROUND(AA11,3) -> 73.663 | AG11: =ROUND(AB11,3) -> 0.769 | AH11: =ROUND(AC11,3) -> 51.953 | AJ11: Belgium | AK11: CH4 | AL11: =VLOOKUP($AJ11,Landcover!$A$3:$K$30,5,FALSE)/1000 -> 8.914 | AM11: =VLOOKUP($AJ11,Landcover!$A$3:$K$30,6,FALSE)/1000 -> 8.113 | AN11: =VLOOKUP($AJ11,Landcover!$A$3:$K$30,8,FALSE)/1000 -> 8.633 | AO11: =VLOOKUP($AJ11,Landcover!$A$3:$K$30,11,FALSE)/1000 -> 0.139 | AP11: =VLOOKUP($AJ11,Landcover!$A$3:$K$30,7,FALSE)/1000 -> 0.39 | AR11: =SUM('GHG data from Eurostat'!CX17,'GHG data from Eurostat'!DC17,'GHG data from Eurostat'!DG17,'GHG data from Eurostat'!DM17,'GHG data from Eurostat'!DP17,'GHG data from Eurostat'!DV17) -> 0 | AS11: ='GHG data from Eurostat'!DS17+'GHG data from Eurostat'!DT17 -> 0 | AT11: ='GHG data from Eurostat'!EA17+'GHG data from Eurostat'!EB17 -> 0 | AU11: ='GHG data from Eurostat'!ED17 -> 0 | AV11: ='GHG data from Eurostat'!EL17 -> 0 | AW11: =SUM(AR11:AV11) -> 0 | AX11: =IFERROR(AR11*1000/AL11,0) -> 0 | AY11: =IFERROR(AS11*1000/AM11,0) -> 0 | AZ11: =IFERROR(AT11*1000/AN11,0) -> 0 | BA11: =IFERROR(AU11*1000/AO11,0) -> 0 | BB11: =IFERROR(AV11*1000/AP11,0) -> 0 | BD11: =ROUND(AX11,4) -> 0 | BE11: =ROUND(AY11,4) -> 0 | BF11: =ROUND(AZ11,4) -> 0 | BG11: =ROUND(BA11,4) -> 0 | BH11: =ROUND(BB11,4) -> 0 | BJ11: =AJ11 -> Belgium | BK11: **CH4 | BL11: ='GHG data from Eurostat'!EP17 -> 0
A12: Ireland | B12: 0.471645 | C12: 6.59349 | D12: 1.38 | E12: 0.380725 | G12: Belgium | H12: N2O | I12: =VLOOKUP($G12,$A$5:$E$32,2,FALSE) -> 1.862739 | J12: =VLOOKUP($G12,$A$5:$E$32,3,FALSE) -> 2.39809 | K12: =VLOOKUP($G12,$A$5:$E$32,4,FALSE) -> 4.281 | L12: =VLOOKUP($G12,$A$5:$E$32,5,FALSE) -> 0.015591 | M12: ='GHG data from Eurostat'!CP18 -> 0 | N12: ='GHG data from Eurostat'!CN18 -> 0 | O12: ='GHG data from Eurostat'!CQ18 -> 0 | P12: ='GHG data from Eurostat'!CO18 -> 0 | Q12: ='GHG data from Eurostat'!CU18 -> 0.00015 | R12: =IFERROR(('GHG data from Eurostat'!CS18+'GHG data from Eurostat'!CW18),0) -> 0.00137 | S12: ='GHG data from Eurostat'!CV18 -> 7e-05 | T12: ='GHG data from Eurostat'!CT18 -> 0 | U12: =(Q12+M12)*1000 -> 0.15 | V12: =(R12+N12)*1000 -> 1.37 | W12: =(S12+O12)*1000 -> 0.07 | X12: =(T12+P12)*1000 -> 0 | Y12: =SUM(U12:X12) -> 1.59 | Z12: =IFERROR((M12+Q12)*1000/I12,0) -> 0.080526579 | AA12: =IFERROR((N12+R12)*1000/J12,0) -> 0.57128798 | AB12: =IFERROR((O12+S12)*1000/K12,0) -> 0.01635132 | AC12: =IFERROR((P12+T12)*1000/L12,0) -> 0 | AE12: =ROUND(Z12,3) -> 0.081 | AF12: =ROUND(AA12,3) -> 0.571 | AG12: =ROUND(AB12,3) -> 0.016 | AH12: =ROUND(AC12,3) -> 0 | AJ12: Belgium | AK12: N2O | AL12: =VLOOKUP($AJ12,Landcover!$A$3:$K$30,5,FALSE)/1000 -> 8.914 | AM12: =VLOOKUP($AJ12,Landcover!$A$3:$K$30,6,FALSE)/1000 -> 8.113 | AN12: =VLOOKUP($AJ12,Landcover!$A$3:$K$30,8,FALSE)/1000 -> 8.633 | AO12: =VLOOKUP($AJ12,Landcover!$A$3:$K$30,11,FALSE)/1000 -> 0.139 | AP12: =VLOOKUP($AJ12,Landcover!$A$3:$K$30,7,FALSE)/1000 -> 0.39 | AR12: =SUM('GHG data from Eurostat'!CX18,'GHG data from Eurostat'!DC18,'GHG data from Eurostat'!DG18,'GHG data from Eurostat'!DM18,'GHG data from Eurostat'!DP18,'GHG data from Eurostat'!DV18) -> 0.0095 | AS12: ='GHG data from Eurostat'!DS18+'GHG data from Eurostat'!DT18 -> 0 | AT12: ='GHG data from Eurostat'!EA18+'GHG data from Eurostat'!EB18 -> 0 | AU12: ='GHG data from Eurostat'!ED18 -> 0 | AV12: ='GHG data from Eurostat'!EL18 -> 0 | AW12: =SUM(AR12:AV12) -> 0.0095 | AX12: =IFERROR(AR12*1000/AL12,0) -> 1.0657393 | AY12: =IFERROR(AS12*1000/AM12,0) -> 0 | AZ12: =IFERROR(AT12*1000/AN12,0) -> 0 | BA12: =IFERROR(AU12*1000/AO12,0) -> 0 | BB12: =IFERROR(AV12*1000/AP12,0) -> 0 | BD12: =ROUND(AX12,4) -> 1.0657 | BE12: =ROUND(AY12,4) -> 0 | BF12: =ROUND(AZ12,4) -> 0 | BG12: =ROUND(BA12,4) -> 0 | BH12: =ROUND(BB12,4) -> 0 | BJ12: =AJ12 -> Belgium | BK12: **N2O | BL12: ='GHG data from Eurostat'!EP18 -> 0
