Workbook

Sheet Fertiliser_data
A1: Source: | B1: https://doi.org/10.5061/dryad.59zw3r2mq | J1: N % in Ammonium Nitrate (common N fertliser product in the EU) | K1: P % in DAP (common P fertliser product) | L1: K% in MOP (common K fertliser product)
J2: 0.335 | K2: 0.2 | L2: 0.5
A3: There is some imputation of values which seems mostly sensible. For crops that account for smaller areas the values can sometimes
A4: a bit strange. Nuts in particular do not seem to be well covered. But this provides a good start which covers all countries and crops.
A6: Crop Code | B6: Crop | C6: Country | D6: CC | F6: N (kg/ha) | G6: P (kg/ha) | H6: K (kg/ha) | I6: Urea (kg/ha) - application rates | J6: SSP (kg/ha) application rates | K6: MOP (kg/ha) application rates | L6: Total fertiliser application (Mt/1000sqkm)
A7: BRL | B7: Barley | C7: Austria | D7: =VLOOKUP(C7,cc!$A$2:$B$28,2,FALSE) -> AT | E7: =CONCATENATE(D7,A7) -> ATBRL | F7: 59 | G7: 4 | H7: 9 | I7: =F7/$J$2 -> 176.1194 | J7: =G7/$K$2 -> 20 | K7: =H7/$L$2 -> 18 | L7: =(I7+J7+K7)*0.0001 -> 0.02141194
A8: GRP | B8: Grapes | C8: Austria | D8: =VLOOKUP(C8,cc!$A$2:$B$28,2,FALSE) -> AT | E8: =CONCATENATE(D8,A8) -> ATGRP | F8: 36 | G8: 5 | H8: 11 | I8: =F8/$J$2 -> 107.46269 | J8: =G8/$K$2 -> 25 | K8: =H8/$L$2 -> 22 | L8: =(I8+J8+K8)*0.0001 -> 0.015446269
A9: MAI | B9: Maize (corn) | C9: Austria | D9: =VLOOKUP(C9,cc!$A$2:$B$28,2,FALSE) -> AT | E9: =CONCATENATE(D9,A9) -> ATMAI | F9: 115 | G9: 19 | H9: 39 | I9: =F9/$J$2 -> 343.28358 | J9: =G9/$K$2 -> 95 | K9: =H9/$L$2 -> 78 | L9: =(I9+J9+K9)*0.0001 -> 0.051628358
A10: MOS | B10: Minor Oil Seeds | C10: Austria | D10: =VLOOKUP(C10,cc!$A$2:$B$28,2,FALSE) -> AT | E10: =CONCATENATE(D10,A10) -> ATMOS | F10: 28 | G10: 4 | H10: 8 | I10: =F10/$J$2 -> 83.58209 | J10: =G10/$K$2 -> 20 | K10: =H10/$L$2 -> 16 | L10: =(I10+J10+K10)*0.0001 -> 0.011958209
A11: RAP | B11: Rape or colza seed | C11: Austria | D11: =VLOOKUP(C11,cc!$A$2:$B$28,2,FALSE) -> AT | E11: =CONCATENATE(D11,A11) -> ATRAP | F11: 128 | G11: 11 | H11: 28 | I11: =F11/$J$2 -> 382.08955 | J11: =G11/$K$2 -> 55 | K11: =H11/$L$2 -> 56 | L11: =(I11+J11+K11)*0.0001 -> 0.049308955
A12: RYE | B12: Rye | C12: Austria | D12: =VLOOKUP(C12,cc!$A$2:$B$28,2,FALSE) -> AT | E12: =CONCATENATE(D12,A12) -> ATRYE | F12: 59 | G12: 4 | H12: 9 | I12: =F12/$J$2 -> 176.1194 | J12: =G12/$K$2 -> 20 | K12: =H12/$L$2 -> 18 | L12: =(I12+J12+K12)*0.0001 -> 0.02141194
A13: SOY | B13: Soya beans | C13: Austria | D13: =VLOOKUP(C13,cc!$A$2:$B$28,2,FALSE) -> AT | E13: =CONCATENATE(D13,A13) -> ATSOY | F13: 26 | G13: 12 | H13: 28 | I13: =F13/$J$2 -> 77.61194 | J13: =G13/$K$2 -> 60 | K13: =H13/$L$2 -> 56 | L13: =(I13+J13+K13)*0.0001 -> 0.019361194
A14: SUG | B14: Sugar beet | C14: Austria | D14: =VLOOKUP(C14,cc!$A$2:$B$28,2,FALSE) -> AT | E14: =CONCATENATE(D14,A14) -> ATSUG | F14: 88 | G14: 20 | H14: 49 | I14: =F14/$J$2 -> 262.68657 | J14: =G14/$K$2 -> 100 | K14: =H14/$L$2 -> 98 | L14: =(I14+J14+K14)*0.0001 -> 0.046068657
A15: TRT | B15: Triticale | C15: Austria | D15: =VLOOKUP(C15,cc!$A$2:$B$28,2,FALSE) -> AT | E15: =CONCATENATE(D15,A15) -> ATTRT | F15: 59 | G15: 4 | H15: 9 | I15: =F15/$J$2 -> 176.1194 | J15: =G15/$K$2 -> 20 | K15: =H15/$L$2 -> 18 | L15: =(I15+J15+K15)*0.0001 -> 0.02141194
A16: WHE | B16: Wheat | C16: Austria | D16: =VLOOKUP(C16,cc!$A$2:$B$28,2,FALSE) -> AT | E16: =CONCATENATE(D16,A16) -> ATWHE | F16: 118 | G16: 4 | H16: 12 | I16: =F16/$J$2 -> 352.23881 | J16: =G16/$K$2 -> 20 | K16: =H16/$L$2 -> 24 | L16: =(I16+J16+K16)*0.0001 -> 0.039623881
A17: BRL | B17: Barley | C17: Belgium | D17: =VLOOKUP(C17,cc!$A$2:$B$28,2,FALSE) -> BE | E17: =CONCATENATE(D17,A17) -> BEBRL | F17: 130 | G17: 2 | H17: 22 | I17: =F17/$J$2 -> 388.0597 | J17: =G17/$K$2 -> 10 | K17: =H17/$L$2 -> 44 | L17: =(I17+J17+K17)*0.0001 -> 0.04420597
A18: FLX | B18: Flax, raw or retted | C18: Belgium | D18: =VLOOKUP(C18,cc!$A$2:$B$28,2,FALSE) -> BE | E18: =CONCATENATE(D18,A18) -> BEFLX | F18: 181 | G18: 9 | H18: 86 | I18: =F18/$J$2 -> 540.29851 | J18: =G18/$K$2 -> 45 | K18: =H18/$L$2 -> 172 | L18: =(I18+J18+K18)*0.0001 -> 0.075729851
... A267: TRT | B267: Triticale | C267: Sweden | D267: =VLOOKUP(C267,cc!$A$2:$B$28,2,FALSE) -> SE | E267: =CONCATENATE(D267,A267) -> SETRT | F267: 82 | G267: 5 | H267: 13 | I267: =F267/$J$2 -> 244.77612 | J267: =G267/$K$2 -> 25 | K267: =H267/$L$2 -> 26 | L267: =(I267+J267+K267)*0.0001 -> 0.029577612
A270: Source: | B270: https://doi.org/10.5061/dryad.59zw3r2mq

Sheet cc
A1: Country | B1: ISO2
A2: Austria | B2: AT
A3: Belgium | B3: BE
A4: Bulgaria | B4: BG
A5: Cyprus | B5: CY
A6: Czechia | B6: CZ
A7: Germany | B7: DE
A8: Denmark | B8: DK
A9: Spain | B9: ES
A10: Estonia | B10: EE
A11: Finland | B11: FI
A12: France | B12: FR
... A28: Sweden | B28: SE

Sheet IAR
A1: REGION | B1: TECHNOLOGY | C1: Country | D1: Crop | E1: concatenate | F1: Inpu_level | G1: FUEL | H1: MODE_OF_OPERATION | I1: old data (Mt/1000sqkm) | J1: Concatenate Names | K1: Total fertiliser application (Mt/1000sqkm) | L1: corrected fertiliser application (Mt/1000sqkm)-231025
A2: EU | B2: ATL000MAIHI0 | C2: =LEFT(B2,2) -> AT | D2: =MID(B2,7,3) -> MAI | E2: =C2&D2 -> ATMAI | F2: =MID(B2,10,1) -> H | G2: ATLFER | H2: 1 | I2: 0.16 | J2: =B2&G2 -> ATL000MAIHI0ATLFER | K2: =_xlfn.IFNA(IF(F2="H",VLOOKUP(E2,Fertiliser_data!$E$7:$L$267,8,FALSE),VLOOKUP(E2,Fertiliser_data!$E$7:$L$267,8,FALSE)*0.65),IF(F2="H",0.038,(0.038*0.65))) -> 0.051628358 | L2: =IF($C2="IE",$K2*CF_231025!$E$16,$K2/VLOOKUP($C2,CF_231025!$A$2:$E$28,5,FALSE)) -> 0.01302845
A3: EU | B3: ATL000MAIHR0 | C3: =LEFT(B3,2) -> AT | D3: =MID(B3,7,3) -> MAI | E3: =C3&D3 -> ATMAI | F3: =MID(B3,10,1) -> H | G3: ATLFER | H3: 1 | I3: 0.16 | J3: =B3&G3 -> ATL000MAIHR0ATLFER | K3: =_xlfn.IFNA(IF(F3="H",VLOOKUP(E3,Fertiliser_data!$E$7:$L$267,8,FALSE),VLOOKUP(E3,Fertiliser_data!$E$7:$L$267,8,FALSE)*0.65),IF(F3="H",0.038,(0.038*0.65))) -> 0.051628358 | L3: =IF($C3="IE",$K3*CF_231025!$E$16,$K3/VLOOKUP($C3,CF_231025!$A$2:$E$28,5,FALSE)) -> 0.01302845
A4: EU | B4: ATL000MAILI0 | C4: =LEFT(B4,2) -> AT | D4: =MID(B4,7,3) -> MAI | E4: =C4&D4 -> ATMAI | F4: =MID(B4,10,1) -> L | G4: ATLFER | H4: 1 | I4: 0.06 | J4: =B4&G4 -> ATL000MAILI0ATLFER | K4: =_xlfn.IFNA(IF(F4="H",VLOOKUP(E4,Fertiliser_data!$E$7:$L$267,8,FALSE),VLOOKUP(E4,Fertiliser_data!$E$7:$L$267,8,FALSE)*0.65),IF(F4="H",0.038,(0.038*0.65))) -> 0.033558433 | L4: =IF($C4="IE",$K4*CF_231025!$E$16,$K4/VLOOKUP($C4,CF_231025!$A$2:$E$28,5,FALSE)) -> 0.0084684923
A5: EU | B5: ATL000MAILR0 | C5: =LEFT(B5,2) -> AT | D5: =MID(B5,7,3) -> MAI | E5: =C5&D5 -> ATMAI | F5: =MID(B5,10,1) -> L | G5: ATLFER | H5: 1 | I5: 0.06 | J5: =B5&G5 -> ATL000MAILR0ATLFER | K5: =_xlfn.IFNA(IF(F5="H",VLOOKUP(E5,Fertiliser_data!$E$7:$L$267,8,FALSE),VLOOKUP(E5,Fertiliser_data!$E$7:$L$267,8,FALSE)*0.65),IF(F5="H",0.038,(0.038*0.65))) -> 0.033558433 | L5: =IF($C5="IE",$K5*CF_231025!$E$16,$K5/VLOOKUP($C5,CF_231025!$A$2:$E$28,5,FALSE)) -> 0.0084684923
A6: EU | B6: ATL000RAPHI0 | C6: =LEFT(B6,2) -> AT | D6: =MID(B6,7,3) -> RAP | E6: =C6&D6 -> ATRAP | F6: =MID(B6,10,1) -> H | G6: ATLFER | H6: 1 | I6: 0.26 | J6: =B6&G6 -> ATL000RAPHI0ATLFER | K6: =_xlfn.IFNA(IF(F6="H",VLOOKUP(E6,Fertiliser_data!$E$7:$L$267,8,FALSE),VLOOKUP(E6,Fertiliser_data!$E$7:$L$267,8,FALSE)*0.65),IF(F6="H",0.038,(0.038*0.65))) -> 0.049308955 | L6: =IF($C6="IE",$K6*CF_231025!$E$16,$K6/VLOOKUP($C6,CF_231025!$A$2:$E$28,5,FALSE)) -> 0.012443147
A7: EU | B7: ATL000RAPHR0 | C7: =LEFT(B7,2) -> AT | D7: =MID(B7,7,3) -> RAP | E7: =C7&D7 -> ATRAP | F7: =MID(B7,10,1) -> H | G7: ATLFER | H7: 1 | I7: 0.26 | J7: =B7&G7 -> ATL000RAPHR0ATLFER | K7: =_xlfn.IFNA(IF(F7="H",VLOOKUP(E7,Fertiliser_data!$E$7:$L$267,8,FALSE),VLOOKUP(E7,Fertiliser_data!$E$7:$L$267,8,FALSE)*0.65),IF(F7="H",0.038,(0.038*0.65))) -> 0.049308955 | L7: =IF($C7="IE",$K7*CF_231025!$E$16,$K7/VLOOKUP($C7,CF_231025!$A$2:$E$28,5,FALSE)) -> 0.012443147
A8: EU | B8: ATL000RAPLI0 | C8: =LEFT(B8,2) -> AT | D8: =MID(B8,7,3) -> RAP | E8: =C8&D8 -> ATRAP | F8: =MID(B8,10,1) -> L | G8: ATLFER | H8: 1 | I8: 0.1 | J8: =B8&G8 -> ATL000RAPLI0ATLFER | K8: =_xlfn.IFNA(IF(F8="H",VLOOKUP(E8,Fertiliser_data!$E$7:$L$267,8,FALSE),VLOOKUP(E8,Fertiliser_data!$E$7:$L$267,8,FALSE)*0.65),IF(F8="H",0.038,(0.038*0.65))) -> 0.032050821 | L8: =IF($C8="IE",$K8*CF_231025!$E$16,$K8/VLOOKUP($C8,CF_231025!$A$2:$E$28,5,FALSE)) -> 0.0080880455
A9: EU | B9: ATL000RAPLR0 | C9: =LEFT(B9,2) -> AT | D9: =MID(B9,7,3) -> RAP | E9: =C9&D9 -> ATRAP | F9: =MID(B9,10,1) -> L | G9: ATLFER | H9: 1 | I9: 0.1 | J9: =B9&G9 -> ATL000RAPLR0ATLFER | K9: =_xlfn.IFNA(IF(F9="H",VLOOKUP(E9,Fertiliser_data!$E$7:$L$267,8,FALSE),VLOOKUP(E9,Fertiliser_data!$E$7:$L$267,8,FALSE)*0.65),IF(F9="H",0.038,(0.038*0.65))) -> 0.032050821 | L9: =IF($C9="IE",$K9*CF_231025!$E$16,$K9/VLOOKUP($C9,CF_231025!$A$2:$E$28,5,FALSE)) -> 0.0080880455
A10: EU | B10: ATL000SOYHI0 | C10: =LEFT(B10,2) -> AT | D10: =MID(B10,7,3) -> SOY | E10: =C10&D10 -> ATSOY | F10: =MID(B10,10,1) -> H | G10: ATLFER | H10: 1 | I10: 0.17 | J10: =B10&G10 -> ATL000SOYHI0ATLFER | K10: =_xlfn.IFNA(IF(F10="H",VLOOKUP(E10,Fertiliser_data!$E$7:$L$267,8,FALSE),VLOOKUP(E10,Fertiliser_data!$E$7:$L$267,8,FALSE)*0.65),IF(F10="H",0.038,(0.038*0.65))) -> 0.019361194 | L10: =IF($C10="IE",$K10*CF_231025!$E$16,$K10/VLOOKUP($C10,CF_231025!$A$2:$E$28,5,FALSE)) -> 0.0048858099
A11: EU | B11: ATL000SOYHR0 | C11: =LEFT(B11,2) -> AT | D11: =MID(B11,7,3) -> SOY | E11: =C11&D11 -> ATSOY | F11: =MID(B11,10,1) -> H | G11: ATLFER | H11: 1 | I11: 0.17 | J11: =B11&G11 -> ATL000SOYHR0ATLFER | K11: =_xlfn.IFNA(IF(F11="H",VLOOKUP(E11,Fertiliser_data!$E$7:$L$267,8,FALSE),VLOOKUP(E11,Fertiliser_data!$E$7:$L$267,8,FALSE)*0.65),IF(F11="H",0.038,(0.038*0.65))) -> 0.019361194 | L11: =IF($C11="IE",$K11*CF_231025!$E$16,$K11/VLOOKUP($C11,CF_231025!$A$2:$E$28,5,FALSE)) -> 0.0048858099
A12: EU | B12: ATL000SOYLI0 | C12: =LEFT(B12,2) -> AT | D12: =MID(B12,7,3) -> SOY | E12: =C12&D12 -> ATSOY | F12: =MID(B12,10,1) -> L | G12: ATLFER | H12: 1 | I12: 0.06 | J12: =B12&G12 -> ATL000SOYLI0ATLFER | K12: =_xlfn.IFNA(IF(F12="H",VLOOKUP(E12,Fertiliser_data!$E$7:$L$267,8,FALSE),VLOOKUP(E12,Fertiliser_data!$E$7:$L$267,8,FALSE)*0.65),IF(F12="H",0.038,(0.038*0.65))) -> 0.012584776 | L12: =IF($C12="IE",$K12*CF_231025!$E$16,$K12/VLOOKUP($C12,CF_231025!$A$2:$E$28,5,FALSE)) -> 0.0031757764
A13: EU | B13: ATL000SOYLR0 | C13: =LEFT(B13,2) -> AT | D13: =MID(B13,7,3) -> SOY | E13: =C13&D13 -> ATSOY | F13: =MID(B13,10,1) -> L | G13: ATLFER | H13: 1 | I13: 0.06 | J13: =B13&G13 -> ATL000SOYLR0ATLFER | K13: =_xlfn.IFNA(IF(F13="H",VLOOKUP(E13,Fertiliser_data!$E$7:$L$267,8,FALSE),VLOOKUP(E13,Fertiliser_data!$E$7:$L$267,8,FALSE)*0.65),IF(F13="H",0.038,(0.038*0.65))) -> 0.012584776 | L13: =IF($C13="IE",$K13*CF_231025!$E$16,$K13/VLOOKUP($C13,CF_231025!$A$2:$E$28,5,FALSE)) -> 0.0031757764
... A1081: EU | B1081: SKL000WHELR0 | C1081: =LEFT(B1081,2) -> SK | D1081: =MID(B1081,7,3) -> WHE | E1081: =C1081&D1081 -> SKWHE | F1081: =MID(B1081,10,1) -> L | G1081: SKLFER | H1081: 1 | I1081: 0.07 | J1081: =B1081&G1081 -> SKL000WHELR0SKLFER | K1081: =_xlfn.IFNA(IF(F1081="H",VLOOKUP(E1081,Fertiliser_data!$E$7:$L$267,8,FALSE),VLOOKUP(E1081,Fertiliser_data!$E$7:$L$267,8,FALSE)*0.65),IF(F1081="H",0.038,(0.038*0.65))) -> 0.030163881 | L1081: =IF($C1081="IE",$K1081*CF_231025!$E$16,$K1081/VLOOKUP($C1081,CF_231025!$A$2:$E$28,5,FALSE)) -> 0.0088091614

Sheet CF_231025
C1: actual 2021 | D1: model | E1: CF_231025
A2: AT | B2: Austria | C2: 0.104076 | D2: 0.41242612 | E2: 3.9627399
A3: BE | B3: Belgium | C3: 0.1359689 | D3: 0.3793202 | E3: 2.789757
A4: BG | B4: Bulgaria | C4: 0.374726 | D4: 0.96158656 | E4: 2.5661058
A5: CY | B5: Cyprus | C5: 0.010065333 | D5: 0.096122901 | E5: 9.5498975
A6: CZ | B6: Czechia | C6: 0.325429 | D6: 1.0861572 | E6: 3.3376165
A7: DE | B7: Germany | C7: 1.349387 | D7: 4.2329007 | E7: 3.1369064
A8: DK | B8: Denmark | C8: 0.21724 | D8: 0.74058059 | E8: 3.4090434
A9: EE | B9: Estonia | C9: 0.051724 | D9: 0.16719771 | E9: 3.2324977
A10: ES | B10: Spain | C10: 1.202941 | D10: 3.5769912 | E10: 2.9735383
A11: FI | B11: Finland | C11: 0.158568 | D11: 0.53501226 | E11: 3.3740241
A12: FR | B12: France | C12: 2.152726 | D12: 6.1250518 | E12: 2.8452538
A13: GR | B13: Greece | C13: 0.238826 | D13: 0.70726112 | E13: 2.9614075
... A15: HU | B15: Hungary | C15: 0.506837 | D15: 1.3537733 | E15: 2.671023
A16: IE | B16: Ireland | C16: 0.445232 | D16: 0.21364549 | E16: 2.0839757 | F16: to be multiplied
A17: IT | B17: Italy | C17: 0.672415 | D17: 2.9931131 | E17: 4.4512884
A18: LT | B18: Lithuania | C18: 0.211616 | D18: 0.59210347 | E18: 2.798009
A19: LU | B19: Luxembourg | C19: 0.014347 | D19: 0.023363172 | E19: 1.628436
A20: LV | B20: Latvia | C20: 0.098955 | D20: 0.30607677 | E20: 3.0930905
A21: MT | B21: Malta | C21: 0.00063066667 | D21: 0.0045589715 | E21: 7.2288131
A22: NL | B22: Netherlands | C22: 0.2176 | D22: 0.34390735 | E22: 1.5804566
A23: PL | B23: Poland | C23: 1.194505 | D23: 3.403076 | E23: 2.8489424
A24: PT | B24: Portugal | C24: 0.113598 | D24: 0.3889941 | E24: 3.4243042
A25: RO | B25: Romania | C25: 0.61453 | D25: 1.8232066 | E25: 2.966831
A26: SE | B26: Sweden | C26: 0.2128 | D26: 0.52516724 | E26: 2.4678912
A27: SI | B27: Slovenia | C27: 0.032326 | D27: 0.084731192 | E27: 2.6211468
A28: SK | B28: Slovakia | C28: 0.140531 | D28: 0.48119907 | E28: 3.4241489

Sheet Match_Log
A1: Country | B1: Crop | C1: Matched Crop (source) | D1: Match score | E1: N (kg/ha) | F1: P (kg/ha) | G1: K (kg/ha)
A2: Austria | B2: Barley | C2: Barley | D2: 100 | E2: 59 | F2: 4 | G2: 9
A3: Austria | B3: Grapes | C3: Grapes | D3: 100 | E3: 36 | F3: 5 | G3: 11
A4: Austria | B4: Maize (corn) | C4: Maize | D4: 100 | E4: 115 | F4: 19 | G4: 39
A5: Austria | B5: Minor Oil Seeds
A6: Austria | B6: All other crops
A7: Austria | B7: Rape or colza seed
A8: Austria | B8: Rye | C8: Rye | D8: 100 | E8: 59 | F8: 4 | G8: 9
A9: Austria | B9: Soya beans
A10: Austria | B10: Sugar beet | C10: Sugar beet | D10: 100 | E10: 88 | F10: 20 | G10: 49
A11: Austria | B11: Wheat & Triticale | C11: Wheat | D11: 100 | E11: 118 | F11: 4 | G11: 12
A12: Belgium | B12: Barley | C12: Barley | D12: 100 | E12: 130 | F12: 2 | G12: 22
A13: Belgium | B13: Flax, raw or retted
A14: Belgium | B14: Lettuce and chicory | C14: Lettuce and chicory | D14: 100 | E14: 132 | F14: 17 | G14: 64
A15: Belgium | B15: Maize (corn) | C15: Maize | D15: 100 | E15: 53 | F15: 7 | G15: 19
A16: Belgium | B16: All other crops
A17: Belgium | B17: Peas, green | C17: Peas green | D17: 95.238095 | E17: 135 | F17: 17 | G17: 65
A18: Belgium | B18: Potatoes | C18: Potatoes | D18: 100 | E18: 183 | F18: 15 | G18: 133
A19: Belgium | B19: Rape or colza seed
A20: Belgium | B20: Sugar beet | C20: Sugar beet | D20: 100 | E20: 124 | F20: 12 | G20: 105
A21: Belgium | B21: Wheat & Triticale | C21: Wheat | D21: 100 | E21: 182 | F21: 3 | G21: 19
A22: Bulgaria | B22: Barley | C22: Barley | D22: 100 | E22: 15 | F22: 5 | G22: 1
A23: Bulgaria | B23: Grapes | C23: Grapes | D23: 100 | E23: 15 | F23: 5 | G23: 1
A24: Bulgaria | B24: Maize (corn) | C24: Maize | D24: 100 | E24: 125 | F24: 7 | G24: 12
A25: Bulgaria | B25: All other crops
A26: Bulgaria | B26: Other pulses n.e.c.
A27: Bulgaria | B27: Peas, dry | C27: Peas dry | D27: 94.117647 | E27: 10 | F27: 4 | G27: 5
A28: Bulgaria | B28: Potatoes | C28: Potatoes | D28: 100 | E28: 278 | F28: 82 | G28: 139
A29: Bulgaria | B29: Rape or colza seed
A30: Bulgaria | B30: Sunflower seed | C30: Sunflower seed | D30: 100 | E30: 20 | F30: 5 | G30: 1
A31: Bulgaria | B31: Wheat & Triticale | C31: Wheat | D31: 100 | E31: 119 | F31: 10 | G31: 7
A32: Croatia | B32: Barley | C32: Barley | D32: 100 | E32: 66 | F32: 5 | G32: 12
A33: Croatia | B33: Green corn (maize)
A34: Croatia | B34: Grapes | C34: Grapes | D34: 100 | E34: 36 | F34: 16 | G34: 38
A35: Croatia | B35: Maize (corn) | C35: Maize | D35: 100 | E35: 135 | F35: 12 | G35: 21
A36: Croatia | B36: Olives | C36: Olives | D36: 100 | E36: 54 | F36: 16 | G36: 45
A37: Croatia | B37: All other crops
A38: Croatia | B38: Rape or colza seed
A39: Croatia | B39: Soya beans
A40: Croatia | B40: Sunflower seed | C40: Sunflower seed | D40: 100 | E40: 54 | F40: 16 | G40: 44
...
